Workbook

Sheet Visualisation

Sheet Units
A1: Quantity | B1: Unit | C1: Explanation
A2: =Nodes!J2 -> Old Production Capacity Gas | B2: MSm3/h | C2: Mega (or million) standard cubic metres per hour. One standard cubic meter means the amount of gas which occupies a Cubic Meter at fifteen (15) Degrees Celsius and a pressure of one hundred one decimal three two five (101.325) kPa.
A3: =Nodes!M2 -> Production Costs Gas | B3: NOK / MSm3
A4: =Nodes!N2 -> Storage Capacity Gas | B4: MSm3
A5: =Nodes!O2 -> Entry Storage Costs Gas | B5: NOK / MSm3
A6: =Nodes!P2 -> Entry Costs Gas Stage 1 | B6: NOK / MSm3
A7: =Nodes!Q2 -> Exit Costs Gas Stage 1 | B7: NOK / MSm3
A8: =Arcs!M1 -> Flow costs Gas | B8: NOK / MSm3
A9: =Arcs!#REF! -> #REF! | B9: MSm3/h
A10: Demand | B10: MSm3/h

Sheet Nodes
G1: Gas | V1: Hydrogen
A2: ID | B2: Name | C2: Type | D2: X_coordinate | E2: Y_coordinate | F2: Note | G2: TSO entry costs Gas | H2: TSO exit costs Gas | I2: Production Capacity Gas | J2: Old Production Capacity Gas | K2: Entry Capacity Gas | L2: Exit Capacity Gas | M2: Production Costs Gas | N2: Storage Capacity Gas | O2: Entry Storage Costs Gas | P2: Entry Costs Gas Stage 1 | Q2: Exit Costs Gas Stage 1 | R2: Entry Costs Gas Stage 2 | S2: Exit Costs Gas Stage 2 | T2: Entry Costs Gas Stage 3 | U2: Exit Costs Gas Stage 3 | V2: TSO entry costs Hydrogen | W2: TSO exit costs Hydrogen | X2: Production Capacity Hydrogen | Y2: Entry Capacity Hydrogen | Z2: Exit Capacity Hydrogen | AA2: Production Costs Hydrogen | AB2: Storage Capacity Hydrogen | AC2: Entry Storage Costs Hydrogen | AD2: Entry Costs Hydrogen Stage 1 | AE2: Exit Costs Hydrogen Stage 1 | AF2: Entry Costs Hydrogen Stage 2 | AG2: Exit Costs Hydrogen Stage 2 | AH2: Entry Costs Hydrogen Stage 3 | AI2: Exit Costs Hydrogen Stage 3
A3: 1 | B3: AASTA HANSTEEN PLEM | D3: 7.107227 | E3: 67.05561 | G3: 5 | H3: 5 | I3: =SUMIFS(ProductionCapacities!$F$2:$F$51,ProductionCapacities!$E$2:$E$51,Nodes!B3) -> 23.970863 | J3: 8889.595 | K3: 500 | L3: 500 | M3: 10 | N3: =IF(C3="Market",3000,0) -> 0 | O3: =IF(C3="Market",0.374,0.375) -> 0.375 | P3: 5 | Q3: 5 | R3: 5.2 | S3: 5.2 | T3: 5.4 | U3: 5.4 | V3: 5 | W3: 5 | X3: 100 | Y3: 0 | Z3: 0 | AA3: =M3 -> 10 | AB3: 0 | AC3: =O3 -> 0.375 | AD3: =P3 -> 5 | AE3: =Q3 -> 5 | AF3: =R3 -> 5.2 | AG3: =S3 -> 5.2 | AH3: =T3 -> 5.4 | AI3: =U3 -> 5.4
A4: 2 | B4: aSGARD ERB | D4: 4.6885411 | E4: 62.302729 | G4: 5 | H4: 5 | I4: =SUMIFS(ProductionCapacities!$F$2:$F$51,ProductionCapacities!$E$2:$E$51,Nodes!B4) -> 0 | J4: 0 | K4: 500 | L4: 500 | M4: 10 | N4: =IF(C4="Market",3000,0) -> 0 | O4: =IF(C4="Market",0.374,0.375) -> 0.375 | P4: 5 | Q4: 5 | R4: 5.2 | S4: 5.2 | T4: 5.4 | U4: 5.4 | V4: 5 | W4: 5 | X4: 100 | Y4: 0 | Z4: 0 | AA4: =M4 -> 10 | AB4: 0 | AC4: =O4 -> 0.375 | AD4: =P4 -> 5 | AE4: =Q4 -> 5 | AF4: =R4 -> 5.2 | AG4: =S4 -> 5.2 | AH4: =T4 -> 5.4 | AI4: =U4 -> 5.4
A5: 3 | B5: aSGARD T | D5: 6.8036598 | E5: 65.094472 | F5: Los | G5: 5 | H5: 5 | I5: =SUMIFS(ProductionCapacities!$F$2:$F$51,ProductionCapacities!$E$2:$E$51,Nodes!B5) -> 28.969463 | J5: 0 | K5: 500 | L5: 500 | M5: 10 | N5: =IF(C5="Market",3000,0) -> 0 | O5: =IF(C5="Market",0.374,0.375) -> 0.375 | P5: 5 | Q5: 5 | R5: 5.2 | S5: 5.2 | T5: 5.4 | U5: 5.4 | V5: 5 | W5: 5 | X5: 100 | Y5: 0 | Z5: 0 | AA5: =M5 -> 10 | AB5: 0 | AC5: =O5 -> 0.375 | AD5: =P5 -> 5 | AE5: =Q5 -> 5 | AF5: =R5 -> 5.2 | AG5: =S5 -> 5.2 | AH5: =T5 -> 5.4 | AI5: =U5 -> 5.4
A6: 4 | B6: B-11 | D6: 4.5569471 | E6: 55.458982 | G6: 5 | H6: 5 | I6: =SUMIFS(ProductionCapacities!$F$2:$F$51,ProductionCapacities!$E$2:$E$51,Nodes!B6) -> 0 | J6: 0 | K6: 500 | L6: 500 | M6: 10 | N6: =IF(C6="Market",3000,0) -> 0 | O6: =IF(C6="Market",0.374,0.375) -> 0.375 | P6: 5 | Q6: 5 | R6: 5.2 | S6: 5.2 | T6: 5.4 | U6: 5.4 | V6: 5 | W6: 5 | X6: 100 | Y6: 0 | Z6: 0 | AA6: =M6 -> 10 | AB6: 0 | AC6: =O6 -> 0.375 | AD6: =P6 -> 5 | AE6: =Q6 -> 5 | AF6: =R6 -> 5.2 | AG6: =S6 -> 5.2 | AH6: =T6 -> 5.4 | AI6: =U6 -> 5.4
A7: 5 | B7: BALTIC ENTRANCE | D7: 6.5038 | E7: 55.71 | G7: 5 | H7: 5 | I7: =SUMIFS(ProductionCapacities!$F$2:$F$51,ProductionCapacities!$E$2:$E$51,Nodes!B7) -> 0 | J7: 0 | K7: 500 | L7: 500 | M7: 10 | N7: =IF(C7="Market",3000,0) -> 0 | O7: =IF(C7="Market",0.374,0.375) -> 0.375 | P7: 5 | Q7: 5 | R7: 5.2 | S7: 5.2 | T7: 5.4 | U7: 5.4 | V7: 5 | W7: 5 | X7: 100 | Y7: 0 | Z7: 0 | AA7: =M7 -> 10 | AB7: 0 | AC7: =O7 -> 0.375 | AD7: =P7 -> 5 | AE7: =Q7 -> 5 | AF7: =R7 -> 5.2 | AG7: =S7 -> 5.2 | AH7: =T7 -> 5.4 | AI7: =U7 -> 5.4
A8: 6 | B8: BRAGE | D8: 2.898055 | E8: 60.560633 | F8: Los | G8: 5 | H8: 5 | I8: =SUMIFS(ProductionCapacities!$F$2:$F$51,ProductionCapacities!$E$2:$E$51,Nodes!B8) -> 0.35852055 | J8: 0 | K8: 500 | L8: 500 | M8: 10 | N8: =IF(C8="Market",3000,0) -> 0 | O8: =IF(C8="Market",0.374,0.375) -> 0.375 | P8: 5 | Q8: 5 | R8: 5.2 | S8: 5.2 | T8: 5.4 | U8: 5.4 | V8: 5 | W8: 5 | X8: 100 | Y8: 0 | Z8: 0 | AA8: =M8 -> 10 | AB8: 0 | AC8: =O8 -> 0.375 | AD8: =P8 -> 5 | AE8: =Q8 -> 5 | AF8: =R8 -> 5.2 | AG8: =S8 -> 5.2 | AH8: =T8 -> 5.4 | AI8: =U8 -> 5.4
A9: 7 | B9: BRAGE-T | D9: 3.0378255 | E9: 60.543329 | F9: Los | G9: 5 | H9: 5 | I9: =SUMIFS(ProductionCapacities!$F$2:$F$51,ProductionCapacities!$E$2:$E$51,Nodes!B9) -> 0 | J9: 48.065 | K9: 500 | L9: 500 | M9: 10 | N9: =IF(C9="Market",3000,0) -> 0 | O9: =IF(C9="Market",0.374,0.375) -> 0.375 | P9: 5 | Q9: 5 | R9: 5.2 | S9: 5.2 | T9: 5.4 | U9: 5.4 | V9: 5 | W9: 5 | X9: 100 | Y9: 0 | Z9: 0 | AA9: =M9 -> 10 | AB9: 0 | AC9: =O9 -> 0.375 | AD9: =P9 -> 5 | AE9: =Q9 -> 5 | AF9: =R9 -> 5.2 | AG9: =S9 -> 5.2 | AH9: =T9 -> 5.4 | AI9: =U9 -> 5.4
A10: 8 | B10: CATS PLATFORM | D10: 1.803328 | E10: 57.758069 | G10: 5 | H10: 5 | I10: 48 | J10: 1282.342 | K10: 500 | L10: 500 | M10: 10 | N10: =IF(C10="Market",3000,0) -> 0 | O10: =IF(C10="Market",0.374,0.375) -> 0.375 | P10: 5 | Q10: 5 | R10: 5.2 | S10: 5.2 | T10: 5.4 | U10: 5.4 | V10: 5 | W10: 5 | X10: 100 | Y10: 0 | Z10: 0 | AA10: =M10 -> 10 | AB10: 0 | AC10: =O10 -> 0.375 | AD10: =P10 -> 5 | AE10: =Q10 -> 5 | AF10: =R10 -> 5.2 | AG10: =S10 -> 5.2 | AH10: =T10 -> 5.4 | AI10: =U10 -> 5.4
A11: 9 | B11: Denmark 1 | D11: 8.4073 | E11: 55.745 | G11: 5 | H11: 5 | I11: =SUMIFS(ProductionCapacities!$F$2:$F$51,ProductionCapacities!$E$2:$E$51,Nodes!B11) -> 0 | J11: 0 | K11: 500 | L11: 500 | M11: 10 | N11: =IF(C11="Market",3000,0) -> 0 | O11: =IF(C11="Market",0.374,0.375) -> 0.375 | P11: 5 | Q11: 5 | R11: 5.2 | S11: 5.2 | T11: 5.4 | U11: 5.4 | V11: 5 | W11: 5 | X11: 100 | Y11: 0 | Z11: 0 | AA11: =M11 -> 10 | AB11: 0 | AC11: =O11 -> 0.375 | AD11: =P11 -> 5 | AE11: =Q11 -> 5 | AF11: =R11 -> 5.2 | AG11: =S11 -> 5.2 | AH11: =T11 -> 5.4 | AI11: =U11 -> 5.4
A12: 10 | B12: Denmark 2 | D12: 9.3108 | E12: 55.617 | G12: 5 | H12: 5 | I12: =SUMIFS(ProductionCapacities!$F$2:$F$51,ProductionCapacities!$E$2:$E$51,Nodes!B12) -> 0 | J12: 0 | K12: 500 | L12: 500 | M12: 10 | N12: =IF(C12="Market",3000,0) -> 0 | O12: =IF(C12="Market",0.374,0.375) -> 0.375 | P12: 5 | Q12: 5 | R12: 5.2 | S12: 5.2 | T12: 5.4 | U12: 5.4 | V12: 5 | W12: 5 | X12: 100 | Y12: 0 | Z12: 0 | AA12: =M12 -> 10 | AB12: 0 | AC12: =O12 -> 0.375 | AD12: =P12 -> 5 | AE12: =Q12 -> 5 | AF12: =R12 -> 5.2 | AG12: =S12 -> 5.2 | AH12: =T12 -> 5.4 | AI12: =U12 -> 5.4
A13: 11 | B13: Denmark 3 | D13: 10.7951 | E13: 55.287 | G13: 5 | H13: 5 | I13: =SUMIFS(ProductionCapacities!$F$2:$F$51,ProductionCapacities!$E$2:$E$51,Nodes!B13) -> 0 | J13: 0 | K13: 500 | L13: 500 | M13: 10 | N13: =IF(C13="Market",3000,0) -> 0 | O13: =IF(C13="Market",0.374,0.375) -> 0.375 | P13: 5 | Q13: 5 | R13: 5.2 | S13: 5.2 | T13: 5.4 | U13: 5.4 | V13: 5 | W13: 5 | X13: 100 | Y13: 0 | Z13: 0 | AA13: =M13 -> 10 | AB13: 0 | AC13: =O13 -> 0.375 | AD13: =P13 -> 5 | AE13: =Q13 -> 5 | AF13: =R13 -> 5.2 | AG13: =S13 -> 5.2 | AH13: =T13 -> 5.4 | AI13: =U13 -> 5.4
A14: 12 | B14: Denmark 4 | D14: 11.2102 | E14: 55.389 | G14: 5 | H14: 5 | I14: =SUMIFS(ProductionCapacities!$F$2:$F$51,ProductionCapacities!$E$2:$E$51,Nodes!B14) -> 0 | J14: 0 | K14: 500 | L14: 500 | M14: 10 | N14: =IF(C14="Market",3000,0) -> 0 | O14: =IF(C14="Market",0.374,0.375) -> 0.375 | P14: 5 | Q14: 5 | R14: 5.2 | S14: 5.2 | T14: 5.4 | U14: 5.4 | V14: 5 | W14: 5 | X14: 100 | Y14: 0 | Z14: 0 | AA14: =M14 -> 10 | AB14: 0 | AC14: =O14 -> 0.375 | AD14: =P14 -> 5 | AE14: =Q14 -> 5 | AF14: =R14 -> 5.2 | AG14: =S14 -> 5.2 | AH14: =T14 -> 5.4 | AI14: =U14 -> 5.4
A15: 13 | B15: DRAUGEN | D15: 6.441258 | E15: 64.233255 | F15: Los | G15: 5 | H15: 5 | I15: =SUMIFS(ProductionCapacities!$F$2:$F$51,ProductionCapacities!$E$2:$E$51,Nodes!B15) -> 0.010191781 | J15: 48.065 | K15: 500 | L15: 500 | M15: 10 | N15: =IF(C15="Market",3000,0) -> 0 | O15: =IF(C15="Market",0.374,0.375) -> 0.375 | P15: 5 | Q15: 5 | R15: 5.2 | S15: 5.2 | T15: 5.4 | U15: 5.4 | V15: 5 | W15: 5 | X15: 100 | Y15: 0 | Z15: 0 | AA15: =M15 -> 10 | AB15: 0 | AC15: =O15 -> 0.375 | AD15: =P15 -> 5 | AE15: =Q15 -> 5 | AF15: =R15 -> 5.2 | AG15: =S15 -> 5.2 | AH15: =T15 -> 5.4 | AI15: =U15 -> 5.4
A16: 14 | B16: DRAUGEN T | D16: 7.7910261 | E16: 64.350568 | G16: 5 | H16: 5 | I16: =SUMIFS(ProductionCapacities!$F$2:$F$51,ProductionCapacities!$E$2:$E$51,Nodes!B16) -> 0 | J16: 48.065 | K16: 500 | L16: 500 | M16: 10 | N16: =IF(C16="Market",3000,0) -> 0 | O16: =IF(C16="Market",0.374,0.375) -> 0.375 | P16: 5 | Q16: 5 | R16: 5.2 | S16: 5.2 | T16: 5.4 | U16: 5.4 | V16: 5 | W16: 5 | X16: 100 | Y16: 0 | Z16: 0 | AA16: =M16 -> 10 | AB16: 0 | AC16: =O16 -> 0.375 | AD16: =P16 -> 5 | AE16: =Q16 -> 5 | AF16: =R16 -> 5.2 | AG16: =S16 -> 5.2 | AH16: =T16 -> 5.4 | AI16: =U16 -> 5.4
A17: 15 | B17: DRAUPNER E | D17: 2.4644042 | E17: 58.188149 | G17: 5 | H17: 5 | I17: =SUMIFS(ProductionCapacities!$F$2:$F$51,ProductionCapacities!$E$2:$E$51,Nodes!B17) -> 0 | J17: 0 | K17: 500 | L17: 500 | M17: 10 | N17: =IF(C17="Market",3000,0) -> 0 | O17: =IF(C17="Market",0.374,0.375) -> 0.375 | P17: 5 | Q17: 5 | R17: 5.2 | S17: 5.2 | T17: 5.4 | U17: 5.4 | V17: 5 | W17: 5 | X17: 100 | Y17: 0 | Z17: 0 | AA17: =M17 -> 10 | AB17: 0 | AC17: =O17 -> 0.375 | AD17: =P17 -> 5 | AE17: =Q17 -> 5 | AF17: =R17 -> 5.2 | AG17: =S17 -> 5.2 | AH17: =T17 -> 5.4 | AI17: =U17 -> 5.4
A18: 16 | B18: DRAUPNER S | D18: 2.473733 | E18: 58.184409 | G18: 5 | H18: 5 | I18: =SUMIFS(ProductionCapacities!$F$2:$F$51,ProductionCapacities!$E$2:$E$51,Nodes!B18) -> 0 | J18: 0 | K18: 500 | L18: 500 | M18: 10 | N18: =IF(C18="Market",3000,0) -> 0 | O18: =IF(C18="Market",0.374,0.375) -> 0.375 | P18: 5 | Q18: 5 | R18: 5.2 | S18: 5.2 | T18: 5.4 | U18: 5.4 | V18: 5 | W18: 5 | X18: 100 | Y18: 0 | Z18: 0 | AA18: =M18 -> 10 | AB18: 0 | AC18: =O18 -> 0.375 | AD18: =P18 -> 5 | AE18: =Q18 -> 5 | AF18: =R18 -> 5.2 | AG18: =S18 -> 5.2 | AH18: =T18 -> 5.4 | AI18: =U18 -> 5.4
A19: 17 | B19: DUNKERQUE | C19: Market | D19: 2.252709 | E19: 51.046406 | G19: 5 | H19: 5 | I19: =SUMIFS(ProductionCapacities!$F$2:$F$51,ProductionCapacities!$E$2:$E$51,Nodes!B19) -> 0 | J19: 1214.6 | K19: 500 | L19: 500 | M19: 10 | N19: =IF(C19="Market",3000,0) -> 3000 | O19: =IF(C19="Market",0.374,0.375) -> 0.374 | P19: 5 | Q19: 5 | R19: 5.2 | S19: 5.2 | T19: 5.4 | U19: 5.4 | V19: 5 | W19: 5 | X19: 100 | Y19: 0 | Z19: 0 | AA19: =M19 -> 10 | AB19: 0 | AC19: =O19 -> 0.374 | AD19: =P19 -> 5 | AE19: =Q19 -> 5 | AF19: =R19 -> 5.2 | AG19: =S19 -> 5.2 | AH19: =T19 -> 5.4 | AI19: =U19 -> 5.4
A20: 18 | B20: EASINGTON | C20: Market | D20: 0.116031 | E20: 53.659231 | G20: 5 | H20: 5 | I20: =SUMIFS(ProductionCapacities!$F$2:$F$51,ProductionCapacities!$E$2:$E$51,Nodes!B20) -> 0 | J20: 0 | K20: 500 | L20: 500 | M20: 10 | N20: =IF(C20="Market",3000,0) -> 3000 | O20: =IF(C20="Market",0.374,0.375) -> 0.374 | P20: 5 | Q20: 5 | R20: 5.2 | S20: 5.2 | T20: 5.4 | U20: 5.4 | V20: 5 | W20: 5 | X20: 100 | Y20: 0 | Z20: 0 | AA20: =M20 -> 10 | AB20: 0 | AC20: =O20 -> 0.374 | AD20: =P20 -> 5 | AE20: =Q20 -> 5 | AF20: =R20 -> 5.2 | AG20: =S20 -> 5.2 | AH20: =T20 -> 5.4 | AI20: =U20 -> 5.4
A21: 19 | B21: EDVARD GRIEG | D21: 1.3911371 | E21: 59.477978 | F21: Los | G21: 5 | H21: 5 | I21: =SUMIFS(ProductionCapacities!$F$2:$F$51,ProductionCapacities!$E$2:$E$51,Nodes!B21) -> 4.0645178 | J21: 48.065 | K21: 500 | L21: 500 | M21: 10 | N21: =IF(C21="Market",3000,0) -> 0 | O21: =IF(C21="Market",0.374,0.375) -> 0.375 | P21: 5 | Q21: 5 | R21: 5.2 | S21: 5.2 | T21: 5.4 | U21: 5.4 | V21: 5 | W21: 5 | X21: 100 | Y21: 0 | Z21: 0 | AA21: =M21 -> 10 | AB21: 0 | AC21: =O21 -> 0.375 | AD21: =P21 -> 5 | AE21: =Q21 -> 5 | AF21: =R21 -> 5.2 | AG21: =S21 -> 5.2 | AH21: =T21 -> 5.4 | AI21: =U21 -> 5.4
A22: 20 | B22: EKOFISK J | D22: 3.23 | E22: 56.55 | G22: 5 | H22: 5 | I22: =SUMIFS(ProductionCapacities!$F$2:$F$51,ProductionCapacities!$E$2:$E$51,Nodes!B22) -> 3.8482712 | J22: 578.785 | K22: 500 | L22: 500 | M22: 10 | N22: =IF(C22="Market",3000,0) -> 0 | O22: =IF(C22="Market",0.374,0.375) -> 0.375 | P22: 5 | Q22: 5 | R22: 5.2 | S22: 5.2 | T22: 5.4 | U22: 5.4 | V22: 5 | W22: 5 | X22: 100 | Y22: 0 | Z22: 0 | AA22: =M22 -> 10 | AB22: 0 | AC22: =O22 -> 0.375 | AD22: =P22 -> 5 | AE22: =Q22 -> 5 | AF22: =R22 -> 5.2 | AG22: =S22 -> 5.2 | AH22: =T22 -> 5.4 | AI22: =U22 -> 5.4
A23: 21 | B23: DORNUM | C23: Market | D23: 7.32642 | E23: 53.6797 | G23: 5 | H23: 5 | I23: =SUMIFS(ProductionCapacities!$F$2:$F$51,ProductionCapacities!$E$2:$E$51,Nodes!B23) -> 0 | J23: 0 | K23: 500 | L23: 500 | M23: 10 | N23: =IF(C23="Market",3000,0) -> 3000 | O23: =IF(C23="Market",0.374,0.375) -> 0.374 | P23: 5 | Q23: 5 | R23: 5.2 | S23: 5.2 | T23: 5.4 | U23: 5.4 | V23: 5 | W23: 5 | X23: 100 | Y23: 0 | Z23: 0 | AA23: =M23 -> 10 | AB23: 0 | AC23: =O23 -> 0.374 | AD23: =P23 -> 5 | AE23: =Q23 -> 5 | AF23: =R23 -> 5.2 | AG23: =S23 -> 5.2 | AH23: =T23 -> 5.4 | AI23: =U23 -> 5.4
A24: 22 | B24: EMDEN | C24: Market | D24: 7.18929 | E24: 53.3462 | G24: 5 | H24: 5 | I24: =SUMIFS(ProductionCapacities!$F$2:$F$51,ProductionCapacities!$E$2:$E$51,Nodes!B24) -> 0 | J24: 0 | K24: 500 | L24: 500 | M24: 10 | N24: =IF(C24="Market",3000,0) -> 3000 | O24: =IF(C24="Market",0.374,0.375) -> 0.374 | P24: 5 | Q24: 5 | R24: 5.2 | S24: 5.2 | T24: 5.4 | U24: 5.4 | V24: 5 | W24: 5 | X24: 100 | Y24: 0 | Z24: 0 | AA24: =M24 -> 10 | AB24: 0 | AC24: =O24 -> 0.374 | AD24: =P24 -> 5 | AE24: =Q24 -> 5 | AF24: =R24 -> 5.2 | AG24: =S24 -> 5.2 | AH24: =T24 -> 5.4 | AI24: =U24 -> 5.4
A25: 23 | B25: EUROPIPE-SCP | D25: 4.222622 | E25: 55.706969 | G25: 5 | H25: 5 | I25: =SUMIFS(ProductionCapacities!$F$2:$F$51,ProductionCapacities!$E$2:$E$51,Nodes!B25) -> 0 | J25: 0 | K25: 500 | L25: 500 | M25: 10 | N25: =IF(C25="Market",3000,0) -> 0 | O25: =IF(C25="Market",0.374,0.375) -> 0.375 | P25: 5 | Q25: 5 | R25: 5.2 | S25: 5.2 | T25: 5.4 | U25: 5.4 | V25: 5 | W25: 5 | X25: 100 | Y25: 0 | Z25: 0 | AA25: =M25 -> 10 | AB25: 0 | AC25: =O25 -> 0.375 | AD25: =P25 -> 5 | AE25: =Q25 -> 5 | AF25: =R25 -> 5.2 | AG25: =S25 -> 5.2 | AH25: =T25 -> 5.4 | AI25: =U25 -> 5.4
A26: 24 | B26: FLAGS-T | D26: 1.7001891 | E26: 61.022018 | G26: 5 | H26: 5 | I26: =SUMIFS(ProductionCapacities!$F$2:$F$51,ProductionCapacities!$E$2:$E$51,Nodes!B26) -> 0 | J26: 0 | K26: 500 | L26: 500 | M26: 10 | N26: =IF(C26="Market",3000,0) -> 0 | O26: =IF(C26="Market",0.374,0.375) -> 0.375 | P26: 5 | Q26: 5 | R26: 5.2 | S26: 5.2 | T26: 5.4 | U26: 5.4 | V26: 5 | W26: 5 | X26: 100 | Y26: 0 | Z26: 0 | AA26: =M26 -> 10 | AB26: 0 | AC26: =O26 -> 0.375 | AD26: =P26 -> 5 | AE26: =Q26 -> 5 | AF26: =R26 -> 5.2 | AG26: =S26 -> 5.2 | AH26: =T26 -> 5.4 | AI26: =U26 -> 5.4
A27: 25 | B27: FRIGG TP1-Y | D27: 2.0113877 | E27: 60.502035 | F27: Los | G27: 5 | H27: 5 | I27: =SUMIFS(ProductionCapacities!$F$2:$F$51,ProductionCapacities!$E$2:$E$51,Nodes!B27) -> 0 | J27: 0 | K27: 500 | L27: 500 | M27: 10 | N27: =IF(C27="Market",3000,0) -> 0 | O27: =IF(C27="Market",0.374,0.375) -> 0.375 | P27: 5 | Q27: 5 | R27: 5.2 | S27: 5.2 | T27: 5.4 | U27: 5.4 | V27: 5 | W27: 5 | X27: 100 | Y27: 0 | Z27: 0 | AA27: =M27 -> 10 | AB27: 0 | AC27: =O27 -> 0.375 | AD27: =P27 -> 5 | AE27: =Q27 -> 5 | AF27: =R27 -> 5.2 | AG27: =S27 -> 5.2 | AH27: =T27 -> 5.4 | AI27: =U27 -> 5.4
A28: 26 | B28: GJoA | D28: 1.6999853 | E28: 61.020798 | F28: Los | G28: 5 | H28: 5 | I28: =SUMIFS(ProductionCapacities!$F$2:$F$51,ProductionCapacities!$E$2:$E$51,Nodes!B28) -> 10.738132 | J28: 2588.081 | K28: 500 | L28: 500 | M28: 10 | N28: =IF(C28="Market",3000,0) -> 0 | O28: =IF(C28="Market",0.374,0.375) -> 0.375 | P28: 5 | Q28: 5 | R28: 5.2 | S28: 5.2 | T28: 5.4 | U28: 5.4 | V28: 5 | W28: 5 | X28: 100 | Y28: 0 | Z28: 0 | AA28: =M28 -> 10 | AB28: 0 | AC28: =O28 -> 0.375 | AD28: =P28 -> 5 | AE28: =Q28 -> 5 | AF28: =R28 -> 5.2 | AG28: =S28 -> 5.2 | AH28: =T28 -> 5.4 | AI28: =U28 -> 5.4
A29: 27 | B29: GJoA-T | D29: 3.9049898 | E29: 61.330194 | F29: Los | G29: 5 | H29: 5 | I29: =SUMIFS(ProductionCapacities!$F$2:$F$51,ProductionCapacities!$E$2:$E$51,Nodes!B29) -> 0 | J29: 2588.081 | K29: 500 | L29: 500 | M29: 10 | N29: =IF(C29="Market",3000,0) -> 0 | O29: =IF(C29="Market",0.374,0.375) -> 0.375 | P29: 5 | Q29: 5 | R29: 5.2 | S29: 5.2 | T29: 5.4 | U29: 5.4 | V29: 5 | W29: 5 | X29: 100 | Y29: 0 | Z29: 0 | AA29: =M29 -> 10 | AB29: 0 | AC29: =O29 -> 0.375 | AD29: =P29 -> 5 | AE29: =Q29 -> 5 | AF29: =R29 -> 5.2 | AG29: =S29 -> 5.2 | AH29: =T29 -> 5.4 | AI29: =U29 -> 5.4
A30: 28 | B30: GRANE | D30: 2.4873353 | E30: 59.169726 | G30: 5 | H30: 5 | I30: =SUMIFS(ProductionCapacities!$F$2:$F$51,ProductionCapacities!$E$2:$E$51,Nodes!B30) -> 0 | J30: 48.065 | K30: 500 | L30: 500 | M30: 10 | N30: =IF(C30="Market",3000,0) -> 0 | O30: =IF(C30="Market",0.374,0.375) -> 0.375 | P30: 5 | Q30: 5 | R30: 5.2 | S30: 5.2 | T30: 5.4 | U30: 5.4 | V30: 5 | W30: 5 | X30: 100 | Y30: 0 | Z30: 0 | AA30: =M30 -> 10 | AB30: 0 | AC30: =O30 -> 0.375 | AD30: =P30 -> 5 | AE30: =Q30 -> 5 | AF30: =R30 -> 5.2 | AG30: =S30 -> 5.2 | AH30: =T30 -> 5.4 | AI30: =U30 -> 5.4
A31: 29 | B31: GUDRUN | D31: 1.7504701 | E31: 58.842411 | G31: 5 | H31: 5 | I31: =SUMIFS(ProductionCapacities!$F$2:$F$51,ProductionCapacities!$E$2:$E$51,Nodes!B31) -> 0 | J31: 667.002 | K31: 500 | L31: 500 | M31: 10 | N31: =IF(C31="Market",3000,0) -> 0 | O31: =IF(C31="Market",0.374,0.375) -> 0.375 | P31: 5 | Q31: 5 | R31: 5.2 | S31: 5.2 | T31: 5.4 | U31: 5.4 | V31: 5 | W31: 5 | X31: 100 | Y31: 0 | Z31: 0 | AA31: =M31 -> 10 | AB31: 0 | AC31: =O31 -> 0.375 | AD31: =P31 -> 5 | AE31: =Q31 -> 5 | AF31: =R31 -> 5.2 | AG31: =S31 -> 5.2 | AH31: =T31 -> 5.4 | AI31: =U31 -> 5.4
A32: 30 | B32: H-7 BP | D32: 6.0406336 | E32: 54.505801 | G32: 5 | H32: 5 | I32: =SUMIFS(ProductionCapacities!$F$2:$F$51,ProductionCapacities!$E$2:$E$51,Nodes!B32) -> 0 | J32: 0 | K32: 500 | L32: 500 | M32: 10 | N32: =IF(C32="Market",3000,0) -> 0 | O32: =IF(C32="Market",0.374,0.375) -> 0.375 | P32: 5 | Q32: 5 | R32: 5.2 | S32: 5.2 | T32: 5.4 | U32: 5.4 | V32: 5 | W32: 5 | X32: 100 | Y32: 0 | Z32: 0 | AA32: =M32 -> 10 | AB32: 0 | AC32: =O32 -> 0.375 | AD32: =P32 -> 5 | AE32: =Q32 -> 5 | AF32: =R32 -> 5.2 | AG32: =S32 -> 5.2 | AH32: =T32 -> 5.4 | AI32: =U32 -> 5.4
A33: 31 | B33: HEIDRUN | D33: 7.3202454 | E33: 65.3215 | F33: Los | G33: 5 | H33: 5 | I33: =SUMIFS(ProductionCapacities!$F$2:$F$51,ProductionCapacities!$E$2:$E$51,Nodes!B33) -> 4.2217397 | J33: 1214.6 | K33: 500 | L33: 500 | M33: 10 | N33: =IF(C33="Market",3000,0) -> 0 | O33: =IF(C33="Market",0.374,0.375) -> 0.375 | P33: 5 | Q33: 5 | R33: 5.2 | S33: 5.2 | T33: 5.4 | U33: 5.4 | V33: 5 | W33: 5 | X33: 100 | Y33: 0 | Z33: 0 | AA33: =M33 -> 10 | AB33: 0 | AC33: =O33 -> 0.375 | AD33: =P33 -> 5 | AE33: =Q33 -> 5 | AF33: =R33 -> 5.2 | AG33: =S33 -> 5.2 | AH33: =T33 -> 5.4 | AI33: =U33 -> 5.4
A34: 32 | B34: HEIMDAL | D34: 2.2345226 | E34: 59.570738 | G34: 5 | H34: 5 | I34: =SUMIFS(ProductionCapacities!$F$2:$F$51,ProductionCapacities!$E$2:$E$51,Nodes!B34) -> 0.072424658 | J34: 1329.308 | K34: 500 | L34: 500 | M34: 10 | N34: =IF(C34="Market",3000,0) -> 0 | O34: =IF(C34="Market",0.374,0.375) -> 0.375 | P34: 5 | Q34: 5 | R34: 5.2 | S34: 5.2 | T34: 5.4 | U34: 5.4 | V34: 5 | W34: 5 | X34: 100 | Y34: 0 | Z34: 0 | AA34: =M34 -> 10 | AB34: 0 | AC34: =O34 -> 0.375 | AD34: =P34 -> 5 | AE34: =Q34 -> 5 | AF34: =R34 -> 5.2 | AG34: =S34 -> 5.2 | AH34: =T34 -> 5.4 | AI34: =U34 -> 5.4
A35: 33 | B35: HEIMDAL HRP | D35: 2.2352255 | E35: 59.571075 | G35: 5 | H35: 5 | I35: =SUMIFS(ProductionCapacities!$F$2:$F$51,ProductionCapacities!$E$2:$E$51,Nodes!B35) -> 0 | J35: 1329.308 | K35: 500 | L35: 500 | M35: 10 | N35: =IF(C35="Market",3000,0) -> 0 | O35: =IF(C35="Market",0.374,0.375) -> 0.375 | P35: 5 | Q35: 5 | R35: 5.2 | S35: 5.2 | T35: 5.4 | U35: 5.4 | V35: 5 | W35: 5 | X35: 100 | Y35: 0 | Z35: 0 | AA35: =M35 -> 10 | AB35: 0 | AC35: =O35 -> 0.375 | AD35: =P35 -> 5 | AE35: =Q35 -> 5 | AF35: =R35 -> 5.2 | AG35: =S35 -> 5.2 | AH35: =T35 -> 5.4 | AI35: =U35 -> 5.4
A36: 34 | B36: JOHAN SVERDRUP RP | D36: 5.054176 | E36: 59.326808 | F36: Los | G36: 5 | H36: 5 | I36: =SUMIFS(ProductionCapacities!$F$2:$F$51,ProductionCapacities!$E$2:$E$51,Nodes!B36) -> 2.304789 | J36: 8889.595 | K36: 500 | L36: 500 | M36: 10 | N36: =IF(C36="Market",3000,0) -> 0 | O36: =IF(C36="Market",0.374,0.375) -> 0.375 | P36: 5 | Q36: 5 | R36: 5.2 | S36: 5.2 | T36: 5.4 | U36: 5.4 | V36: 5 | W36: 5 | X36: 100 | Y36: 0 | Z36: 0 | AA36: =M36 -> 10 | AB36: 0 | AC36: =O36 -> 0.375 | AD36: =P36 -> 5 | AE36: =Q36 -> 5 | AF36: =R36 -> 5.2 | AG36: =S36 -> 5.2 | AH36: =T36 -> 5.4 | AI36: =U36 -> 5.4
A37: 35 | B37: JOHAN SVERDRUP STATPIPE PLEM | D37: 2.5577715 | E37: 58.841931 | F37: Los | G37: 5 | H37: 5 | I37: =SUMIFS(ProductionCapacities!$F$2:$F$51,ProductionCapacities!$E$2:$E$51,Nodes!B37) -> 0 | J37: 8889.595 | K37: 500 | L37: 500 | M37: 10 | N37: =IF(C37="Market",3000,0) -> 0 | O37: =IF(C37="Market",0.374,0.375) -> 0.375 | P37: 5 | Q37: 5 | R37: 5.2 | S37: 5.2 | T37: 5.4 | U37: 5.4 | V37: 5 | W37: 5 | X37: 100 | Y37: 0 | Z37: 0 | AA37: =M37 -> 10 | AB37: 0 | AC37: =O37 -> 0.375 | AD37: =P37 -> 5 | AE37: =Q37 -> 5 | AF37: =R37 -> 5.2 | AG37: =S37 -> 5.2 | AH37: =T37 -> 5.4 | AI37: =U37 -> 5.4
A38: 36 | B38: KaRSTo | D38: 5.5129213 | E38: 59.272116 | G38: 5 | H38: 5 | I38: =SUMIFS(ProductionCapacities!$F$2:$F$51,ProductionCapacities!$E$2:$E$51,Nodes!B38) -> 0 | J38: 0 | K38: 500 | L38: 500 | M38: 10 | N38: =IF(C38="Market",3000,0) -> 0 | O38: =IF(C38="Market",0.374,0.375) -> 0.375 | P38: 5 | Q38: 5 | R38: 5.2 | S38: 5.2 | T38: 5.4 | U38: 5.4 | V38: 5 | W38: 5 | X38: 100 | Y38: 0 | Z38: 0 | AA38: =M38 -> 10 | AB38: 0 | AC38: =O38 -> 0.375 | AD38: =P38 -> 5 | AE38: =Q38 -> 5 | AF38: =R38 -> 5.2 | AG38: =S38 -> 5.2 | AH38: =T38 -> 5.4 | AI38: =U38 -> 5.4
A39: 37 | B39: KOLLSNES | D39: 4.838597 | E39: 60.545348 | G39: 5 | H39: 5 | I39: =SUMIFS(ProductionCapacities!$F$2:$F$51,ProductionCapacities!$E$2:$E$51,Nodes!B39) -> 0 | J39: 0 | K39: 500 | L39: 500 | M39: 10 | N39: =IF(C39="Market",3000,0) -> 0 | O39: =IF(C39="Market",0.374,0.375) -> 0.375 | P39: 5 | Q39: 5 | R39: 5.2 | S39: 5.2 | T39: 5.4 | U39: 5.4 | V39: 5 | W39: 5 | X39: 100 | Y39: 0 | Z39: 0 | AA39: =M39 -> 10 | AB39: 0 | AC39: =O39 -> 0.375 | AD39: =P39 -> 5 | AE39: =Q39 -> 5 | AF39: =R39 -> 5.2 | AG39: =S39 -> 5.2 | AH39: =T39 -> 5.4 | AI39: =U39 -> 5.4
A40: 38 | B40: KVITEBJoRN | D40: 2.5070781 | E40: 61.077582 | G40: 5 | H40: 5 | I40: =SUMIFS(ProductionCapacities!$F$2:$F$51,ProductionCapacities!$E$2:$E$51,Nodes!B40) -> 26.032537 | J40: 508.403 | K40: 500 | L40: 500 | M40: 10 | N40: =IF(C40="Market",3000,0) -> 0 | O40: =IF(C40="Market",0.374,0.375) -> 0.375 | P40: 5 | Q40: 5 | R40: 5.2 | S40: 5.2 | T40: 5.4 | U40: 5.4 | V40: 5 | W40: 5 | X40: 100 | Y40: 0 | Z40: 0 | AA40: =M40 -> 10 | AB40: 0 | AC40: =O40 -> 0.375 | AD40: =P40 -> 5 | AE40: =Q40 -> 5 | AF40: =R40 -> 5.2 | AG40: =S40 -> 5.2 | AH40: =T40 -> 5.4 | AI40: =U40 -> 5.4
...

Sheet Demand Stage 1
A1: Node Number | B1: 1
A2: Probability | B2: 1
B3: gas or mix | J3: pure hydrogen
A4: Hour | B4: ='Demand Stage 2'!B4 -> ST.FERGUS | C4: ='Demand Stage 2'!C4 -> EASINGTON | D4: ='Demand Stage 2'!D4 -> TEESSIDE | E4: ='Demand Stage 2'!E4 -> EMDEN | F4: DORNUM | G4: ='Demand Stage 2'!G4 -> ZEEBRUGGE | H4: ='Demand Stage 2'!H4 -> DUNKERQUE | I4: ='Demand Stage 2'!I4 -> POLAND | J4: ='Demand Stage 2'!J4 -> ST.FERGUS | K4: ='Demand Stage 2'!K4 -> EASINGTON | L4: ='Demand Stage 2'!L4 -> TEESSIDE | M4: ='Demand Stage 2'!M4 -> EMDEN | N4: DORNUM | O4: ='Demand Stage 2'!O4 -> ZEEBRUGGE | P4: ='Demand Stage 2'!P4 -> DUNKERQUE | Q4: ='Demand Stage 2'!Q4 -> POLAND
A5: 0 | B5: ='Demand Stage 2'!B43 -> 10 | C5: ='Demand Stage 2'!C43 -> 10 | D5: ='Demand Stage 2'!D43 -> 10 | E5: ='Demand Stage 2'!E43 -> 40 | F5: ='Demand Stage 2'!F43 -> 40 | G5: ='Demand Stage 2'!G43 -> 40 | H5: ='Demand Stage 2'!H43 -> 40 | I5: ='Demand Stage 2'!I43 -> 20 | J5: 0 | K5: 0 | L5: 0 | M5: 0 | N5: 0 | O5: 0 | P5: 0 | Q5: 0
A6: 1 | B6: ='Demand Stage 2'!B44 -> 10 | C6: ='Demand Stage 2'!C44 -> 10 | D6: ='Demand Stage 2'!D44 -> 10 | E6: ='Demand Stage 2'!E44 -> 40 | F6: ='Demand Stage 2'!F44 -> 40 | G6: ='Demand Stage 2'!G44 -> 40 | H6: ='Demand Stage 2'!H44 -> 40 | I6: ='Demand Stage 2'!I44 -> 20 | J6: 0 | K6: 0 | L6: 0 | M6: 0 | N6: 0 | O6: 0 | P6: 0 | Q6: 0
A7: 2 | B7: ='Demand Stage 2'!B45 -> 10 | C7: ='Demand Stage 2'!C45 -> 10 | D7: ='Demand Stage 2'!D45 -> 10 | E7: ='Demand Stage 2'!E45 -> 40 | F7: ='Demand Stage 2'!F45 -> 40 | G7: ='Demand Stage 2'!G45 -> 40 | H7: ='Demand Stage 2'!H45 -> 40 | I7: ='Demand Stage 2'!I45 -> 20 | J7: 0 | K7: 0 | L7: 0 | M7: 0 | N7: 0 | O7: 0 | P7: 0 | Q7: 0
A8: 3 | B8: ='Demand Stage 2'!B46 -> 10 | C8: ='Demand Stage 2'!C46 -> 10 | D8: ='Demand Stage 2'!D46 -> 10 | E8: ='Demand Stage 2'!E46 -> 40 | F8: ='Demand Stage 2'!F46 -> 40 | G8: ='Demand Stage 2'!G46 -> 40 | H8: ='Demand Stage 2'!H46 -> 40 | I8: ='Demand Stage 2'!I46 -> 20 | J8: 0 | K8: 0 | L8: 0 | M8: 0 | N8: 0 | O8: 0 | P8: 0 | Q8: 0
A9: 4 | B9: ='Demand Stage 2'!B47 -> 10 | C9: ='Demand Stage 2'!C47 -> 10 | D9: ='Demand Stage 2'!D47 -> 10 | E9: ='Demand Stage 2'!E47 -> 45 | F9: ='Demand Stage 2'!F47 -> 45 | G9: ='Demand Stage 2'!G47 -> 40 | H9: ='Demand Stage 2'!H47 -> 45 | I9: ='Demand Stage 2'!I47 -> 20 | J9: 0 | K9: 0 | L9: 0 | M9: 0 | N9: 0 | O9: 0 | P9: 0 | Q9: 0
A10: 5 | B10: ='Demand Stage 2'!B48 -> 10 | C10: ='Demand Stage 2'!C48 -> 10 | D10: ='Demand Stage 2'!D48 -> 10 | E10: ='Demand Stage 2'!E48 -> 40 | F10: ='Demand Stage 2'!F48 -> 40 | G10: ='Demand Stage 2'!G48 -> 40 | H10: ='Demand Stage 2'!H48 -> 35 | I10: ='Demand Stage 2'!I48 -> 20 | J10: 0 | K10: 0 | L10: 0 | M10: 0 | N10: 0 | O10: 0 | P10: 0 | Q10: 0
A11: 6 | B11: ='Demand Stage 2'!B49 -> 10 | C11: ='Demand Stage 2'!C49 -> 10 | D11: ='Demand Stage 2'!D49 -> 10 | E11: ='Demand Stage 2'!E49 -> 40 | F11: ='Demand Stage 2'!F49 -> 40 | G11: ='Demand Stage 2'!G49 -> 40 | H11: ='Demand Stage 2'!H49 -> 35 | I11: ='Demand Stage 2'!I49 -> 20 | J11: 0 | K11: 0 | L11: 0 | M11: 0 | N11: 0 | O11: 0 | P11: 0 | Q11: 0
A12: 7 | B12: ='Demand Stage 2'!B50 -> 10 | C12: ='Demand Stage 2'!C50 -> 10 | D12: ='Demand Stage 2'!D50 -> 10 | E12: ='Demand Stage 2'!E50 -> 45 | F12: ='Demand Stage 2'!F50 -> 45 | G12: ='Demand Stage 2'!G50 -> 40 | H12: ='Demand Stage 2'!H50 -> 40 | I12: ='Demand Stage 2'!I50 -> 20 | J12: 0 | K12: 0 | L12: 0 | M12: 0 | N12: 0 | O12: 0 | P12: 0 | Q12: 0
A13: 8
A14: 9
A15: 10
A16: 11
A17: 12
A18: 13
A19: 14
A20: 15
A21: 16
A22: 17
A23: 18
A24: 19
... A28: 23

Sheet Demand Stage 2
A1: Node Number | B1: 9 | R1: =B1+Parameters!$B$7 -> 17 | AH1: =R1+Parameters!$B$7 -> 25 | AX1: =AH1+Parameters!$B$7 -> 33
A2: Probability | B2: 0.25 | R2: =B2 -> 0.25 | AH2: =B2 -> 0.25 | AX2: =B2 -> 0.25
B3: gas or mix | J3: pure hydrogen | R3: gas or mix | Z3: pure hydrogen | AH3: gas or mix | AP3: pure hydrogen | AX3: gas or mix | BF3: pure hydrogen
A4: Hour | B4: ST.FERGUS | C4: EASINGTON | D4: TEESSIDE | E4: EMDEN | F4: DORNUM | G4: ZEEBRUGGE | H4: DUNKERQUE | I4: POLAND | J4: =B4 -> ST.FERGUS | K4: =C4 -> EASINGTON | L4: =D4 -> TEESSIDE | M4: =E4 -> EMDEN | N4: =F4 -> DORNUM | O4: =G4 -> ZEEBRUGGE | P4: =H4 -> DUNKERQUE | Q4: =I4 -> POLAND | R4: =B4 -> ST.FERGUS | S4: =C4 -> EASINGTON | T4: =D4 -> TEESSIDE | U4: =E4 -> EMDEN | V4: =F4 -> DORNUM | W4: =G4 -> ZEEBRUGGE | X4: =H4 -> DUNKERQUE | Y4: =I4 -> POLAND | ... BE4: =AO4 -> POLAND | BF4: =AQ4 -> EASINGTON | BG4: =AR4 -> TEESSIDE | BH4: =AS4 -> EMDEN | BI4: =AT4 -> DORNUM | BJ4: =AU4 -> ZEEBRUGGE | BK4: =AV4 -> DUNKERQUE | BL4: =AW4 -> POLAND | BM4: =AX4 -> ST.FERGUS
A5: 0 | B5: =B31+B43 -> 10 | C5: =C31+C43 -> 10 | D5: =D31+D43 -> 10 | E5: =E31+E43 -> 40 | F5: =F31+F43 -> 40 | G5: =G31+G43 -> 40 | H5: =H31+H43 -> 40 | I5: =I31+I43 -> 20 | J5: 0 | K5: 0 | L5: 0 | M5: 0 | N5: 0 | O5: 0 | P5: 0 | Q5: 0 | R5: =R31+B43 -> 10 | S5: =S31+C43 -> 10 | T5: =T31+D43 -> 10 | U5: =U31+E43 -> 40 | V5: =V31+F43 -> 40 | W5: =W31+G43 -> 40 | X5: =X31+H43 -> 40 | Y5: =Y31+I43 -> 20 | Z5: 0 | AA5: 0 | AB5: 0 | AC5: 0 | AD5: 0 | AE5: 0 | AF5: 0 | AG5: 0 | AH5: =AH31+B43 -> 10 | AI5: =AI31+C43 -> 10 | AJ5: =AJ31+D43 -> 10 | AK5: =AK31+E43 -> 40 | AL5: =AL31+F43 -> 40 | AM5: =AM31+G43 -> 40 | AN5: =AN31+H43 -> 40 | AO5: =AO31+I43 -> 20 | AP5: 0 | AQ5: 0 | AR5: 0 | AS5: 0 | AT5: 0 | AU5: 0 | AV5: 0 | AW5: 0 | AX5: =AX31+B43 -> 10 | AY5: =AY31+C43 -> 10 | AZ5: =AZ31+D43 -> 10 | BA5: =BA31+E43 -> 40 | BB5: =BB31+F43 -> 40 | BC5: =BC31+G43 -> 40 | BD5: =BD31+H43 -> 40 | BE5: =BE31+I43 -> 20 | BF5: 0 | BG5: 0 | BH5: 0 | BI5: 0 | BJ5: 0 | BK5: 0 | BL5: 0 | BM5: 0
A6: 1 | B6: =B32+B44 -> 10 | C6: =C32+C44 -> 10 | D6: =D32+D44 -> 10 | E6: =E32+E44 -> 40 | F6: =F32+F44 -> 40 | G6: =G32+G44 -> 40 | H6: =H32+H44 -> 40 | I6: =I32+I44 -> 20 | J6: 0 | K6: 0 | L6: 0 | M6: 0 | N6: 0 | O6: 0 | P6: 0 | Q6: 0 | R6: =R32+B44 -> 10 | S6: =S32+C44 -> 10 | T6: =T32+D44 -> 10 | U6: =U32+E44 -> 40 | V6: =V32+F44 -> 40 | W6: =W32+G44 -> 40 | X6: =X32+H44 -> 40 | Y6: =Y32+I44 -> 20 | Z6: 0 | AA6: 0 | AB6: 0 | AC6: 0 | AD6: 0 | AE6: 0 | AF6: 0 | AG6: 0 | AH6: =AH32+B44 -> 10 | AI6: =AI32+C44 -> 10 | AJ6: =AJ32+D44 -> 10 | AK6: =AK32+E44 -> 40 | AL6: =AL32+F44 -> 40 | AM6: =AM32+G44 -> 40 | AN6: =AN32+H44 -> 40 | AO6: =AO32+I44 -> 20 | AP6: =AP5*0.5 -> 0 | AQ6: =AQ5*0.5 -> 0 | AR6: =AR5*0.5 -> 0 | AS6: =AS5*0.5 -> 0 | AT6: =AT5*0.5 -> 0 | AU6: =AU5*0.5 -> 0 | AV6: =AV5*0.5 -> 0 | AW6: 0 | AX6: =AX32+B44 -> 10 | AY6: =AY32+C44 -> 10 | AZ6: =AZ32+D44 -> 10 | BA6: =BA32+E44 -> 40 | BB6: =BB32+F44 -> 40 | BC6: =BC32+G44 -> 40 | BD6: =BD32+H44 -> 40 | BE6: =BE32+I44 -> 20 | BF6: 0 | BG6: 0 | BH6: 0 | BI6: 0 | BJ6: 0 | BK6: 0 | BL6: 0 | BM6: 0
A7: 2 | B7: =B33+B45 -> 10 | C7: =C33+C45 -> 10 | D7: =D33+D45 -> 10 | E7: =E33+E45 -> 40 | F7: =F33+F45 -> 40 | G7: =G33+G45 -> 40 | H7: =H33+H45 -> 40 | I7: =I33+I45 -> 20 | J7: 0 | K7: 0 | L7: 0 | M7: 0 | N7: 0 | O7: 0 | P7: 0 | Q7: 0 | R7: =R33+B45 -> 10 | S7: =S33+C45 -> 10 | T7: =T33+D45 -> 10 | U7: =U33+E45 -> 40 | V7: =V33+F45 -> 40 | W7: =W33+G45 -> 40 | X7: =X33+H45 -> 40 | Y7: =Y33+I45 -> 20 | Z7: 0 | AA7: 0 | AB7: 0 | AC7: 0 | AD7: 0 | AE7: 0 | AF7: 0 | AG7: 0 | AH7: =AH33+B45 -> 10 | AI7: =AI33+C45 -> 10 | AJ7: =AJ33+D45 -> 10 | AK7: =AK33+E45 -> 40 | AL7: =AL33+F45 -> 40 | AM7: =AM33+G45 -> 40 | AN7: =AN33+H45 -> 40 | AO7: =AO33+I45 -> 20 | AP7: 0 | AQ7: 0 | AR7: 0 | AS7: 0 | AT7: 0 | AU7: 0 | AV7: 0 | AW7: 0 | AX7: =AX33+B45 -> 10 | AY7: =AY33+C45 -> 10 | AZ7: =AZ33+D45 -> 10 | BA7: =BA33+E45 -> 40 | BB7: =BB33+F45 -> 40 | BC7: =BC33+G45 -> 40 | BD7: =BD33+H45 -> 40 | BE7: =BE33+I45 -> 20 | BF7: 0 | BG7: 0 | BH7: 0 | BI7: 0 | BJ7: 0 | BK7: 0 | BL7: 0 | BM7: 0
A8: 3 | B8: =B34+B46 -> 10 | C8: =C34+C46 -> 10 | D8: =D34+D46 -> 10 | E8: =E34+E46 -> 40 | F8: =F34+F46 -> 40 | G8: =G34+G46 -> 40 | H8: =H34+H46 -> 40 | I8: =I34+I46 -> 20 | J8: 0 | K8: 0 | L8: 0 | M8: 0 | N8: 0 | O8: 0 | P8: 0 | Q8: 0 | R8: =R34+B46 -> 10 | S8: =S34+C46 -> 10 | T8: =T34+D46 -> 10 | U8: =U34+E46 -> 40 | V8: =V34+F46 -> 40 | W8: =W34+G46 -> 40 | X8: =X34+H46 -> 40 | Y8: =Y34+I46 -> 20 | Z8: 0 | AA8: 0 | AB8: 0 | AC8: 0 | AD8: 0 | AE8: 0 | AF8: 0 | AG8: 0 | AH8: =AH34+B46 -> 10 | AI8: =AI34+C46 -> 10 | AJ8: =AJ34+D46 -> 10 | AK8: =AK34+E46 -> 40 | AL8: =AL34+F46 -> 40 | AM8: =AM34+G46 -> 40 | AN8: =AN34+H46 -> 40 | AO8: =AO34+I46 -> 20 | AP8: 0 | AQ8: 0 | AR8: 0 | AS8: 0 | AT8: 0 | AU8: 0 | AV8: 0 | AW8: 0 | AX8: =AX34+B46 -> 10 | AY8: =AY34+C46 -> 10 | AZ8: =AZ34+D46 -> 10 | BA8: =BA34+E46 -> 40 | BB8: =BB34+F46 -> 40 | BC8: =BC34+G46 -> 40 | BD8: =BD34+H46 -> 40 | BE8: =BE34+I46 -> 20 | BF8: 0 | BG8: 0 | BH8: 0 | BI8: 0 | BJ8: 0 | BK8: 0 | BL8: 0 | BM8: 0
A9: 4 | B9: =B35+B47 -> 13 | C9: =C35+C47 -> 13 | D9: =D35+D47 -> 10 | E9: =E35+E47 -> 50 | F9: =F35+F47 -> 50 | G9: =G35+G47 -> 40 | H9: =H35+H47 -> 50 | I9: =I35+I47 -> 20 | R9: =R35+B47 -> 7 | S9: =S35+C47 -> 7 | T9: =T35+D47 -> 10 | U9: =U35+E47 -> 50 | V9: =V35+F47 -> 50 | W9: =W35+G47 -> 40 | X9: =X35+H47 -> 40 | Y9: =Y35+I47 -> 20 | AH9: =AH35+B47 -> 13 | AI9: =AI35+C47 -> 13 | AJ9: =AJ35+D47 -> 10 | AK9: =AK35+E47 -> 40 | AL9: =AL35+F47 -> 40 | AM9: =AM35+G47 -> 40 | AN9: =AN35+H47 -> 50 | AO9: =AO35+I47 -> 20 | AX9: =AX35+B47 -> 7 | AY9: =AY35+C47 -> 7 | AZ9: =AZ35+D47 -> 10 | BA9: =BA35+E47 -> 40 | BB9: =BB35+F47 -> 40 | BC9: =BC35+G47 -> 40 | BD9: =BD35+H47 -> 40 | BE9: =BE35+I47 -> 20
A10: 5 | B10: =B36+B48 -> 10 | C10: =C36+C48 -> 10 | D10: =D36+D48 -> 10 | E10: =E36+E48 -> 40 | F10: =F36+F48 -> 40 | G10: =G36+G48 -> 40 | H10: =H36+H48 -> 35 | I10: =I36+I48 -> 20 | R10: =R36+B48 -> 10 | S10: =S36+C48 -> 10 | T10: =T36+D48 -> 10 | U10: =U36+E48 -> 40 | V10: =V36+F48 -> 40 | W10: =W36+G48 -> 40 | X10: =X36+H48 -> 35 | Y10: =Y36+I48 -> 20 | AH10: =AH36+B48 -> 10 | AI10: =AI36+C48 -> 10 | AJ10: =AJ36+D48 -> 10 | AK10: =AK36+E48 -> 40 | AL10: =AL36+F48 -> 40 | AM10: =AM36+G48 -> 40 | AN10: =AN36+H48 -> 35 | AO10: =AO36+I48 -> 20 | AX10: =AX36+B48 -> 10 | AY10: =AY36+C48 -> 10 | AZ10: =AZ36+D48 -> 10 | BA10: =BA36+E48 -> 40 | BB10: =BB36+F48 -> 40 | BC10: =BC36+G48 -> 40 | BD10: =BD36+H48 -> 35 | BE10: =BE36+I48 -> 20
A11: 6 | B11: =B37+B49 -> 10 | C11: =C37+C49 -> 10 | D11: =D37+D49 -> 10 | E11: =E37+E49 -> 40 | F11: =F37+F49 -> 40 | G11: =G37+G49 -> 40 | H11: =H37+H49 -> 35 | I11: =I37+I49 -> 20 | R11: =R37+B49 -> 10 | S11: =S37+C49 -> 10 | T11: =T37+D49 -> 10 | U11: =U37+E49 -> 40 | V11: =V37+F49 -> 40 | W11: =W37+G49 -> 40 | X11: =X37+H49 -> 35 | Y11: =Y37+I49 -> 20 | AH11: =AH37+B49 -> 10 | AI11: =AI37+C49 -> 10 | AJ11: =AJ37+D49 -> 10 | AK11: =AK37+E49 -> 40 | AL11: =AL37+F49 -> 40 | AM11: =AM37+G49 -> 40 | AN11: =AN37+H49 -> 35 | AO11: =AO37+I49 -> 20 | AX11: =AX37+B49 -> 10 | AY11: =AY37+C49 -> 10 | AZ11: =AZ37+D49 -> 10 | BA11: =BA37+E49 -> 40 | BB11: =BB37+F49 -> 40 | BC11: =BC37+G49 -> 40 | BD11: =BD37+H49 -> 35 | BE11: =BE37+I49 -> 20
A12: 7 | B12: =B38+B50 -> 13 | C12: =C38+C50 -> 13 | D12: =D38+D50 -> 10 | E12: =E38+E50 -> 50 | F12: =F38+F50 -> 50 | G12: =G38+G50 -> 40 | H12: =H38+H50 -> 45 | I12: =I38+I50 -> 20 | R12: =R38+B50 -> 7 | S12: =S38+C50 -> 7 | T12: =T38+D50 -> 10 | U12: =U38+E50 -> 50 | V12: =V38+F50 -> 50 | W12: =W38+G50 -> 40 | X12: =X38+H50 -> 35 | Y12: =Y38+I50 -> 20 | AH12: =AH38+B50 -> 13 | AI12: =AI38+C50 -> 13 | AJ12: =AJ38+D50 -> 10 | AK12: =AK38+E50 -> 40 | AL12: =AL38+F50 -> 40 | AM12: =AM38+G50 -> 40 | AN12: =AN38+H50 -> 45 | AO12: =AO38+I50 -> 20 | AX12: =AX38+B50 -> 7 | AY12: =AY38+C50 -> 7 | AZ12: =AZ38+D50 -> 10 | BA12: =BA38+E50 -> 40 | BB12: =BB38+F50 -> 40 | BC12: =BC38+G50 -> 40 | BD12: =BD38+H50 -> 35 | BE12: =BE38+I50 -> 20
A13: 8
A14: 9
A15: 10
A16: 11
A17: 12
A18: 13
A19: 14
A20: 15
A21: 16
A22: 17
A23: 18
A24: 19
... A28: 23
B30: Delta
A31: 0 | B31: 0 | C31: 0 | D31: 0 | E31: 0 | F31: 0 | G31: 0 | H31: 0 | I31: 0 | R31: 0 | S31: 0 | T31: 0 | U31: 0 | V31: 0 | W31: 0 | X31: 0 | Y31: 0 | AH31: 0 | AI31: 0 | AJ31: 0 | AK31: 0 | AL31: 0 | AM31: 0 | AN31: 0 | AO31: 0 | AX31: 0 | AY31: 0 | AZ31: 0 | BA31: 0 | BB31: 0 | BC31: 0 | BD31: 0 | BE31: 0
A32: 1 | B32: 0 | C32: 0 | D32: 0 | E32: 0 | F32: 0 | G32: 0 | H32: 0 | I32: 0 | R32: 0 | S32: 0 | T32: 0 | U32: 0 | V32: 0 | W32: 0 | X32: 0 | Y32: 0 | AH32: 0 | AI32: 0 | AJ32: 0 | AK32: 0 | AL32: 0 | AM32: 0 | AN32: 0 | AO32: 0 | AX32: 0 | AY32: 0 | AZ32: 0 | BA32: 0 | BB32: 0 | BC32: 0 | BD32: 0 | BE32: 0
A33: 2 | B33: 0 | C33: 0 | D33: 0 | E33: 0 | F33: 0 | G33: 0 | H33: 0 | I33: 0 | R33: 0 | S33: 0 | T33: 0 | U33: 0 | V33: 0 | W33: 0 | X33: 0 | Y33: 0 | AH33: 0 | AI33: 0 | AJ33: 0 | AK33: 0 | AL33: 0 | AM33: 0 | AN33: 0 | AO33: 0 | AX33: 0 | AY33: 0 | AZ33: 0 | BA33: 0 | BB33: 0 | BC33: 0 | BD33: 0 | BE33: 0
A34: 3 | B34: 0 | C34: 0 | D34: 0 | E34: 0 | F34: 0 | G34: 0 | H34: 0 | I34: 0 | R34: 0 | S34: 0 | T34: 0 | U34: 0 | V34: 0 | W34: 0 | X34: 0 | Y34: 0 | AH34: 0 | AI34: 0 | AJ34: 0 | AK34: 0 | AL34: 0 | AM34: 0 | AN34: 0 | AO34: 0 | AX34: 0 | AY34: 0 | AZ34: 0 | BA34: 0 | BB34: 0 | BC34: 0 | BD34: 0 | BE34: 0
A35: 4 | B35: 3 | C35: 3 | D35: 0 | E35: 5 | F35: 5 | G35: 0 | H35: 5 | I35: 0 | R35: -3 | S35: -3 | T35: 0 | U35: 5 | V35: 5 | W35: 0 | X35: -5 | Y35: 0 | AH35: 3 | AI35: 3 | AJ35: 0 | AK35: -5 | AL35: -5 | AM35: 0 | AN35: 5 | AO35: 0 | AX35: -3 | AY35: -3 | AZ35: 0 | BA35: -5 | BB35: -5 | BC35: 0 | BD35: -5 | BE35: 0
A36: 5 | B36: 0 | C36: 0 | D36: 0 | E36: 0 | F36: 0 | G36: 0 | H36: 0 | I36: 0 | R36: 0 | S36: 0 | T36: 0 | U36: 0 | V36: 0 | W36: 0 | X36: 0 | Y36: 0 | AH36: 0 | AI36: 0 | AJ36: 0 | AK36: 0 | AL36: 0 | AM36: 0 | AN36: 0 | AO36: 0 | AX36: 0 | AY36: 0 | AZ36: 0 | BA36: 0 | BB36: 0 | BC36: 0 | BD36: 0 | BE36: 0
A37: 6 | B37: 0 | C37: 0 | D37: 0 | E37: 0 | F37: 0 | G37: 0 | H37: 0 | I37: 0 | R37: 0 | S37: 0 | T37: 0 | U37: 0 | V37: 0 | W37: 0 | X37: 0 | Y37: 0 | AH37: 0 | AI37: 0 | AJ37: 0 | AK37: 0 | AL37: 0 | AM37: 0 | AN37: 0 | AO37: 0 | AX37: 0 | AY37: 0 | AZ37: 0 | BA37: 0 | BB37: 0 | BC37: 0 | BD37: 0 | BE37: 0
A38: 7 | B38: 3 | C38: 3 | D38: 0 | E38: 5 | F38: 5 | G38: 0 | H38: 5 | I38: 0 | R38: -3 | S38: -3 | T38: 0 | U38: 5 | V38: 5 | W38: 0 | X38: -5 | Y38: 0 | AH38: 3 | AI38: 3 | AJ38: 0 | AK38: -5 | AL38: -5 | AM38: 0 | AN38: 5 | AO38: 0 | AX38: -3 | AY38: -3 | AZ38: 0 | BA38: -5 | BB38: -5 | BC38: 0 | BD38: -5 | BE38: 0
H41: Sum Probabilities | I41: =SUM(B2:BM2) -> 1
B42: Basis
B43: 10 | C43: 10 | D43: 10 | E43: 40 | F43: 40 | G43: 40 | H43: 40 | I43: 20 | K43: =SUM(B43:I43) -> 210
B44: 10 | C44: 10 | D44: 10 | E44: 40 | F44: 40 | G44: 40 | H44: 40 | I44: 20
B45: 10 | C45: 10 | D45: 10 | E45: 40 | F45: 40 | G45: 40 | H45: 40 | I45: 20
B46: 10 | C46: 10 | D46: 10 | E46: 40 | F46: 40 | G46: 40 | H46: 40 | I46: 20
...

Sheet Demand Stage 3
A1: Node Number | B1: =(Parameters!B8+1)*Parameters!B7 + 1 -> 41 | R1: =B1+Parameters!$B$7 -> 49 | AH1: =R1+Parameters!$B$7 -> 57 | AX1: =AH1+Parameters!$B$7 -> 65 | BN1: =AX1+Parameters!$B$7 -> 73 | CD1: =BN1+Parameters!$B$7 -> 81 | CT1: =CD1+Parameters!$B$7 -> 89 | DJ1: =CT1+Parameters!$B$7 -> 97 | DZ1: =DJ1+Parameters!$B$7 -> 105 | EP1: =DZ1+Parameters!$B$7 -> 113 | FF1: =EP1+Parameters!$B$7 -> 121 | FV1: =FF1+Parameters!$B$7 -> 129 | GL1: =FV1+Parameters!$B$7 -> 137 | HB1: =GL1+Parameters!$B$7 -> 145 | HR1: =HB1+Parameters!$B$7 -> 153 | IH1: =HR1+Parameters!$B$7 -> 161
A2: Probability | B2: =1/16 -> 0.0625 | R2: =B2 -> 0.0625 | AH2: =R2 -> 0.0625 | AX2: =AH2 -> 0.0625 | BN2: =AX2 -> 0.0625 | CD2: =BN2 -> 0.0625 | CT2: =CD2 -> 0.0625 | DJ2: =CT2 -> 0.0625 | DZ2: =DJ2 -> 0.0625 | EP2: =DZ2 -> 0.0625 | FF2: =EP2 -> 0.0625 | FV2: =FF2 -> 0.0625 | GL2: =FV2 -> 0.0625 | HB2: =GL2 -> 0.0625 | HR2: =HB2 -> 0.0625 | IH2: =HR2 -> 0.0625
A3: Parent Node Number | B3: 9 | R3: 9 | AH3: 9 | AX3: 9 | BN3: 17 | CD3: 17 | CT3: 17 | DJ3: 17 | DZ3: 25 | EP3: 25 | FF3: 25 | FV3: 25 | GL3: 33 | HB3: 33 | HR3: 33 | IH3: 33
B4: gas or mix | J4: pure hydrogen | R4: gas or mix | Z4: pure hydrogen | AH4: gas or mix | AP4: pure hydrogen | AX4: gas or mix | BF4: pure hydrogen | BN4: gas or mix | BV4: pure hydrogen | CD4: gas or mix | CL4: pure hydrogen | CT4: gas or mix | DB4: pure hydrogen | DJ4: gas or mix | DR4: pure hydrogen | DZ4: gas or mix | EH4: pure hydrogen | EP4: gas or mix | EX4: pure hydrogen | FF4: gas or mix | FN4: pure hydrogen | FV4: gas or mix | GD4: pure hydrogen | GL4: gas or mix | GT4: pure hydrogen | HB4: gas or mix | HJ4: pure hydrogen | HR4: gas or mix | HZ4: pure hydrogen | IH4: gas or mix | IP4: pure hydrogen
A5: Hour | B5: ='Demand Stage 2'!B4 -> ST.FERGUS | C5: ='Demand Stage 2'!C4 -> EASINGTON | D5: ='Demand Stage 2'!D4 -> TEESSIDE | E5: ='Demand Stage 2'!E4 -> EMDEN | F5: ='Demand Stage 2'!F4 -> DORNUM | G5: ='Demand Stage 2'!G4 -> ZEEBRUGGE | H5: ='Demand Stage 2'!H4 -> DUNKERQUE | I5: ='Demand Stage 2'!I4 -> POLAND | ... Q5: ='Demand Stage 2'!Q4 -> POLAND | R5: ='Demand Stage 2'!B4 -> ST.FERGUS | S5: ='Demand Stage 2'!C4 -> EASINGTON | T5: ='Demand Stage 2'!D4 -> TEESSIDE | U5: ='Demand Stage 2'!E4 -> EMDEN | V5: ='Demand Stage 2'!F4 -> DORNUM | W5: ='Demand Stage 2'!G4 -> ZEEBRUGGE | X5: ='Demand Stage 2'!H4 -> DUNKERQUE | Y5: ='Demand Stage 2'!I4 -> POLAND | ... AG5: ='Demand Stage 2'!Q4 -> POLAND | AH5: ='Demand Stage 2'!B4 -> ST.FERGUS | AI5: ='Demand Stage 2'!C4 -> EASINGTON | AJ5: ='Demand Stage 2'!D4 -> TEESSIDE | AK5: ='Demand Stage 2'!E4 -> EMDEN | AL5: ='Demand Stage 2'!F4 -> DORNUM | AM5: ='Demand Stage 2'!G4 -> ZEEBRUGGE | AN5: ='Demand Stage 2'!H4 -> DUNKERQUE | AO5: ='Demand Stage 2'!I4 -> POLAND | ... AW5: ='Demand Stage 2'!Q4 -> POLAND | AX5: ='Demand Stage 2'!B4 -> ST.FERGUS | AY5: ='Demand Stage 2'!C4 -> EASINGTON | AZ5: ='Demand Stage 2'!D4 -> TEESSIDE | BA5: ='Demand Stage 2'!E4 -> EMDEN | BB5: ='Demand Stage 2'!F4 -> DORNUM | BC5: ='Demand Stage 2'!G4 -> ZEEBRUGGE | BD5: ='Demand Stage 2'!H4 -> DUNKERQUE | BE5: ='Demand Stage 2'!I4 -> POLAND | ... CC5: ='Demand Stage 2'!AG4 -> POLAND | CD5: =BN5 -> ST.FERGUS | CE5: =BO5 -> EASINGTON | CF5: =BP5 -> TEESSIDE | CG5: =BQ5 -> EMDEN | CH5: =BR5 -> DORNUM | CI5: =BS5 -> ZEEBRUGGE | CJ5: =BT5 -> DUNKERQUE | CK5: =BU5 -> POLAND | ... DY5: =DI5 -> POLAND | DZ5: ='Demand Stage 2'!AH4 -> ST.FERGUS | EA5: ='Demand Stage 2'!AI4 -> EASINGTON | EB5: ='Demand Stage 2'!AJ4 -> TEESSIDE | EC5: ='Demand Stage 2'!AK4 -> EMDEN | ED5: ='Demand Stage 2'!AL4 -> DORNUM | EE5: ='Demand Stage 2'!AM4 -> ZEEBRUGGE | EF5: ='Demand Stage 2'!AN4 -> DUNKERQUE | EG5: ='Demand Stage 2'!AO4 -> POLAND | ... EO5: ='Demand Stage 2'!AW4 -> POLAND | EP5: =DZ5 -> ST.FERGUS | EQ5: =EA5 -> EASINGTON | ER5: =EB5 -> TEESSIDE | ES5: =EC5 -> EMDEN | ET5: =ED5 -> DORNUM | EU5: =EE5 -> ZEEBRUGGE | EV5: =EF5 -> DUNKERQUE | EW5: =EG5 -> POLAND | ... GK5: =FU5 -> POLAND | GL5: ='Demand Stage 2'!AX4 -> ST.FERGUS | GM5: ='Demand Stage 2'!AY4 -> EASINGTON | GN5: ='Demand Stage 2'!AZ4 -> TEESSIDE | GO5: ='Demand Stage 2'!BA4 -> EMDEN | GP5: ='Demand Stage 2'!BB4 -> DORNUM | GQ5: ='Demand Stage 2'!BC4 -> ZEEBRUGGE | GR5: ='Demand Stage 2'!BD4 -> DUNKERQUE | GS5: ='Demand Stage 2'!BE4 -> POLAND | ... HA5: ='Demand Stage 2'!BM4 -> ST.FERGUS | HB5: =GL5 -> ST.FERGUS | HC5: =GM5 -> EASINGTON | HD5: =GN5 -> TEESSIDE | HE5: =GO5 -> EMDEN | HF5: =GP5 -> DORNUM | HG5: =GQ5 -> ZEEBRUGGE | HH5: =GR5 -> DUNKERQUE | HI5: =GS5 -> POLAND | ... IW5: =IG5 -> ST.FERGUS
A6: 0 | B6: ='Demand Stage 2'!B5 -> 10 | C6: ='Demand Stage 2'!C5 -> 10 | D6: ='Demand Stage 2'!D5 -> 10 | E6: ='Demand Stage 2'!E5 -> 40 | F6: ='Demand Stage 2'!F5 -> 40 | G6: ='Demand Stage 2'!G5 -> 40 | H6: ='Demand Stage 2'!H5 -> 40 | I6: ='Demand Stage 2'!I5 -> 20 | ... Q6: ='Demand Stage 2'!Q5 -> 0 | R6: ='Demand Stage 2'!B5 -> 10 | S6: ='Demand Stage 2'!C5 -> 10 | T6: ='Demand Stage 2'!D5 -> 10 | U6: ='Demand Stage 2'!E5 -> 40 | V6: ='Demand Stage 2'!F5 -> 40 | W6: ='Demand Stage 2'!G5 -> 40 | X6: ='Demand Stage 2'!H5 -> 40 | Y6: ='Demand Stage 2'!I5 -> 20 | ... AG6: ='Demand Stage 2'!Q5 -> 0 | AH6: ='Demand Stage 2'!B5 -> 10 | AI6: ='Demand Stage 2'!C5 -> 10 | AJ6: ='Demand Stage 2'!D5 -> 10 | AK6: ='Demand Stage 2'!E5 -> 40 | AL6: ='Demand Stage 2'!F5 -> 40 | AM6: ='Demand Stage 2'!G5 -> 40 | AN6: ='Demand Stage 2'!H5 -> 40 | AO6: ='Demand Stage 2'!I5 -> 20 | ... AW6: ='Demand Stage 2'!Q5 -> 0 | AX6: ='Demand Stage 2'!B5 -> 10 | AY6: ='Demand Stage 2'!C5 -> 10 | AZ6: ='Demand Stage 2'!D5 -> 10 | BA6: ='Demand Stage 2'!E5 -> 40 | BB6: ='Demand Stage 2'!F5 -> 40 | BC6: ='Demand Stage 2'!G5 -> 40 | BD6: ='Demand Stage 2'!H5 -> 40 | BE6: ='Demand Stage 2'!I5 -> 20 | ... CC6: ='Demand Stage 2'!AG5 -> 0 | CD6: =BN6 -> 10 | CE6: =BO6 -> 10 | CF6: =BP6 -> 10 | CG6: =BQ6 -> 40 | CH6: =BR6 -> 40 | CI6: =BS6 -> 40 | CJ6: =BT6 -> 40 | CK6: =BU6 -> 20 | ... DY6: =DI6 -> 0 | DZ6: ='Demand Stage 2'!AH5 -> 10 | EA6: ='Demand Stage 2'!AI5 -> 10 | EB6: ='Demand Stage 2'!AJ5 -> 10 | EC6: ='Demand Stage 2'!AK5 -> 40 | ED6: ='Demand Stage 2'!AL5 -> 40 | EE6: ='Demand Stage 2'!AM5 -> 40 | EF6: ='Demand Stage 2'!AN5 -> 40 | EG6: ='Demand Stage 2'!AO5 -> 20 | ... EO6: ='Demand Stage 2'!AW5 -> 0 | EP6: =DZ6 -> 10 | EQ6: =EA6 -> 10 | ER6: =EB6 -> 10 | ES6: =EC6 -> 40 | ET6: =ED6 -> 40 | EU6: =EE6 -> 40 | EV6: =EF6 -> 40 | EW6: =EG6 -> 20 | ... GK6: =FU6 -> 0 | GL6: ='Demand Stage 2'!AX5 -> 10 | GM6: ='Demand Stage 2'!AY5 -> 10 | GN6: ='Demand Stage 2'!AZ5 -> 10 | GO6: ='Demand Stage 2'!BA5 -> 40 | GP6: ='Demand Stage 2'!BB5 -> 40 | GQ6: ='Demand Stage 2'!BC5 -> 40 | GR6: ='Demand Stage 2'!BD5 -> 40 | GS6: ='Demand Stage 2'!BE5 -> 20 | ... HA6: ='Demand Stage 2'!BM5 -> 0 | HB6: =GL6 -> 10 | HC6: =GM6 -> 10 | HD6: =GN6 -> 10 | HE6: =GO6 -> 40 | HF6: =GP6 -> 40 | HG6: =GQ6 -> 40 | HH6: =GR6 -> 40 | HI6: =GS6 -> 20 | ... IW6: =IG6 -> 0
A7: 1 | B7: ='Demand Stage 2'!B6 -> 10 | C7: ='Demand Stage 2'!C6 -> 10 | D7: ='Demand Stage 2'!D6 -> 10 | E7: ='Demand Stage 2'!E6 -> 40 | F7: ='Demand Stage 2'!F6 -> 40 | G7: ='Demand Stage 2'!G6 -> 40 | H7: ='Demand Stage 2'!H6 -> 40 | I7: ='Demand Stage 2'!I6 -> 20 | ... Q7: ='Demand Stage 2'!Q6 -> 0 | R7: ='Demand Stage 2'!B6 -> 10 | S7: ='Demand Stage 2'!C6 -> 10 | T7: ='Demand Stage 2'!D6 -> 10 | U7: ='Demand Stage 2'!E6 -> 40 | V7: ='Demand Stage 2'!F6 -> 40 | W7: ='Demand Stage 2'!G6 -> 40 | X7: ='Demand Stage 2'!H6 -> 40 | Y7: ='Demand Stage 2'!I6 -> 20 | ... AG7: ='Demand Stage 2'!Q6 -> 0 | AH7: ='Demand Stage 2'!B6 -> 10 | AI7: ='Demand Stage 2'!C6 -> 10 | AJ7: ='Demand Stage 2'!D6 -> 10 | AK7: ='Demand Stage 2'!E6 -> 40 | AL7: ='Demand Stage 2'!F6 -> 40 | AM7: ='Demand Stage 2'!G6 -> 40 | AN7: ='Demand Stage 2'!H6 -> 40 | AO7: ='Demand Stage 2'!I6 -> 20 | ... AW7: ='Demand Stage 2'!Q6 -> 0 | AX7: ='Demand Stage 2'!B6 -> 10 | AY7: ='Demand Stage 2'!C6 -> 10 | AZ7: ='Demand Stage 2'!D6 -> 10 | BA7: ='Demand Stage 2'!E6 -> 40 | BB7: ='Demand Stage 2'!F6 -> 40 | BC7: ='Demand Stage 2'!G6 -> 40 | BD7: ='Demand Stage 2'!H6 -> 40 | BE7: ='Demand Stage 2'!I6 -> 20 | ... CC7: ='Demand Stage 2'!AG6 -> 0 | CD7: =BN7 -> 10 | CE7: =BO7 -> 10 | CF7: =BP7 -> 10 | CG7: =BQ7 -> 40 | CH7: =BR7 -> 40 | CI7: =BS7 -> 40 | CJ7: =BT7 -> 40 | CK7: =BU7 -> 20 | ... DY7: =DI7 -> 0 | DZ7: ='Demand Stage 2'!AH6 -> 10 | EA7: ='Demand Stage 2'!AI6 -> 10 | EB7: ='Demand Stage 2'!AJ6 -> 10 | EC7: ='Demand Stage 2'!AK6 -> 40 | ED7: ='Demand Stage 2'!AL6 -> 40 | EE7: ='Demand Stage 2'!AM6 -> 40 | EF7: ='Demand Stage 2'!AN6 -> 40 | EG7: ='Demand Stage 2'!AO6 -> 20 | ... EO7: ='Demand Stage 2'!AW6 -> 0 | EP7: =DZ7 -> 10 | EQ7: =EA7 -> 10 | ER7: =EB7 -> 10 | ES7: =EC7 -> 40 | ET7: =ED7 -> 40 | EU7: =EE7 -> 40 | EV7: =EF7 -> 40 | EW7: =EG7 -> 20 | ... GK7: =FU7 -> 0 | GL7: ='Demand Stage 2'!AX6 -> 10 | GM7: ='Demand Stage 2'!AY6 -> 10 | GN7: ='Demand Stage 2'!AZ6 -> 10 | GO7: ='Demand Stage 2'!BA6 -> 40 | GP7: ='Demand Stage 2'!BB6 -> 40 | GQ7: ='Demand Stage 2'!BC6 -> 40 | GR7: ='Demand Stage 2'!BD6 -> 40 | GS7: ='Demand Stage 2'!BE6 -> 20 | ... HA7: ='Demand Stage 2'!BM6 -> 0 | HB7: =GL7 -> 10 | HC7: =GM7 -> 10 | HD7: =GN7 -> 10 | HE7: =GO7 -> 40 | HF7: =GP7 -> 40 | HG7: =GQ7 -> 40 | HH7: =GR7 -> 40 | HI7: =GS7 -> 20 | ... IW7: =IG7 -> 0
A8: 2 | B8: ='Demand Stage 2'!B7 -> 10 | C8: ='Demand Stage 2'!C7 -> 10 | D8: ='Demand Stage 2'!D7 -> 10 | E8: ='Demand Stage 2'!E7 -> 40 | F8: ='Demand Stage 2'!F7 -> 40 | G8: ='Demand Stage 2'!G7 -> 40 | H8: ='Demand Stage 2'!H7 -> 40 | I8: ='Demand Stage 2'!I7 -> 20 | ... Q8: ='Demand Stage 2'!Q7 -> 0 | R8: ='Demand Stage 2'!B7 -> 10 | S8: ='Demand Stage 2'!C7 -> 10 | T8: ='Demand Stage 2'!D7 -> 10 | U8: ='Demand Stage 2'!E7 -> 40 | V8: ='Demand Stage 2'!F7 -> 40 | W8: ='Demand Stage 2'!G7 -> 40 | X8: ='Demand Stage 2'!H7 -> 40 | Y8: ='Demand Stage 2'!I7 -> 20 | ... AG8: ='Demand Stage 2'!Q7 -> 0 | AH8: ='Demand Stage 2'!B7 -> 10 | AI8: ='Demand Stage 2'!C7 -> 10 | AJ8: ='Demand Stage 2'!D7 -> 10 | AK8: ='Demand Stage 2'!E7 -> 40 | AL8: ='Demand Stage 2'!F7 -> 40 | AM8: ='Demand Stage 2'!G7 -> 40 | AN8: ='Demand Stage 2'!H7 -> 40 | AO8: ='Demand Stage 2'!I7 -> 20 | ... AW8: ='Demand Stage 2'!Q7 -> 0 | AX8: ='Demand Stage 2'!B7 -> 10 | AY8: ='Demand Stage 2'!C7 -> 10 | AZ8: ='Demand Stage 2'!D7 -> 10 | BA8: ='Demand Stage 2'!E7 -> 40 | BB8: ='Demand Stage 2'!F7 -> 40 | BC8: ='Demand Stage 2'!G7 -> 40 | BD8: ='Demand Stage 2'!H7 -> 40 | BE8: ='Demand Stage 2'!I7 -> 20 | ... CC8: ='Demand Stage 2'!AG7 -> 0 | CD8: =BN8 -> 10 | CE8: =BO8 -> 10 | CF8: =BP8 -> 10 | CG8: =BQ8 -> 40 | CH8: =BR8 -> 40 | CI8: =BS8 -> 40 | CJ8: =BT8 -> 40 | CK8: =BU8 -> 20 | ... DY8: =DI8 -> 0 | DZ8: ='Demand Stage 2'!AH7 -> 10 | EA8: ='Demand Stage 2'!AI7 -> 10 | EB8: ='Demand Stage 2'!AJ7 -> 10 | EC8: ='Demand Stage 2'!AK7 -> 40 | ED8: ='Demand Stage 2'!AL7 -> 40 | EE8: ='Demand Stage 2'!AM7 -> 40 | EF8: ='Demand Stage 2'!AN7 -> 40 | EG8: ='Demand Stage 2'!AO7 -> 20 | ... EO8: ='Demand Stage 2'!AW7 -> 0 | EP8: =DZ8 -> 10 | EQ8: =EA8 -> 10 | ER8: =EB8 -> 10 | ES8: =EC8 -> 40 | ET8: =ED8 -> 40 | EU8: =EE8 -> 40 | EV8: =EF8 -> 40 | EW8: =EG8 -> 20 | ... GK8: =FU8 -> 0 | GL8: ='Demand Stage 2'!AX7 -> 10 | GM8: ='Demand Stage 2'!AY7 -> 10 | GN8: ='Demand Stage 2'!AZ7 -> 10 | GO8: ='Demand Stage 2'!BA7 -> 40 | GP8: ='Demand Stage 2'!BB7 -> 40 | GQ8: ='Demand Stage 2'!BC7 -> 40 | GR8: ='Demand Stage 2'!BD7 -> 40 | GS8: ='Demand Stage 2'!BE7 -> 20 | ... HA8: ='Demand Stage 2'!BM7 -> 0 | HB8: =GL8 -> 10 | HC8: =GM8 -> 10 | HD8: =GN8 -> 10 | HE8: =GO8 -> 40 | HF8: =GP8 -> 40 | HG8: =GQ8 -> 40 | HH8: =GR8 -> 40 | HI8: =GS8 -> 20 | ... IW8: =IG8 -> 0
A9: 3 | B9: ='Demand Stage 2'!B8 -> 10 | C9: ='Demand Stage 2'!C8 -> 10 | D9: ='Demand Stage 2'!D8 -> 10 | E9: ='Demand Stage 2'!E8 -> 40 | F9: ='Demand Stage 2'!F8 -> 40 | G9: ='Demand Stage 2'!G8 -> 40 | H9: ='Demand Stage 2'!H8 -> 40 | I9: ='Demand Stage 2'!I8 -> 20 | ... Q9: ='Demand Stage 2'!Q8 -> 0 | R9: ='Demand Stage 2'!B8 -> 10 | S9: ='Demand Stage 2'!C8 -> 10 | T9: ='Demand Stage 2'!D8 -> 10 | U9: ='Demand Stage 2'!E8 -> 40 | V9: ='Demand Stage 2'!F8 -> 40 | W9: ='Demand Stage 2'!G8 -> 40 | X9: ='Demand Stage 2'!H8 -> 40 | Y9: ='Demand Stage 2'!I8 -> 20 | ... AG9: ='Demand Stage 2'!Q8 -> 0 | AH9: ='Demand Stage 2'!B8 -> 10 | AI9: ='Demand Stage 2'!C8 -> 10 | AJ9: ='Demand Stage 2'!D8 -> 10 | AK9: ='Demand Stage 2'!E8 -> 40 | AL9: ='Demand Stage 2'!F8 -> 40 | AM9: ='Demand Stage 2'!G8 -> 40 | AN9: ='Demand Stage 2'!H8 -> 40 | AO9: ='Demand Stage 2'!I8 -> 20 | ... AW9: ='Demand Stage 2'!Q8 -> 0 | AX9: ='Demand Stage 2'!B8 -> 10 | AY9: ='Demand Stage 2'!C8 -> 10 | AZ9: ='Demand Stage 2'!D8 -> 10 | BA9: ='Demand Stage 2'!E8 -> 40 | BB9: ='Demand Stage 2'!F8 -> 40 | BC9: ='Demand Stage 2'!G8 -> 40 | BD9: ='Demand Stage 2'!H8 -> 40 | BE9: ='Demand Stage 2'!I8 -> 20 | ... CC9: ='Demand Stage 2'!AG8 -> 0 | CD9: =BN9 -> 10 | CE9: =BO9 -> 10 | CF9: =BP9 -> 10 | CG9: =BQ9 -> 40 | CH9: =BR9 -> 40 | CI9: =BS9 -> 40 | CJ9: =BT9 -> 40 | CK9: =BU9 -> 20 | ... DY9: =DI9 -> 0 | DZ9: ='Demand Stage 2'!AH8 -> 10 | EA9: ='Demand Stage 2'!AI8 -> 10 | EB9: ='Demand Stage 2'!AJ8 -> 10 | EC9: ='Demand Stage 2'!AK8 -> 40 | ED9: ='Demand Stage 2'!AL8 -> 40 | EE9: ='Demand Stage 2'!AM8 -> 40 | EF9: ='Demand Stage 2'!AN8 -> 40 | EG9: ='Demand Stage 2'!AO8 -> 20 | ... EO9: ='Demand Stage 2'!AW8 -> 0 | EP9: =DZ9 -> 10 | EQ9: =EA9 -> 10 | ER9: =EB9 -> 10 | ES9: =EC9 -> 40 | ET9: =ED9 -> 40 | EU9: =EE9 -> 40 | EV9: =EF9 -> 40 | EW9: =EG9 -> 20 | ... GK9: =FU9 -> 0 | GL9: ='Demand Stage 2'!AX8 -> 10 | GM9: ='Demand Stage 2'!AY8 -> 10 | GN9: ='Demand Stage 2'!AZ8 -> 10 | GO9: ='Demand Stage 2'!BA8 -> 40 | GP9: ='Demand Stage 2'!BB8 -> 40 | GQ9: ='Demand Stage 2'!BC8 -> 40 | GR9: ='Demand Stage 2'!BD8 -> 40 | GS9: ='Demand Stage 2'!BE8 -> 20 | ... HA9: ='Demand Stage 2'!BM8 -> 0 | HB9: =GL9 -> 10 | HC9: =GM9 -> 10 | HD9: =GN9 -> 10 | HE9: =GO9 -> 40 | HF9: =GP9 -> 40 | HG9: =GQ9 -> 40 | HH9: =GR9 -> 40 | HI9: =GS9 -> 20 | ... IW9: =IG9 -> 0
A10: 4 | B10: ='Demand Stage 2'!B9 -> 13 | C10: ='Demand Stage 2'!C9 -> 13 | D10: ='Demand Stage 2'!D9 -> 10 | E10: ='Demand Stage 2'!E9 -> 50 | F10: ='Demand Stage 2'!F9 -> 50 | G10: ='Demand Stage 2'!G9 -> 40 | H10: ='Demand Stage 2'!H9 -> 50 | I10: ='Demand Stage 2'!I9 -> 20 | R10: ='Demand Stage 2'!B9 -> 13 | S10: ='Demand Stage 2'!C9 -> 13 | T10: ='Demand Stage 2'!D9 -> 10 | U10: ='Demand Stage 2'!E9 -> 50 | V10: ='Demand Stage 2'!F9 -> 50 | W10: ='Demand Stage 2'!G9 -> 40 | X10: ='Demand Stage 2'!H9 -> 50 | Y10: ='Demand Stage 2'!I9 -> 20 | AH10: ='Demand Stage 2'!B9 -> 13 | AI10: ='Demand Stage 2'!C9 -> 13 | AJ10: ='Demand Stage 2'!D9 -> 10 | AK10: ='Demand Stage 2'!E9 -> 50 | AL10: ='Demand Stage 2'!F9 -> 50 | AM10: ='Demand Stage 2'!G9 -> 40 | AN10: ='Demand Stage 2'!H9 -> 50 | AO10: ='Demand Stage 2'!I9 -> 20 | AX10: ='Demand Stage 2'!B9 -> 13 | AY10: ='Demand Stage 2'!C9 -> 13 | AZ10: ='Demand Stage 2'!D9 -> 10 | BA10: ='Demand Stage 2'!E9 -> 50 | BB10: ='Demand Stage 2'!F9 -> 50 | BC10: ='Demand Stage 2'!G9 -> 40 | BD10: ='Demand Stage 2'!H9 -> 50 | BE10: ='Demand Stage 2'!I9 -> 20 | BN10: ='Demand Stage 2'!R9 -> 7 | BO10: ='Demand Stage 2'!S9 -> 7 | BP10: ='Demand Stage 2'!T9 -> 10 | BQ10: ='Demand Stage 2'!U9 -> 50 | BR10: ='Demand Stage 2'!V9 -> 50 | BS10: ='Demand Stage 2'!W9 -> 40 | BT10: ='Demand Stage 2'!X9 -> 40 | BU10: ='Demand Stage 2'!Y9 -> 20 | CD10: =BN10 -> 7 | CE10: =BO10 -> 7 | CF10: =BP10 -> 10 | CG10: =BQ10 -> 50 | CH10: =BR10 -> 50 | CI10: =BS10 -> 40 | CJ10: =BT10 -> 40 | CK10: =BU10 -> 20 | CT10: =CD10 -> 7 | CU10: =CE10 -> 7 | CV10: =CF10 -> 10 | CW10: =CG10 -> 50 | CX10: =CH10 -> 50 | CY10: =CI10 -> 40 | CZ10: =CJ10 -> 40 | DA10: =CK10 -> 20 | DJ10: =CT10 -> 7 | DK10: =CU10 -> 7 | DL10: =CV10 -> 10 | DM10: =CW10 -> 50 | DN10: =CX10 -> 50 | DO10: =CY10 -> 40 | DP10: =CZ10 -> 40 | DQ10: =DA10 -> 20 | DZ10: ='Demand Stage 2'!AH9 -> 13 | EA10: ='Demand Stage 2'!AI9 -> 13 | EB10: ='Demand Stage 2'!AJ9 -> 10 | EC10: ='Demand Stage 2'!AK9 -> 40 | ED10: ='Demand Stage 2'!AL9 -> 40 | EE10: ='Demand Stage 2'!AM9 -> 40 | EF10: ='Demand Stage 2'!AN9 -> 50 | EG10: ='Demand Stage 2'!AO9 -> 20 | EP10: =DZ10 -> 13 | EQ10: =EA10 -> 13 | ER10: =EB10 -> 10 | ES10: =EC10 -> 40 | ET10: =ED10 -> 40 | EU10: =EE10 -> 40 | EV10: =EF10 -> 50 | EW10: =EG10 -> 20 | FF10: =EP10 -> 13 | FG10: =EQ10 -> 13 | FH10: =ER10 -> 10 | FI10: =ES10 -> 40 | FJ10: =ET10 -> 40 | FK10: =EU10 -> 40 | FL10: =EV10 -> 50 | FM10: =EW10 -> 20 | FV10: =FF10 -> 13 | FW10: =FG10 -> 13 | FX10: =FH10 -> 10 | FY10: =FI10 -> 40 | FZ10: =FJ10 -> 40 | GA10: =FK10 -> 40 | GB10: =FL10 -> 50 | GC10: =FM10 -> 20 | GL10: ='Demand Stage 2'!AX9 -> 7 | GM10: ='Demand Stage 2'!AY9 -> 7 | GN10: ='Demand Stage 2'!AZ9 -> 10 | GO10: ='Demand Stage 2'!BA9 -> 40 | GP10: ='Demand Stage 2'!BB9 -> 40 | GQ10: ='Demand Stage 2'!BC9 -> 40 | GR10: ='Demand Stage 2'!BD9 -> 40 | GS10: ='Demand Stage 2'!BE9 -> 20 | HB10: =GL10 -> 7 | HC10: =GM10 -> 7 | HD10: =GN10 -> 10 | HE10: =GO10 -> 40 | HF10: =GP10 -> 40 | HG10: =GQ10 -> 40 | HH10: =GR10 -> 40 | HI10: =GS10 -> 20 | HR10: =HB10 -> 7 | HS10: =HC10 -> 7 | HT10: =HD10 -> 10 | HU10: =HE10 -> 40 | HV10: =HF10 -> 40 | HW10: =HG10 -> 40 | HX10: =HH10 -> 40 | HY10: =HI10 -> 20 | IH10: =HR10 -> 7 | II10: =HS10 -> 7 | IJ10: =HT10 -> 10 | IK10: =HU10 -> 40 | IL10: =HV10 -> 40 | IM10: =HW10 -> 40 | IN10: =HX10 -> 40 | IO10: =HY10 -> 20
A11: 5 | B11: ='Demand Stage 2'!B10 -> 10 | C11: ='Demand Stage 2'!C10 -> 10 | D11: ='Demand Stage 2'!D10 -> 10 | E11: ='Demand Stage 2'!E10 -> 40 | F11: ='Demand Stage 2'!F10 -> 40 | G11: ='Demand Stage 2'!G10 -> 40 | H11: ='Demand Stage 2'!H10 -> 35 | I11: ='Demand Stage 2'!I10 -> 20 | R11: ='Demand Stage 2'!B10 -> 10 | S11: ='Demand Stage 2'!C10 -> 10 | T11: ='Demand Stage 2'!D10 -> 10 | U11: ='Demand Stage 2'!E10 -> 40 | V11: ='Demand Stage 2'!F10 -> 40 | W11: ='Demand Stage 2'!G10 -> 40 | X11: ='Demand Stage 2'!H10 -> 35 | Y11: ='Demand Stage 2'!I10 -> 20 | AH11: ='Demand Stage 2'!B10 -> 10 | AI11: ='Demand Stage 2'!C10 -> 10 | AJ11: ='Demand Stage 2'!D10 -> 10 | AK11: ='Demand Stage 2'!E10 -> 40 | AL11: ='Demand Stage 2'!F10 -> 40 | AM11: ='Demand Stage 2'!G10 -> 40 | AN11: ='Demand Stage 2'!H10 -> 35 | AO11: ='Demand Stage 2'!I10 -> 20 | AX11: ='Demand Stage 2'!B10 -> 10 | AY11: ='Demand Stage 2'!C10 -> 10 | AZ11: ='Demand Stage 2'!D10 -> 10 | BA11: ='Demand Stage 2'!E10 -> 40 | BB11: ='Demand Stage 2'!F10 -> 40 | BC11: ='Demand Stage 2'!G10 -> 40 | BD11: ='Demand Stage 2'!H10 -> 35 | BE11: ='Demand Stage 2'!I10 -> 20 | BN11: ='Demand Stage 2'!R10 -> 10 | BO11: ='Demand Stage 2'!S10 -> 10 | BP11: ='Demand Stage 2'!T10 -> 10 | BQ11: ='Demand Stage 2'!U10 -> 40 | BR11: ='Demand Stage 2'!V10 -> 40 | BS11: ='Demand Stage 2'!W10 -> 40 | BT11: ='Demand Stage 2'!X10 -> 35 | BU11: ='Demand Stage 2'!Y10 -> 20 | CD11: =BN11 -> 10 | CE11: =BO11 -> 10 | CF11: =BP11 -> 10 | CG11: =BQ11 -> 40 | CH11: =BR11 -> 40 | CI11: =BS11 -> 40 | CJ11: =BT11 -> 35 | CK11: =BU11 -> 20 | CT11: =CD11 -> 10 | CU11: =CE11 -> 10 | CV11: =CF11 -> 10 | CW11: =CG11 -> 40 | CX11: =CH11 -> 40 | CY11: =CI11 -> 40 | CZ11: =CJ11 -> 35 | DA11: =CK11 -> 20 | DJ11: =CT11 -> 10 | DK11: =CU11 -> 10 | DL11: =CV11 -> 10 | DM11: =CW11 -> 40 | DN11: =CX11 -> 40 | DO11: =CY11 -> 40 | DP11: =CZ11 -> 35 | DQ11: =DA11 -> 20 | DZ11: ='Demand Stage 2'!AH10 -> 10 | EA11: ='Demand Stage 2'!AI10 -> 10 | EB11: ='Demand Stage 2'!AJ10 -> 10 | EC11: ='Demand Stage 2'!AK10 -> 40 | ED11: ='Demand Stage 2'!AL10 -> 40 | EE11: ='Demand Stage 2'!AM10 -> 40 | EF11: ='Demand Stage 2'!AN10 -> 35 | EG11: ='Demand Stage 2'!AO10 -> 20 | EP11: =DZ11 -> 10 | EQ11: =EA11 -> 10 | ER11: =EB11 -> 10 | ES11: =EC11 -> 40 | ET11: =ED11 -> 40 | EU11: =EE11 -> 40 | EV11: =EF11 -> 35 | EW11: =EG11 -> 20 | FF11: =EP11 -> 10 | FG11: =EQ11 -> 10 | FH11: =ER11 -> 10 | FI11: =ES11 -> 40 | FJ11: =ET11 -> 40 | FK11: =EU11 -> 40 | FL11: =EV11 -> 35 | FM11: =EW11 -> 20 | FV11: =FF11 -> 10 | FW11: =FG11 -> 10 | FX11: =FH11 -> 10 | FY11: =FI11 -> 40 | FZ11: =FJ11 -> 40 | GA11: =FK11 -> 40 | GB11: =FL11 -> 35 | GC11: =FM11 -> 20 | GL11: ='Demand Stage 2'!AX10 -> 10 | GM11: ='Demand Stage 2'!AY10 -> 10 | GN11: ='Demand Stage 2'!AZ10 -> 10 | GO11: ='Demand Stage 2'!BA10 -> 40 | GP11: ='Demand Stage 2'!BB10 -> 40 | GQ11: ='Demand Stage 2'!BC10 -> 40 | GR11: ='Demand Stage 2'!BD10 -> 35 | GS11: ='Demand Stage 2'!BE10 -> 20 | HB11: =GL11 -> 10 | HC11: =GM11 -> 10 | HD11: =GN11 -> 10 | HE11: =GO11 -> 40 | HF11: =GP11 -> 40 | HG11: =GQ11 -> 40 | HH11: =GR11 -> 35 | HI11: =GS11 -> 20 | HR11: =HB11 -> 10 | HS11: =HC11 -> 10 | HT11: =HD11 -> 10 | HU11: =HE11 -> 40 | HV11: =HF11 -> 40 | HW11: =HG11 -> 40 | HX11: =HH11 -> 35 | HY11: =HI11 -> 20 | IH11: =HR11 -> 10 | II11: =HS11 -> 10 | IJ11: =HT11 -> 10 | IK11: =HU11 -> 40 | IL11: =HV11 -> 40 | IM11: =HW11 -> 40 | IN11: =HX11 -> 35 | IO11: =HY11 -> 20
