Workbook

Sheet Nodes
H1: Gas | V1: Hydrogen
A2: ID | B2: Name | C2: Type | D2: X_coordinate | E2: Y_coordinate | F2: Extra note | G2: Note | H2: TSO entry costs Gas | I2: TSO exit costs Gas | J2: Production Capacity Gas | K2: Entry Capacity Gas | L2: Exit Capacity Gas | M2: Production Costs Gas | N2: Storage Capacity Gas | O2: Entry Storage Costs Gas | P2: Entry Costs Gas Stage 1 | Q2: Exit Costs Gas Stage 1 | R2: Entry Costs Gas Stage 2 | S2: Exit Costs Gas Stage 2 | T2: Entry Costs Gas Stage 3 | U2: Exit Costs Gas Stage 3 | V2: TSO entry costs Hydrogen | W2: TSO exit costs Hydrogen | X2: Production Capacity Hydrogen | Y2: Entry Capacity Hydrogen | Z2: Exit Capacity Hydrogen | AA2: Production Costs Hydrogen | AB2: Storage Capacity Hydrogen | AC2: Entry Storage Costs Hydrogen | AD2: Entry Costs Hydrogen Stage 1 | AE2: Exit Costs Hydrogen Stage 1 | AF2: Entry Costs Hydrogen Stage 2 | AG2: Exit Costs Hydrogen Stage 2 | AH2: Entry Costs Hydrogen Stage 3 | AI2: Exit Costs Hydrogen Stage 3
A3: 1 | B3: AASTA HANSTEEN PLEM | D3: 7.107227 | E3: 67.05561 | H3: 5 | I3: 5 | J3: =SUMIFS(ProductionCapacities!$F$2:$F$51,ProductionCapacities!$E$2:$E$51,Nodes!B3)/8*1000000*0.01/1000 -> 30.443818 | K3: 500 | L3: 500 | M3: 9 | N3: =IF(F3="Storage",1000,0) -> 0 | O3: =IF(F3="Storage",0.299,0.3) -> 0.3 | P3: =IF(F3="Dummy",0,1) -> 1 | Q3: =IF(F3="Dummy",0,1) -> 1 | R3: =P3*1.04 -> 1.04 | S3: =Q3*1.04 -> 1.04 | T3: =P3*1.08 -> 1.08 | U3: =Q3*1.08 -> 1.08 | V3: 5 | W3: 5 | X3: 100 | Y3: 0 | Z3: 0 | AA3: =M3 -> 9 | AB3: 0 | AC3: =O3 -> 0.3 | AD3: =P3 -> 1 | AE3: =Q3 -> 1 | AF3: =R3 -> 1.04 | AG3: =S3 -> 1.04 | AH3: =T3 -> 1.08 | AI3: =U3 -> 1.08
A4: 2 | B4: aSGARD ERB | D4: 4.6885411 | E4: 62.302729 | H4: 5 | I4: 5 | J4: =SUMIFS(ProductionCapacities!$F$2:$F$51,ProductionCapacities!$E$2:$E$51,Nodes!B4)/8*1000000*0.01/1000 -> 0 | K4: 500 | L4: 500 | M4: 9 | N4: =IF(F4="Storage",1000,0) -> 0 | O4: =IF(F4="Storage",0.299,0.3) -> 0.3 | P4: =IF(F4="Dummy",0,1) -> 1 | Q4: =IF(F4="Dummy",0,1) -> 1 | R4: =P4*1.04 -> 1.04 | S4: =Q4*1.04 -> 1.04 | T4: =P4*1.08 -> 1.08 | U4: =Q4*1.08 -> 1.08 | V4: 5 | W4: 5 | X4: 100 | Y4: 0 | Z4: 0 | AA4: =M4 -> 9 | AB4: 0 | AC4: =O4 -> 0.3 | AD4: =P4 -> 1 | AE4: =Q4 -> 1 | AF4: =R4 -> 1.04 | AG4: =S4 -> 1.04 | AH4: =T4 -> 1.08 | AI4: =U4 -> 1.08
A5: 3 | B5: aSGARD T | D5: 6.8036598 | E5: 65.094472 | G5: Los | H5: 5 | I5: 5 | J5: =SUMIFS(ProductionCapacities!$F$2:$F$51,ProductionCapacities!$E$2:$E$51,Nodes!B5)/8*1000000*0.01/1000 -> 12.571315 | K5: 500 | L5: 500 | M5: 9 | N5: =IF(F5="Storage",1000,0) -> 0 | O5: =IF(F5="Storage",0.299,0.3) -> 0.3 | P5: =IF(F5="Dummy",0,1) -> 1 | Q5: =IF(F5="Dummy",0,1) -> 1 | R5: =P5*1.04 -> 1.04 | S5: =Q5*1.04 -> 1.04 | T5: =P5*1.08 -> 1.08 | U5: =Q5*1.08 -> 1.08 | V5: 5 | W5: 5 | X5: 100 | Y5: 0 | Z5: 0 | AA5: =M5 -> 9 | AB5: 0 | AC5: =O5 -> 0.3 | AD5: =P5 -> 1 | AE5: =Q5 -> 1 | AF5: =R5 -> 1.04 | AG5: =S5 -> 1.04 | AH5: =T5 -> 1.08 | AI5: =U5 -> 1.08
A6: 4 | B6: B-11 | D6: 4.5569471 | E6: 55.458982 | H6: 5 | I6: 5 | J6: =SUMIFS(ProductionCapacities!$F$2:$F$51,ProductionCapacities!$E$2:$E$51,Nodes!B6)/8*1000000*0.01/1000 -> 0 | K6: 500 | L6: 500 | M6: 9 | N6: =IF(F6="Storage",1000,0) -> 0 | O6: =IF(F6="Storage",0.299,0.3) -> 0.3 | P6: =IF(F6="Dummy",0,1) -> 1 | Q6: =IF(F6="Dummy",0,1) -> 1 | R6: =P6*1.04 -> 1.04 | S6: =Q6*1.04 -> 1.04 | T6: =P6*1.08 -> 1.08 | U6: =Q6*1.08 -> 1.08 | V6: 5 | W6: 5 | X6: 100 | Y6: 0 | Z6: 0 | AA6: =M6 -> 9 | AB6: 0 | AC6: =O6 -> 0.3 | AD6: =P6 -> 1 | AE6: =Q6 -> 1 | AF6: =R6 -> 1.04 | AG6: =S6 -> 1.04 | AH6: =T6 -> 1.08 | AI6: =U6 -> 1.08
A7: 5 | B7: BALTIC ENTRANCE | D7: 6.5038 | E7: 55.71 | H7: 5 | I7: 5 | J7: =SUMIFS(ProductionCapacities!$F$2:$F$51,ProductionCapacities!$E$2:$E$51,Nodes!B7)/8*1000000*0.01/1000 -> 0 | K7: 500 | L7: 500 | M7: 9 | N7: =IF(F7="Storage",1000,0) -> 0 | O7: =IF(F7="Storage",0.299,0.3) -> 0.3 | P7: =IF(F7="Dummy",0,1) -> 1 | Q7: =IF(F7="Dummy",0,1) -> 1 | R7: =P7*1.04 -> 1.04 | S7: =Q7*1.04 -> 1.04 | T7: =P7*1.08 -> 1.08 | U7: =Q7*1.08 -> 1.08 | V7: 5 | W7: 5 | X7: 100 | Y7: 0 | Z7: 0 | AA7: =M7 -> 9 | AB7: 0 | AC7: =O7 -> 0.3 | AD7: =P7 -> 1 | AE7: =Q7 -> 1 | AF7: =R7 -> 1.04 | AG7: =S7 -> 1.04 | AH7: =T7 -> 1.08 | AI7: =U7 -> 1.08
A8: 6 | B8: BRAGE | D8: 2.898055 | E8: 60.560633 | G8: Los | H8: 5 | I8: 5 | J8: =SUMIFS(ProductionCapacities!$F$2:$F$51,ProductionCapacities!$E$2:$E$51,Nodes!B8)/8*1000000*0.01/1000 -> 0.16460616 | K8: 500 | L8: 500 | M8: 9 | N8: =IF(F8="Storage",1000,0) -> 0 | O8: =IF(F8="Storage",0.299,0.3) -> 0.3 | P8: =IF(F8="Dummy",0,1) -> 1 | Q8: =IF(F8="Dummy",0,1) -> 1 | R8: =P8*1.04 -> 1.04 | S8: =Q8*1.04 -> 1.04 | T8: =P8*1.08 -> 1.08 | U8: =Q8*1.08 -> 1.08 | V8: 5 | W8: 5 | X8: 100 | Y8: 0 | Z8: 0 | AA8: =M8 -> 9 | AB8: 0 | AC8: =O8 -> 0.3 | AD8: =P8 -> 1 | AE8: =Q8 -> 1 | AF8: =R8 -> 1.04 | AG8: =S8 -> 1.04 | AH8: =T8 -> 1.08 | AI8: =U8 -> 1.08
A9: 7 | B9: BRAGE-T | D9: 3.0378255 | E9: 60.543329 | G9: Los | H9: 5 | I9: 5 | J9: =SUMIFS(ProductionCapacities!$F$2:$F$51,ProductionCapacities!$E$2:$E$51,Nodes!B9)/8*1000000*0.01/1000 -> 0 | K9: 500 | L9: 500 | M9: 9 | N9: =IF(F9="Storage",1000,0) -> 0 | O9: =IF(F9="Storage",0.299,0.3) -> 0.3 | P9: =IF(F9="Dummy",0,1) -> 1 | Q9: =IF(F9="Dummy",0,1) -> 1 | R9: =P9*1.04 -> 1.04 | S9: =Q9*1.04 -> 1.04 | T9: =P9*1.08 -> 1.08 | U9: =Q9*1.08 -> 1.08 | V9: 5 | W9: 5 | X9: 100 | Y9: 0 | Z9: 0 | AA9: =M9 -> 9 | AB9: 0 | AC9: =O9 -> 0.3 | AD9: =P9 -> 1 | AE9: =Q9 -> 1 | AF9: =R9 -> 1.04 | AG9: =S9 -> 1.04 | AH9: =T9 -> 1.08 | AI9: =U9 -> 1.08
A10: 8 | B10: CATS PLATFORM | D10: 1.803328 | E10: 57.758069 | H10: 5 | I10: 5 | J10: =48/8*1000000*0.01/1000 -> 60 | K10: 500 | L10: 500 | M10: 9 | N10: =IF(F10="Storage",1000,0) -> 0 | O10: =IF(F10="Storage",0.299,0.3) -> 0.3 | P10: =IF(F10="Dummy",0,1) -> 1 | Q10: =IF(F10="Dummy",0,1) -> 1 | R10: =P10*1.04 -> 1.04 | S10: =Q10*1.04 -> 1.04 | T10: =P10*1.08 -> 1.08 | U10: =Q10*1.08 -> 1.08 | V10: 5 | W10: 5 | X10: 100 | Y10: 0 | Z10: 0 | AA10: =M10 -> 9 | AB10: 0 | AC10: =O10 -> 0.3 | AD10: =P10 -> 1 | AE10: =Q10 -> 1 | AF10: =R10 -> 1.04 | AG10: =S10 -> 1.04 | AH10: =T10 -> 1.08 | AI10: =U10 -> 1.08
A11: 9 | B11: Denmark 1 | D11: 8.4073 | E11: 55.745 | H11: 5 | I11: 5 | J11: =SUMIFS(ProductionCapacities!$F$2:$F$51,ProductionCapacities!$E$2:$E$51,Nodes!B11)/8*1000000*0.01/1000 -> 0 | K11: 500 | L11: 500 | M11: 9 | N11: =IF(F11="Storage",1000,0) -> 0 | O11: =IF(F11="Storage",0.299,0.3) -> 0.3 | P11: =IF(F11="Dummy",0,1) -> 1 | Q11: =IF(F11="Dummy",0,1) -> 1 | R11: =P11*1.04 -> 1.04 | S11: =Q11*1.04 -> 1.04 | T11: =P11*1.08 -> 1.08 | U11: =Q11*1.08 -> 1.08 | V11: 5 | W11: 5 | X11: 100 | Y11: 0 | Z11: 0 | AA11: =M11 -> 9 | AB11: 0 | AC11: =O11 -> 0.3 | AD11: =P11 -> 1 | AE11: =Q11 -> 1 | AF11: =R11 -> 1.04 | AG11: =S11 -> 1.04 | AH11: =T11 -> 1.08 | AI11: =U11 -> 1.08
A12: 10 | B12: Denmark 2 | D12: 9.3108 | E12: 55.617 | H12: 5 | I12: 5 | J12: =SUMIFS(ProductionCapacities!$F$2:$F$51,ProductionCapacities!$E$2:$E$51,Nodes!B12)/8*1000000*0.01/1000 -> 0 | K12: 500 | L12: 500 | M12: 9 | N12: =IF(F12="Storage",1000,0) -> 0 | O12: =IF(F12="Storage",0.299,0.3) -> 0.3 | P12: =IF(F12="Dummy",0,1) -> 1 | Q12: =IF(F12="Dummy",0,1) -> 1 | R12: =P12*1.04 -> 1.04 | S12: =Q12*1.04 -> 1.04 | T12: =P12*1.08 -> 1.08 | U12: =Q12*1.08 -> 1.08 | V12: 5 | W12: 5 | X12: 100 | Y12: 0 | Z12: 0 | AA12: =M12 -> 9 | AB12: 0 | AC12: =O12 -> 0.3 | AD12: =P12 -> 1 | AE12: =Q12 -> 1 | AF12: =R12 -> 1.04 | AG12: =S12 -> 1.04 | AH12: =T12 -> 1.08 | AI12: =U12 -> 1.08
A13: 11 | B13: Denmark 3 | D13: 10.7951 | E13: 55.287 | H13: 5 | I13: 5 | J13: =SUMIFS(ProductionCapacities!$F$2:$F$51,ProductionCapacities!$E$2:$E$51,Nodes!B13)/8*1000000*0.01/1000 -> 0 | K13: 500 | L13: 500 | M13: 9 | N13: =IF(F13="Storage",1000,0) -> 0 | O13: =IF(F13="Storage",0.299,0.3) -> 0.3 | P13: =IF(F13="Dummy",0,1) -> 1 | Q13: =IF(F13="Dummy",0,1) -> 1 | R13: =P13*1.04 -> 1.04 | S13: =Q13*1.04 -> 1.04 | T13: =P13*1.08 -> 1.08 | U13: =Q13*1.08 -> 1.08 | V13: 5 | W13: 5 | X13: 100 | Y13: 0 | Z13: 0 | AA13: =M13 -> 9 | AB13: 0 | AC13: =O13 -> 0.3 | AD13: =P13 -> 1 | AE13: =Q13 -> 1 | AF13: =R13 -> 1.04 | AG13: =S13 -> 1.04 | AH13: =T13 -> 1.08 | AI13: =U13 -> 1.08
A14: 12 | B14: Denmark 4 | D14: 11.2102 | E14: 55.389 | H14: 5 | I14: 5 | J14: =SUMIFS(ProductionCapacities!$F$2:$F$51,ProductionCapacities!$E$2:$E$51,Nodes!B14)/8*1000000*0.01/1000 -> 0 | K14: 500 | L14: 500 | M14: 9 | N14: =IF(F14="Storage",1000,0) -> 0 | O14: =IF(F14="Storage",0.299,0.3) -> 0.3 | P14: =IF(F14="Dummy",0,1) -> 1 | Q14: =IF(F14="Dummy",0,1) -> 1 | R14: =P14*1.04 -> 1.04 | S14: =Q14*1.04 -> 1.04 | T14: =P14*1.08 -> 1.08 | U14: =Q14*1.08 -> 1.08 | V14: 5 | W14: 5 | X14: 100 | Y14: 0 | Z14: 0 | AA14: =M14 -> 9 | AB14: 0 | AC14: =O14 -> 0.3 | AD14: =P14 -> 1 | AE14: =Q14 -> 1 | AF14: =R14 -> 1.04 | AG14: =S14 -> 1.04 | AH14: =T14 -> 1.08 | AI14: =U14 -> 1.08
A15: 13 | B15: DRAUGEN | D15: 6.441258 | E15: 64.233255 | G15: Los | H15: 5 | I15: 5 | J15: =SUMIFS(ProductionCapacities!$F$2:$F$51,ProductionCapacities!$E$2:$E$51,Nodes!B15)/8*1000000*0.01/1000 -> 0 | K15: 500 | L15: 500 | M15: 9 | N15: =IF(F15="Storage",1000,0) -> 0 | O15: =IF(F15="Storage",0.299,0.3) -> 0.3 | P15: =IF(F15="Dummy",0,1) -> 1 | Q15: =IF(F15="Dummy",0,1) -> 1 | R15: =P15*1.04 -> 1.04 | S15: =Q15*1.04 -> 1.04 | T15: =P15*1.08 -> 1.08 | U15: =Q15*1.08 -> 1.08 | V15: 5 | W15: 5 | X15: 100 | Y15: 0 | Z15: 0 | AA15: =M15 -> 9 | AB15: 0 | AC15: =O15 -> 0.3 | AD15: =P15 -> 1 | AE15: =Q15 -> 1 | AF15: =R15 -> 1.04 | AG15: =S15 -> 1.04 | AH15: =T15 -> 1.08 | AI15: =U15 -> 1.08
A16: 14 | B16: DRAUGEN T | D16: 7.7910261 | E16: 64.350568 | H16: 5 | I16: 5 | J16: =SUMIFS(ProductionCapacities!$F$2:$F$51,ProductionCapacities!$E$2:$E$51,Nodes!B16)/8*1000000*0.01/1000 -> 0 | K16: 500 | L16: 500 | M16: 9 | N16: =IF(F16="Storage",1000,0) -> 0 | O16: =IF(F16="Storage",0.299,0.3) -> 0.3 | P16: =IF(F16="Dummy",0,1) -> 1 | Q16: =IF(F16="Dummy",0,1) -> 1 | R16: =P16*1.04 -> 1.04 | S16: =Q16*1.04 -> 1.04 | T16: =P16*1.08 -> 1.08 | U16: =Q16*1.08 -> 1.08 | V16: 5 | W16: 5 | X16: 100 | Y16: 0 | Z16: 0 | AA16: =M16 -> 9 | AB16: 0 | AC16: =O16 -> 0.3 | AD16: =P16 -> 1 | AE16: =Q16 -> 1 | AF16: =R16 -> 1.04 | AG16: =S16 -> 1.04 | AH16: =T16 -> 1.08 | AI16: =U16 -> 1.08
A17: 15 | B17: DRAUPNER E | D17: 2.4644042 | E17: 58.188149 | H17: 5 | I17: 5 | J17: =SUMIFS(ProductionCapacities!$F$2:$F$51,ProductionCapacities!$E$2:$E$51,Nodes!B17)/8*1000000*0.01/1000 -> 0 | K17: 500 | L17: 500 | M17: 9 | N17: =IF(F17="Storage",1000,0) -> 0 | O17: =IF(F17="Storage",0.299,0.3) -> 0.3 | P17: =IF(F17="Dummy",0,1) -> 1 | Q17: =IF(F17="Dummy",0,1) -> 1 | R17: =P17*1.04 -> 1.04 | S17: =Q17*1.04 -> 1.04 | T17: =P17*1.08 -> 1.08 | U17: =Q17*1.08 -> 1.08 | V17: 5 | W17: 5 | X17: 100 | Y17: 0 | Z17: 0 | AA17: =M17 -> 9 | AB17: 0 | AC17: =O17 -> 0.3 | AD17: =P17 -> 1 | AE17: =Q17 -> 1 | AF17: =R17 -> 1.04 | AG17: =S17 -> 1.04 | AH17: =T17 -> 1.08 | AI17: =U17 -> 1.08
A18: 16 | B18: DRAUPNER S | D18: 2.473733 | E18: 58.184409 | H18: 5 | I18: 5 | J18: =SUMIFS(ProductionCapacities!$F$2:$F$51,ProductionCapacities!$E$2:$E$51,Nodes!B18)/8*1000000*0.01/1000 -> 0 | K18: 500 | L18: 500 | M18: 9 | N18: =IF(F18="Storage",1000,0) -> 0 | O18: =IF(F18="Storage",0.299,0.3) -> 0.3 | P18: =IF(F18="Dummy",0,1) -> 1 | Q18: =IF(F18="Dummy",0,1) -> 1 | R18: =P18*1.04 -> 1.04 | S18: =Q18*1.04 -> 1.04 | T18: =P18*1.08 -> 1.08 | U18: =Q18*1.08 -> 1.08 | V18: 5 | W18: 5 | X18: 100 | Y18: 0 | Z18: 0 | AA18: =M18 -> 9 | AB18: 0 | AC18: =O18 -> 0.3 | AD18: =P18 -> 1 | AE18: =Q18 -> 1 | AF18: =R18 -> 1.04 | AG18: =S18 -> 1.04 | AH18: =T18 -> 1.08 | AI18: =U18 -> 1.08
A19: 17 | B19: DUNKERQUE | C19: Market | D19: 2.252709 | E19: 51.046406 | F19: Storage | H19: 5 | I19: 5 | J19: =SUMIFS(ProductionCapacities!$F$2:$F$51,ProductionCapacities!$E$2:$E$51,Nodes!B19)/8*1000000*0.01/1000 -> 0 | K19: 500 | L19: 500 | M19: 9 | N19: =IF(F19="Storage",1000,0) -> 1000 | O19: =IF(F19="Storage",0.299,0.3) -> 0.299 | P19: =IF(F19="Dummy",0,1) -> 1 | Q19: =IF(F19="Dummy",0,1) -> 1 | R19: =P19*1.04 -> 1.04 | S19: =Q19*1.04 -> 1.04 | T19: =P19*1.08 -> 1.08 | U19: =Q19*1.08 -> 1.08 | V19: 5 | W19: 5 | X19: 100 | Y19: 0 | Z19: 0 | AA19: =M19 -> 9 | AB19: 0 | AC19: =O19 -> 0.299 | AD19: =P19 -> 1 | AE19: =Q19 -> 1 | AF19: =R19 -> 1.04 | AG19: =S19 -> 1.04 | AH19: =T19 -> 1.08 | AI19: =U19 -> 1.08
A20: 18 | B20: EASINGTON | C20: Market | D20: 0.116031 | E20: 53.659231 | F20: Storage | H20: 5 | I20: 5 | J20: =SUMIFS(ProductionCapacities!$F$2:$F$51,ProductionCapacities!$E$2:$E$51,Nodes!B20)/8*1000000*0.01/1000 -> 0 | K20: 500 | L20: 500 | M20: 9 | N20: =IF(F20="Storage",1000,0) -> 1000 | O20: =IF(F20="Storage",0.299,0.3) -> 0.299 | P20: =IF(F20="Dummy",0,1) -> 1 | Q20: =IF(F20="Dummy",0,1) -> 1 | R20: =P20*1.04 -> 1.04 | S20: =Q20*1.04 -> 1.04 | T20: =P20*1.08 -> 1.08 | U20: =Q20*1.08 -> 1.08 | V20: 5 | W20: 5 | X20: 100 | Y20: 0 | Z20: 0 | AA20: =M20 -> 9 | AB20: 0 | AC20: =O20 -> 0.299 | AD20: =P20 -> 1 | AE20: =Q20 -> 1 | AF20: =R20 -> 1.04 | AG20: =S20 -> 1.04 | AH20: =T20 -> 1.08 | AI20: =U20 -> 1.08
A21: 19 | B21: EDVARD GRIEG | D21: 1.3911371 | E21: 59.477978 | G21: Los | H21: 5 | I21: 5 | J21: =SUMIFS(ProductionCapacities!$F$2:$F$51,ProductionCapacities!$E$2:$E$51,Nodes!B21)/8*1000000*0.01/1000 -> 7.1669589 | K21: 500 | L21: 500 | M21: 9 | N21: =IF(F21="Storage",1000,0) -> 0 | O21: =IF(F21="Storage",0.299,0.3) -> 0.3 | P21: =IF(F21="Dummy",0,1) -> 1 | Q21: =IF(F21="Dummy",0,1) -> 1 | R21: =P21*1.04 -> 1.04 | S21: =Q21*1.04 -> 1.04 | T21: =P21*1.08 -> 1.08 | U21: =Q21*1.08 -> 1.08 | V21: 5 | W21: 5 | X21: 100 | Y21: 0 | Z21: 0 | AA21: =M21 -> 9 | AB21: 0 | AC21: =O21 -> 0.3 | AD21: =P21 -> 1 | AE21: =Q21 -> 1 | AF21: =R21 -> 1.04 | AG21: =S21 -> 1.04 | AH21: =T21 -> 1.08 | AI21: =U21 -> 1.08
A22: 20 | B22: EKOFISK J | D22: 3.23 | E22: 56.55 | H22: 5 | I22: 5 | J22: =SUMIFS(ProductionCapacities!$F$2:$F$51,ProductionCapacities!$E$2:$E$51,Nodes!B22)/8*1000000*0.01/1000 -> 4.0659795 | K22: 500 | L22: 500 | M22: 9 | N22: =IF(F22="Storage",1000,0) -> 0 | O22: =IF(F22="Storage",0.299,0.3) -> 0.3 | P22: =IF(F22="Dummy",0,1) -> 1 | Q22: =IF(F22="Dummy",0,1) -> 1 | R22: =P22*1.04 -> 1.04 | S22: =Q22*1.04 -> 1.04 | T22: =P22*1.08 -> 1.08 | U22: =Q22*1.08 -> 1.08 | V22: 5 | W22: 5 | X22: 100 | Y22: 0 | Z22: 0 | AA22: =M22 -> 9 | AB22: 0 | AC22: =O22 -> 0.3 | AD22: =P22 -> 1 | AE22: =Q22 -> 1 | AF22: =R22 -> 1.04 | AG22: =S22 -> 1.04 | AH22: =T22 -> 1.08 | AI22: =U22 -> 1.08
A23: 21 | B23: DORNUM | D23: 7.32642 | E23: 53.6797 | F23: Storage | H23: 5 | I23: 5 | J23: =SUMIFS(ProductionCapacities!$F$2:$F$51,ProductionCapacities!$E$2:$E$51,Nodes!B23)/8*1000000*0.01/1000 -> 0 | K23: 500 | L23: 500 | M23: 9 | N23: =IF(F23="Storage",1000,0) -> 1000 | O23: =IF(F23="Storage",0.299,0.3) -> 0.299 | P23: =IF(F23="Dummy",0,1) -> 1 | Q23: =IF(F23="Dummy",0,1) -> 1 | R23: =P23*1.04 -> 1.04 | S23: =Q23*1.04 -> 1.04 | T23: =P23*1.08 -> 1.08 | U23: =Q23*1.08 -> 1.08 | V23: 5 | W23: 5 | X23: 100 | Y23: 0 | Z23: 0 | AA23: =M23 -> 9 | AB23: 0 | AC23: =O23 -> 0.299 | AD23: =P23 -> 1 | AE23: =Q23 -> 1 | AF23: =R23 -> 1.04 | AG23: =S23 -> 1.04 | AH23: =T23 -> 1.08 | AI23: =U23 -> 1.08
A24: 22 | B24: EMDEN | D24: 7.18929 | E24: 53.3462 | F24: Storage | H24: 5 | I24: 5 | J24: =SUMIFS(ProductionCapacities!$F$2:$F$51,ProductionCapacities!$E$2:$E$51,Nodes!B24)/8*1000000*0.01/1000 -> 0 | K24: 500 | L24: 500 | M24: 9 | N24: =IF(F24="Storage",1000,0) -> 1000 | O24: =IF(F24="Storage",0.299,0.3) -> 0.299 | P24: =IF(F24="Dummy",0,1) -> 1 | Q24: =IF(F24="Dummy",0,1) -> 1 | R24: =P24*1.04 -> 1.04 | S24: =Q24*1.04 -> 1.04 | T24: =P24*1.08 -> 1.08 | U24: =Q24*1.08 -> 1.08 | V24: 5 | W24: 5 | X24: 100 | Y24: 0 | Z24: 0 | AA24: =M24 -> 9 | AB24: 0 | AC24: =O24 -> 0.299 | AD24: =P24 -> 1 | AE24: =Q24 -> 1 | AF24: =R24 -> 1.04 | AG24: =S24 -> 1.04 | AH24: =T24 -> 1.08 | AI24: =U24 -> 1.08
A25: 23 | B25: EUROPIPE-SCP | D25: 4.222622 | E25: 55.706969 | H25: 5 | I25: 5 | J25: =SUMIFS(ProductionCapacities!$F$2:$F$51,ProductionCapacities!$E$2:$E$51,Nodes!B25)/8*1000000*0.01/1000 -> 0 | K25: 500 | L25: 500 | M25: 9 | N25: =IF(F25="Storage",1000,0) -> 0 | O25: =IF(F25="Storage",0.299,0.3) -> 0.3 | P25: =IF(F25="Dummy",0,1) -> 1 | Q25: =IF(F25="Dummy",0,1) -> 1 | R25: =P25*1.04 -> 1.04 | S25: =Q25*1.04 -> 1.04 | T25: =P25*1.08 -> 1.08 | U25: =Q25*1.08 -> 1.08 | V25: 5 | W25: 5 | X25: 100 | Y25: 0 | Z25: 0 | AA25: =M25 -> 9 | AB25: 0 | AC25: =O25 -> 0.3 | AD25: =P25 -> 1 | AE25: =Q25 -> 1 | AF25: =R25 -> 1.04 | AG25: =S25 -> 1.04 | AH25: =T25 -> 1.08 | AI25: =U25 -> 1.08
A26: 24 | B26: FLAGS-T | D26: 1.7001891 | E26: 61.022018 | H26: 5 | I26: 5 | J26: =SUMIFS(ProductionCapacities!$F$2:$F$51,ProductionCapacities!$E$2:$E$51,Nodes!B26)/8*1000000*0.01/1000 -> 0 | K26: 500 | L26: 500 | M26: 9 | N26: =IF(F26="Storage",1000,0) -> 0 | O26: =IF(F26="Storage",0.299,0.3) -> 0.3 | P26: =IF(F26="Dummy",0,1) -> 1 | Q26: =IF(F26="Dummy",0,1) -> 1 | R26: =P26*1.04 -> 1.04 | S26: =Q26*1.04 -> 1.04 | T26: =P26*1.08 -> 1.08 | U26: =Q26*1.08 -> 1.08 | V26: 5 | W26: 5 | X26: 100 | Y26: 0 | Z26: 0 | AA26: =M26 -> 9 | AB26: 0 | AC26: =O26 -> 0.3 | AD26: =P26 -> 1 | AE26: =Q26 -> 1 | AF26: =R26 -> 1.04 | AG26: =S26 -> 1.04 | AH26: =T26 -> 1.08 | AI26: =U26 -> 1.08
A27: 25 | B27: FRIGG TP1-Y | D27: 2.0113877 | E27: 60.502035 | G27: Los | H27: 5 | I27: 5 | J27: =SUMIFS(ProductionCapacities!$F$2:$F$51,ProductionCapacities!$E$2:$E$51,Nodes!B27)/8*1000000*0.01/1000 -> 0 | K27: 500 | L27: 500 | M27: 9 | N27: =IF(F27="Storage",1000,0) -> 0 | O27: =IF(F27="Storage",0.299,0.3) -> 0.3 | P27: =IF(F27="Dummy",0,1) -> 1 | Q27: =IF(F27="Dummy",0,1) -> 1 | R27: =P27*1.04 -> 1.04 | S27: =Q27*1.04 -> 1.04 | T27: =P27*1.08 -> 1.08 | U27: =Q27*1.08 -> 1.08 | V27: 5 | W27: 5 | X27: 100 | Y27: 0 | Z27: 0 | AA27: =M27 -> 9 | AB27: 0 | AC27: =O27 -> 0.3 | AD27: =P27 -> 1 | AE27: =Q27 -> 1 | AF27: =R27 -> 1.04 | AG27: =S27 -> 1.04 | AH27: =T27 -> 1.08 | AI27: =U27 -> 1.08
A28: 26 | B28: GJoA | D28: 1.6999853 | E28: 61.020798 | G28: Los | H28: 5 | I28: 5 | J28: =SUMIFS(ProductionCapacities!$F$2:$F$51,ProductionCapacities!$E$2:$E$51,Nodes!B28)/8*1000000*0.01/1000 -> 13.934692 | K28: 500 | L28: 500 | M28: 9 | N28: =IF(F28="Storage",1000,0) -> 0 | O28: =IF(F28="Storage",0.299,0.3) -> 0.3 | P28: =IF(F28="Dummy",0,1) -> 1 | Q28: =IF(F28="Dummy",0,1) -> 1 | R28: =P28*1.04 -> 1.04 | S28: =Q28*1.04 -> 1.04 | T28: =P28*1.08 -> 1.08 | U28: =Q28*1.08 -> 1.08 | V28: 5 | W28: 5 | X28: 100 | Y28: 0 | Z28: 0 | AA28: =M28 -> 9 | AB28: 0 | AC28: =O28 -> 0.3 | AD28: =P28 -> 1 | AE28: =Q28 -> 1 | AF28: =R28 -> 1.04 | AG28: =S28 -> 1.04 | AH28: =T28 -> 1.08 | AI28: =U28 -> 1.08
A29: 27 | B29: GJoA-T | D29: 3.9049898 | E29: 61.330194 | G29: Los | H29: 5 | I29: 5 | J29: =SUMIFS(ProductionCapacities!$F$2:$F$51,ProductionCapacities!$E$2:$E$51,Nodes!B29)/8*1000000*0.01/1000 -> 0 | K29: 500 | L29: 500 | M29: 9 | N29: =IF(F29="Storage",1000,0) -> 0 | O29: =IF(F29="Storage",0.299,0.3) -> 0.3 | P29: =IF(F29="Dummy",0,1) -> 1 | Q29: =IF(F29="Dummy",0,1) -> 1 | R29: =P29*1.04 -> 1.04 | S29: =Q29*1.04 -> 1.04 | T29: =P29*1.08 -> 1.08 | U29: =Q29*1.08 -> 1.08 | V29: 5 | W29: 5 | X29: 100 | Y29: 0 | Z29: 0 | AA29: =M29 -> 9 | AB29: 0 | AC29: =O29 -> 0.3 | AD29: =P29 -> 1 | AE29: =Q29 -> 1 | AF29: =R29 -> 1.04 | AG29: =S29 -> 1.04 | AH29: =T29 -> 1.08 | AI29: =U29 -> 1.08
A30: 28 | B30: GRANE | D30: 2.4873353 | E30: 59.169726 | H30: 5 | I30: 5 | J30: =SUMIFS(ProductionCapacities!$F$2:$F$51,ProductionCapacities!$E$2:$E$51,Nodes!B30)/8*1000000*0.01/1000 -> 0 | K30: 500 | L30: 500 | M30: 9 | N30: =IF(F30="Storage",1000,0) -> 0 | O30: =IF(F30="Storage",0.299,0.3) -> 0.3 | P30: =IF(F30="Dummy",0,1) -> 1 | Q30: =IF(F30="Dummy",0,1) -> 1 | R30: =P30*1.04 -> 1.04 | S30: =Q30*1.04 -> 1.04 | T30: =P30*1.08 -> 1.08 | U30: =Q30*1.08 -> 1.08 | V30: 5 | W30: 5 | X30: 100 | Y30: 0 | Z30: 0 | AA30: =M30 -> 9 | AB30: 0 | AC30: =O30 -> 0.3 | AD30: =P30 -> 1 | AE30: =Q30 -> 1 | AF30: =R30 -> 1.04 | AG30: =S30 -> 1.04 | AH30: =T30 -> 1.08 | AI30: =U30 -> 1.08
A31: 29 | B31: GUDRUN | D31: 1.7504701 | E31: 58.842411 | H31: 5 | I31: 5 | J31: =SUMIFS(ProductionCapacities!$F$2:$F$51,ProductionCapacities!$E$2:$E$51,Nodes!B31)/8*1000000*0.01/1000 -> 0 | K31: 500 | L31: 500 | M31: 9 | N31: =IF(F31="Storage",1000,0) -> 0 | O31: =IF(F31="Storage",0.299,0.3) -> 0.3 | P31: =IF(F31="Dummy",0,1) -> 1 | Q31: =IF(F31="Dummy",0,1) -> 1 | R31: =P31*1.04 -> 1.04 | S31: =Q31*1.04 -> 1.04 | T31: =P31*1.08 -> 1.08 | U31: =Q31*1.08 -> 1.08 | V31: 5 | W31: 5 | X31: 100 | Y31: 0 | Z31: 0 | AA31: =M31 -> 9 | AB31: 0 | AC31: =O31 -> 0.3 | AD31: =P31 -> 1 | AE31: =Q31 -> 1 | AF31: =R31 -> 1.04 | AG31: =S31 -> 1.04 | AH31: =T31 -> 1.08 | AI31: =U31 -> 1.08
A32: 30 | B32: H-7 BP | D32: 6.0406336 | E32: 54.505801 | H32: 5 | I32: 5 | J32: =SUMIFS(ProductionCapacities!$F$2:$F$51,ProductionCapacities!$E$2:$E$51,Nodes!B32)/8*1000000*0.01/1000 -> 0 | K32: 500 | L32: 500 | M32: 9 | N32: =IF(F32="Storage",1000,0) -> 0 | O32: =IF(F32="Storage",0.299,0.3) -> 0.3 | P32: =IF(F32="Dummy",0,1) -> 1 | Q32: =IF(F32="Dummy",0,1) -> 1 | R32: =P32*1.04 -> 1.04 | S32: =Q32*1.04 -> 1.04 | T32: =P32*1.08 -> 1.08 | U32: =Q32*1.08 -> 1.08 | V32: 5 | W32: 5 | X32: 100 | Y32: 0 | Z32: 0 | AA32: =M32 -> 9 | AB32: 0 | AC32: =O32 -> 0.3 | AD32: =P32 -> 1 | AE32: =Q32 -> 1 | AF32: =R32 -> 1.04 | AG32: =S32 -> 1.04 | AH32: =T32 -> 1.08 | AI32: =U32 -> 1.08
A33: 31 | B33: HEIDRUN | D33: 7.3202454 | E33: 65.3215 | G33: Los | H33: 5 | I33: 5 | J33: =SUMIFS(ProductionCapacities!$F$2:$F$51,ProductionCapacities!$E$2:$E$51,Nodes!B33)/8*1000000*0.01/1000 -> 6.5435925 | K33: 500 | L33: 500 | M33: 9 | N33: =IF(F33="Storage",1000,0) -> 0 | O33: =IF(F33="Storage",0.299,0.3) -> 0.3 | P33: =IF(F33="Dummy",0,1) -> 1 | Q33: =IF(F33="Dummy",0,1) -> 1 | R33: =P33*1.04 -> 1.04 | S33: =Q33*1.04 -> 1.04 | T33: =P33*1.08 -> 1.08 | U33: =Q33*1.08 -> 1.08 | V33: 5 | W33: 5 | X33: 100 | Y33: 0 | Z33: 0 | AA33: =M33 -> 9 | AB33: 0 | AC33: =O33 -> 0.3 | AD33: =P33 -> 1 | AE33: =Q33 -> 1 | AF33: =R33 -> 1.04 | AG33: =S33 -> 1.04 | AH33: =T33 -> 1.08 | AI33: =U33 -> 1.08
A34: 32 | B34: HEIMDAL | D34: 2.2345226 | E34: 59.570738 | H34: 5 | I34: 5 | J34: =SUMIFS(ProductionCapacities!$F$2:$F$51,ProductionCapacities!$E$2:$E$51,Nodes!B34)/8*1000000*0.01/1000 -> 0 | K34: 500 | L34: 500 | M34: 9 | N34: =IF(F34="Storage",1000,0) -> 0 | O34: =IF(F34="Storage",0.299,0.3) -> 0.3 | P34: =IF(F34="Dummy",0,1) -> 1 | Q34: =IF(F34="Dummy",0,1) -> 1 | R34: =P34*1.04 -> 1.04 | S34: =Q34*1.04 -> 1.04 | T34: =P34*1.08 -> 1.08 | U34: =Q34*1.08 -> 1.08 | V34: 5 | W34: 5 | X34: 100 | Y34: 0 | Z34: 0 | AA34: =M34 -> 9 | AB34: 0 | AC34: =O34 -> 0.3 | AD34: =P34 -> 1 | AE34: =Q34 -> 1 | AF34: =R34 -> 1.04 | AG34: =S34 -> 1.04 | AH34: =T34 -> 1.08 | AI34: =U34 -> 1.08
A35: 33 | B35: HEIMDAL HRP | D35: 2.2352255 | E35: 59.571075 | H35: 5 | I35: 5 | J35: =SUMIFS(ProductionCapacities!$F$2:$F$51,ProductionCapacities!$E$2:$E$51,Nodes!B35)/8*1000000*0.01/1000 -> 0 | K35: 500 | L35: 500 | M35: 9 | N35: =IF(F35="Storage",1000,0) -> 0 | O35: =IF(F35="Storage",0.299,0.3) -> 0.3 | P35: =IF(F35="Dummy",0,1) -> 1 | Q35: =IF(F35="Dummy",0,1) -> 1 | R35: =P35*1.04 -> 1.04 | S35: =Q35*1.04 -> 1.04 | T35: =P35*1.08 -> 1.08 | U35: =Q35*1.08 -> 1.08 | V35: 5 | W35: 5 | X35: 100 | Y35: 0 | Z35: 0 | AA35: =M35 -> 9 | AB35: 0 | AC35: =O35 -> 0.3 | AD35: =P35 -> 1 | AE35: =Q35 -> 1 | AF35: =R35 -> 1.04 | AG35: =S35 -> 1.04 | AH35: =T35 -> 1.08 | AI35: =U35 -> 1.08
A36: 34 | B36: JOHAN SVERDRUP RP | D36: 5.054176 | E36: 59.326808 | G36: Los | H36: 5 | I36: 5 | J36: =SUMIFS(ProductionCapacities!$F$2:$F$51,ProductionCapacities!$E$2:$E$51,Nodes!B36)/8*1000000*0.01/1000 -> 3.5652432 | K36: 500 | L36: 500 | M36: 9 | N36: =IF(F36="Storage",1000,0) -> 0 | O36: =IF(F36="Storage",0.299,0.3) -> 0.3 | P36: =IF(F36="Dummy",0,1) -> 1 | Q36: =IF(F36="Dummy",0,1) -> 1 | R36: =P36*1.04 -> 1.04 | S36: =Q36*1.04 -> 1.04 | T36: =P36*1.08 -> 1.08 | U36: =Q36*1.08 -> 1.08 | V36: 5 | W36: 5 | X36: 100 | Y36: 0 | Z36: 0 | AA36: =M36 -> 9 | AB36: 0 | AC36: =O36 -> 0.3 | AD36: =P36 -> 1 | AE36: =Q36 -> 1 | AF36: =R36 -> 1.04 | AG36: =S36 -> 1.04 | AH36: =T36 -> 1.08 | AI36: =U36 -> 1.08
A37: 35 | B37: JOHAN SVERDRUP STATPIPE PLEM | D37: 2.5577715 | E37: 58.841931 | G37: Los | H37: 5 | I37: 5 | J37: =SUMIFS(ProductionCapacities!$F$2:$F$51,ProductionCapacities!$E$2:$E$51,Nodes!B37)/8*1000000*0.01/1000 -> 0 | K37: 500 | L37: 500 | M37: 9 | N37: =IF(F37="Storage",1000,0) -> 0 | O37: =IF(F37="Storage",0.299,0.3) -> 0.3 | P37: =IF(F37="Dummy",0,1) -> 1 | Q37: =IF(F37="Dummy",0,1) -> 1 | R37: =P37*1.04 -> 1.04 | S37: =Q37*1.04 -> 1.04 | T37: =P37*1.08 -> 1.08 | U37: =Q37*1.08 -> 1.08 | V37: 5 | W37: 5 | X37: 100 | Y37: 0 | Z37: 0 | AA37: =M37 -> 9 | AB37: 0 | AC37: =O37 -> 0.3 | AD37: =P37 -> 1 | AE37: =Q37 -> 1 | AF37: =R37 -> 1.04 | AG37: =S37 -> 1.04 | AH37: =T37 -> 1.08 | AI37: =U37 -> 1.08
A38: 36 | B38: KaRSTo | D38: 5.5129213 | E38: 59.272116 | H38: 5 | I38: 5 | J38: =SUMIFS(ProductionCapacities!$F$2:$F$51,ProductionCapacities!$E$2:$E$51,Nodes!B38)/8*1000000*0.01/1000 -> 0 | K38: 500 | L38: 500 | M38: 9 | N38: =IF(F38="Storage",1000,0) -> 0 | O38: =IF(F38="Storage",0.299,0.3) -> 0.3 | P38: =IF(F38="Dummy",0,1) -> 1 | Q38: =IF(F38="Dummy",0,1) -> 1 | R38: =P38*1.04 -> 1.04 | S38: =Q38*1.04 -> 1.04 | T38: =P38*1.08 -> 1.08 | U38: =Q38*1.08 -> 1.08 | V38: 5 | W38: 5 | X38: 100 | Y38: 0 | Z38: 0 | AA38: =M38 -> 9 | AB38: 0 | AC38: =O38 -> 0.3 | AD38: =P38 -> 1 | AE38: =Q38 -> 1 | AF38: =R38 -> 1.04 | AG38: =S38 -> 1.04 | AH38: =T38 -> 1.08 | AI38: =U38 -> 1.08
A39: 37 | B39: KOLLSNES | D39: 4.838597 | E39: 60.545348 | H39: 5 | I39: 5 | J39: =SUMIFS(ProductionCapacities!$F$2:$F$51,ProductionCapacities!$E$2:$E$51,Nodes!B39)/8*1000000*0.01/1000 -> 0 | K39: 500 | L39: 500 | M39: 9 | N39: =IF(F39="Storage",1000,0) -> 0 | O39: =IF(F39="Storage",0.299,0.3) -> 0.3 | P39: =IF(F39="Dummy",0,1) -> 1 | Q39: =IF(F39="Dummy",0,1) -> 1 | R39: =P39*1.04 -> 1.04 | S39: =Q39*1.04 -> 1.04 | T39: =P39*1.08 -> 1.08 | U39: =Q39*1.08 -> 1.08 | V39: 5 | W39: 5 | X39: 100 | Y39: 0 | Z39: 0 | AA39: =M39 -> 9 | AB39: 0 | AC39: =O39 -> 0.3 | AD39: =P39 -> 1 | AE39: =Q39 -> 1 | AF39: =R39 -> 1.04 | AG39: =S39 -> 1.04 | AH39: =T39 -> 1.08 | AI39: =U39 -> 1.08
A40: 38 | B40: KVITEBJoRN | D40: 2.5070781 | E40: 61.077582 | H40: 5 | I40: 5 | J40: =SUMIFS(ProductionCapacities!$F$2:$F$51,ProductionCapacities!$E$2:$E$51,Nodes!B40)/8*1000000*0.01/1000 -> 31.193178 | K40: 500 | L40: 500 | M40: 9 | N40: =IF(F40="Storage",1000,0) -> 0 | O40: =IF(F40="Storage",0.299,0.3) -> 0.3 | P40: =IF(F40="Dummy",0,1) -> 1 | Q40: =IF(F40="Dummy",0,1) -> 1 | R40: =P40*1.04 -> 1.04 | S40: =Q40*1.04 -> 1.04 | T40: =P40*1.08 -> 1.08 | U40: =Q40*1.08 -> 1.08 | V40: 5 | W40: 5 | X40: 100 | Y40: 0 | Z40: 0 | AA40: =M40 -> 9 | AB40: 0 | AC40: =O40 -> 0.3 | AD40: =P40 -> 1 | AE40: =Q40 -> 1 | AF40: =R40 -> 1.04 | AG40: =S40 -> 1.04 | AH40: =T40 -> 1.08 | AI40: =U40 -> 1.08
...

Sheet Demand Stage 1
A1: Node Number | B1: 1
A2: Probability | B2: 1
B3: gas or mix | M3: pure hydrogen
A4: Hour | B4: ='Demand Stage 2'!B4 -> ST.FERGUS | C4: ='Demand Stage 2'!C4 -> EASINGTON | D4: ='Demand Stage 2'!D4 -> TEESSIDE | E4: Emden Industry | F4: Emden Consumers | G4: Dornum Industry | H4: Dornum Consumers | I4: Zeebrugge Industry | J4: Zeebrugge Consumers | K4: ='Demand Stage 2'!K4 -> DUNKERQUE | L4: ='Demand Stage 2'!L4 -> POLAND | M4: ='Demand Stage 2'!M4 -> ST.FERGUS | N4: ='Demand Stage 2'!N4 -> EASINGTON | O4: ='Demand Stage 2'!O4 -> TEESSIDE | P4: Emden Industry | Q4: Emden Consumers | R4: Dornum Industry | S4: Dornum Consumers | T4: Zeebrugge Industry | U4: Zeebrugge Consumers | V4: ='Demand Stage 2'!V4 -> DUNKERQUE | W4: ='Demand Stage 2'!W4 -> POLAND
A5: 0 | B5: ='Demand Stage 2'!B43 -> 12.5 | C5: ='Demand Stage 2'!C43 -> 12.5 | D5: ='Demand Stage 2'!D43 -> 12.5 | E5: ='Demand Stage 2'!E43 -> 25 | F5: ='Demand Stage 2'!F43 -> 25 | G5: ='Demand Stage 2'!G43 -> 25 | H5: ='Demand Stage 2'!H43 -> 25 | I5: ='Demand Stage 2'!I43 -> 25 | ... L5: ='Demand Stage 2'!L43 -> 25 | M5: 0 | N5: 0 | O5: 0 | P5: 0 | Q5: 0 | R5: 0 | S5: 0 | T5: 0 | U5: 0 | V5: 0 | W5: 0
A6: 1 | B6: ='Demand Stage 2'!B44 -> 12.5 | C6: ='Demand Stage 2'!C44 -> 12.5 | D6: ='Demand Stage 2'!D44 -> 12.5 | E6: ='Demand Stage 2'!E44 -> 25 | F6: ='Demand Stage 2'!F44 -> 25 | G6: ='Demand Stage 2'!G44 -> 25 | H6: ='Demand Stage 2'!H44 -> 25 | I6: ='Demand Stage 2'!I44 -> 25 | ... L6: ='Demand Stage 2'!L44 -> 25 | M6: 0 | N6: 0 | O6: 0 | P6: 0 | Q6: 0 | R6: 0 | S6: 0 | T6: 0 | U6: 0 | V6: 0 | W6: 0
A7: 2 | B7: ='Demand Stage 2'!B45 -> 12.5 | C7: ='Demand Stage 2'!C45 -> 12.5 | D7: ='Demand Stage 2'!D45 -> 12.5 | E7: ='Demand Stage 2'!E45 -> 25 | F7: ='Demand Stage 2'!F45 -> 25 | G7: ='Demand Stage 2'!G45 -> 25 | H7: ='Demand Stage 2'!H45 -> 25 | I7: ='Demand Stage 2'!I45 -> 25 | ... L7: ='Demand Stage 2'!L45 -> 25 | M7: 0 | N7: 0 | O7: 0 | P7: 0 | Q7: 0 | R7: 0 | S7: 0 | T7: 0 | U7: 0 | V7: 0 | W7: 0
A8: 3 | B8: ='Demand Stage 2'!B46 -> 12.5 | C8: ='Demand Stage 2'!C46 -> 12.5 | D8: ='Demand Stage 2'!D46 -> 12.5 | E8: ='Demand Stage 2'!E46 -> 25 | F8: ='Demand Stage 2'!F46 -> 25 | G8: ='Demand Stage 2'!G46 -> 25 | H8: ='Demand Stage 2'!H46 -> 25 | I8: ='Demand Stage 2'!I46 -> 25 | ... L8: ='Demand Stage 2'!L46 -> 25 | M8: 0 | N8: 0 | O8: 0 | P8: 0 | Q8: 0 | R8: 0 | S8: 0 | T8: 0 | U8: 0 | V8: 0 | W8: 0
A9: 4 | B9: ='Demand Stage 2'!B47 -> 12.5 | C9: ='Demand Stage 2'!C47 -> 12.5 | D9: ='Demand Stage 2'!D47 -> 12.5 | E9: ='Demand Stage 2'!E47 -> 28.125 | F9: ='Demand Stage 2'!F47 -> 28.125 | G9: ='Demand Stage 2'!G47 -> 28.125 | H9: ='Demand Stage 2'!H47 -> 28.125 | I9: ='Demand Stage 2'!I47 -> 25 | ... L9: ='Demand Stage 2'!L47 -> 25 | M9: 0 | N9: 0 | O9: 0 | P9: 0 | Q9: 0 | R9: 0 | S9: 0 | T9: 0 | U9: 0 | V9: 0 | W9: 0
A10: 5 | B10: ='Demand Stage 2'!B48 -> 12.5 | C10: ='Demand Stage 2'!C48 -> 12.5 | D10: ='Demand Stage 2'!D48 -> 12.5 | E10: ='Demand Stage 2'!E48 -> 25 | F10: ='Demand Stage 2'!F48 -> 25 | G10: ='Demand Stage 2'!G48 -> 25 | H10: ='Demand Stage 2'!H48 -> 25 | I10: ='Demand Stage 2'!I48 -> 25 | ... L10: ='Demand Stage 2'!L48 -> 25 | M10: 0 | N10: 0 | O10: 0 | P10: 0 | Q10: 0 | R10: 0 | S10: 0 | T10: 0 | U10: 0 | V10: 0 | W10: 0
A11: 6 | B11: ='Demand Stage 2'!B49 -> 12.5 | C11: ='Demand Stage 2'!C49 -> 12.5 | D11: ='Demand Stage 2'!D49 -> 12.5 | E11: ='Demand Stage 2'!E49 -> 25 | F11: ='Demand Stage 2'!F49 -> 25 | G11: ='Demand Stage 2'!G49 -> 25 | H11: ='Demand Stage 2'!H49 -> 25 | I11: ='Demand Stage 2'!I49 -> 25 | ... L11: ='Demand Stage 2'!L49 -> 25 | M11: 0 | N11: 0 | O11: 0 | P11: 0 | Q11: 0 | R11: 0 | S11: 0 | T11: 0 | U11: 0 | V11: 0 | W11: 0
A12: 7 | B12: ='Demand Stage 2'!B50 -> 12.5 | C12: ='Demand Stage 2'!C50 -> 12.5 | D12: ='Demand Stage 2'!D50 -> 12.5 | E12: ='Demand Stage 2'!E50 -> 28.125 | F12: ='Demand Stage 2'!F50 -> 28.125 | G12: ='Demand Stage 2'!G50 -> 28.125 | H12: ='Demand Stage 2'!H50 -> 28.125 | I12: ='Demand Stage 2'!I50 -> 25 | ... L12: ='Demand Stage 2'!L50 -> 25 | M12: 0 | N12: 0 | O12: 0 | P12: 0 | Q12: 0 | R12: 0 | S12: 0 | T12: 0 | U12: 0 | V12: 0 | W12: 0
A13: 8 | T13: 0 | U13: 0 | V13: 0 | W13: 0
A14: 9 | T14: 0 | U14: 0 | V14: 0 | W14: 0
A15: 10 | T15: 0 | U15: 0 | V15: 0 | W15: 0
A16: 11 | T16: 0 | U16: 0 | V16: 0 | W16: 0
A17: 12 | T17: 0 | U17: 0 | V17: 0 | W17: 0
A18: 13 | T18: 0 | U18: 0 | V18: 0 | W18: 0
A19: 14 | T19: 0 | U19: 0 | V19: 0 | W19: 0
A20: 15 | T20: 0 | U20: 0 | V20: 0 | W20: 0
A21: 16 | T21: 0 | U21: 0 | V21: 0 | W21: 0
A22: 17 | T22: 0 | U22: 0 | V22: 0 | W22: 0
A23: 18 | T23: 0 | U23: 0 | V23: 0 | W23: 0
A24: 19 | T24: 0 | U24: 0 | V24: 0 | W24: 0
... A28: 23 | T28: 0 | U28: 0 | V28: 0 | W28: 0

Sheet Demand Stage 2
A1: Node Number | B1: =1+Parameters!$B$7 -> 9 | X1: =B1+Parameters!$B$7 -> 17 | AT1: =X1+Parameters!$B$7 -> 25 | BP1: =AT1+Parameters!$B$7 -> 33 | CL1: =BP1+Parameters!$B$7 -> 41 | DH1: =CL1+Parameters!$B$7 -> 49 | ED1: =DH1+Parameters!$B$7 -> 57 | EZ1: =ED1+Parameters!$B$7 -> 65 | FV1: =EZ1+Parameters!$B$7 -> 73 | GR1: =FV1+Parameters!$B$7 -> 81 | HN1: =GR1+Parameters!$B$7 -> 89 | IJ1: =HN1+Parameters!$B$7 -> 97 | JF1: =IJ1+Parameters!$B$7 -> 105 | KB1: =JF1+Parameters!$B$7 -> 113 | KX1: =KB1+Parameters!$B$7 -> 121 | LT1: =KX1+Parameters!$B$7 -> 129 | MP1: =LT1+Parameters!$B$7 -> 137 | NL1: =MP1+Parameters!$B$7 -> 145 | OH1: =NL1+Parameters!$B$7 -> 153 | PD1: =OH1+Parameters!$B$7 -> 161 | PZ1: =PD1+Parameters!$B$7 -> 169 | QV1: =PZ1+Parameters!$B$7 -> 177 | RR1: =QV1+Parameters!$B$7 -> 185 | SN1: =RR1+Parameters!$B$7 -> 193 | TJ1: =SN1+Parameters!$B$7 -> 201 | UF1: =TJ1+Parameters!$B$7 -> 209 | VB1: =UF1+Parameters!$B$7 -> 217 | VX1: =VB1+Parameters!$B$7 -> 225 | WT1: =VX1+Parameters!$B$7 -> 233 | XP1: =WT1+Parameters!$B$7 -> 241 | YL1: =XP1+Parameters!$B$7 -> 249 | ZH1: =YL1+Parameters!$B$7 -> 257
A2: Probability | B2: =VLOOKUP(B1,OverwiewSecondStage!$B$1:$H$33,7,FALSE) -> 0 | X2: =VLOOKUP(X1,OverwiewSecondStage!$B$1:$H$33,7,FALSE) -> 0.041666667 | AT2: =VLOOKUP(AT1,OverwiewSecondStage!$B$1:$H$33,7,FALSE) -> 0 | BP2: =VLOOKUP(BP1,OverwiewSecondStage!$B$1:$H$33,7,FALSE) -> 0.041666667 | CL2: =VLOOKUP(CL1,OverwiewSecondStage!$B$1:$H$33,7,FALSE) -> 0 | DH2: =VLOOKUP(DH1,OverwiewSecondStage!$B$1:$H$33,7,FALSE) -> 0.041666667 | ED2: =VLOOKUP(ED1,OverwiewSecondStage!$B$1:$H$33,7,FALSE) -> 0 | EZ2: =VLOOKUP(EZ1,OverwiewSecondStage!$B$1:$H$33,7,FALSE) -> 0.041666667 | FV2: =VLOOKUP(FV1,OverwiewSecondStage!$B$1:$H$33,7,FALSE) -> 0 | GR2: =VLOOKUP(GR1,OverwiewSecondStage!$B$1:$H$33,7,FALSE) -> 0.041666667 | HN2: =VLOOKUP(HN1,OverwiewSecondStage!$B$1:$H$33,7,FALSE) -> 0 | IJ2: =VLOOKUP(IJ1,OverwiewSecondStage!$B$1:$H$33,7,FALSE) -> 0.041666667 | JF2: =VLOOKUP(JF1,OverwiewSecondStage!$B$1:$H$33,7,FALSE) -> 0 | KB2: =VLOOKUP(KB1,OverwiewSecondStage!$B$1:$H$33,7,FALSE) -> 0.041666667 | KX2: =VLOOKUP(KX1,OverwiewSecondStage!$B$1:$H$33,7,FALSE) -> 0 | LT2: =VLOOKUP(LT1,OverwiewSecondStage!$B$1:$H$33,7,FALSE) -> 0.041666667 | MP2: =VLOOKUP(MP1,OverwiewSecondStage!$B$1:$H$33,7,FALSE) -> 0.041666667 | NL2: =VLOOKUP(NL1,OverwiewSecondStage!$B$1:$H$33,7,FALSE) -> 0.041666667 | OH2: =VLOOKUP(OH1,OverwiewSecondStage!$B$1:$H$33,7,FALSE) -> 0.041666667 | PD2: =VLOOKUP(PD1,OverwiewSecondStage!$B$1:$H$33,7,FALSE) -> 0.041666667 | PZ2: =VLOOKUP(PZ1,OverwiewSecondStage!$B$1:$H$33,7,FALSE) -> 0.041666667 | QV2: =VLOOKUP(QV1,OverwiewSecondStage!$B$1:$H$33,7,FALSE) -> 0.041666667 | RR2: =VLOOKUP(RR1,OverwiewSecondStage!$B$1:$H$33,7,FALSE) -> 0.041666667 | SN2: =VLOOKUP(SN1,OverwiewSecondStage!$B$1:$H$33,7,FALSE) -> 0.041666667 | TJ2: =VLOOKUP(TJ1,OverwiewSecondStage!$B$1:$H$33,7,FALSE) -> 0.041666667 | UF2: =VLOOKUP(UF1,OverwiewSecondStage!$B$1:$H$33,7,FALSE) -> 0.041666667 | VB2: =VLOOKUP(VB1,OverwiewSecondStage!$B$1:$H$33,7,FALSE) -> 0.041666667 | VX2: =VLOOKUP(VX1,OverwiewSecondStage!$B$1:$H$33,7,FALSE) -> 0.041666667 | WT2: =VLOOKUP(WT1,OverwiewSecondStage!$B$1:$H$33,7,FALSE) -> 0.041666667 | XP2: =VLOOKUP(XP1,OverwiewSecondStage!$B$1:$H$33,7,FALSE) -> 0.041666667 | YL2: =VLOOKUP(YL1,OverwiewSecondStage!$B$1:$H$33,7,FALSE) -> 0.041666667 | ZH2: =VLOOKUP(ZH1,OverwiewSecondStage!$B$1:$H$33,7,FALSE) -> 0.041666667
B3: gas or mix | M3: pure hydrogen | X3: gas or mix | AI3: pure hydrogen | AT3: gas or mix | BE3: pure hydrogen | BP3: gas or mix | CA3: pure hydrogen | CL3: gas or mix | CW3: pure hydrogen | DH3: gas or mix | DS3: pure hydrogen | ED3: gas or mix | EO3: pure hydrogen | EZ3: gas or mix | FK3: pure hydrogen | FV3: gas or mix | GG3: pure hydrogen | GR3: gas or mix | HC3: pure hydrogen | HN3: gas or mix | HY3: pure hydrogen | IJ3: gas or mix | IU3: pure hydrogen | JF3: gas or mix | JQ3: pure hydrogen | KB3: gas or mix | KM3: pure hydrogen | KX3: gas or mix | LI3: pure hydrogen | LT3: gas or mix | ME3: pure hydrogen | MP3: gas or mix | NA3: pure hydrogen | NL3: gas or mix | NW3: pure hydrogen | OH3: gas or mix | OS3: pure hydrogen | PD3: gas or mix | PO3: pure hydrogen | PZ3: gas or mix | QK3: pure hydrogen | QV3: gas or mix | RG3: pure hydrogen | RR3: gas or mix | SC3: pure hydrogen | SN3: gas or mix | SY3: pure hydrogen | TJ3: gas or mix | TU3: pure hydrogen | UF3: gas or mix | UQ3: pure hydrogen | VB3: gas or mix | VM3: pure hydrogen | VX3: gas or mix | WI3: pure hydrogen | WT3: gas or mix | XE3: pure hydrogen | XP3: gas or mix | YA3: pure hydrogen | YL3: gas or mix | YW3: pure hydrogen | ZH3: gas or mix | ZS3: pure hydrogen
A4: Hour | B4: ST.FERGUS | C4: EASINGTON | D4: TEESSIDE | E4: Emden Industry | F4: Emden Consumers | G4: Dornum Industry | H4: Dornum Consumers | I4: Zeebrugge Industry | J4: Zeebrugge Consumers | K4: DUNKERQUE | L4: POLAND | M4: ST.FERGUS | N4: EASINGTON | O4: TEESSIDE | P4: Emden Industry | Q4: Emden Consumers | R4: Dornum Industry | S4: Dornum Consumers | T4: Zeebrugge Industry | U4: Zeebrugge Consumers | V4: DUNKERQUE | W4: POLAND | X4: ST.FERGUS | Y4: EASINGTON | Z4: TEESSIDE | AA4: Emden Industry | AB4: Emden Consumers | AC4: Dornum Industry | AD4: Dornum Consumers | AE4: Zeebrugge Industry | AF4: Zeebrugge Consumers | AG4: DUNKERQUE | AH4: POLAND | AI4: ST.FERGUS | AJ4: EASINGTON | AK4: TEESSIDE | AL4: Emden Industry | AM4: Emden Consumers | AN4: Dornum Industry | AO4: Dornum Consumers | AP4: Zeebrugge Industry | AQ4: Zeebrugge Consumers | AR4: DUNKERQUE | AS4: POLAND | AT4: ST.FERGUS | AU4: EASINGTON | AV4: TEESSIDE | AW4: Emden Industry | AX4: Emden Consumers | AY4: Dornum Industry | AZ4: Dornum Consumers | BA4: Zeebrugge Industry | BB4: Zeebrugge Consumers | BC4: DUNKERQUE | BD4: POLAND | BE4: ST.FERGUS | BF4: EASINGTON | BG4: TEESSIDE | BH4: Emden Industry | BI4: Emden Consumers | BJ4: Dornum Industry | BK4: Dornum Consumers | BL4: Zeebrugge Industry | BM4: Zeebrugge Consumers | BN4: DUNKERQUE | BO4: POLAND | BP4: ST.FERGUS | BQ4: EASINGTON | BR4: TEESSIDE | BS4: Emden Industry | BT4: Emden Consumers | BU4: Dornum Industry | BV4: Dornum Consumers | BW4: Zeebrugge Industry | BX4: Zeebrugge Consumers | BY4: DUNKERQUE | BZ4: POLAND | CA4: ST.FERGUS | CB4: EASINGTON | CC4: TEESSIDE | CD4: Emden Industry | CE4: Emden Consumers | CF4: Dornum Industry | CG4: Dornum Consumers | CH4: Zeebrugge Industry | CI4: Zeebrugge Consumers | CJ4: DUNKERQUE | CK4: POLAND | CL4: ST.FERGUS | CM4: EASINGTON | CN4: TEESSIDE | CO4: Emden Industry | CP4: Emden Consumers | CQ4: Dornum Industry | CR4: Dornum Consumers | CS4: Zeebrugge Industry | CT4: Zeebrugge Consumers | CU4: DUNKERQUE | CV4: POLAND | CW4: ST.FERGUS | CX4: EASINGTON | CY4: TEESSIDE | CZ4: Emden Industry | DA4: Emden Consumers | DB4: Dornum Industry | DC4: Dornum Consumers | DD4: Zeebrugge Industry | DE4: Zeebrugge Consumers | DF4: DUNKERQUE | DG4: POLAND | DH4: ST.FERGUS | DI4: EASINGTON | DJ4: TEESSIDE | DK4: Emden Industry | DL4: Emden Consumers | DM4: Dornum Industry | DN4: Dornum Consumers | DO4: Zeebrugge Industry | DP4: Zeebrugge Consumers | DQ4: DUNKERQUE | DR4: POLAND | DS4: ST.FERGUS | DT4: EASINGTON | DU4: TEESSIDE | DV4: Emden Industry | DW4: Emden Consumers | DX4: Dornum Industry | DY4: Dornum Consumers | DZ4: Zeebrugge Industry | EA4: Zeebrugge Consumers | EB4: DUNKERQUE | EC4: POLAND | ED4: ST.FERGUS | EE4: EASINGTON | EF4: TEESSIDE | EG4: Emden Industry | EH4: Emden Consumers | EI4: Dornum Industry | EJ4: Dornum Consumers | EK4: Zeebrugge Industry | EL4: Zeebrugge Consumers | EM4: DUNKERQUE | EN4: POLAND | EO4: ST.FERGUS | EP4: EASINGTON | EQ4: TEESSIDE | ER4: Emden Industry | ES4: Emden Consumers | ET4: Dornum Industry | EU4: Dornum Consumers | EV4: Zeebrugge Industry | EW4: Zeebrugge Consumers | EX4: DUNKERQUE | EY4: POLAND | EZ4: ST.FERGUS | FA4: EASINGTON | FB4: TEESSIDE | FC4: Emden Industry | FD4: Emden Consumers | FE4: Dornum Industry | FF4: Dornum Consumers | FG4: Zeebrugge Industry | FH4: Zeebrugge Consumers | FI4: DUNKERQUE | FJ4: POLAND | FK4: ST.FERGUS | FL4: EASINGTON | FM4: TEESSIDE | FN4: Emden Industry | FO4: Emden Consumers | FP4: Dornum Industry | FQ4: Dornum Consumers | FR4: Zeebrugge Industry | FS4: Zeebrugge Consumers | FT4: DUNKERQUE | FU4: POLAND | FV4: ST.FERGUS | FW4: EASINGTON | FX4: TEESSIDE | FY4: Emden Industry | FZ4: Emden Consumers | GA4: Dornum Industry | GB4: Dornum Consumers | GC4: Zeebrugge Industry | GD4: Zeebrugge Consumers | GE4: DUNKERQUE | GF4: POLAND | GG4: ST.FERGUS | GH4: EASINGTON | GI4: TEESSIDE | GJ4: Emden Industry | GK4: Emden Consumers | GL4: Dornum Industry | GM4: Dornum Consumers | GN4: Zeebrugge Industry | GO4: Zeebrugge Consumers | GP4: DUNKERQUE | GQ4: POLAND | GR4: ST.FERGUS | GS4: EASINGTON | GT4: TEESSIDE | GU4: Emden Industry | GV4: Emden Consumers | GW4: Dornum Industry | GX4: Dornum Consumers | GY4: Zeebrugge Industry | GZ4: Zeebrugge Consumers | HA4: DUNKERQUE | HB4: POLAND | HC4: ST.FERGUS | HD4: EASINGTON | HE4: TEESSIDE | HF4: Emden Industry | HG4: Emden Consumers | HH4: Dornum Industry | HI4: Dornum Consumers | HJ4: Zeebrugge Industry | HK4: Zeebrugge Consumers | HL4: DUNKERQUE | HM4: POLAND | HN4: ST.FERGUS | HO4: EASINGTON | HP4: TEESSIDE | HQ4: Emden Industry | HR4: Emden Consumers | HS4: Dornum Industry | HT4: Dornum Consumers | HU4: Zeebrugge Industry | HV4: Zeebrugge Consumers | HW4: DUNKERQUE | HX4: POLAND | HY4: ST.FERGUS | HZ4: EASINGTON | IA4: TEESSIDE | IB4: Emden Industry | IC4: Emden Consumers | ID4: Dornum Industry | IE4: Dornum Consumers | IF4: Zeebrugge Industry | IG4: Zeebrugge Consumers | IH4: DUNKERQUE | II4: POLAND | IJ4: ST.FERGUS | IK4: EASINGTON | IL4: TEESSIDE | IM4: Emden Industry | IN4: Emden Consumers | IO4: Dornum Industry | IP4: Dornum Consumers | IQ4: Zeebrugge Industry | IR4: Zeebrugge Consumers | IS4: DUNKERQUE | IT4: POLAND | IU4: ST.FERGUS | IV4: EASINGTON | IW4: TEESSIDE | IX4: Emden Industry | IY4: Emden Consumers | IZ4: Dornum Industry | JA4: Dornum Consumers | JB4: Zeebrugge Industry | JC4: Zeebrugge Consumers | JD4: DUNKERQUE | JE4: POLAND | JF4: ST.FERGUS | JG4: EASINGTON | JH4: TEESSIDE | JI4: Emden Industry | JJ4: Emden Consumers | JK4: Dornum Industry | JL4: Dornum Consumers | JM4: Zeebrugge Industry | JN4: Zeebrugge Consumers | JO4: DUNKERQUE | JP4: POLAND | JQ4: ST.FERGUS | JR4: EASINGTON | JS4: TEESSIDE | JT4: Emden Industry | JU4: Emden Consumers | JV4: Dornum Industry | JW4: Dornum Consumers | JX4: Zeebrugge Industry | JY4: Zeebrugge Consumers | JZ4: DUNKERQUE | KA4: POLAND | KB4: ST.FERGUS | KC4: EASINGTON | KD4: TEESSIDE | KE4: Emden Industry | KF4: Emden Consumers | KG4: Dornum Industry | KH4: Dornum Consumers | KI4: Zeebrugge Industry | KJ4: Zeebrugge Consumers | KK4: DUNKERQUE | KL4: POLAND | KM4: ST.FERGUS | KN4: EASINGTON | KO4: TEESSIDE | KP4: Emden Industry | KQ4: Emden Consumers | KR4: Dornum Industry | KS4: Dornum Consumers | KT4: Zeebrugge Industry | KU4: Zeebrugge Consumers | KV4: DUNKERQUE | KW4: POLAND | KX4: ST.FERGUS | KY4: EASINGTON | KZ4: TEESSIDE | LA4: Emden Industry | LB4: Emden Consumers | LC4: Dornum Industry | LD4: Dornum Consumers | LE4: Zeebrugge Industry | LF4: Zeebrugge Consumers | LG4: DUNKERQUE | LH4: POLAND | LI4: ST.FERGUS | LJ4: EASINGTON | LK4: TEESSIDE | LL4: Emden Industry | LM4: Emden Consumers | LN4: Dornum Industry | LO4: Dornum Consumers | LP4: Zeebrugge Industry | LQ4: Zeebrugge Consumers | LR4: DUNKERQUE | LS4: POLAND | LT4: ST.FERGUS | LU4: EASINGTON | LV4: TEESSIDE | LW4: Emden Industry | LX4: Emden Consumers | LY4: Dornum Industry | LZ4: Dornum Consumers | MA4: Zeebrugge Industry | MB4: Zeebrugge Consumers | MC4: DUNKERQUE | MD4: POLAND | ME4: ST.FERGUS | MF4: EASINGTON | MG4: TEESSIDE | MH4: Emden Industry | MI4: Emden Consumers | MJ4: Dornum Industry | MK4: Dornum Consumers | ML4: Zeebrugge Industry | MM4: Zeebrugge Consumers | MN4: DUNKERQUE | MO4: POLAND | MP4: ST.FERGUS | MQ4: EASINGTON | MR4: TEESSIDE | MS4: Emden Industry | MT4: Emden Consumers | MU4: Dornum Industry | MV4: Dornum Consumers | MW4: Zeebrugge Industry | MX4: Zeebrugge Consumers | MY4: DUNKERQUE | MZ4: POLAND | NA4: ST.FERGUS | NB4: EASINGTON | NC4: TEESSIDE | ND4: Emden Industry | NE4: Emden Consumers | NF4: Dornum Industry | NG4: Dornum Consumers | NH4: Zeebrugge Industry | NI4: Zeebrugge Consumers | NJ4: DUNKERQUE | NK4: POLAND | NL4: ST.FERGUS | NM4: EASINGTON | NN4: TEESSIDE | NO4: Emden Industry | NP4: Emden Consumers | NQ4: Dornum Industry | NR4: Dornum Consumers | NS4: Zeebrugge Industry | NT4: Zeebrugge Consumers | NU4: DUNKERQUE | NV4: POLAND | NW4: ST.FERGUS | NX4: EASINGTON | NY4: TEESSIDE | NZ4: Emden Industry | OA4: Emden Consumers | OB4: Dornum Industry | OC4: Dornum Consumers | OD4: Zeebrugge Industry | OE4: Zeebrugge Consumers | OF4: DUNKERQUE | OG4: POLAND | OH4: ST.FERGUS | OI4: EASINGTON | OJ4: TEESSIDE | OK4: Emden Industry | OL4: Emden Consumers | OM4: Dornum Industry | ON4: Dornum Consumers | OO4: Zeebrugge Industry | OP4: Zeebrugge Consumers | OQ4: DUNKERQUE | OR4: POLAND | OS4: ST.FERGUS | OT4: EASINGTON | OU4: TEESSIDE | OV4: Emden Industry | OW4: Emden Consumers | OX4: Dornum Industry | OY4: Dornum Consumers | OZ4: Zeebrugge Industry | PA4: Zeebrugge Consumers | PB4: DUNKERQUE | PC4: POLAND | PD4: ST.FERGUS | PE4: EASINGTON | PF4: TEESSIDE | PG4: Emden Industry | PH4: Emden Consumers | PI4: Dornum Industry | PJ4: Dornum Consumers | PK4: Zeebrugge Industry | PL4: Zeebrugge Consumers | PM4: DUNKERQUE | PN4: POLAND | PO4: ST.FERGUS | PP4: EASINGTON | PQ4: TEESSIDE | PR4: Emden Industry | PS4: Emden Consumers | PT4: Dornum Industry | PU4: Dornum Consumers | PV4: Zeebrugge Industry | PW4: Zeebrugge Consumers | PX4: DUNKERQUE | PY4: POLAND | PZ4: ST.FERGUS | QA4: EASINGTON | QB4: TEESSIDE | QC4: Emden Industry | QD4: Emden Consumers | QE4: Dornum Industry | QF4: Dornum Consumers | QG4: Zeebrugge Industry | QH4: Zeebrugge Consumers | QI4: DUNKERQUE | QJ4: POLAND | QK4: ST.FERGUS | QL4: EASINGTON | QM4: TEESSIDE | QN4: Emden Industry | QO4: Emden Consumers | QP4: Dornum Industry | QQ4: Dornum Consumers | QR4: Zeebrugge Industry | QS4: Zeebrugge Consumers | QT4: DUNKERQUE | QU4: POLAND | QV4: ST.FERGUS | QW4: EASINGTON | QX4: TEESSIDE | QY4: Emden Industry | QZ4: Emden Consumers | RA4: Dornum Industry | RB4: Dornum Consumers | RC4: Zeebrugge Industry | RD4: Zeebrugge Consumers | RE4: DUNKERQUE | RF4: POLAND | RG4: ST.FERGUS | RH4: EASINGTON | RI4: TEESSIDE | RJ4: Emden Industry | RK4: Emden Consumers | RL4: Dornum Industry | RM4: Dornum Consumers | RN4: Zeebrugge Industry | RO4: Zeebrugge Consumers | RP4: DUNKERQUE | RQ4: POLAND | RR4: ST.FERGUS | RS4: EASINGTON | RT4: TEESSIDE | RU4: Emden Industry | RV4: Emden Consumers | RW4: Dornum Industry | RX4: Dornum Consumers | RY4: Zeebrugge Industry | RZ4: Zeebrugge Consumers | SA4: DUNKERQUE | SB4: POLAND | SC4: ST.FERGUS | SD4: EASINGTON | SE4: TEESSIDE | SF4: Emden Industry | SG4: Emden Consumers | SH4: Dornum Industry | SI4: Dornum Consumers | SJ4: Zeebrugge Industry | SK4: Zeebrugge Consumers | SL4: DUNKERQUE | SM4: POLAND | SN4: ST.FERGUS | SO4: EASINGTON | SP4: TEESSIDE | SQ4: Emden Industry | SR4: Emden Consumers | SS4: Dornum Industry | ST4: Dornum Consumers | SU4: Zeebrugge Industry | SV4: Zeebrugge Consumers | SW4: DUNKERQUE | SX4: POLAND | SY4: ST.FERGUS | SZ4: EASINGTON | TA4: TEESSIDE | TB4: Emden Industry | TC4: Emden Consumers | TD4: Dornum Industry | TE4: Dornum Consumers | TF4: Zeebrugge Industry | TG4: Zeebrugge Consumers | TH4: DUNKERQUE | TI4: POLAND | TJ4: ST.FERGUS | TK4: EASINGTON | TL4: TEESSIDE | TM4: Emden Industry | TN4: Emden Consumers | TO4: Dornum Industry | TP4: Dornum Consumers | TQ4: Zeebrugge Industry | TR4: Zeebrugge Consumers | TS4: DUNKERQUE | TT4: POLAND | TU4: ST.FERGUS | TV4: EASINGTON | TW4: TEESSIDE | TX4: Emden Industry | TY4: Emden Consumers | TZ4: Dornum Industry | UA4: Dornum Consumers | UB4: Zeebrugge Industry | UC4: Zeebrugge Consumers | UD4: DUNKERQUE | UE4: POLAND | UF4: ST.FERGUS | UG4: EASINGTON | UH4: TEESSIDE | UI4: Emden Industry | UJ4: Emden Consumers | UK4: Dornum Industry | UL4: Dornum Consumers | UM4: Zeebrugge Industry | UN4: Zeebrugge Consumers | UO4: DUNKERQUE | UP4: POLAND | UQ4: ST.FERGUS | UR4: EASINGTON | US4: TEESSIDE | UT4: Emden Industry | UU4: Emden Consumers | UV4: Dornum Industry | UW4: Dornum Consumers | UX4: Zeebrugge Industry | UY4: Zeebrugge Consumers | UZ4: DUNKERQUE | VA4: POLAND | VB4: ST.FERGUS | VC4: EASINGTON | VD4: TEESSIDE | VE4: Emden Industry | VF4: Emden Consumers | VG4: Dornum Industry | VH4: Dornum Consumers | VI4: Zeebrugge Industry | VJ4: Zeebrugge Consumers | VK4: DUNKERQUE | VL4: POLAND | VM4: ST.FERGUS | VN4: EASINGTON | VO4: TEESSIDE | VP4: Emden Industry | VQ4: Emden Consumers | VR4: Dornum Industry | VS4: Dornum Consumers | VT4: Zeebrugge Industry | VU4: Zeebrugge Consumers | VV4: DUNKERQUE | VW4: POLAND | VX4: ST.FERGUS | VY4: EASINGTON | VZ4: TEESSIDE | WA4: Emden Industry | WB4: Emden Consumers | WC4: Dornum Industry | WD4: Dornum Consumers | WE4: Zeebrugge Industry | WF4: Zeebrugge Consumers | WG4: DUNKERQUE | WH4: POLAND | WI4: ST.FERGUS | WJ4: EASINGTON | WK4: TEESSIDE | WL4: Emden Industry | WM4: Emden Consumers | WN4: Dornum Industry | WO4: Dornum Consumers | WP4: Zeebrugge Industry | WQ4: Zeebrugge Consumers | WR4: DUNKERQUE | WS4: POLAND | WT4: ST.FERGUS | WU4: EASINGTON | WV4: TEESSIDE | WW4: Emden Industry | WX4: Emden Consumers | WY4: Dornum Industry | WZ4: Dornum Consumers | XA4: Zeebrugge Industry | XB4: Zeebrugge Consumers | XC4: DUNKERQUE | XD4: POLAND | XE4: ST.FERGUS | XF4: EASINGTON | XG4: TEESSIDE | XH4: Emden Industry | XI4: Emden Consumers | XJ4: Dornum Industry | XK4: Dornum Consumers | XL4: Zeebrugge Industry | XM4: Zeebrugge Consumers | XN4: DUNKERQUE | XO4: POLAND | XP4: ST.FERGUS | XQ4: EASINGTON | XR4: TEESSIDE | XS4: Emden Industry | XT4: Emden Consumers | XU4: Dornum Industry | XV4: Dornum Consumers | XW4: Zeebrugge Industry | XX4: Zeebrugge Consumers | XY4: DUNKERQUE | XZ4: POLAND | YA4: ST.FERGUS | YB4: EASINGTON | YC4: TEESSIDE | YD4: Emden Industry | YE4: Emden Consumers | YF4: Dornum Industry | YG4: Dornum Consumers | YH4: Zeebrugge Industry | YI4: Zeebrugge Consumers | YJ4: DUNKERQUE | YK4: POLAND | YL4: ST.FERGUS | YM4: EASINGTON | YN4: TEESSIDE | YO4: Emden Industry | YP4: Emden Consumers | YQ4: Dornum Industry | YR4: Dornum Consumers | YS4: Zeebrugge Industry | YT4: Zeebrugge Consumers | YU4: DUNKERQUE | YV4: POLAND | YW4: ST.FERGUS | YX4: EASINGTON | YY4: TEESSIDE | YZ4: Emden Industry | ZA4: Emden Consumers | ZB4: Dornum Industry | ZC4: Dornum Consumers | ZD4: Zeebrugge Industry | ZE4: Zeebrugge Consumers | ZF4: DUNKERQUE | ZG4: POLAND | ZH4: ST.FERGUS | ZI4: EASINGTON | ZJ4: TEESSIDE | ZK4: Emden Industry | ZL4: Emden Consumers | ZM4: Dornum Industry | ZN4: Dornum Consumers | ZO4: Zeebrugge Industry | ZP4: Zeebrugge Consumers | ZQ4: DUNKERQUE | ZR4: POLAND | ZS4: ST.FERGUS | ZT4: EASINGTON | ZU4: TEESSIDE | ZV4: Emden Industry | ZW4: Emden Consumers | ZX4: Dornum Industry | ZY4: Dornum Consumers | ZZ4: Zeebrugge Industry | AAA4: Zeebrugge Consumers | AAB4: DUNKERQUE | AAC4: POLAND
