Workbook

Sheet Visualisation

Sheet Units
A1: Quantity | B1: Unit | C1: Explanation
A2: =Nodes!J2 -> Temp | B2: MSm3/h | C2: Mega (or million) standard cubic metres per hour. One standard cubic meter means the amount of gas which occupies a Cubic Meter at fifteen (15) Degrees Celsius and a pressure of one hundred one decimal three two five (101.325) kPa.
A3: =Nodes!M2 -> Production Costs Gas | B3: NOK / MSm3
A4: =Nodes!N2 -> Storage Capacity Gas | B4: MSm3
A5: =Nodes!O2 -> Entry Storage Costs Gas | B5: NOK / MSm3
A6: =Nodes!P2 -> Entry Costs Gas Stage 1 | B6: NOK / MSm3
A7: =Nodes!Q2 -> Exit Costs Gas Stage 1 | B7: NOK / MSm3
A8: =Arcs!M1 -> Flow costs Gas | B8: NOK / MSm3
A9: =Arcs!#REF! -> #REF! | B9: MSm3/h
A10: Demand | B10: MSm3/h

Sheet Nodes
G1: Gas | V1: Hydrogen
A2: ID | B2: Name | C2: Type | D2: X_coordinate | E2: Y_coordinate | F2: Note | G2: TSO entry costs Gas | H2: TSO exit costs Gas | I2: Production Capacity Gas | J2: Temp | K2: Entry Capacity Gas | L2: Exit Capacity Gas | M2: Production Costs Gas | N2: Storage Capacity Gas | O2: Entry Storage Costs Gas | P2: Entry Costs Gas Stage 1 | Q2: Exit Costs Gas Stage 1 | R2: Entry Costs Gas Stage 2 | S2: Exit Costs Gas Stage 2 | T2: Entry Costs Gas Stage 3 | U2: Exit Costs Gas Stage 3 | V2: TSO entry costs Hydrogen | W2: TSO exit costs Hydrogen | X2: Production Capacity Hydrogen | Y2: Entry Capacity Hydrogen | Z2: Exit Capacity Hydrogen | AA2: Production Costs Hydrogen | AB2: Storage Capacity Hydrogen | AC2: Entry Storage Costs Hydrogen | AD2: Entry Costs Hydrogen Stage 1 | AE2: Exit Costs Hydrogen Stage 1 | AF2: Entry Costs Hydrogen Stage 2 | AG2: Exit Costs Hydrogen Stage 2 | AH2: Entry Costs Hydrogen Stage 3 | AI2: Exit Costs Hydrogen Stage 3
A3: 1 | B3: MELKoYA | D3: 23.587348 | E3: 70.685444 | G3: 5 | H3: 5 | I3: =J3/1000 -> 0.11905 | J3: 119.05 | K3: 500 | L3: 500 | M3: 1 | N3: 0 | O3: 0 | P3: 1 | Q3: 1 | R3: 0.1 | S3: 0.1 | T3: 0.35 | U3: 0.35 | V3: 5 | W3: 5 | X3: 0 | Y3: 0 | Z3: 0 | AA3: 1 | AB3: 0 | AC3: 1 | AD3: 1 | AE3: 1 | AF3: 3 | AG3: 3 | AH3: 5 | AI3: 5
A4: 2 | B4: SNoHVIT PLEM-1 | D4: 21.226542 | E4: 71.571335 | G4: 5 | H4: 5 | I4: =J4/1000 -> 8.889595 | J4: 8889.595 | K4: 500 | L4: 500 | M4: 1 | N4: 0 | O4: 0 | P4: 1 | Q4: 1 | R4: 0.1 | S4: 0.1 | T4: 0.35 | U4: 0.35 | V4: 5 | W4: 5 | X4: 0 | Y4: 0 | Z4: 0 | AA4: 1 | AB4: 0 | AC4: 1 | AD4: 1 | AE4: 1 | AF4: 3 | AG4: 3 | AH4: 5 | AI4: 5
A5: 3 | B5: AASTA HANSTEEN PLEM | D5: 7.107227 | E5: 67.05561 | G5: 5 | H5: 5 | I5: =J5/1000 -> 8.889595 | J5: 8889.595 | K5: 500 | L5: 500 | M5: 1 | N5: 0 | O5: 0 | P5: 1 | Q5: 1 | R5: 0.1 | S5: 0.1 | T5: 0.35 | U5: 0.35 | V5: 5 | W5: 5 | X5: 0 | Y5: 0 | Z5: 0 | AA5: 1 | AB5: 0 | AC5: 1 | AD5: 1 | AE5: 1 | AF5: 3 | AG5: 3 | AH5: 5 | AI5: 5
A6: 4 | B6: NORNE ERB | D6: 8.0785441 | E6: 66.029331 | G6: 5 | H6: 5 | I6: =J6/1000 -> 1.041051 | J6: 1041.051 | K6: 500 | L6: 500 | M6: 1 | N6: 0 | O6: 0 | P6: 1 | Q6: 1 | R6: 0.1 | S6: 0.1 | T6: 0.35 | U6: 0.35 | V6: 5 | W6: 5 | X6: 0 | Y6: 0 | Z6: 0 | AA6: 1 | AB6: 0 | AC6: 1 | AD6: 1 | AE6: 1 | AF6: 3 | AG6: 3 | AH6: 5 | AI6: 5
A7: 5 | B7: SKARV ERB | D7: 7.6558328 | E7: 65.693744 | G7: 5 | H7: 5 | I7: =J7/1000 -> 0.048065 | J7: 48.065 | K7: 500 | L7: 500 | M7: 1 | N7: 0 | O7: 0 | P7: 1 | Q7: 1 | R7: 0.1 | S7: 0.1 | T7: 0.35 | U7: 0.35 | V7: 5 | W7: 5 | X7: 0 | Y7: 0 | Z7: 0 | AA7: 1 | AB7: 0 | AC7: 1 | AD7: 1 | AE7: 1 | AF7: 3 | AG7: 3 | AH7: 5 | AI7: 5
A8: 6 | B8: HEIDRUN | D8: 7.3202454 | E8: 65.3215 | G8: 5 | H8: 5 | I8: =J8/1000 -> 1.2146 | J8: 1214.6 | K8: 500 | L8: 500 | M8: 1 | N8: 0 | O8: 0 | P8: 1 | Q8: 1 | R8: 0.1 | S8: 0.1 | T8: 0.35 | U8: 0.35 | V8: 5 | W8: 5 | X8: 0 | Y8: 0 | Z8: 0 | AA8: 1 | AB8: 0 | AC8: 1 | AD8: 1 | AE8: 1 | AF8: 3 | AG8: 3 | AH8: 5 | AI8: 5
A9: 7 | B9: aSGARD T | D9: 6.8036598 | E9: 65.094472 | G9: 5 | H9: 5 | I9: =J9/1000 -> 0 | J9: 0 | K9: 500 | L9: 500 | M9: 1 | N9: 0 | O9: 0 | P9: 1 | Q9: 1 | R9: 0.1 | S9: 0.1 | T9: 0.35 | U9: 0.35 | V9: 5 | W9: 5 | X9: 0 | Y9: 0 | Z9: 0 | AA9: 1 | AB9: 0 | AC9: 1 | AD9: 1 | AE9: 1 | AF9: 3 | AG9: 3 | AH9: 5 | AI9: 5
A10: 8 | B10: NORNE/HEIDRUN T | D10: 6.801461 | E10: 65.084516 | G10: 5 | H10: 5 | I10: =J10/1000 -> 1.2146 | J10: 1214.6 | K10: 500 | L10: 500 | M10: 1 | N10: 0 | O10: 0 | P10: 1 | Q10: 1 | R10: 0.1 | S10: 0.1 | T10: 0.35 | U10: 0.35 | V10: 5 | W10: 5 | X10: 0 | Y10: 0 | Z10: 0 | AA10: 1 | AB10: 0 | AC10: 1 | AD10: 1 | AE10: 1 | AF10: 3 | AG10: 3 | AH10: 5 | AI10: 5
A11: 9 | B11: DRAUGEN T | D11: 7.7910261 | E11: 64.350568 | G11: 5 | H11: 5 | I11: =J11/1000 -> 0.048065 | J11: 48.065 | K11: 500 | L11: 500 | M11: 1 | N11: 0 | O11: 0 | P11: 1 | Q11: 1 | R11: 0.1 | S11: 0.1 | T11: 0.35 | U11: 0.35 | V11: 5 | W11: 5 | X11: 0 | Y11: 0 | Z11: 0 | AA11: 1 | AB11: 0 | AC11: 1 | AD11: 1 | AE11: 1 | AF11: 3 | AG11: 3 | AH11: 5 | AI11: 5
A12: 10 | B12: DRAUGEN | D12: 6.441258 | E12: 64.233255 | G12: 5 | H12: 5 | I12: =J12/1000 -> 0.048065 | J12: 48.065 | K12: 500 | L12: 500 | M12: 1 | N12: 0 | O12: 0 | P12: 1 | Q12: 1 | R12: 0.1 | S12: 0.1 | T12: 0.35 | U12: 0.35 | V12: 5 | W12: 5 | X12: 0 | Y12: 0 | Z12: 0 | AA12: 1 | AB12: 0 | AC12: 1 | AD12: 1 | AE12: 1 | AF12: 3 | AG12: 3 | AH12: 5 | AI12: 5
A13: 11 | B13: ORMEN LANGE A | D13: 5.3867636 | E13: 63.528082 | G13: 5 | H13: 5 | I13: =J13/1000 -> 0.048065 | J13: 48.065 | K13: 500 | L13: 500 | M13: 1 | N13: 0 | O13: 0 | P13: 1 | Q13: 1 | R13: 0.1 | S13: 0.1 | T13: 0.35 | U13: 0.35 | V13: 5 | W13: 5 | X13: 0 | Y13: 0 | Z13: 0 | AA13: 1 | AB13: 0 | AC13: 1 | AD13: 1 | AE13: 1 | AF13: 3 | AG13: 3 | AH13: 5 | AI13: 5
A14: 12 | B14: ORMEN LANGE B | D14: 5.386516 | E14: 63.528076 | G14: 5 | H14: 5 | I14: =J14/1000 -> 0 | J14: 0 | K14: 500 | L14: 500 | M14: 1 | N14: 0 | O14: 0 | P14: 1 | Q14: 1 | R14: 0.1 | S14: 0.1 | T14: 0.35 | U14: 0.35 | V14: 5 | W14: 5 | X14: 0 | Y14: 0 | Z14: 0 | AA14: 1 | AB14: 0 | AC14: 1 | AD14: 1 | AE14: 1 | AF14: 3 | AG14: 3 | AH14: 5 | AI14: 5
... A64: 62 | B64: EMDEN 2 | D64: 7.18929 | E64: 53.3462 | G64: 5 | H64: 5 | I64: =J64/1000 -> 0 | J64: 0 | K64: 500 | L64: 500 | M64: 1 | N64: 0 | O64: 0 | P64: 1 | Q64: 1 | R64: 0.1 | S64: 0.1 | T64: 0.35 | U64: 0.35 | V64: 5 | W64: 5 | X64: 0 | Y64: 0 | Z64: 0 | AA64: 1 | AB64: 0 | AC64: 1 | AD64: 1 | AE64: 1 | AF64: 3 | AG64: 3 | AH64: 5 | AI64: 5
J67: Je produceert toch in DK voor vraag in PL?

Sheet Demand Stage 1
A1: Node Number | B1: 1
A2: Probability | B2: 1
A3: Parent Node Number
B4: gas or mix | J4: pure hydrogen
A5: Hour | B5: ='Demand Stage 2'!B4 -> ST.FERGUS | C5: ='Demand Stage 2'!C4 -> EASINGTON | D5: ='Demand Stage 2'!D4 -> TEESSIDE | E5: ='Demand Stage 2'!E4 -> EMDEN | F5: ='Demand Stage 2'!F4 -> EMDEN 2 | G5: ='Demand Stage 2'!G4 -> ZEEBRUGGE | H5: ='Demand Stage 2'!H4 -> DUNKERQUE | I5: ='Demand Stage 2'!I4 -> POLAND | ... Q5: ='Demand Stage 2'!Q4 -> POLAND
A6: 0 | B6: ='Demand Stage 2'!B43 -> 10 | C6: ='Demand Stage 2'!C43 -> 10 | D6: ='Demand Stage 2'!D43 -> 10 | E6: ='Demand Stage 2'!E43 -> 40 | F6: ='Demand Stage 2'!F43 -> 40 | G6: ='Demand Stage 2'!G43 -> 40 | H6: ='Demand Stage 2'!H43 -> 40 | I6: ='Demand Stage 2'!I43 -> 20 | J6: 0 | K6: 0 | L6: 0 | M6: 0 | N6: 0 | O6: 0 | P6: 0 | Q6: 0
A7: 1 | B7: ='Demand Stage 2'!B44 -> 10 | C7: ='Demand Stage 2'!C44 -> 10 | D7: ='Demand Stage 2'!D44 -> 10 | E7: ='Demand Stage 2'!E44 -> 45 | F7: ='Demand Stage 2'!F44 -> 45 | G7: ='Demand Stage 2'!G44 -> 40 | H7: ='Demand Stage 2'!H44 -> 45 | I7: ='Demand Stage 2'!I44 -> 20 | J7: 0 | K7: 0 | L7: 0 | M7: 0 | N7: 0 | O7: 0 | P7: 0 | Q7: 0
A8: 2 | B8: ='Demand Stage 2'!B45 -> 10 | C8: ='Demand Stage 2'!C45 -> 10 | D8: ='Demand Stage 2'!D45 -> 10 | E8: ='Demand Stage 2'!E45 -> 40 | F8: ='Demand Stage 2'!F45 -> 40 | G8: ='Demand Stage 2'!G45 -> 40 | H8: ='Demand Stage 2'!H45 -> 35 | I8: ='Demand Stage 2'!I45 -> 20 | J8: 0 | K8: 0 | L8: 0 | M8: 0 | N8: 0 | O8: 0 | P8: 0 | Q8: 0
A9: 3 | B9: ='Demand Stage 2'!B46 -> 10 | C9: ='Demand Stage 2'!C46 -> 10 | D9: ='Demand Stage 2'!D46 -> 10 | E9: ='Demand Stage 2'!E46 -> 45 | F9: ='Demand Stage 2'!F46 -> 45 | G9: ='Demand Stage 2'!G46 -> 40 | H9: ='Demand Stage 2'!H46 -> 40 | I9: ='Demand Stage 2'!I46 -> 20 | J9: 0 | K9: 0 | L9: 0 | M9: 0 | N9: 0 | O9: 0 | P9: 0 | Q9: 0
A10: 4
A11: 5
A12: 6
A13: 7
A14: 8
A15: 9
A16: 10
A17: 11
A18: 12
A19: 13
A20: 14
A21: 15
... A29: 23

Sheet Demand Stage 2
A1: Node Number | B1: 2 | R1: =B1+Parameters!$B$5 -> 6 | AH1: =R1+Parameters!$B$5 -> 10 | AX1: =AH1+Parameters!$B$5 -> 14
A2: Probability | B2: 0.25 | R2: =B2 -> 0.25 | AH2: =B2 -> 0.25 | AX2: =B2 -> 0.25
B3: gas or mix | J3: pure hydrogen | R3: gas or mix | Z3: pure hydrogen | AH3: gas or mix | AP3: pure hydrogen | AX3: gas or mix | BF3: pure hydrogen
A4: Hour | B4: ST.FERGUS | C4: EASINGTON | D4: TEESSIDE | E4: EMDEN | F4: EMDEN 2 | G4: ZEEBRUGGE | H4: DUNKERQUE | I4: POLAND | J4: =B4 -> ST.FERGUS | K4: =C4 -> EASINGTON | L4: =D4 -> TEESSIDE | M4: =E4 -> EMDEN | N4: =F4 -> EMDEN 2 | O4: =G4 -> ZEEBRUGGE | P4: =H4 -> DUNKERQUE | Q4: =I4 -> POLAND | R4: =B4 -> ST.FERGUS | S4: =C4 -> EASINGTON | T4: =D4 -> TEESSIDE | U4: =E4 -> EMDEN | V4: =F4 -> EMDEN 2 | W4: =G4 -> ZEEBRUGGE | X4: =H4 -> DUNKERQUE | Y4: =I4 -> POLAND | ... BE4: =AO4 -> POLAND | BF4: =AQ4 -> EASINGTON | BG4: =AR4 -> TEESSIDE | BH4: =AS4 -> EMDEN | BI4: =AT4 -> EMDEN 2 | BJ4: =AU4 -> ZEEBRUGGE | BK4: =AV4 -> DUNKERQUE | BL4: =AW4 -> POLAND | BM4: =AX4 -> ST.FERGUS
A5: 0 | B5: =B31+B43 -> 10 | C5: =C31+C43 -> 10 | D5: =D31+D43 -> 10 | E5: =E31+E43 -> 40 | F5: =F31+F43 -> 40 | G5: =G31+G43 -> 40 | H5: =H31+H43 -> 40 | I5: =I31+I43 -> 20 | J5: 0 | K5: 0 | L5: 0 | M5: 0 | N5: 0 | O5: 0 | P5: 0 | Q5: 0 | R5: =R31+B43 -> 10 | S5: =S31+C43 -> 10 | T5: =T31+D43 -> 10 | U5: =U31+E43 -> 40 | V5: =V31+F43 -> 40 | W5: =W31+G43 -> 40 | X5: =X31+H43 -> 40 | Y5: =Y31+I43 -> 20 | Z5: 0 | AA5: 0 | AB5: 0 | AC5: 0 | AD5: 0 | AE5: 0 | AF5: 0 | AG5: 0 | AH5: =AH31+B43 -> 10 | AI5: =AI31+C43 -> 10 | AJ5: =AJ31+D43 -> 10 | AK5: =AK31+E43 -> 40 | AL5: =AL31+F43 -> 40 | AM5: =AM31+G43 -> 40 | AN5: =AN31+H43 -> 40 | AO5: =AO31+I43 -> 20 | AP5: 0 | AQ5: 0 | AR5: 0 | AS5: 0 | AT5: 0 | AU5: 0 | AV5: 0 | AW5: 0 | AX5: =AX31+B43 -> 10 | AY5: =AY31+C43 -> 10 | AZ5: =AZ31+D43 -> 10 | BA5: =BA31+E43 -> 40 | BB5: =BB31+F43 -> 40 | BC5: =BC31+G43 -> 40 | BD5: =BD31+H43 -> 40 | BE5: =BE31+I43 -> 20 | BF5: 0 | BG5: 0 | BH5: 0 | BI5: 0 | BJ5: 0 | BK5: 0 | BL5: 0 | BM5: 0
A6: 1 | B6: =B32+B44 -> 10 | C6: =C32+C44 -> 10 | D6: =D32+D44 -> 10 | E6: =E32+E44 -> 50 | F6: =F32+F44 -> 50 | G6: =G32+G44 -> 40 | H6: =H32+H44 -> 50 | I6: =I32+I44 -> 20 | J6: 0 | K6: 0 | L6: 0 | M6: 0 | N6: 0 | O6: 0 | P6: 0 | Q6: 0 | R6: =R32+B44 -> 10 | S6: =S32+C44 -> 10 | T6: =T32+D44 -> 10 | U6: =U32+E44 -> 40 | V6: =V32+F44 -> 40 | W6: =W32+G44 -> 40 | X6: =X32+H44 -> 50 | Y6: =Y32+I44 -> 20 | Z6: 0 | AA6: 0 | AB6: 0 | AC6: 0 | AD6: 0 | AE6: 0 | AF6: 0 | AG6: 0 | AH6: =AH32+B44 -> 10 | AI6: =AI32+C44 -> 10 | AJ6: =AJ32+D44 -> 10 | AK6: =AK32+E44 -> 50 | AL6: =AL32+F44 -> 50 | AM6: =AM32+G44 -> 40 | AN6: =AN32+H44 -> 40 | AO6: =AO32+I44 -> 20 | AP6: =AP5*0.5 -> 0 | AQ6: =AQ5*0.5 -> 0 | AR6: =AR5*0.5 -> 0 | AS6: =AS5*0.5 -> 0 | AT6: =AT5*0.5 -> 0 | AU6: =AU5*0.5 -> 0 | AV6: =AV5*0.5 -> 0 | AW6: 0 | AX6: =AX32+B44 -> 10 | AY6: =AY32+C44 -> 10 | AZ6: =AZ32+D44 -> 10 | BA6: =BA32+E44 -> 40 | BB6: =BB32+F44 -> 40 | BC6: =BC32+G44 -> 40 | BD6: =BD32+H44 -> 40 | BE6: =BE32+I44 -> 20 | BF6: 0 | BG6: 0 | BH6: 0 | BI6: 0 | BJ6: 0 | BK6: 0 | BL6: 0 | BM6: 0
A7: 2 | B7: =B33+B45 -> 10 | C7: =C33+C45 -> 10 | D7: =D33+D45 -> 10 | E7: =E33+E45 -> 40 | F7: =F33+F45 -> 40 | G7: =G33+G45 -> 40 | H7: =H33+H45 -> 35 | I7: =I33+I45 -> 20 | J7: 0 | K7: 0 | L7: 0 | M7: 0 | N7: 0 | O7: 0 | P7: 0 | Q7: 0 | R7: =R33+B45 -> 10 | S7: =S33+C45 -> 10 | T7: =T33+D45 -> 10 | U7: =U33+E45 -> 40 | V7: =V33+F45 -> 40 | W7: =W33+G45 -> 40 | X7: =X33+H45 -> 35 | Y7: =Y33+I45 -> 20 | Z7: 0 | AA7: 0 | AB7: 0 | AC7: 0 | AD7: 0 | AE7: 0 | AF7: 0 | AG7: 0 | AH7: =AH33+B45 -> 10 | AI7: =AI33+C45 -> 10 | AJ7: =AJ33+D45 -> 10 | AK7: =AK33+E45 -> 40 | AL7: =AL33+F45 -> 40 | AM7: =AM33+G45 -> 40 | AN7: =AN33+H45 -> 35 | AO7: =AO33+I45 -> 20 | AP7: 0 | AQ7: 0 | AR7: 0 | AS7: 0 | AT7: 0 | AU7: 0 | AV7: 0 | AW7: 0 | AX7: =AX33+B45 -> 10 | AY7: =AY33+C45 -> 10 | AZ7: =AZ33+D45 -> 10 | BA7: =BA33+E45 -> 40 | BB7: =BB33+F45 -> 40 | BC7: =BC33+G45 -> 40 | BD7: =BD33+H45 -> 35 | BE7: =BE33+I45 -> 20 | BF7: 0 | BG7: 0 | BH7: 0 | BI7: 0 | BJ7: 0 | BK7: 0 | BL7: 0 | BM7: 0
A8: 3 | B8: =B34+B46 -> 10 | C8: =C34+C46 -> 10 | D8: =D34+D46 -> 10 | E8: =E34+E46 -> 50 | F8: =F34+F46 -> 50 | G8: =G34+G46 -> 40 | H8: =H34+H46 -> 45 | I8: =I34+I46 -> 20 | J8: 0 | K8: 0 | L8: 0 | M8: 0 | N8: 0 | O8: 0 | P8: 0 | Q8: 0 | R8: =R34+B46 -> 10 | S8: =S34+C46 -> 10 | T8: =T34+D46 -> 10 | U8: =U34+E46 -> 40 | V8: =V34+F46 -> 40 | W8: =W34+G46 -> 40 | X8: =X34+H46 -> 45 | Y8: =Y34+I46 -> 20 | Z8: 0 | AA8: 0 | AB8: 0 | AC8: 0 | AD8: 0 | AE8: 0 | AF8: 0 | AG8: 0 | AH8: =AH34+B46 -> 10 | AI8: =AI34+C46 -> 10 | AJ8: =AJ34+D46 -> 10 | AK8: =AK34+E46 -> 50 | AL8: =AL34+F46 -> 50 | AM8: =AM34+G46 -> 40 | AN8: =AN34+H46 -> 35 | AO8: =AO34+I46 -> 20 | AP8: 0 | AQ8: 0 | AR8: 0 | AS8: 0 | AT8: 0 | AU8: 0 | AV8: 0 | AW8: 0 | AX8: =AX34+B46 -> 10 | AY8: =AY34+C46 -> 10 | AZ8: =AZ34+D46 -> 10 | BA8: =BA34+E46 -> 40 | BB8: =BB34+F46 -> 40 | BC8: =BC34+G46 -> 40 | BD8: =BD34+H46 -> 35 | BE8: =BE34+I46 -> 20 | BF8: 0 | BG8: 0 | BH8: 0 | BI8: 0 | BJ8: 0 | BK8: 0 | BL8: 0 | BM8: 0
A9: 4
A10: 5
A11: 6
A12: 7
A13: 8
A14: 9
A15: 10
A16: 11
A17: 12
A18: 13
A19: 14
A20: 15
... A28: 23
B30: Delta
B31: 0 | C31: 0 | D31: 0 | E31: 0 | F31: 0 | G31: 0 | H31: 0 | I31: 0 | R31: 0 | S31: 0 | T31: 0 | U31: 0 | V31: 0 | W31: 0 | X31: 0 | Y31: 0 | AH31: 0 | AI31: 0 | AJ31: 0 | AK31: 0 | AL31: 0 | AM31: 0 | AN31: 0 | AO31: 0 | AX31: 0 | AY31: 0 | AZ31: 0 | BA31: 0 | BB31: 0 | BC31: 0 | BD31: 0 | BE31: 0
B32: 0 | C32: 0 | D32: 0 | E32: 5 | F32: 5 | G32: 0 | H32: 5 | I32: 0 | R32: 0 | S32: 0 | T32: 0 | U32: -5 | V32: -5 | W32: 0 | X32: 5 | Y32: 0 | AH32: 0 | AI32: 0 | AJ32: 0 | AK32: 5 | AL32: 5 | AM32: 0 | AN32: -5 | AO32: 0 | AX32: 0 | AY32: 0 | AZ32: 0 | BA32: -5 | BB32: -5 | BC32: 0 | BD32: -5 | BE32: 0
B33: 0 | C33: 0 | D33: 0 | E33: 0 | F33: 0 | G33: 0 | H33: 0 | I33: 0 | R33: 0 | S33: 0 | T33: 0 | U33: 0 | V33: 0 | W33: 0 | X33: 0 | Y33: 0 | AH33: 0 | AI33: 0 | AJ33: 0 | AK33: 0 | AL33: 0 | AM33: 0 | AN33: 0 | AO33: 0 | AX33: 0 | AY33: 0 | AZ33: 0 | BA33: 0 | BB33: 0 | BC33: 0 | BD33: 0 | BE33: 0
B34: 0 | C34: 0 | D34: 0 | E34: 5 | F34: 5 | G34: 0 | H34: 5 | I34: 0 | R34: 0 | S34: 0 | T34: 0 | U34: -5 | V34: -5 | W34: 0 | X34: 5 | Y34: 0 | AH34: 0 | AI34: 0 | AJ34: 0 | AK34: 5 | AL34: 5 | AM34: 0 | AN34: -5 | AO34: 0 | AX34: 0 | AY34: 0 | AZ34: 0 | BA34: -5 | BB34: -5 | BC34: 0 | BD34: -5 | BE34: 0
H41: Sum Probabilities | I41: =SUM(B2:BM2) -> 1
B42: Basis
B43: 10 | C43: 10 | D43: 10 | E43: 40 | F43: 40 | G43: 40 | H43: 40 | I43: 20 | K43: =SUM(B43:I43) -> 210
B44: 10 | C44: 10 | D44: 10 | E44: 45 | F44: 45 | G44: 40 | H44: 45 | I44: 20 | K44: =SUM(B44:I44) -> 225
B45: 10 | C45: 10 | D45: 10 | E45: 40 | F45: 40 | G45: 40 | H45: 35 | I45: 20 | K45: =SUM(B45:I45) -> 205
B46: 10 | C46: 10 | D46: 10 | E46: 45 | F46: 45 | G46: 40 | H46: 40 | I46: 20 | K46: =SUM(B46:I46) -> 220
B49: Data Ruud
B50: UKD | C50: DEU | D50: BEL | E50: FRA | F50: DK
B51: 30 | C51: 80 | D51: 40 | E51: 40
B52: 30 | C52: 90 | D52: 40 | E52: 45
B53: 30 | C53: 80 | D53: 40 | E53: 35
B54: 30 | C54: 90 | D54: 40 | E54: 40

Sheet Demand Stage 3
A1: Node Number | B1: 18 | R1: =B1+Parameters!$B$5 -> 22 | AH1: =R1+Parameters!$B$5 -> 26 | AX1: =AH1+Parameters!$B$5 -> 30 | BN1: =AX1+Parameters!$B$5 -> 34 | CD1: =BN1+Parameters!$B$5 -> 38 | CT1: =CD1+Parameters!$B$5 -> 42 | DJ1: =CT1+Parameters!$B$5 -> 46 | DZ1: =DJ1+Parameters!$B$5 -> 50 | EP1: =DZ1+Parameters!$B$5 -> 54 | FF1: =EP1+Parameters!$B$5 -> 58 | FV1: =FF1+Parameters!$B$5 -> 62 | GL1: =FV1+Parameters!$B$5 -> 66 | HB1: =GL1+Parameters!$B$5 -> 70 | HR1: =HB1+Parameters!$B$5 -> 74 | IH1: =HR1+Parameters!$B$5 -> 78
A2: Probability | B2: =1/16 -> 0.0625 | R2: =B2 -> 0.0625 | AH2: =R2 -> 0.0625 | AX2: =AH2 -> 0.0625 | BN2: =AX2 -> 0.0625 | CD2: =BN2 -> 0.0625 | CT2: =CD2 -> 0.0625 | DJ2: =CT2 -> 0.0625 | DZ2: =DJ2 -> 0.0625 | EP2: =DZ2 -> 0.0625 | FF2: =EP2 -> 0.0625 | FV2: =FF2 -> 0.0625 | GL2: =FV2 -> 0.0625 | HB2: =GL2 -> 0.0625 | HR2: =HB2 -> 0.0625 | IH2: =HR2 -> 0.0625
A3: Parent Node Number | B3: 2 | R3: 2 | AH3: 2 | AX3: 2 | BN3: 6 | CD3: 6 | CT3: 6 | DJ3: 6 | DZ3: 10 | EP3: 10 | FF3: 10 | FV3: 10 | GL3: 14 | HB3: 14 | HR3: 14 | IH3: 14
B4: gas or mix | J4: pure hydrogen | R4: gas or mix | Z4: pure hydrogen | AH4: gas or mix | AP4: pure hydrogen | AX4: gas or mix | BF4: pure hydrogen | BN4: gas or mix | BV4: pure hydrogen | CD4: gas or mix | CL4: pure hydrogen | CT4: gas or mix | DB4: pure hydrogen | DJ4: gas or mix | DR4: pure hydrogen | DZ4: gas or mix | EH4: pure hydrogen | EP4: gas or mix | EX4: pure hydrogen | FF4: gas or mix | FN4: pure hydrogen | FV4: gas or mix | GD4: pure hydrogen | GL4: gas or mix | GT4: pure hydrogen | HB4: gas or mix | HJ4: pure hydrogen | HR4: gas or mix | HZ4: pure hydrogen | IH4: gas or mix | IP4: pure hydrogen
A5: Hour | B5: ='Demand Stage 2'!B4 -> ST.FERGUS | C5: ='Demand Stage 2'!C4 -> EASINGTON | D5: ='Demand Stage 2'!D4 -> TEESSIDE | E5: ='Demand Stage 2'!E4 -> EMDEN | F5: ='Demand Stage 2'!F4 -> EMDEN 2 | G5: ='Demand Stage 2'!G4 -> ZEEBRUGGE | H5: ='Demand Stage 2'!H4 -> DUNKERQUE | I5: ='Demand Stage 2'!I4 -> POLAND | ... Q5: ='Demand Stage 2'!Q4 -> POLAND | R5: ='Demand Stage 2'!B4 -> ST.FERGUS | S5: ='Demand Stage 2'!C4 -> EASINGTON | T5: ='Demand Stage 2'!D4 -> TEESSIDE | U5: ='Demand Stage 2'!E4 -> EMDEN | V5: ='Demand Stage 2'!F4 -> EMDEN 2 | W5: ='Demand Stage 2'!G4 -> ZEEBRUGGE | X5: ='Demand Stage 2'!H4 -> DUNKERQUE | Y5: ='Demand Stage 2'!I4 -> POLAND | ... AG5: ='Demand Stage 2'!Q4 -> POLAND | AH5: ='Demand Stage 2'!B4 -> ST.FERGUS | AI5: ='Demand Stage 2'!C4 -> EASINGTON | AJ5: ='Demand Stage 2'!D4 -> TEESSIDE | AK5: ='Demand Stage 2'!E4 -> EMDEN | AL5: ='Demand Stage 2'!F4 -> EMDEN 2 | AM5: ='Demand Stage 2'!G4 -> ZEEBRUGGE | AN5: ='Demand Stage 2'!H4 -> DUNKERQUE | AO5: ='Demand Stage 2'!I4 -> POLAND | ... AW5: ='Demand Stage 2'!Q4 -> POLAND | AX5: ='Demand Stage 2'!B4 -> ST.FERGUS | AY5: ='Demand Stage 2'!C4 -> EASINGTON | AZ5: ='Demand Stage 2'!D4 -> TEESSIDE | BA5: ='Demand Stage 2'!E4 -> EMDEN | BB5: ='Demand Stage 2'!F4 -> EMDEN 2 | BC5: ='Demand Stage 2'!G4 -> ZEEBRUGGE | BD5: ='Demand Stage 2'!H4 -> DUNKERQUE | BE5: ='Demand Stage 2'!I4 -> POLAND | ... CC5: ='Demand Stage 2'!AG4 -> POLAND | CD5: =BN5 -> ST.FERGUS | CE5: =BO5 -> EASINGTON | CF5: =BP5 -> TEESSIDE | CG5: =BQ5 -> EMDEN | CH5: =BR5 -> EMDEN 2 | CI5: =BS5 -> ZEEBRUGGE | CJ5: =BT5 -> DUNKERQUE | CK5: =BU5 -> POLAND | ... DY5: =DI5 -> POLAND | DZ5: ='Demand Stage 2'!AH4 -> ST.FERGUS | EA5: ='Demand Stage 2'!AI4 -> EASINGTON | EB5: ='Demand Stage 2'!AJ4 -> TEESSIDE | EC5: ='Demand Stage 2'!AK4 -> EMDEN | ED5: ='Demand Stage 2'!AL4 -> EMDEN 2 | EE5: ='Demand Stage 2'!AM4 -> ZEEBRUGGE | EF5: ='Demand Stage 2'!AN4 -> DUNKERQUE | EG5: ='Demand Stage 2'!AO4 -> POLAND | ... EO5: ='Demand Stage 2'!AW4 -> POLAND | EP5: =DZ5 -> ST.FERGUS | EQ5: =EA5 -> EASINGTON | ER5: =EB5 -> TEESSIDE | ES5: =EC5 -> EMDEN | ET5: =ED5 -> EMDEN 2 | EU5: =EE5 -> ZEEBRUGGE | EV5: =EF5 -> DUNKERQUE | EW5: =EG5 -> POLAND | ... GK5: =FU5 -> POLAND | GL5: ='Demand Stage 2'!AX4 -> ST.FERGUS | GM5: ='Demand Stage 2'!AY4 -> EASINGTON | GN5: ='Demand Stage 2'!AZ4 -> TEESSIDE | GO5: ='Demand Stage 2'!BA4 -> EMDEN | GP5: ='Demand Stage 2'!BB4 -> EMDEN 2 | GQ5: ='Demand Stage 2'!BC4 -> ZEEBRUGGE | GR5: ='Demand Stage 2'!BD4 -> DUNKERQUE | GS5: ='Demand Stage 2'!BE4 -> POLAND | ... HA5: ='Demand Stage 2'!BM4 -> ST.FERGUS | HB5: =GL5 -> ST.FERGUS | HC5: =GM5 -> EASINGTON | HD5: =GN5 -> TEESSIDE | HE5: =GO5 -> EMDEN | HF5: =GP5 -> EMDEN 2 | HG5: =GQ5 -> ZEEBRUGGE | HH5: =GR5 -> DUNKERQUE | HI5: =GS5 -> POLAND | ... IW5: =IG5 -> ST.FERGUS
A6: 0 | B6: ='Demand Stage 2'!B5 -> 10 | C6: ='Demand Stage 2'!C5 -> 10 | D6: ='Demand Stage 2'!D5 -> 10 | E6: ='Demand Stage 2'!E5 -> 40 | F6: ='Demand Stage 2'!F5 -> 40 | G6: ='Demand Stage 2'!G5 -> 40 | H6: ='Demand Stage 2'!H5 -> 40 | I6: ='Demand Stage 2'!I5 -> 20 | ... Q6: ='Demand Stage 2'!Q5 -> 0 | R6: ='Demand Stage 2'!B5 -> 10 | S6: ='Demand Stage 2'!C5 -> 10 | T6: ='Demand Stage 2'!D5 -> 10 | U6: ='Demand Stage 2'!E5 -> 40 | V6: ='Demand Stage 2'!F5 -> 40 | W6: ='Demand Stage 2'!G5 -> 40 | X6: ='Demand Stage 2'!H5 -> 40 | Y6: ='Demand Stage 2'!I5 -> 20 | ... AG6: ='Demand Stage 2'!Q5 -> 0 | AH6: ='Demand Stage 2'!B5 -> 10 | AI6: ='Demand Stage 2'!C5 -> 10 | AJ6: ='Demand Stage 2'!D5 -> 10 | AK6: ='Demand Stage 2'!E5 -> 40 | AL6: ='Demand Stage 2'!F5 -> 40 | AM6: ='Demand Stage 2'!G5 -> 40 | AN6: ='Demand Stage 2'!H5 -> 40 | AO6: ='Demand Stage 2'!I5 -> 20 | ... AW6: ='Demand Stage 2'!Q5 -> 0 | AX6: ='Demand Stage 2'!B5 -> 10 | AY6: ='Demand Stage 2'!C5 -> 10 | AZ6: ='Demand Stage 2'!D5 -> 10 | BA6: ='Demand Stage 2'!E5 -> 40 | BB6: ='Demand Stage 2'!F5 -> 40 | BC6: ='Demand Stage 2'!G5 -> 40 | BD6: ='Demand Stage 2'!H5 -> 40 | BE6: ='Demand Stage 2'!I5 -> 20 | ... CC6: ='Demand Stage 2'!AG5 -> 0 | CD6: =BN6 -> 10 | CE6: =BO6 -> 10 | CF6: =BP6 -> 10 | CG6: =BQ6 -> 40 | CH6: =BR6 -> 40 | CI6: =BS6 -> 40 | CJ6: =BT6 -> 40 | CK6: =BU6 -> 20 | ... DY6: =DI6 -> 0 | DZ6: ='Demand Stage 2'!AH5 -> 10 | EA6: ='Demand Stage 2'!AI5 -> 10 | EB6: ='Demand Stage 2'!AJ5 -> 10 | EC6: ='Demand Stage 2'!AK5 -> 40 | ED6: ='Demand Stage 2'!AL5 -> 40 | EE6: ='Demand Stage 2'!AM5 -> 40 | EF6: ='Demand Stage 2'!AN5 -> 40 | EG6: ='Demand Stage 2'!AO5 -> 20 | ... EO6: ='Demand Stage 2'!AW5 -> 0 | EP6: =DZ6 -> 10 | EQ6: =EA6 -> 10 | ER6: =EB6 -> 10 | ES6: =EC6 -> 40 | ET6: =ED6 -> 40 | EU6: =EE6 -> 40 | EV6: =EF6 -> 40 | EW6: =EG6 -> 20 | ... GK6: =FU6 -> 0 | GL6: ='Demand Stage 2'!AX5 -> 10 | GM6: ='Demand Stage 2'!AY5 -> 10 | GN6: ='Demand Stage 2'!AZ5 -> 10 | GO6: ='Demand Stage 2'!BA5 -> 40 | GP6: ='Demand Stage 2'!BB5 -> 40 | GQ6: ='Demand Stage 2'!BC5 -> 40 | GR6: ='Demand Stage 2'!BD5 -> 40 | GS6: ='Demand Stage 2'!BE5 -> 20 | ... HA6: ='Demand Stage 2'!BM5 -> 0 | HB6: =GL6 -> 10 | HC6: =GM6 -> 10 | HD6: =GN6 -> 10 | HE6: =GO6 -> 40 | HF6: =GP6 -> 40 | HG6: =GQ6 -> 40 | HH6: =GR6 -> 40 | HI6: =GS6 -> 20 | ... IW6: =IG6 -> 0
A7: 1 | B7: ='Demand Stage 2'!B6 -> 10 | C7: ='Demand Stage 2'!C6 -> 10 | D7: ='Demand Stage 2'!D6 -> 10 | E7: ='Demand Stage 2'!E6 -> 50 | F7: ='Demand Stage 2'!F6 -> 50 | G7: ='Demand Stage 2'!G6 -> 40 | H7: ='Demand Stage 2'!H6 -> 50 | I7: ='Demand Stage 2'!I6 -> 20 | ... Q7: ='Demand Stage 2'!Q6 -> 0 | R7: ='Demand Stage 2'!B6 -> 10 | S7: ='Demand Stage 2'!C6 -> 10 | T7: ='Demand Stage 2'!D6 -> 10 | U7: ='Demand Stage 2'!E6 -> 50 | V7: ='Demand Stage 2'!F6 -> 50 | W7: ='Demand Stage 2'!G6 -> 40 | X7: ='Demand Stage 2'!H6 -> 50 | Y7: ='Demand Stage 2'!I6 -> 20 | ... AG7: ='Demand Stage 2'!Q6 -> 0 | AH7: ='Demand Stage 2'!B6 -> 10 | AI7: ='Demand Stage 2'!C6 -> 10 | AJ7: ='Demand Stage 2'!D6 -> 10 | AK7: ='Demand Stage 2'!E6 -> 50 | AL7: ='Demand Stage 2'!F6 -> 50 | AM7: ='Demand Stage 2'!G6 -> 40 | AN7: ='Demand Stage 2'!H6 -> 50 | AO7: ='Demand Stage 2'!I6 -> 20 | ... AW7: ='Demand Stage 2'!Q6 -> 0 | AX7: ='Demand Stage 2'!B6 -> 10 | AY7: ='Demand Stage 2'!C6 -> 10 | AZ7: ='Demand Stage 2'!D6 -> 10 | BA7: ='Demand Stage 2'!E6 -> 50 | BB7: ='Demand Stage 2'!F6 -> 50 | BC7: ='Demand Stage 2'!G6 -> 40 | BD7: ='Demand Stage 2'!H6 -> 50 | BE7: ='Demand Stage 2'!I6 -> 20 | ... CC7: ='Demand Stage 2'!AG6 -> 0 | CD7: =BN7 -> 10 | CE7: =BO7 -> 10 | CF7: =BP7 -> 10 | CG7: =BQ7 -> 40 | CH7: =BR7 -> 40 | CI7: =BS7 -> 40 | CJ7: =BT7 -> 50 | CK7: =BU7 -> 20 | ... DY7: =DI7 -> 0 | DZ7: ='Demand Stage 2'!AH6 -> 10 | EA7: ='Demand Stage 2'!AI6 -> 10 | EB7: ='Demand Stage 2'!AJ6 -> 10 | EC7: ='Demand Stage 2'!AK6 -> 50 | ED7: ='Demand Stage 2'!AL6 -> 50 | EE7: ='Demand Stage 2'!AM6 -> 40 | EF7: ='Demand Stage 2'!AN6 -> 40 | EG7: ='Demand Stage 2'!AO6 -> 20 | ... EO7: ='Demand Stage 2'!AW6 -> 0 | EP7: =DZ7 -> 10 | EQ7: =EA7 -> 10 | ER7: =EB7 -> 10 | ES7: =EC7 -> 50 | ET7: =ED7 -> 50 | EU7: =EE7 -> 40 | EV7: =EF7 -> 40 | EW7: =EG7 -> 20 | ... GK7: =FU7 -> 0 | GL7: ='Demand Stage 2'!AX6 -> 10 | GM7: ='Demand Stage 2'!AY6 -> 10 | GN7: ='Demand Stage 2'!AZ6 -> 10 | GO7: ='Demand Stage 2'!BA6 -> 40 | GP7: ='Demand Stage 2'!BB6 -> 40 | GQ7: ='Demand Stage 2'!BC6 -> 40 | GR7: ='Demand Stage 2'!BD6 -> 40 | GS7: ='Demand Stage 2'!BE6 -> 20 | ... HA7: ='Demand Stage 2'!BM6 -> 0 | HB7: =GL7 -> 10 | HC7: =GM7 -> 10 | HD7: =GN7 -> 10 | HE7: =GO7 -> 40 | HF7: =GP7 -> 40 | HG7: =GQ7 -> 40 | HH7: =GR7 -> 40 | HI7: =GS7 -> 20 | ... IW7: =IG7 -> 0
A8: 2 | B8: ='Demand Stage 2'!B7 -> 10 | C8: ='Demand Stage 2'!C7 -> 10 | D8: ='Demand Stage 2'!D7 -> 10 | E8: ='Demand Stage 2'!E7 -> 40 | F8: ='Demand Stage 2'!F7 -> 40 | G8: ='Demand Stage 2'!G7 -> 40 | H8: ='Demand Stage 2'!H7 -> 35 | I8: ='Demand Stage 2'!I7 -> 20 | ... Q8: ='Demand Stage 2'!Q7 -> 0 | R8: ='Demand Stage 2'!B7 -> 10 | S8: ='Demand Stage 2'!C7 -> 10 | T8: ='Demand Stage 2'!D7 -> 10 | U8: ='Demand Stage 2'!E7 -> 40 | V8: ='Demand Stage 2'!F7 -> 40 | W8: ='Demand Stage 2'!G7 -> 40 | X8: ='Demand Stage 2'!H7 -> 35 | Y8: ='Demand Stage 2'!I7 -> 20 | ... AG8: ='Demand Stage 2'!Q7 -> 0 | AH8: ='Demand Stage 2'!B7 -> 10 | AI8: ='Demand Stage 2'!C7 -> 10 | AJ8: ='Demand Stage 2'!D7 -> 10 | AK8: ='Demand Stage 2'!E7 -> 40 | AL8: ='Demand Stage 2'!F7 -> 40 | AM8: ='Demand Stage 2'!G7 -> 40 | AN8: ='Demand Stage 2'!H7 -> 35 | AO8: ='Demand Stage 2'!I7 -> 20 | ... AW8: ='Demand Stage 2'!Q7 -> 0 | AX8: ='Demand Stage 2'!B7 -> 10 | AY8: ='Demand Stage 2'!C7 -> 10 | AZ8: ='Demand Stage 2'!D7 -> 10 | BA8: ='Demand Stage 2'!E7 -> 40 | BB8: ='Demand Stage 2'!F7 -> 40 | BC8: ='Demand Stage 2'!G7 -> 40 | BD8: ='Demand Stage 2'!H7 -> 35 | BE8: ='Demand Stage 2'!I7 -> 20 | ... CC8: ='Demand Stage 2'!AG7 -> 0 | CD8: =BN8 -> 10 | CE8: =BO8 -> 10 | CF8: =BP8 -> 10 | CG8: =BQ8 -> 40 | CH8: =BR8 -> 40 | CI8: =BS8 -> 40 | CJ8: =BT8 -> 35 | CK8: =BU8 -> 20 | ... DY8: =DI8 -> 0 | DZ8: ='Demand Stage 2'!AH7 -> 10 | EA8: ='Demand Stage 2'!AI7 -> 10 | EB8: ='Demand Stage 2'!AJ7 -> 10 | EC8: ='Demand Stage 2'!AK7 -> 40 | ED8: ='Demand Stage 2'!AL7 -> 40 | EE8: ='Demand Stage 2'!AM7 -> 40 | EF8: ='Demand Stage 2'!AN7 -> 35 | EG8: ='Demand Stage 2'!AO7 -> 20 | ... EO8: ='Demand Stage 2'!AW7 -> 0 | EP8: =DZ8 -> 10 | EQ8: =EA8 -> 10 | ER8: =EB8 -> 10 | ES8: =EC8 -> 40 | ET8: =ED8 -> 40 | EU8: =EE8 -> 40 | EV8: =EF8 -> 35 | EW8: =EG8 -> 20 | ... GK8: =FU8 -> 0 | GL8: ='Demand Stage 2'!AX7 -> 10 | GM8: ='Demand Stage 2'!AY7 -> 10 | GN8: ='Demand Stage 2'!AZ7 -> 10 | GO8: ='Demand Stage 2'!BA7 -> 40 | GP8: ='Demand Stage 2'!BB7 -> 40 | GQ8: ='Demand Stage 2'!BC7 -> 40 | GR8: ='Demand Stage 2'!BD7 -> 35 | GS8: ='Demand Stage 2'!BE7 -> 20 | ... HA8: ='Demand Stage 2'!BM7 -> 0 | HB8: =GL8 -> 10 | HC8: =GM8 -> 10 | HD8: =GN8 -> 10 | HE8: =GO8 -> 40 | HF8: =GP8 -> 40 | HG8: =GQ8 -> 40 | HH8: =GR8 -> 35 | HI8: =GS8 -> 20 | ... IW8: =IG8 -> 0
A9: 3 | B9: ='Demand Stage 2'!B8 -> 10 | C9: ='Demand Stage 2'!C8 -> 10 | D9: ='Demand Stage 2'!D8 -> 10 | E9: ='Demand Stage 2'!E8 -> 50 | F9: ='Demand Stage 2'!F8 -> 50 | G9: ='Demand Stage 2'!G8 -> 40 | H9: ='Demand Stage 2'!H8 -> 45 | I9: ='Demand Stage 2'!I8 -> 20 | ... Q9: ='Demand Stage 2'!Q8 -> 0 | R9: ='Demand Stage 2'!B8 -> 10 | S9: ='Demand Stage 2'!C8 -> 10 | T9: ='Demand Stage 2'!D8 -> 10 | U9: ='Demand Stage 2'!E8 -> 50 | V9: ='Demand Stage 2'!F8 -> 50 | W9: ='Demand Stage 2'!G8 -> 40 | X9: ='Demand Stage 2'!H8 -> 45 | Y9: ='Demand Stage 2'!I8 -> 20 | ... AG9: ='Demand Stage 2'!Q8 -> 0 | AH9: ='Demand Stage 2'!B8 -> 10 | AI9: ='Demand Stage 2'!C8 -> 10 | AJ9: ='Demand Stage 2'!D8 -> 10 | AK9: ='Demand Stage 2'!E8 -> 50 | AL9: ='Demand Stage 2'!F8 -> 50 | AM9: ='Demand Stage 2'!G8 -> 40 | AN9: ='Demand Stage 2'!H8 -> 45 | AO9: ='Demand Stage 2'!I8 -> 20 | ... AW9: ='Demand Stage 2'!Q8 -> 0 | AX9: ='Demand Stage 2'!B8 -> 10 | AY9: ='Demand Stage 2'!C8 -> 10 | AZ9: ='Demand Stage 2'!D8 -> 10 | BA9: ='Demand Stage 2'!E8 -> 50 | BB9: ='Demand Stage 2'!F8 -> 50 | BC9: ='Demand Stage 2'!G8 -> 40 | BD9: ='Demand Stage 2'!H8 -> 45 | BE9: ='Demand Stage 2'!I8 -> 20 | ... CC9: ='Demand Stage 2'!AG8 -> 0 | CD9: =BN9 -> 10 | CE9: =BO9 -> 10 | CF9: =BP9 -> 10 | CG9: =BQ9 -> 40 | CH9: =BR9 -> 40 | CI9: =BS9 -> 40 | CJ9: =BT9 -> 45 | CK9: =BU9 -> 20 | ... DY9: =DI9 -> 0 | DZ9: ='Demand Stage 2'!AH8 -> 10 | EA9: ='Demand Stage 2'!AI8 -> 10 | EB9: ='Demand Stage 2'!AJ8 -> 10 | EC9: ='Demand Stage 2'!AK8 -> 50 | ED9: ='Demand Stage 2'!AL8 -> 50 | EE9: ='Demand Stage 2'!AM8 -> 40 | EF9: ='Demand Stage 2'!AN8 -> 35 | EG9: ='Demand Stage 2'!AO8 -> 20 | ... EO9: ='Demand Stage 2'!AW8 -> 0 | EP9: =DZ9 -> 10 | EQ9: =EA9 -> 10 | ER9: =EB9 -> 10 | ES9: =EC9 -> 50 | ET9: =ED9 -> 50 | EU9: =EE9 -> 40 | EV9: =EF9 -> 35 | EW9: =EG9 -> 20 | ... GK9: =FU9 -> 0 | GL9: ='Demand Stage 2'!AX8 -> 10 | GM9: ='Demand Stage 2'!AY8 -> 10 | GN9: ='Demand Stage 2'!AZ8 -> 10 | GO9: ='Demand Stage 2'!BA8 -> 40 | GP9: ='Demand Stage 2'!BB8 -> 40 | GQ9: ='Demand Stage 2'!BC8 -> 40 | GR9: ='Demand Stage 2'!BD8 -> 35 | GS9: ='Demand Stage 2'!BE8 -> 20 | ... HA9: ='Demand Stage 2'!BM8 -> 0 | HB9: =GL9 -> 10 | HC9: =GM9 -> 10 | HD9: =GN9 -> 10 | HE9: =GO9 -> 40 | HF9: =GP9 -> 40 | HG9: =GQ9 -> 40 | HH9: =GR9 -> 35 | HI9: =GS9 -> 20 | ... IW9: =IG9 -> 0
A10: 4
A11: 5
A12: 6
A13: 7
A14: 8
A15: 9
A16: 10
A17: 11
A18: 12
A19: 13
A20: 14
A21: 15
... A29: 23
B33: Sum Probabilities | C33: =SUM(B2:IW2) -> 1

Sheet SalesPriceGasMix
A1: Hour | B1: ST.FERGUS | C1: EASINGTON | D1: TEESSIDE | E1: EMDEN | F1: EMDEN 2 | G1: ZEEBRUGGE | H1: DUNKERQUE | I1: POLAND
A2: 1 | B2: 26 | C2: 26 | D2: 26 | E2: 28 | F2: 28 | G2: 29 | H2: 30 | I2: 30
A3: 2 | B3: 28 | C3: 28 | D3: 28 | E3: 30 | F3: 30 | G3: 31 | H3: 32 | I3: 30
A4: 3 | B4: 27 | C4: 27 | D4: 27 | E4: 29 | F4: 29 | G4: 30 | H4: 31 | I4: 30
A5: 4 | B5: 29 | C5: 29 | D5: 29 | E5: 31 | F5: 31 | G5: 32 | H5: 33 | I5: 30

Sheet SalesPricePureHydrogen
A1: Hour | B1: ST.FERGUS | C1: EASINGTON | D1: TEESSIDE | E1: EMDEN | F1: EMDEN 2 | G1: ZEEBRUGGE | H1: DUNKERQUE | I1: POLAND
A2: 1 | B2: 1 | C2: 1 | D2: 1 | E2: 1 | F2: 1 | G2: 1 | H2: 1 | I2: 1
A3: 2 | B3: 1 | C3: 1 | D3: 1 | E3: 1 | F3: 1 | G3: 1 | H3: 1 | I3: 1
A4: 3 | B4: 1 | C4: 1 | D4: 1 | E4: 1 | F4: 1 | G4: 1 | H4: 1 | I4: 1
A5: 4 | B5: 1 | C5: 1 | D5: 1 | E5: 1 | F5: 1 | G5: 1 | H5: 1 | I5: 1

Sheet Parameters
A1: Name | B1: Value
A2: Loss rate | B2: 0
A3: Allowed percentage | B3: 1
A4: Gamma | B4: 0.25
A5: Number hours | B5: 4
A6: Stage 2 nodes | B6: 4
A7: Stage 3 nodes | B7: 16
A8: Number markets | B8: 8
A9: Number shippers | B9: 9

Sheet Arcs
A1: ID | B1: Name | C1: curOperNam | D1: curPhase | E1: curPhDate | F1: Source | G1: Sink | H1: geometry | I1: Capacity | J1: Note | K1: Source_ID | L1: Sink_ID | M1: Flow costs Gas | N1: Flow costs Hydrogen
A2: 1 | B2: Statpipe | C2: OKEA ASA | D2: IN SERVICE | E2: 1993-09-23 | F2: BRAGE | G2: BRAGE-T | H2: LINESTRING (2.8963509232204276 60.56011387499288, 3.0081770764843703 60.54330065370974, 3.0361264151934804 60.54281098835386) | I2: 100 | J2: =IF(I2=100,"Capacity unknown","") -> Capacity unknown | K2: =INDEX(Nodes!$A:$A,MATCH(Arcs!F2,Nodes!$B:$B,0)) -> 23 | L2: =INDEX(Nodes!$A:$A,MATCH(Arcs!G2,Nodes!$B:$B,0)) -> 26 | M2: 1 | N2: 1
A3: 2 | B3: Draugen Gasseksport | C3: OKEA ASA | D3: IN SERVICE | E3: 2000-10-10 | F3: DRAUGEN | G3: DRAUGEN T | H3: LINESTRING (6.439513710701037 64.2329284780315, 6.449055151210916 64.23122552146818, 6.9889691272997645 64.16618923704642, 7.002129636522198 64.1654333609896, 7.062959750852773 64.16582309393723, 7.079793180607852 64.1684484007406, 7.315588528377448 64.21648815910106, 7.404876944904599 64.22853570382964, 7.7111336534916886 64.26379673831497, 7.742816609118542 64.26662022380145, 7.7583349842149065 64.26951952443925, 7.768576121988894 64.27321979697747, 7.777126085464185 64.27877412682054, 7.794889263285606 64.30243431539115, 7.799528206240841 64.30605051942663, 7.814497208966536 64.31468805195007, 7.818431088596768 64.31892227349209, 7.822468792099478 64.3260716173518, 7.822654557749491 64.32997778178854, 7.820946211228841 64.33460195407923, 7.813834552501298 64.34114814350907, 7.803842909263228 64.34577121958141, 7.789322217253073 64.35026182872208) | I3: 5 | J3: =IF(I3=100,"Capacity unknown","") | K3: =INDEX(Nodes!$A:$A,MATCH(Arcs!F3,Nodes!$B:$B,0)) -> 10 | L3: =INDEX(Nodes!$A:$A,MATCH(Arcs!G3,Nodes!$B:$B,0)) -> 9 | M3: 1 | N3: 1
A4: 3 | B4: Asgard Transport | C4: Gassco AS | D4: IN SERVICE | E4: 2000-10-04 | F4: aSGARD ERB | G4: KaRSTo | H4: LINESTRING (4.686853131474261 62.302302667129126, 4.718448369792201 62.33153457574122, 4.688439971644288 62.3037851068389, 4.686853131474261 62.302302667129126) | I4: 70 | J4: =IF(I4=100,"Capacity unknown","") | K4: =INDEX(Nodes!$A:$A,MATCH(Arcs!F4,Nodes!$B:$B,0)) -> 15 | L4: =INDEX(Nodes!$A:$A,MATCH(Arcs!G4,Nodes!$B:$B,0)) -> 33 | M4: 1 | N4: 1
A5: 4 | B5: Europipe I | C5: Gassco AS | D5: IN SERVICE | E5: 1995-10-01 | F5: DRAUPNER E | G5: EUROPIPE-SCP | H5: LINESTRING (2.4628033065972583 58.187535644407276, 2.4552520524712187 58.184953438321706, 2.4452049867077155 58.180375145706634, 2.436617995005262 58.175027843433966, 2.429810080350187 58.16903554003433, 2.4242352589667133 58.16170720354026, 2.4216804587721366 58.15572095378309, 2.420763668776968 58.150490752095145, 2.426013302961221 57.79197297830305, 2.4273683651050777 57.744652296305, 2.4307660116249323 57.731640871117875, 2.5189763662906746 57.54282418963404, 2.525334834467185 57.53571501317608, 2.533882330387126 57.52932388902057, 2.626753808075191 57.48140630803102, 2.634996253186544 57.476003215383955, 2.6416436818262556 57.469978081185985, 2.892508614943398 57.19726841667463, 3.1808761081020624 56.87852461127476, 3.3815273271602124 56.652408055910364, 3.3877327714301955 56.645227877927695, 3.3940302923778023 56.63614363434331, 3.407040228398652 56.62094625631261, 3.488556990884267 56.527907966634345, 3.5023358534307882 56.514987678083074, 3.5316709132669435 56.48164286007732, 3.7483611486674855 56.23177571073057, 3.7531254465816257 56.227200607773526, 3.7643760649266835 56.218642442647905, 3.7697814095819724 56.21326931952618, 3.790266850389006 56.18931372836613, 3.839064504651688 56.126131109314514, 3.934679180445567 56.01437035940241, 4.162862090050761 55.74384669140317, 4.169082473425813 55.737766554617956, 4.174770772717963 55.73361347786694, 4.22120097485071 55.70629307727897) | I5: 46 | J5: =IF(I5=100,"Capacity unknown","") | K5: =INDEX(Nodes!$A:$A,MATCH(Arcs!F5,Nodes!$B:$B,0)) -> 41 | L5: =INDEX(Nodes!$A:$A,MATCH(Arcs!G5,Nodes!$B:$B,0)) -> 53 | M5: 1 | N5: 1
A6: 5 | B6: Europipe I | C6: Gassco AS | D6: IN SERVICE | E6: 1995-10-01 | F6: EUROPIPE-SCP | G6: EMDEN | H6: LINESTRING (7.32514696267687 53.678990373954015, 7.4011991596642055 53.6717909446933, 7.457720037063928 53.69159219597222, 7.459880117479199 53.690792192525514, 7.392222039507814 53.80041408933186, 7.385774700403287 53.806039206561145, 7.376466304590163 53.81106727365384, 7.328866404808301 53.83265948047898, 7.288392929172429 53.8464035035132, 7.278673552321244 53.8504395333066, 7.262380893760357 53.85808161218755, 7.228824429980407 53.87731789016703, 7.198848206644844 53.891721046428636, 7.074762247452948 53.94774357279723, 7.057455583514114 53.95463561550292, 6.935184657906649 54.01079416322335, 6.913802682890788 54.024247379246496, 6.899254985907223 54.03447256177636, 6.723974812853038 54.149766498876836, 6.711057289384026 54.15570555657124, 6.682101245030956 54.16490554899234, 6.669647722687629 54.17118562296475, 6.656208075879919 54.1805967904066, 6.6363099722722305 54.199142191830155, 6.626373370356491 54.21000044551771, 6.614460706207759 54.221186688736346, 6.5628532775701665 54.255379267317224, 6.308824390950888 54.42001799284584, 6.070030196798607 54.57315649992453, 5.825662722185294 54.72824000985346, 5.538138196814379 54.90863989146273, 5.192243895422825 55.12265125287183, 4.842733392057502 55.33561553316483, 4.433070006211278 55.58123923441443, 4.22120097485071 55.70629307727897) | I6: 46 | J6: =IF(I6=100,"Capacity unknown","") | K6: =INDEX(Nodes!$A:$A,MATCH(Arcs!F6,Nodes!$B:$B,0)) -> 53 | L6: =INDEX(Nodes!$A:$A,MATCH(Arcs!G6,Nodes!$B:$B,0)) -> 55 | M6: 1 | N6: 1
A7: 6 | B7: Europipe II | C7: Gassco AS | D7: IN SERVICE | E7: 1999-10-01 | F7: KaRSTo | G7: EMDEN | H7: LINESTRING (7.32514696267687 53.678990373954015, 7.4018391191549755 53.6736910140084, 7.457720037063928 53.69159219597222, 7.3912040184029255 53.80023307253265, 7.385839745862257 53.804597159626695, 7.376585359132399 53.80937321896535, 7.207379156798347 53.86794435123968, 7.196257682974817 53.873948430963466, 7.189033325096543 53.87948353680844, 7.1828019512158905 53.88638469845168, 7.179239668743901 53.892571865029815, 7.07287915992026 54.238568222291235, 6.954123952986654 54.618748694382255, 6.951744735480611 54.62355083050632, 6.9475274407248255 54.629238976605, 6.91435341083016 54.66494882157537, 6.844013037278041 54.77318271501995, 6.82572387531898 54.79395421902926, 6.822869642321458 54.798776351217526, 6.82105105899166 54.81517188666376, 6.817557502901281 54.82935532914016, 6.8184742056092515 54.83919367254637, 6.822799022993953 54.84828902798043, 6.851084508911495 54.88695264766349, 6.853805318302932 54.89497494962288, 6.853867156811409 54.8999491191781, 6.852907985843898 54.90438225926019, 6.762586539463472 55.14724854526278, 6.732610119020615 55.225489892557896, 6.7192063448907815 55.2675981877146, 6.659437622153171 55.41888172462993, 6.55948781700785 55.68425977905299, 6.376442937430352 56.163945446675825, 6.366990912207593 56.18532809009322, 6.29007689498581 56.37653394351937, 6.2266440960601335 56.5419370636239, 6.153750360678373 56.72334266488432, 6.144533402332305 56.742187229560564, 6.136373445064696 56.76175383205678, 6.124713422188593 56.78046136477, 6.117670442948578 56.801375028289215, 6.112261406836086 56.82496880591513, 6.045868384363048 56.988414877144784, 6.029937475492769 57.0268990706172, 6.027259235876948 57.03122819487978, 6.019634679573686 57.04025043069543, 6.0164003707718985 57.045980598748336, 6.01129617661792 57.073485524093144, 6.006053392813598 57.090137060133635, 5.882265323070877 57.389813406797785, 5.843181573649857 57.48274231021467, 5.787723210177421 57.578864147378475, 5.744195143467337 57.70012603894833, 5.743078892679234 57.70559322438704, 5.7430824558562765 57.71647661920235, 5.74153615304275 57.72293083557926, 5.713664200236187 57.776762469129466, 5.705743181431557 57.8094292930658, 5.702134676544558 57.81916460592942, 5.671704604767221 57.87246119397898, 5.666207992134112 57.88345153086098, 5.663974538366843 57.8928358476163, 5.661309827761735 57.91690221334874, 5.659574547773731 57.92263240230303, 5.634282228764614 57.962359561519165, 5.626826441051245 57.97661599626146, 5.6015447869922745 58.04900234957891, 5.498052523352002 58.276132480791766, 5.44886896626917 58.400045469897265, 5.33373284953689 58.63294373411097, 5.27303743191979 58.76560394442499, 5.255784732723547 58.83989350175517, 5.253779094368541 58.85331797723998, 5.253486657785566 58.86321034148343, 5.256935376568359 58.964048133727054, 5.260937900080833 58.97762868624936, 5.3341410520985 59.13667047515026, 5.336396470526604 59.15135705078712, 5.337335211527728 59.1805031525413, 5.338832006547012 59.18612938060962, 5.341812890901496 59.19071158688051, 5.346003841716669 59.194587780810494, 5.351645846687613 59.19819598159988, 5.359979924926262 59.20192321817846, 5.45263349810432 59.22752925491493, 5.460363677174937 59.228590384492115, 5.49151883392187 59.245650386055004, 5.495891764726569 59.250106603985515, 5.500656462097981 59.260094034013406, 5.511409601642026 59.27158221781404) | I7: 71 | J7: =IF(I7=100,"Capacity unknown","") | K7: =INDEX(Nodes!$A:$A,MATCH(Arcs!F7,Nodes!$B:$B,0)) -> 33 | L7: =INDEX(Nodes!$A:$A,MATCH(Arcs!G7,Nodes!$B:$B,0)) -> 55 | M7: 1 | N7: 1
A8: 7 | B8: Franpipe | C8: Gassco AS | D8: IN SERVICE | E8: 1998-07-01 | F8: DRAUPNER E | G8: DUNKERQUE | H8: LINESTRING (2.462793932626184 58.187564308871586, 2.4407347681738827 58.18254916875378, 2.426581608721842 58.17758981075382, 2.4141335463681033 58.171497432927865, 2.4037985870977585 58.164382044429516, 2.3958257278646333 58.15645865623247, 2.3905159669324467 58.14794428002664, 2.3878312920834315 58.13908592432718, 2.3942545139056106 57.74391486502216, 2.387481133220786 57.46549682910719, 2.3888157116288666 57.11516541679584, 2.390744497161882 57.09724380729154, 2.396017361690176 57.07950824522029, 2.3998048184557836 57.07076898278174, 2.4097907794122495 57.05365550019906, 2.63990297551028 56.7267347917067, 2.8607632624317807 56.40789431612352, 2.867710756570045 56.39981411825243, 3.061844761120804 56.24502205988923, 3.24525613774847 56.09731012445693, 3.2632701670217603 56.082428823517695, 3.2789201643187957 56.06675446732257, 3.2857666484025527 56.0586242675889, 3.2971025757273944 56.04181282137616, 3.4010379791351397 55.86237586888284, 3.408059811401045 55.844858349797924, 3.410425202336356 55.83597407256406, 3.4120395757060216 55.82703578471101, 3.4127432600317906 55.809071176508034, 3.3431789865448183 55.19035530975019, 3.282337974893751 54.63431698371356, 3.1851965057591403 54.01682552402704, 3.135769926735322 53.694618487704055, 3.0911947458113174 53.26400114276598, 3.091156317275986 53.24603256896663, 3.0942339600355293 53.22816003421934, 3.2037699603857526 52.80179077223789, 3.2071115923871907 52.783934247959635, 3.207720884431341 52.77495397222961, 3.2074711561753078 52.765962686469784, 3.205415660530116 52.7480320991446, 3.174522790252268 52.5240867312607, 3.1739213229452417 52.506119163544994, 3.18474229895764 52.41647849224174, 3.184623839880268 52.39849993148289, 3.1584716876897474 52.183331965428664, 3.1555421524577936 52.16545238011896, 3.1498395442142417 52.14781977147627, 3.141337856629478 52.130630145252326, 3.1267442708620528 52.10520119669943, 3.1198786288976716 52.08774058135959, 3.117578838818818 52.078859281936154, 3.0872904764791085 51.86391334551881, 3.0871567363904235 51.854948069918784, 3.0909870791640435 51.84630384878643, 3.0890822929111246 51.83749555821743, 3.080738311574879 51.83022124217935, 3.0608402312024108 51.817139618953796, 3.0517792256296037 51.81012430290981, 2.9980102156698405 51.76771440474135, 2.9809162426556606 51.75320277034245, 2.8184741674922567 51.626732099228725, 2.8031982578395813 51.61149546550424, 2.7205786636528777 51.51668869826472, 2.7104296225124846 51.51038639641104, 2.6460147788171158 51.490312068927075, 2.623609610011189 51.479092482289715, 2.6099223823597675 51.47649424938388, 2.595557080088606 51.47593306874132, 2.581872851999604 51.47335883653051, 2.5705497621159252 51.46785754506058, 2.53871559060467 51.44962964446193, 2.5289405669249545 51.443045338935626, 2.520946608594902 51.43557602778169, 2.4738328880111853 51.39038916096986, 2.4678189927197107 51.38225585339655, 2.443803698849599 51.33988033575361, 2.436647766224928 51.33215202744673, 2.425260671340582 51.326791740203085, 2.412102485705382 51.32320948480792, 2.401068407625747 51.317544192701256, 2.3832054235947027 51.303486576859704, 2.3756774805384007 51.295837266918205, 2.3693475758917097 51.2877729586066, 2.311210966950842 51.195854609782266, 2.2945163201719656 51.17100869498148, 2.2815557795434653 51.14530079847652, 2.2727493489165576 51.11890593020748, 2.2667172274891216 51.08385184294803, 2.263658413378572 51.075073553186826, 2.255355726345203 51.05789195982969, 2.251373994112591 51.04555455657972) | I8: 55 | J8: =IF(I8=100,"Capacity unknown","") | K8: =INDEX(Nodes!$A:$A,MATCH(Arcs!F8,Nodes!$B:$B,0)) -> 41 | L8: =INDEX(Nodes!$A:$A,MATCH(Arcs!G8,Nodes!$B:$B,0)) -> 57 | M8: 1 | N8: 1
A9: 8 | B9: Kvitebjorn Gassror | C9: Gassco AS | D9: IN SERVICE | E9: 2004-09-26 | F9: KVITEBJoRN | G9: KOLLSNES | H9: LINESTRING (2.505334724239661 61.07707774169544, 2.5156455681055907 61.071997878159074, 2.5377977279092474 61.062647978419804, 2.5646782087413573 61.055777788606115, 2.5935935079498407 61.0428191329123, 2.6304754065886806 61.03267211951432, 2.6736810405753033 61.0142813077769, 2.691757822526383 61.00430190560882, 2.724656463325102 60.99193841544909, 2.7895566473072657 60.965345963761706, 2.913002584879702 60.9191345135096, 3.0241658483214495 60.87601292793791, 3.1000395791199953 60.84453761159612, 3.172550595707477 60.81665202010422, 3.3402050598966624 60.75399914125977, 3.4108706043382027 60.72244745743365, 3.4877486817090713 60.693158054533534, 3.5033281260282663 60.68867962360441, 3.594309140523922 60.67182678982449, 3.6199527070745785 60.66853871729266, 3.671705600727987 60.65977667129293, 3.8279352729208194 60.6449427054429, 3.9666037675743664 60.6243633591868, 4.106784461393816 60.60645441721475, 4.49082348304984 60.543371875521764, 4.57487746809513 60.52691946001078, 4.594357104033375 60.52176202389192, 4.638453194429097 60.50789177918331, 4.660990819612634 60.5039169817447, 4.675405125324347 60.50311603612439, 4.689631966698213 60.503573987585554, 4.720515491488312 60.508407762922886, 4.737185003204646 60.51374492891444, 4.7556554022336295 60.5227901439113, 4.779853432830677 60.528390623758156, 4.7989680591442845 60.53742821614213, 4.817711490441821 60.54090757731105, 4.824484073357435 60.543738272883424, 4.8354464342204535 60.54606225557832) | I9: 27 | J9: =IF(I9=100,"Capacity unknown","") | K9: =INDEX(Nodes!$A:$A,MATCH(Arcs!F9,Nodes!$B:$B,0)) -> 19 | L9: =INDEX(Nodes!$A:$A,MATCH(Arcs!G9,Nodes!$B:$B,0)) -> 25 | M9: 1 | N9: 1
A10: 9 | B10: Langeled | C10: Gassco AS | D10: IN SERVICE | E10: 2007-09-13 | F10: NYHAMNA | G10: SLEIPNER R | H10: LINESTRING (6.944126203226062 62.851181615233024, 6.958395523951621 62.86029927747193, 6.959437244320278 62.86393865781273, 6.9570327642936345 62.86726899544155, 6.951934588436433 62.8697485892215, 6.921528053263533 62.87815616721939, 6.899386123315378 62.89035198884869, 6.886777842767185 62.8953836300255, 6.877956384860074 62.898088257304074, 6.866665841970104 62.89970943684877, 6.83570513329627 62.90083445610842, 6.793422846264172 62.90430929058319, 6.784754991596397 62.90599916839668, 6.776374110964865 62.909314176300974, 6.770653550753617 62.91340362970615, 6.76783554845767 62.9183133113238, 6.767935965344757 62.921849679595034, 6.771996710328848 62.93271442488213, 6.769980083879582 62.941404632985616, 6.76733956506815 62.94464722628713, 6.763156912161753 62.94771813255899, 6.7510231137718995 62.95249799976163, 6.7421721503336025 62.95411539341296, 6.732601671465161 62.954748545754484, 6.66374699991203 62.95367576380796, 6.645619018729286 62.9524738731098, 6.612273046705815 62.9544190547306, 6.550780152010196 62.951316856424924, 6.459188607203072 62.934301539519794, 6.436844037625559 62.92923133783547, 6.2005430893532365 62.89161792298806, 6.171018100836043 62.88602500007172, 6.096305416462524 62.86645392639351, 5.841660615074013 62.809678282241926, 5.192750669676527 62.653437105178334, 5.179054745778569 62.64927875317483, 5.168065967344774 62.644197239808406, 5.161009295330372 62.63946674097722, 5.141530320079816 62.623131317043836, 4.978638417356975 62.472305442665856, 4.960700515785536 62.457911797772326, 4.947616128029106 62.441595527969056, 4.924426817586714 62.42423768153443, 4.900299455459889 62.399883390834034, 4.893937102167241 62.394756156317406, 4.882526842824044 62.38867896282539, 4.787859027736522 62.350121134033316, 4.659694523144031 62.30671041013584, 4.649196899707808 62.301716644888145, 4.640969617538731 62.29586456608697, 4.386800200301029 62.05731660282345, 4.344596452933942 61.99795702500478, 4.331978453627834 61.97310312695476, 4.312378293852157 61.949851377941584, 4.304935303551111 61.93804432811713, 4.296090688329816 61.928999211186444, 4.290280306466911 61.91951923933059, 4.284526071151988 61.91219084348436, 4.279965704523582 61.90785330319081, 4.263948932725386 61.89570280908999, 4.234825690039018 61.878516550479596, 4.20494980972435 61.85583690118129, 4.1858528843090435 61.83818917221627, 4.181106630707915 61.83232569146734, 4.174332658602673 61.82054916939476, 4.16149276505776 61.80677740603877, 4.153950028858588 61.79639329452358, 4.146609219179174 61.78214474499531, 4.141779098870773 61.75823321677975, 4.139030309714342 61.75356762390407, 4.127781706248229 61.73913591233521, 4.121785130033305 61.733547084116445, 4.0794075301593695 61.703920441550636, 4.014854046984061 61.655223097072806, 4.01100086725725 61.65054986033026, 4.004321738780614 61.63960116278898, 3.9908766863041434 61.62634439799704, 3.9843833160585347 61.61492647855347, 3.9745948550849732 61.5914574134949, 3.970326636309154 61.58571601473945, 3.962803048038805 61.57820067011437, 3.629607258110459 61.34867237440673, 3.5752092436308605 61.30916132071472, 3.494087609241543 61.25485213912258, 3.4597742196430663 61.230654135216966, 3.4462868956168147 61.21859523561273, 3.4216982246851844 61.202263567473395, 3.4093542306531215 61.193119224210825, 3.3995006317451986 61.18327298233412, 3.397093442024004 61.17968699604514, 3.393819791372758 61.17213737438463, 3.3900507889606226 61.140908998705584, 3.389776202126317 61.13067757906042, 3.391300162378597 61.1097913188949, 3.388695423088713 61.09106420854371, 3.3892034290231026 61.07052127145189, 3.3862908686188864 61.052000159780484, 3.386362031653565 61.041101147310734, 3.3853111305414125 61.030797236791564, 3.3855537990687727 61.00959814382851, 3.382780905819289 60.9697634940148, 3.384481065935622 60.952997271426035, 3.381848548125957 60.92743396013548, 3.383092846115363 60.88817922032942, 3.38124857775132 60.87563980145837, 3.3803649341987922 60.854005804957886, 3.3827216333948305 60.83870067770924, 3.382445159220309 60.82787414445291, 3.3802421990845675 60.81266814554372, 3.3820061365706895 60.7709871741128, 3.382273086189696 60.74561464662316, 3.3785967067959195 60.72934810312221, 3.3788071556994534 60.70830160864621, 3.3779709834892895 60.69950838184881, 3.37592077600572 60.69018487629203, 3.376504560987115 60.67432657520458, 3.3753646170917464 60.66132175647101, 3.3714182916589293 60.64587921742628, 3.3715713883183196 60.6226391881461, 3.370418808309397 60.60499933435139, 3.369268180546799 60.600181171316635, 3.3597410039294595 60.5760025693117, 3.356536744401816 60.56340591320805, 3.3532057786795852 60.557344083931305, 3.345279347989877 60.5476504659061, 3.3240438579901035 60.531559185660484, 3.300682079642526 60.515635731140485, 3.282358438439253 60.50493486214748, 3.2609818019447743 60.488809247282354, 3.2298410553365464 60.470119933555196, 3.170495063566217 60.42807960522853, 3.1233680792447562 60.396446326663835, 3.1166119253331637 60.38970159767318, 3.079377328322243 60.34205754789581, 3.077626587173248 60.33710204413744, 3.0322829970271283 60.07278245829359, 2.664302445883573 59.239975130681586, 2.289287471492959 58.75941515474237, 2.034339921087082 58.43834759060378, 2.030182684178442 58.43442970075392, 2.023888448104477 58.43041259822925, 1.9164397893768848 58.37203959978089) | I10: 75 | J10: =IF(I10=100,"Capacity unknown","") | K10: =INDEX(Nodes!$A:$A,MATCH(Arcs!F10,Nodes!$B:$B,0)) -> 14 | L10: =INDEX(Nodes!$A:$A,MATCH(Arcs!G10,Nodes!$B:$B,0)) -> 40 | M10: 1 | N10: 1
A11: 10 | B11: Langeled | C11: Gassco AS | D11: IN SERVICE | E11: 2006-10-01 | F11: SLEIPNER R | G11: EASINGTON | H11: LINESTRING (1.899695221113172 58.36436527043758, 1.8784147277470742 58.35608339708614, 1.850138658654632 58.341038489896164, 1.8409389688885731 58.32889193053247, 1.8254206604383028 58.316987892258354, 1.817204956533934 58.30553737567446, 1.799309087369085 58.29205066522481, 1.7869555250903297 58.27498589443389, 1.764993670007685 58.25877703540146, 1.749683217143433 58.23750107623741, 1.7358973286119976 58.22686252056317, 1.6188505027315663 58.10889481118326, 1.6125886598478378 58.10165547269084, 1.6101848864723851 58.09512920791515, 1.6102523595573162 58.08450582652492, 1.6000687353883531 58.047421366318446, 1.5013792065167715 57.84171876517869, 1.4040590209838884 57.63632581368914, 1.3179819853842516 57.51537844049209, 1.29433545304512 57.44339959195478, 1.1896400889962824 57.223380512825265, 1.187218640410845 57.208822969644636, 1.1685140002338135 57.04565799932774, 1.1688008648754984 56.807433667010045, 1.1680780376993984 56.80277649561659, 1.166123156518566 56.79867132827492, 1.1590063798473484 56.788821896865095, 1.1120108933437145 56.747194865586714, 1.107709988244552 56.74221363897368, 0.9372868461785486 56.44282315190418, 0.9361600473351338 56.43712394120704, 0.9374433255271666 56.43100874594434, 0.9404375971719453 56.42611961415787, 0.9562207131693672 56.40818519010667, 0.9584770060263339 56.402298014848355, 0.9582082510818832 56.396023795107276, 0.8252127156613631 55.972768641740736, 0.7029410893581942 55.57533666453199, 0.6506142793224539 55.05845672177157, 0.5901340949215869 54.44661982830093, 0.5385180611860005 54.329051369838716, 0.3965376078347606 54.16261624745859, 0.2969573911825778 53.959658493290895, 0.2740877003561589 53.90673851599404, 0.266623964650687 53.89413602111301, 0.1891298583283023 53.72956281570764, 0.1795411137006649 53.71570425739035, 0.1712915183957134 53.69839260535605, 0.1678125985223448 53.69372441440906, 0.162787629415652 53.68945121737258, 0.1283854800068933 53.67071220389232, 0.1225264955098541 53.666328993356274, 0.1145815833180996 53.65843864590715) | I11: 72 | J11: =IF(I11=100,"Capacity unknown","") | K11: =INDEX(Nodes!$A:$A,MATCH(Arcs!F11,Nodes!$B:$B,0)) -> 40 | L11: =INDEX(Nodes!$A:$A,MATCH(Arcs!G11,Nodes!$B:$B,0)) -> 54 | M11: 1 | N11: 1
A12: 11 | B12: Norne Gasstransport | C12: Gassco AS | D12: IN SERVICE | E12: 2001-02-05 | F12: NORNE ERB | G12: NORNE/HEIDRUN T | H12: LINESTRING (8.076739809297488 66.0290992001487, 8.049952275789764 66.03461122233705, 8.035274630789567 66.03578610056198, 8.020745093151788 66.03552691927945, 8.005136630697196 66.03362665528284, 7.9916243513180385 66.03027735399247, 7.980457256940544 66.02558502288387, 7.972929349330346 66.02022070578727, 7.969554515997286 66.01604748821262, 7.968156733270531 66.0122253088075, 7.96428376514426 65.98140094910526, 7.9653086077705195 65.97001747590772, 7.9644519857133345 65.9641962177665, 7.942484711062593 65.91358780424298, 7.937239044184883 65.906003419779, 7.896733556792352 65.86248309230324, 7.885406442938344 65.84367615932851, 7.8844501200532 65.83346771392577, 7.881150449543889 65.82695939843613, 7.878190546808611 65.82396023617277, 7.864722738061047 65.81391265092375, 7.837636371099828 65.80448193205186, 7.828952414651774 65.7991486033899, 7.792946698166718 65.7611895676376, 7.7632301135033455 65.7246886685379, 7.756237371962055 65.71716626704935, 7.751546688410944 65.71005491009879, 7.743322892885875 65.70263849870216, 7.738034904854274 65.69959430736218, 7.714613695874004 65.68989662049826, 7.6910600134438365 65.67252360651625, 7.665076124627933 65.65681363456532, 7.617081927697724 65.63362708656271, 7.551842006791016 65.59710977056594, 7.511467699108599 65.57969855702473, 7.465527269203192 65.5610662259892, 7.385117687556028 65.51147217787529, 7.287001952985897 65.46914122757471, 7.26798671189772 65.46238871704533, 7.260522735840396 65.45800944362855, 7.257023876196616 65.45407223588359, 7.242717150681102 65.42772695397366, 7.215395845411127 65.37347134086356, 7.208600948218103 65.33887780173625, 7.206963770594495 65.32587723438796, 7.202632686463978 65.31002251496722, 7.200227812604905 65.30685635306799, 7.156537079376469 65.26442704817285, 7.15054808814501 65.26104683484508, 7.1279918556371085 65.25224919695133, 7.109142767445553 65.24333059793251, 7.073263195053345 65.217534086688, 7.061720612881881 65.20507442560248, 7.024843484883916 65.17211360186565, 6.985108536241274 65.1497961918335, 6.9600837249260525 65.13341520619272, 6.950211905367923 65.12537275104032, 6.934112979023002 65.11554514688243, 6.903849653220438 65.10400130210719, 6.871178380308759 65.09037434117272, 6.862755247975175 65.08778813231534, 6.846844815577928 65.085628852136, 6.799674199493331 65.08422923098904) | I12: 7 | J12: =IF(I12=100,"Capacity unknown","") | K12: =INDEX(Nodes!$A:$A,MATCH(Arcs!F12,Nodes!$B:$B,0)) -> 4 | L12: =INDEX(Nodes!$A:$A,MATCH(Arcs!G12,Nodes!$B:$B,0)) -> 8 | M12: 1 | N12: 1
A13: 12 | B13: Norpipe Gassledning | C13: Gassco AS | D13: IN SERVICE | E13: 1998-08-18 | F13: NORPIPE Y | G13: EKOFISK J | H13: LINESTRING (3.3290292860187574 56.489709742026285, 3.305546804781628 56.51203524273058, 3.284842350708143 56.5354888160289, 3.2749758273122316 56.542294936603795, 3.261916303978955 56.54694794399001, 3.2445327335121013 56.549902840591834, 3.2366435192292764 56.55009975366412, 3.227394481609175 56.54814556522217) | I13: 32 | J13: =IF(I13=100,"Capacity unknown","") | K13: =INDEX(Nodes!$A:$A,MATCH(Arcs!F13,Nodes!$B:$B,0)) -> 46 | L13: =INDEX(Nodes!$A:$A,MATCH(Arcs!G13,Nodes!$B:$B,0)) -> 45 | M13: 1 | N13: 1
... A45: 44 | B45: Zeepipe I | C45: Gassco AS | D45: IN SERVICE | E45: 1993-10-01 | F45: SLEIPNER R | G45: DRAUPNER S | H45: LINESTRING (1.9143993643152986 58.364468438442366, 1.9173904614043764 58.36293314114221, 2.002333380060846 58.32729991768154, 2.2304039685719563 58.251683041865476, 2.2683414693356005 58.241147135854945, 2.4627678978090968 58.19033356020892) | I45: 55 | J45: =IF(I45=100,"Capacity unknown","") | K45: =INDEX(Nodes!$A:$A,MATCH(Arcs!F45,Nodes!$B:$B,0)) -> 40 | L45: =INDEX(Nodes!$A:$A,MATCH(Arcs!G45,Nodes!$B:$B,0)) -> 42 | M45: 1 | N45: 1
A46: 45 | B46: Baltic Pipe | F46: BALTIC ENTRANCE | G46: Denmark 1 | H46: LINESTRING (8.40599954145113 55.744355829654246, 8.177592315602979 55.77635410385294, 6.518139759559453 55.71135025950466, 6.502439404798719 55.70935001634503) | I46: 100 | J46: =IF(I46=100,"Capacity unknown","") -> Capacity unknown | K46: =INDEX(Nodes!$A:$A,MATCH(Arcs!F46,Nodes!$B:$B,0)) -> 47 | L46: =INDEX(Nodes!$A:$A,MATCH(Arcs!G46,Nodes!$B:$B,0)) -> 58 | M46: 1 | N46: 1
A47: 46 | B47: Baltic Pipe | F47: Denmark 2 | G47: Denmark 3 | H47: LINESTRING (10.79388011885061 55.286368989345874, 10.743178106255938 55.30436900190291, 10.682376288978503 55.30936845834846, 10.645975309356023 55.309368031843036, 10.603374235670925 55.30736746506849, 10.566872677067275 55.323367574785536, 10.540571897933582 55.325367333201406, 10.534471625589266 55.32836736244413, 10.522370649344895 55.34636782581958, 10.51626990595621 55.36236829261592, 10.502069270438142 55.36936836131065, 10.467568197927822 55.37336809012607, 10.467568887024816 55.35436745060885, 10.439268996740388 55.330366310272304, 10.374367038417814 55.33636574769954, 10.317665300907096 55.342365280888146, 10.275062157187168 55.397366628450875, 10.0278531919811 55.46136585622288, 9.794745005683897 55.51436486796232, 9.725142331883513 55.536364778773326, 9.663939955430543 55.55636472164552, 9.554235724942519 55.591364588703776, 9.482533553341405 55.59836396447529, 9.448832469017304 55.60336372838686, 9.3095282775057 55.61636249087426) | I47: 100 | J47: =IF(I47=100,"Capacity unknown","") -> Capacity unknown | K47: =INDEX(Nodes!$A:$A,MATCH(Arcs!F47,Nodes!$B:$B,0)) -> 59 | L47: =INDEX(Nodes!$A:$A,MATCH(Arcs!G47,Nodes!$B:$B,0)) -> 60 | M47: 1 | N47: 1
