Workbook

Sheet Visualisation

Sheet Units
A1: Quantity | B1: Unit | C1: Explanation
A2: =Nodes!J2 -> Old Production Capacity Gas | B2: MSm3/h | C2: Mega (or million) standard cubic metres per hour. One standard cubic meter means the amount of gas which occupies a Cubic Meter at fifteen (15) Degrees Celsius and a pressure of one hundred one decimal three two five (101.325) kPa.
A3: =Nodes!M2 -> Production Costs Gas | B3: NOK / MSm3
A4: =Nodes!N2 -> Storage Capacity Gas | B4: MSm3
A5: =Nodes!O2 -> Entry Storage Costs Gas | B5: NOK / MSm3
A6: =Nodes!P2 -> Entry Costs Gas Stage 1 | B6: NOK / MSm3
A7: =Nodes!Q2 -> Exit Costs Gas Stage 1 | B7: NOK / MSm3
A8: =Arcs!M1 -> Flow costs Gas | B8: NOK / MSm3
A9: =Arcs!#REF! -> #REF! | B9: MSm3/h
A10: Demand | B10: MSm3/h

Sheet Nodes
G1: Gas | V1: Hydrogen
A2: ID | B2: Name | C2: Type | D2: X_coordinate | E2: Y_coordinate | F2: Note | G2: TSO entry costs Gas | H2: TSO exit costs Gas | I2: Production Capacity Gas | J2: Old Production Capacity Gas | K2: Entry Capacity Gas | L2: Exit Capacity Gas | M2: Production Costs Gas | N2: Storage Capacity Gas | O2: Entry Storage Costs Gas | P2: Entry Costs Gas Stage 1 | Q2: Exit Costs Gas Stage 1 | R2: Entry Costs Gas Stage 2 | S2: Exit Costs Gas Stage 2 | T2: Entry Costs Gas Stage 3 | U2: Exit Costs Gas Stage 3 | V2: TSO entry costs Hydrogen | W2: TSO exit costs Hydrogen | X2: Production Capacity Hydrogen | Y2: Entry Capacity Hydrogen | Z2: Exit Capacity Hydrogen | AA2: Production Costs Hydrogen | AB2: Storage Capacity Hydrogen | AC2: Entry Storage Costs Hydrogen | AD2: Entry Costs Hydrogen Stage 1 | AE2: Exit Costs Hydrogen Stage 1 | AF2: Entry Costs Hydrogen Stage 2 | AG2: Exit Costs Hydrogen Stage 2 | AH2: Entry Costs Hydrogen Stage 3 | AI2: Exit Costs Hydrogen Stage 3
A3: 1 | B3: AASTA HANSTEEN PLEM | D3: 7.107227 | E3: 67.05561 | G3: 5 | H3: 5 | I3: =SUMIFS(ProductionCapacities!$F$2:$F$51,ProductionCapacities!$E$2:$E$51,Nodes!B3) -> 23.970863 | J3: 8889.595 | K3: 500 | L3: 500 | M3: 10 | N3: 100 | O3: 3 | P3: 5 | Q3: 5 | R3: 5.2 | S3: 5.2 | T3: 5.4 | U3: 5.4 | V3: 5 | W3: 5 | X3: 0 | Y3: 0 | Z3: 0 | AA3: 1 | AB3: 0 | AC3: 1 | AD3: 1 | AE3: 1 | AF3: 3 | AG3: 3 | AH3: 5 | AI3: 5
A4: 2 | B4: aSGARD ERB | D4: 4.6885411 | E4: 62.302729 | G4: 5 | H4: 5 | I4: =SUMIFS(ProductionCapacities!$F$2:$F$51,ProductionCapacities!$E$2:$E$51,Nodes!B4) -> 0 | J4: 0 | K4: 500 | L4: 500 | M4: 10 | N4: 100 | O4: 3 | P4: 5 | Q4: 5 | R4: 5.2 | S4: 5.2 | T4: 5.4 | U4: 5.4 | V4: 5 | W4: 5 | X4: 0 | Y4: 0 | Z4: 0 | AA4: 1 | AB4: 0 | AC4: 1 | AD4: 1 | AE4: 1 | AF4: 3 | AG4: 3 | AH4: 5 | AI4: 5
A5: 3 | B5: aSGARD T | D5: 6.8036598 | E5: 65.094472 | F5: Los | G5: 5 | H5: 5 | I5: =SUMIFS(ProductionCapacities!$F$2:$F$51,ProductionCapacities!$E$2:$E$51,Nodes!B5) -> 28.969463 | J5: 0 | K5: 500 | L5: 500 | M5: 10 | N5: 100 | O5: 3 | P5: 5 | Q5: 5 | R5: 5.2 | S5: 5.2 | T5: 5.4 | U5: 5.4 | V5: 5 | W5: 5 | X5: 0 | Y5: 0 | Z5: 0 | AA5: 1 | AB5: 0 | AC5: 1 | AD5: 1 | AE5: 1 | AF5: 3 | AG5: 3 | AH5: 5 | AI5: 5
A6: 4 | B6: B-11 | D6: 4.5569471 | E6: 55.458982 | G6: 5 | H6: 5 | I6: =SUMIFS(ProductionCapacities!$F$2:$F$51,ProductionCapacities!$E$2:$E$51,Nodes!B6) -> 0 | J6: 0 | K6: 500 | L6: 500 | M6: 10 | N6: 100 | O6: 3 | P6: 5 | Q6: 5 | R6: 5.2 | S6: 5.2 | T6: 5.4 | U6: 5.4 | V6: 5 | W6: 5 | X6: 0 | Y6: 0 | Z6: 0 | AA6: 1 | AB6: 0 | AC6: 1 | AD6: 1 | AE6: 1 | AF6: 3 | AG6: 3 | AH6: 5 | AI6: 5
A7: 5 | B7: BALTIC ENTRANCE | D7: 6.5038 | E7: 55.71 | G7: 5 | H7: 5 | I7: =SUMIFS(ProductionCapacities!$F$2:$F$51,ProductionCapacities!$E$2:$E$51,Nodes!B7) -> 0 | J7: 0 | K7: 500 | L7: 500 | M7: 10 | N7: 100 | O7: 3 | P7: 5 | Q7: 5 | R7: 5.2 | S7: 5.2 | T7: 5.4 | U7: 5.4 | V7: 5 | W7: 5 | X7: 0 | Y7: 0 | Z7: 0 | AA7: 1 | AB7: 0 | AC7: 1 | AD7: 1 | AE7: 1 | AF7: 3 | AG7: 3 | AH7: 5 | AI7: 5
A8: 6 | B8: BRAGE | D8: 2.898055 | E8: 60.560633 | F8: Los | G8: 5 | H8: 5 | I8: =SUMIFS(ProductionCapacities!$F$2:$F$51,ProductionCapacities!$E$2:$E$51,Nodes!B8) -> 0.35852055 | J8: 0 | K8: 500 | L8: 500 | M8: 10 | N8: 100 | O8: 3 | P8: 5 | Q8: 5 | R8: 5.2 | S8: 5.2 | T8: 5.4 | U8: 5.4 | V8: 5 | W8: 5 | X8: 0 | Y8: 0 | Z8: 0 | AA8: 1 | AB8: 0 | AC8: 1 | AD8: 1 | AE8: 1 | AF8: 3 | AG8: 3 | AH8: 5 | AI8: 5
A9: 7 | B9: BRAGE-T | D9: 3.0378255 | E9: 60.543329 | F9: Los | G9: 5 | H9: 5 | I9: =SUMIFS(ProductionCapacities!$F$2:$F$51,ProductionCapacities!$E$2:$E$51,Nodes!B9) -> 0 | J9: 48.065 | K9: 500 | L9: 500 | M9: 10 | N9: 100 | O9: 3 | P9: 5 | Q9: 5 | R9: 5.2 | S9: 5.2 | T9: 5.4 | U9: 5.4 | V9: 5 | W9: 5 | X9: 0 | Y9: 0 | Z9: 0 | AA9: 1 | AB9: 0 | AC9: 1 | AD9: 1 | AE9: 1 | AF9: 3 | AG9: 3 | AH9: 5 | AI9: 5
A10: 8 | B10: CATS PLATFORM | D10: 1.803328 | E10: 57.758069 | G10: 5 | H10: 5 | I10: 48 | J10: 1282.342 | K10: 500 | L10: 500 | M10: 10 | N10: 100 | O10: 3 | P10: 5 | Q10: 5 | R10: 5.2 | S10: 5.2 | T10: 5.4 | U10: 5.4 | V10: 5 | W10: 5 | X10: 0 | Y10: 0 | Z10: 0 | AA10: 1 | AB10: 0 | AC10: 1 | AD10: 1 | AE10: 1 | AF10: 3 | AG10: 3 | AH10: 5 | AI10: 5
A11: 9 | B11: Denmark 1 | D11: 8.4073 | E11: 55.745 | G11: 5 | H11: 5 | I11: =SUMIFS(ProductionCapacities!$F$2:$F$51,ProductionCapacities!$E$2:$E$51,Nodes!B11) -> 0 | J11: 0 | K11: 500 | L11: 500 | M11: 10 | N11: 100 | O11: 3 | P11: 5 | Q11: 5 | R11: 5.2 | S11: 5.2 | T11: 5.4 | U11: 5.4 | V11: 5 | W11: 5 | X11: 0 | Y11: 0 | Z11: 0 | AA11: 1 | AB11: 0 | AC11: 1 | AD11: 1 | AE11: 1 | AF11: 3 | AG11: 3 | AH11: 5 | AI11: 5
A12: 10 | B12: Denmark 2 | D12: 9.3108 | E12: 55.617 | G12: 5 | H12: 5 | I12: =SUMIFS(ProductionCapacities!$F$2:$F$51,ProductionCapacities!$E$2:$E$51,Nodes!B12) -> 0 | J12: 0 | K12: 500 | L12: 500 | M12: 10 | N12: 100 | O12: 3 | P12: 5 | Q12: 5 | R12: 5.2 | S12: 5.2 | T12: 5.4 | U12: 5.4 | V12: 5 | W12: 5 | X12: 0 | Y12: 0 | Z12: 0 | AA12: 1 | AB12: 0 | AC12: 1 | AD12: 1 | AE12: 1 | AF12: 3 | AG12: 3 | AH12: 5 | AI12: 5
A13: 11 | B13: Denmark 3 | D13: 10.7951 | E13: 55.287 | G13: 5 | H13: 5 | I13: =SUMIFS(ProductionCapacities!$F$2:$F$51,ProductionCapacities!$E$2:$E$51,Nodes!B13) -> 0 | J13: 0 | K13: 500 | L13: 500 | M13: 10 | N13: 100 | O13: 3 | P13: 5 | Q13: 5 | R13: 5.2 | S13: 5.2 | T13: 5.4 | U13: 5.4 | V13: 5 | W13: 5 | X13: 0 | Y13: 0 | Z13: 0 | AA13: 1 | AB13: 0 | AC13: 1 | AD13: 1 | AE13: 1 | AF13: 3 | AG13: 3 | AH13: 5 | AI13: 5
A14: 12 | B14: Denmark 4 | D14: 11.2102 | E14: 55.389 | G14: 5 | H14: 5 | I14: =SUMIFS(ProductionCapacities!$F$2:$F$51,ProductionCapacities!$E$2:$E$51,Nodes!B14) -> 0 | J14: 0 | K14: 500 | L14: 500 | M14: 10 | N14: 100 | O14: 3 | P14: 5 | Q14: 5 | R14: 5.2 | S14: 5.2 | T14: 5.4 | U14: 5.4 | V14: 5 | W14: 5 | X14: 0 | Y14: 0 | Z14: 0 | AA14: 1 | AB14: 0 | AC14: 1 | AD14: 1 | AE14: 1 | AF14: 3 | AG14: 3 | AH14: 5 | AI14: 5
A15: 13 | B15: DRAUGEN | D15: 6.441258 | E15: 64.233255 | F15: Los | G15: 5 | H15: 5 | I15: =SUMIFS(ProductionCapacities!$F$2:$F$51,ProductionCapacities!$E$2:$E$51,Nodes!B15) -> 0.010191781 | J15: 48.065 | K15: 500 | L15: 500 | M15: 10 | N15: 100 | O15: 3 | P15: 5 | Q15: 5 | R15: 5.2 | S15: 5.2 | T15: 5.4 | U15: 5.4 | V15: 5 | W15: 5 | X15: 0 | Y15: 0 | Z15: 0 | AA15: 1 | AB15: 0 | AC15: 1 | AD15: 1 | AE15: 1 | AF15: 3 | AG15: 3 | AH15: 5 | AI15: 5
A16: 14 | B16: DRAUGEN T | D16: 7.7910261 | E16: 64.350568 | G16: 5 | H16: 5 | I16: =SUMIFS(ProductionCapacities!$F$2:$F$51,ProductionCapacities!$E$2:$E$51,Nodes!B16) -> 0 | J16: 48.065 | K16: 500 | L16: 500 | M16: 10 | N16: 100 | O16: 3 | P16: 5 | Q16: 5 | R16: 5.2 | S16: 5.2 | T16: 5.4 | U16: 5.4 | V16: 5 | W16: 5 | X16: 0 | Y16: 0 | Z16: 0 | AA16: 1 | AB16: 0 | AC16: 1 | AD16: 1 | AE16: 1 | AF16: 3 | AG16: 3 | AH16: 5 | AI16: 5
A17: 15 | B17: DRAUPNER E | D17: 2.4644042 | E17: 58.188149 | G17: 5 | H17: 5 | I17: =SUMIFS(ProductionCapacities!$F$2:$F$51,ProductionCapacities!$E$2:$E$51,Nodes!B17) -> 0 | J17: 0 | K17: 500 | L17: 500 | M17: 10 | N17: 100 | O17: 3 | P17: 5 | Q17: 5 | R17: 5.2 | S17: 5.2 | T17: 5.4 | U17: 5.4 | V17: 5 | W17: 5 | X17: 0 | Y17: 0 | Z17: 0 | AA17: 1 | AB17: 0 | AC17: 1 | AD17: 1 | AE17: 1 | AF17: 3 | AG17: 3 | AH17: 5 | AI17: 5
A18: 16 | B18: DRAUPNER S | D18: 2.473733 | E18: 58.184409 | G18: 5 | H18: 5 | I18: =SUMIFS(ProductionCapacities!$F$2:$F$51,ProductionCapacities!$E$2:$E$51,Nodes!B18) -> 0 | J18: 0 | K18: 500 | L18: 500 | M18: 10 | N18: 100 | O18: 3 | P18: 5 | Q18: 5 | R18: 5.2 | S18: 5.2 | T18: 5.4 | U18: 5.4 | V18: 5 | W18: 5 | X18: 0 | Y18: 0 | Z18: 0 | AA18: 1 | AB18: 0 | AC18: 1 | AD18: 1 | AE18: 1 | AF18: 3 | AG18: 3 | AH18: 5 | AI18: 5
A19: 17 | B19: DUNKERQUE | C19: Market | D19: 2.252709 | E19: 51.046406 | G19: 5 | H19: 5 | I19: =SUMIFS(ProductionCapacities!$F$2:$F$51,ProductionCapacities!$E$2:$E$51,Nodes!B19) -> 0 | J19: 1214.6 | K19: 500 | L19: 500 | M19: 10 | N19: 100 | O19: 3 | P19: 5 | Q19: 5 | R19: 5.2 | S19: 5.2 | T19: 5.4 | U19: 5.4 | V19: 5 | W19: 5 | X19: 0 | Y19: 0 | Z19: 0 | AA19: 1 | AB19: 0 | AC19: 1 | AD19: 1 | AE19: 1 | AF19: 3 | AG19: 3 | AH19: 5 | AI19: 5
A20: 18 | B20: EASINGTON | C20: Market | D20: 0.116031 | E20: 53.659231 | G20: 5 | H20: 5 | I20: =SUMIFS(ProductionCapacities!$F$2:$F$51,ProductionCapacities!$E$2:$E$51,Nodes!B20) -> 0 | J20: 0 | K20: 500 | L20: 500 | M20: 10 | N20: 100 | O20: 3 | P20: 5 | Q20: 5 | R20: 5.2 | S20: 5.2 | T20: 5.4 | U20: 5.4 | V20: 5 | W20: 5 | X20: 0 | Y20: 0 | Z20: 0 | AA20: 1 | AB20: 0 | AC20: 1 | AD20: 1 | AE20: 1 | AF20: 3 | AG20: 3 | AH20: 5 | AI20: 5
A21: 19 | B21: EDVARD GRIEG | D21: 1.3911371 | E21: 59.477978 | F21: Los | G21: 5 | H21: 5 | I21: =SUMIFS(ProductionCapacities!$F$2:$F$51,ProductionCapacities!$E$2:$E$51,Nodes!B21) -> 4.0645178 | J21: 48.065 | K21: 500 | L21: 500 | M21: 10 | N21: 100 | O21: 3 | P21: 5 | Q21: 5 | R21: 5.2 | S21: 5.2 | T21: 5.4 | U21: 5.4 | V21: 5 | W21: 5 | X21: 0 | Y21: 0 | Z21: 0 | AA21: 1 | AB21: 0 | AC21: 1 | AD21: 1 | AE21: 1 | AF21: 3 | AG21: 3 | AH21: 5 | AI21: 5
A22: 20 | B22: EKOFISK J | D22: 3.23 | E22: 56.55 | G22: 5 | H22: 5 | I22: =SUMIFS(ProductionCapacities!$F$2:$F$51,ProductionCapacities!$E$2:$E$51,Nodes!B22) -> 3.8482712 | J22: 578.785 | K22: 500 | L22: 500 | M22: 10 | N22: 100 | O22: 3 | P22: 5 | Q22: 5 | R22: 5.2 | S22: 5.2 | T22: 5.4 | U22: 5.4 | V22: 5 | W22: 5 | X22: 0 | Y22: 0 | Z22: 0 | AA22: 1 | AB22: 0 | AC22: 1 | AD22: 1 | AE22: 1 | AF22: 3 | AG22: 3 | AH22: 5 | AI22: 5
A23: 21 | B23: DORNUM | C23: Market | D23: 7.32642 | E23: 53.6797 | G23: 5 | H23: 5 | I23: =SUMIFS(ProductionCapacities!$F$2:$F$51,ProductionCapacities!$E$2:$E$51,Nodes!B23) -> 0 | J23: 0 | K23: 500 | L23: 500 | M23: 10 | N23: 100 | O23: 3 | P23: 5 | Q23: 5 | R23: 5.2 | S23: 5.2 | T23: 5.4 | U23: 5.4 | V23: 5 | W23: 5 | X23: 0 | Y23: 0 | Z23: 0 | AA23: 1 | AB23: 0 | AC23: 1 | AD23: 1 | AE23: 1 | AF23: 3 | AG23: 3 | AH23: 5 | AI23: 5
A24: 22 | B24: EMDEN | C24: Market | D24: 7.18929 | E24: 53.3462 | G24: 5 | H24: 5 | I24: =SUMIFS(ProductionCapacities!$F$2:$F$51,ProductionCapacities!$E$2:$E$51,Nodes!B24) -> 0 | J24: 0 | K24: 500 | L24: 500 | M24: 10 | N24: 100 | O24: 3 | P24: 5 | Q24: 5 | R24: 5.2 | S24: 5.2 | T24: 5.4 | U24: 5.4 | V24: 5 | W24: 5 | X24: 0 | Y24: 0 | Z24: 0 | AA24: 1 | AB24: 0 | AC24: 1 | AD24: 1 | AE24: 1 | AF24: 3 | AG24: 3 | AH24: 5 | AI24: 5
A25: 23 | B25: EUROPIPE-SCP | D25: 4.222622 | E25: 55.706969 | G25: 5 | H25: 5 | I25: =SUMIFS(ProductionCapacities!$F$2:$F$51,ProductionCapacities!$E$2:$E$51,Nodes!B25) -> 0 | J25: 0 | K25: 500 | L25: 500 | M25: 10 | N25: 100 | O25: 3 | P25: 5 | Q25: 5 | R25: 5.2 | S25: 5.2 | T25: 5.4 | U25: 5.4 | V25: 5 | W25: 5 | X25: 0 | Y25: 0 | Z25: 0 | AA25: 1 | AB25: 0 | AC25: 1 | AD25: 1 | AE25: 1 | AF25: 3 | AG25: 3 | AH25: 5 | AI25: 5
A26: 24 | B26: FLAGS-T | D26: 1.7001891 | E26: 61.022018 | G26: 5 | H26: 5 | I26: =SUMIFS(ProductionCapacities!$F$2:$F$51,ProductionCapacities!$E$2:$E$51,Nodes!B26) -> 0 | J26: 0 | K26: 500 | L26: 500 | M26: 10 | N26: 100 | O26: 3 | P26: 5 | Q26: 5 | R26: 5.2 | S26: 5.2 | T26: 5.4 | U26: 5.4 | V26: 5 | W26: 5 | X26: 0 | Y26: 0 | Z26: 0 | AA26: 1 | AB26: 0 | AC26: 1 | AD26: 1 | AE26: 1 | AF26: 3 | AG26: 3 | AH26: 5 | AI26: 5
A27: 25 | B27: FRIGG TP1-Y | D27: 2.0113877 | E27: 60.502035 | F27: Los | G27: 5 | H27: 5 | I27: =SUMIFS(ProductionCapacities!$F$2:$F$51,ProductionCapacities!$E$2:$E$51,Nodes!B27) -> 0 | J27: 0 | K27: 500 | L27: 500 | M27: 10 | N27: 100 | O27: 3 | P27: 5 | Q27: 5 | R27: 5.2 | S27: 5.2 | T27: 5.4 | U27: 5.4 | V27: 5 | W27: 5 | X27: 0 | Y27: 0 | Z27: 0 | AA27: 1 | AB27: 0 | AC27: 1 | AD27: 1 | AE27: 1 | AF27: 3 | AG27: 3 | AH27: 5 | AI27: 5
A28: 26 | B28: GJoA | D28: 1.6999853 | E28: 61.020798 | F28: Los | G28: 5 | H28: 5 | I28: =SUMIFS(ProductionCapacities!$F$2:$F$51,ProductionCapacities!$E$2:$E$51,Nodes!B28) -> 10.738132 | J28: 2588.081 | K28: 500 | L28: 500 | M28: 10 | N28: 100 | O28: 3 | P28: 5 | Q28: 5 | R28: 5.2 | S28: 5.2 | T28: 5.4 | U28: 5.4 | V28: 5 | W28: 5 | X28: 0 | Y28: 0 | Z28: 0 | AA28: 1 | AB28: 0 | AC28: 1 | AD28: 1 | AE28: 1 | AF28: 3 | AG28: 3 | AH28: 5 | AI28: 5
A29: 27 | B29: GJoA-T | D29: 3.9049898 | E29: 61.330194 | F29: Los | G29: 5 | H29: 5 | I29: =SUMIFS(ProductionCapacities!$F$2:$F$51,ProductionCapacities!$E$2:$E$51,Nodes!B29) -> 0 | J29: 2588.081 | K29: 500 | L29: 500 | M29: 10 | N29: 100 | O29: 3 | P29: 5 | Q29: 5 | R29: 5.2 | S29: 5.2 | T29: 5.4 | U29: 5.4 | V29: 5 | W29: 5 | X29: 0 | Y29: 0 | Z29: 0 | AA29: 1 | AB29: 0 | AC29: 1 | AD29: 1 | AE29: 1 | AF29: 3 | AG29: 3 | AH29: 5 | AI29: 5
A30: 28 | B30: GRANE | D30: 2.4873353 | E30: 59.169726 | G30: 5 | H30: 5 | I30: =SUMIFS(ProductionCapacities!$F$2:$F$51,ProductionCapacities!$E$2:$E$51,Nodes!B30) -> 0 | J30: 48.065 | K30: 500 | L30: 500 | M30: 10 | N30: 100 | O30: 3 | P30: 5 | Q30: 5 | R30: 5.2 | S30: 5.2 | T30: 5.4 | U30: 5.4 | V30: 5 | W30: 5 | X30: 0 | Y30: 0 | Z30: 0 | AA30: 1 | AB30: 0 | AC30: 1 | AD30: 1 | AE30: 1 | AF30: 3 | AG30: 3 | AH30: 5 | AI30: 5
A31: 29 | B31: GUDRUN | D31: 1.7504701 | E31: 58.842411 | G31: 5 | H31: 5 | I31: =SUMIFS(ProductionCapacities!$F$2:$F$51,ProductionCapacities!$E$2:$E$51,Nodes!B31) -> 0 | J31: 667.002 | K31: 500 | L31: 500 | M31: 10 | N31: 100 | O31: 3 | P31: 5 | Q31: 5 | R31: 5.2 | S31: 5.2 | T31: 5.4 | U31: 5.4 | V31: 5 | W31: 5 | X31: 0 | Y31: 0 | Z31: 0 | AA31: 1 | AB31: 0 | AC31: 1 | AD31: 1 | AE31: 1 | AF31: 3 | AG31: 3 | AH31: 5 | AI31: 5
A32: 30 | B32: H-7 BP | D32: 6.0406336 | E32: 54.505801 | G32: 5 | H32: 5 | I32: =SUMIFS(ProductionCapacities!$F$2:$F$51,ProductionCapacities!$E$2:$E$51,Nodes!B32) -> 0 | J32: 0 | K32: 500 | L32: 500 | M32: 10 | N32: 100 | O32: 3 | P32: 5 | Q32: 5 | R32: 5.2 | S32: 5.2 | T32: 5.4 | U32: 5.4 | V32: 5 | W32: 5 | X32: 0 | Y32: 0 | Z32: 0 | AA32: 1 | AB32: 0 | AC32: 1 | AD32: 1 | AE32: 1 | AF32: 3 | AG32: 3 | AH32: 5 | AI32: 5
A33: 31 | B33: HEIDRUN | D33: 7.3202454 | E33: 65.3215 | F33: Los | G33: 5 | H33: 5 | I33: =SUMIFS(ProductionCapacities!$F$2:$F$51,ProductionCapacities!$E$2:$E$51,Nodes!B33) -> 4.2217397 | J33: 1214.6 | K33: 500 | L33: 500 | M33: 10 | N33: 100 | O33: 3 | P33: 5 | Q33: 5 | R33: 5.2 | S33: 5.2 | T33: 5.4 | U33: 5.4 | V33: 5 | W33: 5 | X33: 0 | Y33: 0 | Z33: 0 | AA33: 1 | AB33: 0 | AC33: 1 | AD33: 1 | AE33: 1 | AF33: 3 | AG33: 3 | AH33: 5 | AI33: 5
A34: 32 | B34: HEIMDAL | D34: 2.2345226 | E34: 59.570738 | G34: 5 | H34: 5 | I34: =SUMIFS(ProductionCapacities!$F$2:$F$51,ProductionCapacities!$E$2:$E$51,Nodes!B34) -> 0.072424658 | J34: 1329.308 | K34: 500 | L34: 500 | M34: 10 | N34: 100 | O34: 3 | P34: 5 | Q34: 5 | R34: 5.2 | S34: 5.2 | T34: 5.4 | U34: 5.4 | V34: 5 | W34: 5 | X34: 0 | Y34: 0 | Z34: 0 | AA34: 1 | AB34: 0 | AC34: 1 | AD34: 1 | AE34: 1 | AF34: 3 | AG34: 3 | AH34: 5 | AI34: 5
A35: 33 | B35: HEIMDAL HRP | D35: 2.2352255 | E35: 59.571075 | G35: 5 | H35: 5 | I35: =SUMIFS(ProductionCapacities!$F$2:$F$51,ProductionCapacities!$E$2:$E$51,Nodes!B35) -> 0 | J35: 1329.308 | K35: 500 | L35: 500 | M35: 10 | N35: 100 | O35: 3 | P35: 5 | Q35: 5 | R35: 5.2 | S35: 5.2 | T35: 5.4 | U35: 5.4 | V35: 5 | W35: 5 | X35: 0 | Y35: 0 | Z35: 0 | AA35: 1 | AB35: 0 | AC35: 1 | AD35: 1 | AE35: 1 | AF35: 3 | AG35: 3 | AH35: 5 | AI35: 5
A36: 34 | B36: JOHAN SVERDRUP RP | D36: 5.054176 | E36: 59.326808 | F36: Los | G36: 5 | H36: 5 | I36: =SUMIFS(ProductionCapacities!$F$2:$F$51,ProductionCapacities!$E$2:$E$51,Nodes!B36) -> 2.304789 | J36: 8889.595 | K36: 500 | L36: 500 | M36: 10 | N36: 100 | O36: 3 | P36: 5 | Q36: 5 | R36: 5.2 | S36: 5.2 | T36: 5.4 | U36: 5.4 | V36: 5 | W36: 5 | X36: 0 | Y36: 0 | Z36: 0 | AA36: 1 | AB36: 0 | AC36: 1 | AD36: 1 | AE36: 1 | AF36: 3 | AG36: 3 | AH36: 5 | AI36: 5
A37: 35 | B37: JOHAN SVERDRUP STATPIPE PLEM | D37: 2.5577715 | E37: 58.841931 | F37: Los | G37: 5 | H37: 5 | I37: =SUMIFS(ProductionCapacities!$F$2:$F$51,ProductionCapacities!$E$2:$E$51,Nodes!B37) -> 0 | J37: 8889.595 | K37: 500 | L37: 500 | M37: 10 | N37: 100 | O37: 3 | P37: 5 | Q37: 5 | R37: 5.2 | S37: 5.2 | T37: 5.4 | U37: 5.4 | V37: 5 | W37: 5 | X37: 0 | Y37: 0 | Z37: 0 | AA37: 1 | AB37: 0 | AC37: 1 | AD37: 1 | AE37: 1 | AF37: 3 | AG37: 3 | AH37: 5 | AI37: 5
A38: 36 | B38: KaRSTo | D38: 5.5129213 | E38: 59.272116 | G38: 5 | H38: 5 | I38: =SUMIFS(ProductionCapacities!$F$2:$F$51,ProductionCapacities!$E$2:$E$51,Nodes!B38) -> 0 | J38: 0 | K38: 500 | L38: 500 | M38: 10 | N38: 100 | O38: 3 | P38: 5 | Q38: 5 | R38: 5.2 | S38: 5.2 | T38: 5.4 | U38: 5.4 | V38: 5 | W38: 5 | X38: 0 | Y38: 0 | Z38: 0 | AA38: 1 | AB38: 0 | AC38: 1 | AD38: 1 | AE38: 1 | AF38: 3 | AG38: 3 | AH38: 5 | AI38: 5
A39: 37 | B39: KOLLSNES | D39: 4.838597 | E39: 60.545348 | G39: 5 | H39: 5 | I39: =SUMIFS(ProductionCapacities!$F$2:$F$51,ProductionCapacities!$E$2:$E$51,Nodes!B39) -> 0 | J39: 0 | K39: 500 | L39: 500 | M39: 10 | N39: 100 | O39: 3 | P39: 5 | Q39: 5 | R39: 5.2 | S39: 5.2 | T39: 5.4 | U39: 5.4 | V39: 5 | W39: 5 | X39: 0 | Y39: 0 | Z39: 0 | AA39: 1 | AB39: 0 | AC39: 1 | AD39: 1 | AE39: 1 | AF39: 3 | AG39: 3 | AH39: 5 | AI39: 5
A40: 38 | B40: KVITEBJoRN | D40: 2.5070781 | E40: 61.077582 | G40: 5 | H40: 5 | I40: =SUMIFS(ProductionCapacities!$F$2:$F$51,ProductionCapacities!$E$2:$E$51,Nodes!B40) -> 26.032537 | J40: 508.403 | K40: 500 | L40: 500 | M40: 10 | N40: 100 | O40: 3 | P40: 5 | Q40: 5 | R40: 5.2 | S40: 5.2 | T40: 5.4 | U40: 5.4 | V40: 5 | W40: 5 | X40: 0 | Y40: 0 | Z40: 0 | AA40: 1 | AB40: 0 | AC40: 1 | AD40: 1 | AE40: 1 | AF40: 3 | AG40: 3 | AH40: 5 | AI40: 5
...

Sheet Demand Stage 1
A1: Node Number | B1: 1
A2: Probability | B2: 1
B3: gas or mix | J3: pure hydrogen
A4: Hour | B4: ='Demand Stage 2'!B4 -> ST.FERGUS | C4: ='Demand Stage 2'!C4 -> EASINGTON | D4: ='Demand Stage 2'!D4 -> TEESSIDE | E4: ='Demand Stage 2'!E4 -> EMDEN | F4: DORNUM | G4: ='Demand Stage 2'!G4 -> ZEEBRUGGE | H4: ='Demand Stage 2'!H4 -> DUNKERQUE | I4: ='Demand Stage 2'!I4 -> POLAND | J4: ='Demand Stage 2'!J4 -> ST.FERGUS | K4: ='Demand Stage 2'!K4 -> EASINGTON | L4: ='Demand Stage 2'!L4 -> TEESSIDE | M4: ='Demand Stage 2'!M4 -> EMDEN | N4: DORNUM | O4: ='Demand Stage 2'!O4 -> ZEEBRUGGE | P4: ='Demand Stage 2'!P4 -> DUNKERQUE | Q4: ='Demand Stage 2'!Q4 -> POLAND
A5: 0 | B5: ='Demand Stage 2'!B43 -> 10 | C5: ='Demand Stage 2'!C43 -> 10 | D5: ='Demand Stage 2'!D43 -> 10 | E5: ='Demand Stage 2'!E43 -> 40 | F5: ='Demand Stage 2'!F43 -> 40 | G5: ='Demand Stage 2'!G43 -> 40 | H5: ='Demand Stage 2'!H43 -> 40 | I5: ='Demand Stage 2'!I43 -> 20 | J5: 0 | K5: 0 | L5: 0 | M5: 0 | N5: 0 | O5: 0 | P5: 0 | Q5: 0
A6: 1 | B6: ='Demand Stage 2'!B44 -> 10 | C6: ='Demand Stage 2'!C44 -> 10 | D6: ='Demand Stage 2'!D44 -> 10 | E6: ='Demand Stage 2'!E44 -> 45 | F6: ='Demand Stage 2'!F44 -> 45 | G6: ='Demand Stage 2'!G44 -> 40 | H6: ='Demand Stage 2'!H44 -> 45 | I6: ='Demand Stage 2'!I44 -> 20 | J6: 0 | K6: 0 | L6: 0 | M6: 0 | N6: 0 | O6: 0 | P6: 0 | Q6: 0
A7: 2 | B7: ='Demand Stage 2'!B45 -> 10 | C7: ='Demand Stage 2'!C45 -> 10 | D7: ='Demand Stage 2'!D45 -> 10 | E7: ='Demand Stage 2'!E45 -> 40 | F7: ='Demand Stage 2'!F45 -> 40 | G7: ='Demand Stage 2'!G45 -> 40 | H7: ='Demand Stage 2'!H45 -> 35 | I7: ='Demand Stage 2'!I45 -> 20 | J7: 0 | K7: 0 | L7: 0 | M7: 0 | N7: 0 | O7: 0 | P7: 0 | Q7: 0
A8: 3 | B8: ='Demand Stage 2'!B46 -> 10 | C8: ='Demand Stage 2'!C46 -> 10 | D8: ='Demand Stage 2'!D46 -> 10 | E8: ='Demand Stage 2'!E46 -> 45 | F8: ='Demand Stage 2'!F46 -> 45 | G8: ='Demand Stage 2'!G46 -> 40 | H8: ='Demand Stage 2'!H46 -> 40 | I8: ='Demand Stage 2'!I46 -> 20 | J8: 0 | K8: 0 | L8: 0 | M8: 0 | N8: 0 | O8: 0 | P8: 0 | Q8: 0
A9: 4
A10: 5
A11: 6
A12: 7
A13: 8
A14: 9
A15: 10
A16: 11
A17: 12
A18: 13
A19: 14
A20: 15
... A28: 23

Sheet Demand Stage 2
A1: Node Number | B1: 5 | R1: =B1+Parameters!$B$7 -> 9 | AH1: =R1+Parameters!$B$7 -> 13 | AX1: =AH1+Parameters!$B$7 -> 17
A2: Probability | B2: 0.25 | R2: =B2 -> 0.25 | AH2: =B2 -> 0.25 | AX2: =B2 -> 0.25
B3: gas or mix | J3: pure hydrogen | R3: gas or mix | Z3: pure hydrogen | AH3: gas or mix | AP3: pure hydrogen | AX3: gas or mix | BF3: pure hydrogen
A4: Hour | B4: ST.FERGUS | C4: EASINGTON | D4: TEESSIDE | E4: EMDEN | F4: DORNUM | G4: ZEEBRUGGE | H4: DUNKERQUE | I4: POLAND | J4: =B4 -> ST.FERGUS | K4: =C4 -> EASINGTON | L4: =D4 -> TEESSIDE | M4: =E4 -> EMDEN | N4: =F4 -> DORNUM | O4: =G4 -> ZEEBRUGGE | P4: =H4 -> DUNKERQUE | Q4: =I4 -> POLAND | R4: =B4 -> ST.FERGUS | S4: =C4 -> EASINGTON | T4: =D4 -> TEESSIDE | U4: =E4 -> EMDEN | V4: =F4 -> DORNUM | W4: =G4 -> ZEEBRUGGE | X4: =H4 -> DUNKERQUE | Y4: =I4 -> POLAND | ... BE4: =AO4 -> POLAND | BF4: =AQ4 -> EASINGTON | BG4: =AR4 -> TEESSIDE | BH4: =AS4 -> EMDEN | BI4: =AT4 -> DORNUM | BJ4: =AU4 -> ZEEBRUGGE | BK4: =AV4 -> DUNKERQUE | BL4: =AW4 -> POLAND | BM4: =AX4 -> ST.FERGUS
A5: 0 | B5: =B31+B43 -> 10 | C5: =C31+C43 -> 10 | D5: =D31+D43 -> 10 | E5: =E31+E43 -> 40 | F5: =F31+F43 -> 40 | G5: =G31+G43 -> 40 | H5: =H31+H43 -> 40 | I5: =I31+I43 -> 20 | J5: 0 | K5: 0 | L5: 0 | M5: 0 | N5: 0 | O5: 0 | P5: 0 | Q5: 0 | R5: =R31+B43 -> 10 | S5: =S31+C43 -> 10 | T5: =T31+D43 -> 10 | U5: =U31+E43 -> 40 | V5: =V31+F43 -> 40 | W5: =W31+G43 -> 40 | X5: =X31+H43 -> 40 | Y5: =Y31+I43 -> 20 | Z5: 0 | AA5: 0 | AB5: 0 | AC5: 0 | AD5: 0 | AE5: 0 | AF5: 0 | AG5: 0 | AH5: =AH31+B43 -> 10 | AI5: =AI31+C43 -> 10 | AJ5: =AJ31+D43 -> 10 | AK5: =AK31+E43 -> 40 | AL5: =AL31+F43 -> 40 | AM5: =AM31+G43 -> 40 | AN5: =AN31+H43 -> 40 | AO5: =AO31+I43 -> 20 | AP5: 0 | AQ5: 0 | AR5: 0 | AS5: 0 | AT5: 0 | AU5: 0 | AV5: 0 | AW5: 0 | AX5: =AX31+B43 -> 10 | AY5: =AY31+C43 -> 10 | AZ5: =AZ31+D43 -> 10 | BA5: =BA31+E43 -> 40 | BB5: =BB31+F43 -> 40 | BC5: =BC31+G43 -> 40 | BD5: =BD31+H43 -> 40 | BE5: =BE31+I43 -> 20 | BF5: 0 | BG5: 0 | BH5: 0 | BI5: 0 | BJ5: 0 | BK5: 0 | BL5: 0 | BM5: 0
A6: 1 | B6: =B32+B44 -> 10 | C6: =C32+C44 -> 10 | D6: =D32+D44 -> 10 | E6: =E32+E44 -> 50 | F6: =F32+F44 -> 50 | G6: =G32+G44 -> 40 | H6: =H32+H44 -> 50 | I6: =I32+I44 -> 20 | J6: 0 | K6: 0 | L6: 0 | M6: 0 | N6: 0 | O6: 0 | P6: 0 | Q6: 0 | R6: =R32+B44 -> 10 | S6: =S32+C44 -> 10 | T6: =T32+D44 -> 10 | U6: =U32+E44 -> 40 | V6: =V32+F44 -> 40 | W6: =W32+G44 -> 40 | X6: =X32+H44 -> 50 | Y6: =Y32+I44 -> 20 | Z6: 0 | AA6: 0 | AB6: 0 | AC6: 0 | AD6: 0 | AE6: 0 | AF6: 0 | AG6: 0 | AH6: =AH32+B44 -> 10 | AI6: =AI32+C44 -> 10 | AJ6: =AJ32+D44 -> 10 | AK6: =AK32+E44 -> 50 | AL6: =AL32+F44 -> 50 | AM6: =AM32+G44 -> 40 | AN6: =AN32+H44 -> 40 | AO6: =AO32+I44 -> 20 | AP6: =AP5*0.5 -> 0 | AQ6: =AQ5*0.5 -> 0 | AR6: =AR5*0.5 -> 0 | AS6: =AS5*0.5 -> 0 | AT6: =AT5*0.5 -> 0 | AU6: =AU5*0.5 -> 0 | AV6: =AV5*0.5 -> 0 | AW6: 0 | AX6: =AX32+B44 -> 10 | AY6: =AY32+C44 -> 10 | AZ6: =AZ32+D44 -> 10 | BA6: =BA32+E44 -> 40 | BB6: =BB32+F44 -> 40 | BC6: =BC32+G44 -> 40 | BD6: =BD32+H44 -> 40 | BE6: =BE32+I44 -> 20 | BF6: 0 | BG6: 0 | BH6: 0 | BI6: 0 | BJ6: 0 | BK6: 0 | BL6: 0 | BM6: 0
A7: 2 | B7: =B33+B45 -> 10 | C7: =C33+C45 -> 10 | D7: =D33+D45 -> 10 | E7: =E33+E45 -> 40 | F7: =F33+F45 -> 40 | G7: =G33+G45 -> 40 | H7: =H33+H45 -> 35 | I7: =I33+I45 -> 20 | J7: 0 | K7: 0 | L7: 0 | M7: 0 | N7: 0 | O7: 0 | P7: 0 | Q7: 0 | R7: =R33+B45 -> 10 | S7: =S33+C45 -> 10 | T7: =T33+D45 -> 10 | U7: =U33+E45 -> 40 | V7: =V33+F45 -> 40 | W7: =W33+G45 -> 40 | X7: =X33+H45 -> 35 | Y7: =Y33+I45 -> 20 | Z7: 0 | AA7: 0 | AB7: 0 | AC7: 0 | AD7: 0 | AE7: 0 | AF7: 0 | AG7: 0 | AH7: =AH33+B45 -> 10 | AI7: =AI33+C45 -> 10 | AJ7: =AJ33+D45 -> 10 | AK7: =AK33+E45 -> 40 | AL7: =AL33+F45 -> 40 | AM7: =AM33+G45 -> 40 | AN7: =AN33+H45 -> 35 | AO7: =AO33+I45 -> 20 | AP7: 0 | AQ7: 0 | AR7: 0 | AS7: 0 | AT7: 0 | AU7: 0 | AV7: 0 | AW7: 0 | AX7: =AX33+B45 -> 10 | AY7: =AY33+C45 -> 10 | AZ7: =AZ33+D45 -> 10 | BA7: =BA33+E45 -> 40 | BB7: =BB33+F45 -> 40 | BC7: =BC33+G45 -> 40 | BD7: =BD33+H45 -> 35 | BE7: =BE33+I45 -> 20 | BF7: 0 | BG7: 0 | BH7: 0 | BI7: 0 | BJ7: 0 | BK7: 0 | BL7: 0 | BM7: 0
A8: 3 | B8: =B34+B46 -> 10 | C8: =C34+C46 -> 10 | D8: =D34+D46 -> 10 | E8: =E34+E46 -> 50 | F8: =F34+F46 -> 50 | G8: =G34+G46 -> 40 | H8: =H34+H46 -> 45 | I8: =I34+I46 -> 20 | J8: 0 | K8: 0 | L8: 0 | M8: 0 | N8: 0 | O8: 0 | P8: 0 | Q8: 0 | R8: =R34+B46 -> 10 | S8: =S34+C46 -> 10 | T8: =T34+D46 -> 10 | U8: =U34+E46 -> 40 | V8: =V34+F46 -> 40 | W8: =W34+G46 -> 40 | X8: =X34+H46 -> 45 | Y8: =Y34+I46 -> 20 | Z8: 0 | AA8: 0 | AB8: 0 | AC8: 0 | AD8: 0 | AE8: 0 | AF8: 0 | AG8: 0 | AH8: =AH34+B46 -> 10 | AI8: =AI34+C46 -> 10 | AJ8: =AJ34+D46 -> 10 | AK8: =AK34+E46 -> 50 | AL8: =AL34+F46 -> 50 | AM8: =AM34+G46 -> 40 | AN8: =AN34+H46 -> 35 | AO8: =AO34+I46 -> 20 | AP8: 0 | AQ8: 0 | AR8: 0 | AS8: 0 | AT8: 0 | AU8: 0 | AV8: 0 | AW8: 0 | AX8: =AX34+B46 -> 10 | AY8: =AY34+C46 -> 10 | AZ8: =AZ34+D46 -> 10 | BA8: =BA34+E46 -> 40 | BB8: =BB34+F46 -> 40 | BC8: =BC34+G46 -> 40 | BD8: =BD34+H46 -> 35 | BE8: =BE34+I46 -> 20 | BF8: 0 | BG8: 0 | BH8: 0 | BI8: 0 | BJ8: 0 | BK8: 0 | BL8: 0 | BM8: 0
A9: 4
A10: 5
A11: 6
A12: 7
A13: 8
A14: 9
A15: 10
A16: 11
A17: 12
A18: 13
A19: 14
A20: 15
... A28: 23
B30: Delta
B31: 0 | C31: 0 | D31: 0 | E31: 0 | F31: 0 | G31: 0 | H31: 0 | I31: 0 | R31: 0 | S31: 0 | T31: 0 | U31: 0 | V31: 0 | W31: 0 | X31: 0 | Y31: 0 | AH31: 0 | AI31: 0 | AJ31: 0 | AK31: 0 | AL31: 0 | AM31: 0 | AN31: 0 | AO31: 0 | AX31: 0 | AY31: 0 | AZ31: 0 | BA31: 0 | BB31: 0 | BC31: 0 | BD31: 0 | BE31: 0
B32: 0 | C32: 0 | D32: 0 | E32: 5 | F32: 5 | G32: 0 | H32: 5 | I32: 0 | R32: 0 | S32: 0 | T32: 0 | U32: -5 | V32: -5 | W32: 0 | X32: 5 | Y32: 0 | AH32: 0 | AI32: 0 | AJ32: 0 | AK32: 5 | AL32: 5 | AM32: 0 | AN32: -5 | AO32: 0 | AX32: 0 | AY32: 0 | AZ32: 0 | BA32: -5 | BB32: -5 | BC32: 0 | BD32: -5 | BE32: 0
B33: 0 | C33: 0 | D33: 0 | E33: 0 | F33: 0 | G33: 0 | H33: 0 | I33: 0 | R33: 0 | S33: 0 | T33: 0 | U33: 0 | V33: 0 | W33: 0 | X33: 0 | Y33: 0 | AH33: 0 | AI33: 0 | AJ33: 0 | AK33: 0 | AL33: 0 | AM33: 0 | AN33: 0 | AO33: 0 | AX33: 0 | AY33: 0 | AZ33: 0 | BA33: 0 | BB33: 0 | BC33: 0 | BD33: 0 | BE33: 0
B34: 0 | C34: 0 | D34: 0 | E34: 5 | F34: 5 | G34: 0 | H34: 5 | I34: 0 | R34: 0 | S34: 0 | T34: 0 | U34: -5 | V34: -5 | W34: 0 | X34: 5 | Y34: 0 | AH34: 0 | AI34: 0 | AJ34: 0 | AK34: 5 | AL34: 5 | AM34: 0 | AN34: -5 | AO34: 0 | AX34: 0 | AY34: 0 | AZ34: 0 | BA34: -5 | BB34: -5 | BC34: 0 | BD34: -5 | BE34: 0
H41: Sum Probabilities | I41: =SUM(B2:BM2) -> 1
B42: Basis
B43: 10 | C43: 10 | D43: 10 | E43: 40 | F43: 40 | G43: 40 | H43: 40 | I43: 20 | K43: =SUM(B43:I43) -> 210
B44: 10 | C44: 10 | D44: 10 | E44: 45 | F44: 45 | G44: 40 | H44: 45 | I44: 20 | K44: =SUM(B44:I44) -> 225
B45: 10 | C45: 10 | D45: 10 | E45: 40 | F45: 40 | G45: 40 | H45: 35 | I45: 20 | K45: =SUM(B45:I45) -> 205
B46: 10 | C46: 10 | D46: 10 | E46: 45 | F46: 45 | G46: 40 | H46: 40 | I46: 20 | K46: =SUM(B46:I46) -> 220
B49: Data Ruud
B50: UKD | C50: DEU | D50: BEL | E50: FRA | F50: DK
B51: 30 | C51: 80 | D51: 40 | E51: 40
B52: 30 | C52: 90 | D52: 40 | E52: 45
B53: 30 | C53: 80 | D53: 40 | E53: 35
B54: 30 | C54: 90 | D54: 40 | E54: 40

Sheet Demand Stage 3
A1: Node Number | B1: 21 | R1: =B1+Parameters!$B$7 -> 25 | AH1: =R1+Parameters!$B$7 -> 29 | AX1: =AH1+Parameters!$B$7 -> 33 | BN1: =AX1+Parameters!$B$7 -> 37 | CD1: =BN1+Parameters!$B$7 -> 41 | CT1: =CD1+Parameters!$B$7 -> 45 | DJ1: =CT1+Parameters!$B$7 -> 49 | DZ1: =DJ1+Parameters!$B$7 -> 53 | EP1: =DZ1+Parameters!$B$7 -> 57 | FF1: =EP1+Parameters!$B$7 -> 61 | FV1: =FF1+Parameters!$B$7 -> 65 | GL1: =FV1+Parameters!$B$7 -> 69 | HB1: =GL1+Parameters!$B$7 -> 73 | HR1: =HB1+Parameters!$B$7 -> 77 | IH1: =HR1+Parameters!$B$7 -> 81
A2: Probability | B2: =1/16 -> 0.0625 | R2: =B2 -> 0.0625 | AH2: =R2 -> 0.0625 | AX2: =AH2 -> 0.0625 | BN2: =AX2 -> 0.0625 | CD2: =BN2 -> 0.0625 | CT2: =CD2 -> 0.0625 | DJ2: =CT2 -> 0.0625 | DZ2: =DJ2 -> 0.0625 | EP2: =DZ2 -> 0.0625 | FF2: =EP2 -> 0.0625 | FV2: =FF2 -> 0.0625 | GL2: =FV2 -> 0.0625 | HB2: =GL2 -> 0.0625 | HR2: =HB2 -> 0.0625 | IH2: =HR2 -> 0.0625
A3: Parent Node Number | B3: 5 | R3: 5 | AH3: 5 | AX3: 5 | BN3: 9 | CD3: 9 | CT3: 9 | DJ3: 9 | DZ3: 13 | EP3: 13 | FF3: 13 | FV3: 13 | GL3: 17 | HB3: 17 | HR3: 17 | IH3: 17
B4: gas or mix | J4: pure hydrogen | R4: gas or mix | Z4: pure hydrogen | AH4: gas or mix | AP4: pure hydrogen | AX4: gas or mix | BF4: pure hydrogen | BN4: gas or mix | BV4: pure hydrogen | CD4: gas or mix | CL4: pure hydrogen | CT4: gas or mix | DB4: pure hydrogen | DJ4: gas or mix | DR4: pure hydrogen | DZ4: gas or mix | EH4: pure hydrogen | EP4: gas or mix | EX4: pure hydrogen | FF4: gas or mix | FN4: pure hydrogen | FV4: gas or mix | GD4: pure hydrogen | GL4: gas or mix | GT4: pure hydrogen | HB4: gas or mix | HJ4: pure hydrogen | HR4: gas or mix | HZ4: pure hydrogen | IH4: gas or mix | IP4: pure hydrogen
A5: Hour | B5: ='Demand Stage 2'!B4 -> ST.FERGUS | C5: ='Demand Stage 2'!C4 -> EASINGTON | D5: ='Demand Stage 2'!D4 -> TEESSIDE | E5: ='Demand Stage 2'!E4 -> EMDEN | F5: ='Demand Stage 2'!F4 -> DORNUM | G5: ='Demand Stage 2'!G4 -> ZEEBRUGGE | H5: ='Demand Stage 2'!H4 -> DUNKERQUE | I5: ='Demand Stage 2'!I4 -> POLAND | ... Q5: ='Demand Stage 2'!Q4 -> POLAND | R5: ='Demand Stage 2'!B4 -> ST.FERGUS | S5: ='Demand Stage 2'!C4 -> EASINGTON | T5: ='Demand Stage 2'!D4 -> TEESSIDE | U5: ='Demand Stage 2'!E4 -> EMDEN | V5: ='Demand Stage 2'!F4 -> DORNUM | W5: ='Demand Stage 2'!G4 -> ZEEBRUGGE | X5: ='Demand Stage 2'!H4 -> DUNKERQUE | Y5: ='Demand Stage 2'!I4 -> POLAND | ... AG5: ='Demand Stage 2'!Q4 -> POLAND | AH5: ='Demand Stage 2'!B4 -> ST.FERGUS | AI5: ='Demand Stage 2'!C4 -> EASINGTON | AJ5: ='Demand Stage 2'!D4 -> TEESSIDE | AK5: ='Demand Stage 2'!E4 -> EMDEN | AL5: ='Demand Stage 2'!F4 -> DORNUM | AM5: ='Demand Stage 2'!G4 -> ZEEBRUGGE | AN5: ='Demand Stage 2'!H4 -> DUNKERQUE | AO5: ='Demand Stage 2'!I4 -> POLAND | ... AW5: ='Demand Stage 2'!Q4 -> POLAND | AX5: ='Demand Stage 2'!B4 -> ST.FERGUS | AY5: ='Demand Stage 2'!C4 -> EASINGTON | AZ5: ='Demand Stage 2'!D4 -> TEESSIDE | BA5: ='Demand Stage 2'!E4 -> EMDEN | BB5: ='Demand Stage 2'!F4 -> DORNUM | BC5: ='Demand Stage 2'!G4 -> ZEEBRUGGE | BD5: ='Demand Stage 2'!H4 -> DUNKERQUE | BE5: ='Demand Stage 2'!I4 -> POLAND | ... CC5: ='Demand Stage 2'!AG4 -> POLAND | CD5: =BN5 -> ST.FERGUS | CE5: =BO5 -> EASINGTON | CF5: =BP5 -> TEESSIDE | CG5: =BQ5 -> EMDEN | CH5: =BR5 -> DORNUM | CI5: =BS5 -> ZEEBRUGGE | CJ5: =BT5 -> DUNKERQUE | CK5: =BU5 -> POLAND | ... DY5: =DI5 -> POLAND | DZ5: ='Demand Stage 2'!AH4 -> ST.FERGUS | EA5: ='Demand Stage 2'!AI4 -> EASINGTON | EB5: ='Demand Stage 2'!AJ4 -> TEESSIDE | EC5: ='Demand Stage 2'!AK4 -> EMDEN | ED5: ='Demand Stage 2'!AL4 -> DORNUM | EE5: ='Demand Stage 2'!AM4 -> ZEEBRUGGE | EF5: ='Demand Stage 2'!AN4 -> DUNKERQUE | EG5: ='Demand Stage 2'!AO4 -> POLAND | ... EO5: ='Demand Stage 2'!AW4 -> POLAND | EP5: =DZ5 -> ST.FERGUS | EQ5: =EA5 -> EASINGTON | ER5: =EB5 -> TEESSIDE | ES5: =EC5 -> EMDEN | ET5: =ED5 -> DORNUM | EU5: =EE5 -> ZEEBRUGGE | EV5: =EF5 -> DUNKERQUE | EW5: =EG5 -> POLAND | ... GK5: =FU5 -> POLAND | GL5: ='Demand Stage 2'!AX4 -> ST.FERGUS | GM5: ='Demand Stage 2'!AY4 -> EASINGTON | GN5: ='Demand Stage 2'!AZ4 -> TEESSIDE | GO5: ='Demand Stage 2'!BA4 -> EMDEN | GP5: ='Demand Stage 2'!BB4 -> DORNUM | GQ5: ='Demand Stage 2'!BC4 -> ZEEBRUGGE | GR5: ='Demand Stage 2'!BD4 -> DUNKERQUE | GS5: ='Demand Stage 2'!BE4 -> POLAND | ... HA5: ='Demand Stage 2'!BM4 -> ST.FERGUS | HB5: =GL5 -> ST.FERGUS | HC5: =GM5 -> EASINGTON | HD5: =GN5 -> TEESSIDE | HE5: =GO5 -> EMDEN | HF5: =GP5 -> DORNUM | HG5: =GQ5 -> ZEEBRUGGE | HH5: =GR5 -> DUNKERQUE | HI5: =GS5 -> POLAND | ... IW5: =IG5 -> ST.FERGUS
A6: 0 | B6: ='Demand Stage 2'!B5 -> 10 | C6: ='Demand Stage 2'!C5 -> 10 | D6: ='Demand Stage 2'!D5 -> 10 | E6: ='Demand Stage 2'!E5 -> 40 | F6: ='Demand Stage 2'!F5 -> 40 | G6: ='Demand Stage 2'!G5 -> 40 | H6: ='Demand Stage 2'!H5 -> 40 | I6: ='Demand Stage 2'!I5 -> 20 | ... Q6: ='Demand Stage 2'!Q5 -> 0 | R6: ='Demand Stage 2'!B5 -> 10 | S6: ='Demand Stage 2'!C5 -> 10 | T6: ='Demand Stage 2'!D5 -> 10 | U6: ='Demand Stage 2'!E5 -> 40 | V6: ='Demand Stage 2'!F5 -> 40 | W6: ='Demand Stage 2'!G5 -> 40 | X6: ='Demand Stage 2'!H5 -> 40 | Y6: ='Demand Stage 2'!I5 -> 20 | ... AG6: ='Demand Stage 2'!Q5 -> 0 | AH6: ='Demand Stage 2'!B5 -> 10 | AI6: ='Demand Stage 2'!C5 -> 10 | AJ6: ='Demand Stage 2'!D5 -> 10 | AK6: ='Demand Stage 2'!E5 -> 40 | AL6: ='Demand Stage 2'!F5 -> 40 | AM6: ='Demand Stage 2'!G5 -> 40 | AN6: ='Demand Stage 2'!H5 -> 40 | AO6: ='Demand Stage 2'!I5 -> 20 | ... AW6: ='Demand Stage 2'!Q5 -> 0 | AX6: ='Demand Stage 2'!B5 -> 10 | AY6: ='Demand Stage 2'!C5 -> 10 | AZ6: ='Demand Stage 2'!D5 -> 10 | BA6: ='Demand Stage 2'!E5 -> 40 | BB6: ='Demand Stage 2'!F5 -> 40 | BC6: ='Demand Stage 2'!G5 -> 40 | BD6: ='Demand Stage 2'!H5 -> 40 | BE6: ='Demand Stage 2'!I5 -> 20 | ... CC6: ='Demand Stage 2'!AG5 -> 0 | CD6: =BN6 -> 10 | CE6: =BO6 -> 10 | CF6: =BP6 -> 10 | CG6: =BQ6 -> 40 | CH6: =BR6 -> 40 | CI6: =BS6 -> 40 | CJ6: =BT6 -> 40 | CK6: =BU6 -> 20 | ... DY6: =DI6 -> 0 | DZ6: ='Demand Stage 2'!AH5 -> 10 | EA6: ='Demand Stage 2'!AI5 -> 10 | EB6: ='Demand Stage 2'!AJ5 -> 10 | EC6: ='Demand Stage 2'!AK5 -> 40 | ED6: ='Demand Stage 2'!AL5 -> 40 | EE6: ='Demand Stage 2'!AM5 -> 40 | EF6: ='Demand Stage 2'!AN5 -> 40 | EG6: ='Demand Stage 2'!AO5 -> 20 | ... EO6: ='Demand Stage 2'!AW5 -> 0 | EP6: =DZ6 -> 10 | EQ6: =EA6 -> 10 | ER6: =EB6 -> 10 | ES6: =EC6 -> 40 | ET6: =ED6 -> 40 | EU6: =EE6 -> 40 | EV6: =EF6 -> 40 | EW6: =EG6 -> 20 | ... GK6: =FU6 -> 0 | GL6: ='Demand Stage 2'!AX5 -> 10 | GM6: ='Demand Stage 2'!AY5 -> 10 | GN6: ='Demand Stage 2'!AZ5 -> 10 | GO6: ='Demand Stage 2'!BA5 -> 40 | GP6: ='Demand Stage 2'!BB5 -> 40 | GQ6: ='Demand Stage 2'!BC5 -> 40 | GR6: ='Demand Stage 2'!BD5 -> 40 | GS6: ='Demand Stage 2'!BE5 -> 20 | ... HA6: ='Demand Stage 2'!BM5 -> 0 | HB6: =GL6 -> 10 | HC6: =GM6 -> 10 | HD6: =GN6 -> 10 | HE6: =GO6 -> 40 | HF6: =GP6 -> 40 | HG6: =GQ6 -> 40 | HH6: =GR6 -> 40 | HI6: =GS6 -> 20 | ... IW6: =IG6 -> 0
A7: 1 | B7: ='Demand Stage 2'!B6 -> 10 | C7: ='Demand Stage 2'!C6 -> 10 | D7: ='Demand Stage 2'!D6 -> 10 | E7: ='Demand Stage 2'!E6 -> 50 | F7: ='Demand Stage 2'!F6 -> 50 | G7: ='Demand Stage 2'!G6 -> 40 | H7: ='Demand Stage 2'!H6 -> 50 | I7: ='Demand Stage 2'!I6 -> 20 | ... Q7: ='Demand Stage 2'!Q6 -> 0 | R7: ='Demand Stage 2'!B6 -> 10 | S7: ='Demand Stage 2'!C6 -> 10 | T7: ='Demand Stage 2'!D6 -> 10 | U7: ='Demand Stage 2'!E6 -> 50 | V7: ='Demand Stage 2'!F6 -> 50 | W7: ='Demand Stage 2'!G6 -> 40 | X7: ='Demand Stage 2'!H6 -> 50 | Y7: ='Demand Stage 2'!I6 -> 20 | ... AG7: ='Demand Stage 2'!Q6 -> 0 | AH7: ='Demand Stage 2'!B6 -> 10 | AI7: ='Demand Stage 2'!C6 -> 10 | AJ7: ='Demand Stage 2'!D6 -> 10 | AK7: ='Demand Stage 2'!E6 -> 50 | AL7: ='Demand Stage 2'!F6 -> 50 | AM7: ='Demand Stage 2'!G6 -> 40 | AN7: ='Demand Stage 2'!H6 -> 50 | AO7: ='Demand Stage 2'!I6 -> 20 | ... AW7: ='Demand Stage 2'!Q6 -> 0 | AX7: ='Demand Stage 2'!B6 -> 10 | AY7: ='Demand Stage 2'!C6 -> 10 | AZ7: ='Demand Stage 2'!D6 -> 10 | BA7: ='Demand Stage 2'!E6 -> 50 | BB7: ='Demand Stage 2'!F6 -> 50 | BC7: ='Demand Stage 2'!G6 -> 40 | BD7: ='Demand Stage 2'!H6 -> 50 | BE7: ='Demand Stage 2'!I6 -> 20 | ... CC7: ='Demand Stage 2'!AG6 -> 0 | CD7: =BN7 -> 10 | CE7: =BO7 -> 10 | CF7: =BP7 -> 10 | CG7: =BQ7 -> 40 | CH7: =BR7 -> 40 | CI7: =BS7 -> 40 | CJ7: =BT7 -> 50 | CK7: =BU7 -> 20 | ... DY7: =DI7 -> 0 | DZ7: ='Demand Stage 2'!AH6 -> 10 | EA7: ='Demand Stage 2'!AI6 -> 10 | EB7: ='Demand Stage 2'!AJ6 -> 10 | EC7: ='Demand Stage 2'!AK6 -> 50 | ED7: ='Demand Stage 2'!AL6 -> 50 | EE7: ='Demand Stage 2'!AM6 -> 40 | EF7: ='Demand Stage 2'!AN6 -> 40 | EG7: ='Demand Stage 2'!AO6 -> 20 | ... EO7: ='Demand Stage 2'!AW6 -> 0 | EP7: =DZ7 -> 10 | EQ7: =EA7 -> 10 | ER7: =EB7 -> 10 | ES7: =EC7 -> 50 | ET7: =ED7 -> 50 | EU7: =EE7 -> 40 | EV7: =EF7 -> 40 | EW7: =EG7 -> 20 | ... GK7: =FU7 -> 0 | GL7: ='Demand Stage 2'!AX6 -> 10 | GM7: ='Demand Stage 2'!AY6 -> 10 | GN7: ='Demand Stage 2'!AZ6 -> 10 | GO7: ='Demand Stage 2'!BA6 -> 40 | GP7: ='Demand Stage 2'!BB6 -> 40 | GQ7: ='Demand Stage 2'!BC6 -> 40 | GR7: ='Demand Stage 2'!BD6 -> 40 | GS7: ='Demand Stage 2'!BE6 -> 20 | ... HA7: ='Demand Stage 2'!BM6 -> 0 | HB7: =GL7 -> 10 | HC7: =GM7 -> 10 | HD7: =GN7 -> 10 | HE7: =GO7 -> 40 | HF7: =GP7 -> 40 | HG7: =GQ7 -> 40 | HH7: =GR7 -> 40 | HI7: =GS7 -> 20 | ... IW7: =IG7 -> 0
A8: 2 | B8: ='Demand Stage 2'!B7 -> 10 | C8: ='Demand Stage 2'!C7 -> 10 | D8: ='Demand Stage 2'!D7 -> 10 | E8: ='Demand Stage 2'!E7 -> 40 | F8: ='Demand Stage 2'!F7 -> 40 | G8: ='Demand Stage 2'!G7 -> 40 | H8: ='Demand Stage 2'!H7 -> 35 | I8: ='Demand Stage 2'!I7 -> 20 | ... Q8: ='Demand Stage 2'!Q7 -> 0 | R8: ='Demand Stage 2'!B7 -> 10 | S8: ='Demand Stage 2'!C7 -> 10 | T8: ='Demand Stage 2'!D7 -> 10 | U8: ='Demand Stage 2'!E7 -> 40 | V8: ='Demand Stage 2'!F7 -> 40 | W8: ='Demand Stage 2'!G7 -> 40 | X8: ='Demand Stage 2'!H7 -> 35 | Y8: ='Demand Stage 2'!I7 -> 20 | ... AG8: ='Demand Stage 2'!Q7 -> 0 | AH8: ='Demand Stage 2'!B7 -> 10 | AI8: ='Demand Stage 2'!C7 -> 10 | AJ8: ='Demand Stage 2'!D7 -> 10 | AK8: ='Demand Stage 2'!E7 -> 40 | AL8: ='Demand Stage 2'!F7 -> 40 | AM8: ='Demand Stage 2'!G7 -> 40 | AN8: ='Demand Stage 2'!H7 -> 35 | AO8: ='Demand Stage 2'!I7 -> 20 | ... AW8: ='Demand Stage 2'!Q7 -> 0 | AX8: ='Demand Stage 2'!B7 -> 10 | AY8: ='Demand Stage 2'!C7 -> 10 | AZ8: ='Demand Stage 2'!D7 -> 10 | BA8: ='Demand Stage 2'!E7 -> 40 | BB8: ='Demand Stage 2'!F7 -> 40 | BC8: ='Demand Stage 2'!G7 -> 40 | BD8: ='Demand Stage 2'!H7 -> 35 | BE8: ='Demand Stage 2'!I7 -> 20 | ... CC8: ='Demand Stage 2'!AG7 -> 0 | CD8: =BN8 -> 10 | CE8: =BO8 -> 10 | CF8: =BP8 -> 10 | CG8: =BQ8 -> 40 | CH8: =BR8 -> 40 | CI8: =BS8 -> 40 | CJ8: =BT8 -> 35 | CK8: =BU8 -> 20 | ... DY8: =DI8 -> 0 | DZ8: ='Demand Stage 2'!AH7 -> 10 | EA8: ='Demand Stage 2'!AI7 -> 10 | EB8: ='Demand Stage 2'!AJ7 -> 10 | EC8: ='Demand Stage 2'!AK7 -> 40 | ED8: ='Demand Stage 2'!AL7 -> 40 | EE8: ='Demand Stage 2'!AM7 -> 40 | EF8: ='Demand Stage 2'!AN7 -> 35 | EG8: ='Demand Stage 2'!AO7 -> 20 | ... EO8: ='Demand Stage 2'!AW7 -> 0 | EP8: =DZ8 -> 10 | EQ8: =EA8 -> 10 | ER8: =EB8 -> 10 | ES8: =EC8 -> 40 | ET8: =ED8 -> 40 | EU8: =EE8 -> 40 | EV8: =EF8 -> 35 | EW8: =EG8 -> 20 | ... GK8: =FU8 -> 0 | GL8: ='Demand Stage 2'!AX7 -> 10 | GM8: ='Demand Stage 2'!AY7 -> 10 | GN8: ='Demand Stage 2'!AZ7 -> 10 | GO8: ='Demand Stage 2'!BA7 -> 40 | GP8: ='Demand Stage 2'!BB7 -> 40 | GQ8: ='Demand Stage 2'!BC7 -> 40 | GR8: ='Demand Stage 2'!BD7 -> 35 | GS8: ='Demand Stage 2'!BE7 -> 20 | ... HA8: ='Demand Stage 2'!BM7 -> 0 | HB8: =GL8 -> 10 | HC8: =GM8 -> 10 | HD8: =GN8 -> 10 | HE8: =GO8 -> 40 | HF8: =GP8 -> 40 | HG8: =GQ8 -> 40 | HH8: =GR8 -> 35 | HI8: =GS8 -> 20 | ... IW8: =IG8 -> 0
A9: 3 | B9: ='Demand Stage 2'!B8 -> 10 | C9: ='Demand Stage 2'!C8 -> 10 | D9: ='Demand Stage 2'!D8 -> 10 | E9: ='Demand Stage 2'!E8 -> 50 | F9: ='Demand Stage 2'!F8 -> 50 | G9: ='Demand Stage 2'!G8 -> 40 | H9: ='Demand Stage 2'!H8 -> 45 | I9: ='Demand Stage 2'!I8 -> 20 | ... Q9: ='Demand Stage 2'!Q8 -> 0 | R9: ='Demand Stage 2'!B8 -> 10 | S9: ='Demand Stage 2'!C8 -> 10 | T9: ='Demand Stage 2'!D8 -> 10 | U9: ='Demand Stage 2'!E8 -> 50 | V9: ='Demand Stage 2'!F8 -> 50 | W9: ='Demand Stage 2'!G8 -> 40 | X9: ='Demand Stage 2'!H8 -> 45 | Y9: ='Demand Stage 2'!I8 -> 20 | ... AG9: ='Demand Stage 2'!Q8 -> 0 | AH9: ='Demand Stage 2'!B8 -> 10 | AI9: ='Demand Stage 2'!C8 -> 10 | AJ9: ='Demand Stage 2'!D8 -> 10 | AK9: ='Demand Stage 2'!E8 -> 50 | AL9: ='Demand Stage 2'!F8 -> 50 | AM9: ='Demand Stage 2'!G8 -> 40 | AN9: ='Demand Stage 2'!H8 -> 45 | AO9: ='Demand Stage 2'!I8 -> 20 | ... AW9: ='Demand Stage 2'!Q8 -> 0 | AX9: ='Demand Stage 2'!B8 -> 10 | AY9: ='Demand Stage 2'!C8 -> 10 | AZ9: ='Demand Stage 2'!D8 -> 10 | BA9: ='Demand Stage 2'!E8 -> 50 | BB9: ='Demand Stage 2'!F8 -> 50 | BC9: ='Demand Stage 2'!G8 -> 40 | BD9: ='Demand Stage 2'!H8 -> 45 | BE9: ='Demand Stage 2'!I8 -> 20 | ... CC9: ='Demand Stage 2'!AG8 -> 0 | CD9: =BN9 -> 10 | CE9: =BO9 -> 10 | CF9: =BP9 -> 10 | CG9: =BQ9 -> 40 | CH9: =BR9 -> 40 | CI9: =BS9 -> 40 | CJ9: =BT9 -> 45 | CK9: =BU9 -> 20 | ... DY9: =DI9 -> 0 | DZ9: ='Demand Stage 2'!AH8 -> 10 | EA9: ='Demand Stage 2'!AI8 -> 10 | EB9: ='Demand Stage 2'!AJ8 -> 10 | EC9: ='Demand Stage 2'!AK8 -> 50 | ED9: ='Demand Stage 2'!AL8 -> 50 | EE9: ='Demand Stage 2'!AM8 -> 40 | EF9: ='Demand Stage 2'!AN8 -> 35 | EG9: ='Demand Stage 2'!AO8 -> 20 | ... EO9: ='Demand Stage 2'!AW8 -> 0 | EP9: =DZ9 -> 10 | EQ9: =EA9 -> 10 | ER9: =EB9 -> 10 | ES9: =EC9 -> 50 | ET9: =ED9 -> 50 | EU9: =EE9 -> 40 | EV9: =EF9 -> 35 | EW9: =EG9 -> 20 | ... GK9: =FU9 -> 0 | GL9: ='Demand Stage 2'!AX8 -> 10 | GM9: ='Demand Stage 2'!AY8 -> 10 | GN9: ='Demand Stage 2'!AZ8 -> 10 | GO9: ='Demand Stage 2'!BA8 -> 40 | GP9: ='Demand Stage 2'!BB8 -> 40 | GQ9: ='Demand Stage 2'!BC8 -> 40 | GR9: ='Demand Stage 2'!BD8 -> 35 | GS9: ='Demand Stage 2'!BE8 -> 20 | ... HA9: ='Demand Stage 2'!BM8 -> 0 | HB9: =GL9 -> 10 | HC9: =GM9 -> 10 | HD9: =GN9 -> 10 | HE9: =GO9 -> 40 | HF9: =GP9 -> 40 | HG9: =GQ9 -> 40 | HH9: =GR9 -> 35 | HI9: =GS9 -> 20 | ... IW9: =IG9 -> 0
A10: 4
A11: 5
A12: 6
A13: 7
A14: 8
A15: 9
A16: 10
A17: 11
A18: 12
A19: 13
A20: 14
A21: 15
... A29: 23
B33: Sum Probabilities | C33: =SUM(B2:IW2) -> 1

Sheet SalesPriceGasMix
A1: Hour | B1: ST.FERGUS | C1: EASINGTON | D1: TEESSIDE | E1: EMDEN | F1: DORNUM | G1: ZEEBRUGGE | H1: DUNKERQUE | I1: POLAND | K1: Gemiddelde
A2: 1 | B2: 26 | C2: 26 | D2: 26 | E2: 28 | F2: 28 | G2: 29 | H2: 30 | I2: 30 | K2: =AVERAGE(B2:I2) -> 27.875
A3: 2 | B3: 28 | C3: 28 | D3: 28 | E3: 30 | F3: 30 | G3: 31 | H3: 32 | I3: 30 | K3: =AVERAGE(B3:I3) -> 29.625
A4: 3 | B4: 27 | C4: 27 | D4: 27 | E4: 29 | F4: 29 | G4: 30 | H4: 31 | I4: 30 | K4: =AVERAGE(B4:I4) -> 28.75
A5: 4 | B5: 29 | C5: 29 | D5: 29 | E5: 31 | F5: 31 | G5: 32 | H5: 33 | I5: 30 | K5: =AVERAGE(B5:I5) -> 30.5

Sheet SalesPricePureHydrogen
A1: Hour | B1: ST.FERGUS | C1: EASINGTON | D1: TEESSIDE | E1: EMDEN | F1: EMDEN 2 | G1: ZEEBRUGGE | H1: DUNKERQUE | I1: POLAND
A2: 1 | B2: 1 | C2: 1 | D2: 1 | E2: 1 | F2: 1 | G2: 1 | H2: 1 | I2: 1
A3: 2 | B3: 1 | C3: 1 | D3: 1 | E3: 1 | F3: 1 | G3: 1 | H3: 1 | I3: 1
A4: 3 | B4: 1 | C4: 1 | D4: 1 | E4: 1 | F4: 1 | G4: 1 | H4: 1 | I4: 1
A5: 4 | B5: 1 | C5: 1 | D5: 1 | E5: 1 | F5: 1 | G5: 1 | H5: 1 | I5: 1

Sheet Parameters
A1: Name | B1: Value
A2: Loss rate | B2: 0
A3: Allowed percentage Stage 1 | B3: 1
A4: Allowed percentage Stage 2 | B4: 1
A5: Allowed percentage Stage 3 | B5: 1
A6: Gamma | B6: 0.25
A7: Number hours | B7: 4
A8: Stage 2 nodes | B8: 4
A9: Stage 3 nodes | B9: 16
A10: Number markets | B10: 8
A11: Number shippers | B11: 8

Sheet Arcs
A1: ID | B1: Name | C1: curOperNam | D1: curPhase | E1: curPhDate | F1: Source | G1: Sink | H1: geometry | I1: Capacity | J1: Note | K1: Source_ID | L1: Sink_ID | M1: Flow costs Gas | N1: Flow costs Hydrogen | O1: Coordinate Source | P1: Coordinate Sink | Q1: Coordinate Middle
A2: 1 | B2: Statpipe | C2: OKEA ASA | D2: IN SERVICE | E2: 1993-09-23 | F2: BRAGE | G2: BRAGE-T | H2: ="LINESTRING(" & O2 & "," & Q2 & "," & P2 & ")" -> LINESTRING(2.89805500000006 60.5606330000001,2.96794024746388 60.5519809989487,3.0378254949277 60.5433289978974) | I2: 48.1 | J2: =IF(I2=100,"Capacity unknown","") | K2: =INDEX(Nodes!$A:$A,MATCH(Arcs!F2,Nodes!$B:$B,0)) -> 6 | L2: =INDEX(Nodes!$A:$A,MATCH(Arcs!G2,Nodes!$B:$B,0)) -> 7 | M2: 1 | N2: 0.2 | O2: {=SUBSTITUTE(INDEX(Nodes!$A$3:$E$64,Arcs!K2,4) & " " & INDEX(Nodes!$A$3:$E$64,Arcs!K2,5), ",",".")} -> 2.89805500000006 60.5606330000001 | P2: {=SUBSTITUTE(INDEX(Nodes!$A$3:$E$64,Arcs!L2,4) & " " & INDEX(Nodes!$A$3:$E$64,Arcs!L2,5), ",",".")} -> 3.0378254949277 60.5433289978974 | Q2: =SUBSTITUTE(AVERAGE(INDEX(Nodes!$A$3:$E$64,Arcs!K2,4), INDEX(Nodes!$A$3:$E$64,Arcs!L2,4)) & " " & AVERAGE(INDEX(Nodes!$A$3:$E$64,Arcs!K2,5), INDEX(Nodes!$A$3:$E$64,Arcs!L2,5)), ",", ".") -> 2.96794024746388 60.5519809989487
A3: 2 | B3: Draugen Gasseksport | C3: OKEA ASA | D3: IN SERVICE | E3: 2000-10-10 | F3: DRAUGEN | G3: DRAUGEN T | H3: ="LINESTRING(" & O3 & "," & Q3 & "," & P3 & ")" -> LINESTRING(6.44125800000006 64.233255,7.11614205264601 64.2919112956052,7.79102610529196 64.3505675912103) | I3: 5 | J3: =IF(I3=100,"Capacity unknown","") | K3: =INDEX(Nodes!$A:$A,MATCH(Arcs!F3,Nodes!$B:$B,0)) -> 13 | L3: =INDEX(Nodes!$A:$A,MATCH(Arcs!G3,Nodes!$B:$B,0)) -> 14 | M3: 1 | N3: 0.2 | O3: {=SUBSTITUTE(INDEX(Nodes!$A$3:$E$64,Arcs!K3,4) & " " & INDEX(Nodes!$A$3:$E$64,Arcs!K3,5), ",",".")} -> 6.44125800000006 64.233255 | P3: {=SUBSTITUTE(INDEX(Nodes!$A$3:$E$64,Arcs!L3,4) & " " & INDEX(Nodes!$A$3:$E$64,Arcs!L3,5), ",",".")} -> 7.79102610529196 64.3505675912103 | Q3: =SUBSTITUTE(AVERAGE(INDEX(Nodes!$A$3:$E$64,Arcs!K3,4), INDEX(Nodes!$A$3:$E$64,Arcs!L3,4)) & " " & AVERAGE(INDEX(Nodes!$A$3:$E$64,Arcs!K3,5), INDEX(Nodes!$A$3:$E$64,Arcs!L3,5)), ",", ".") -> 7.11614205264601 64.2919112956052
A4: 3 | B4: Asgard Transport | C4: Gassco AS | D4: IN SERVICE | E4: 2000-10-04 | F4: aSGARD ERB | G4: KaRSTo | H4: ="LINESTRING(" & O4 & "," & Q4 & "," & P4 & ")" -> LINESTRING(4.68854112718991 62.3027286385494,5.10073123031673 60.7874221331929,5.51292133344356 59.2721156278364) | I4: 70 | J4: =IF(I4=100,"Capacity unknown","") | K4: =INDEX(Nodes!$A:$A,MATCH(Arcs!F4,Nodes!$B:$B,0)) -> 2 | L4: =INDEX(Nodes!$A:$A,MATCH(Arcs!G4,Nodes!$B:$B,0)) -> 36 | M4: 1 | N4: 0.2 | O4: {=SUBSTITUTE(INDEX(Nodes!$A$3:$E$64,Arcs!K4,4) & " " & INDEX(Nodes!$A$3:$E$64,Arcs!K4,5), ",",".")} -> 4.68854112718991 62.3027286385494 | P4: {=SUBSTITUTE(INDEX(Nodes!$A$3:$E$64,Arcs!L4,4) & " " & INDEX(Nodes!$A$3:$E$64,Arcs!L4,5), ",",".")} -> 5.51292133344356 59.2721156278364 | Q4: =SUBSTITUTE(AVERAGE(INDEX(Nodes!$A$3:$E$64,Arcs!K4,4), INDEX(Nodes!$A$3:$E$64,Arcs!L4,4)) & " " & AVERAGE(INDEX(Nodes!$A$3:$E$64,Arcs!K4,5), INDEX(Nodes!$A$3:$E$64,Arcs!L4,5)), ",", ".") -> 5.10073123031673 60.7874221331929
A5: 4 | B5: Europipe I | C5: Gassco AS | D5: IN SERVICE | E5: 1995-10-01 | F5: DRAUPNER E | G5: EUROPIPE-SCP | H5: ="LINESTRING(" & O5 & "," & Q5 & "," & P5 & ")" -> LINESTRING(2.46440416605363 58.1881490174125,3.34351308302685 56.9475590087063,4.22262200000006 55.7069690000001) | I5: 45.7 | J5: =IF(I5=100,"Capacity unknown","") | K5: =INDEX(Nodes!$A:$A,MATCH(Arcs!F5,Nodes!$B:$B,0)) -> 15 | L5: =INDEX(Nodes!$A:$A,MATCH(Arcs!G5,Nodes!$B:$B,0)) -> 23 | M5: 1 | N5: 0.2 | O5: {=SUBSTITUTE(INDEX(Nodes!$A$3:$E$64,Arcs!K5,4) & " " & INDEX(Nodes!$A$3:$E$64,Arcs!K5,5), ",",".")} -> 2.46440416605363 58.1881490174125 | P5: {=SUBSTITUTE(INDEX(Nodes!$A$3:$E$64,Arcs!L5,4) & " " & INDEX(Nodes!$A$3:$E$64,Arcs!L5,5), ",",".")} -> 4.22262200000006 55.7069690000001 | Q5: =SUBSTITUTE(AVERAGE(INDEX(Nodes!$A$3:$E$64,Arcs!K5,4), INDEX(Nodes!$A$3:$E$64,Arcs!L5,4)) & " " & AVERAGE(INDEX(Nodes!$A$3:$E$64,Arcs!K5,5), INDEX(Nodes!$A$3:$E$64,Arcs!L5,5)), ",", ".") -> 3.34351308302685 56.9475590087063
A6: 5 | B6: Europipe I | C6: Gassco AS | D6: IN SERVICE | E6: 1995-10-01 | F6: EUROPIPE-SCP | G6: DORNUM | H6: ="LINESTRING(" & O6 & "," & Q6 & "," & P6 & ")" -> LINESTRING(4.22262200000006 55.7069690000001,5.77452100000005 54.6933345000001,7.32642000000004 53.6797000000001) | I6: 45.7 | J6: =IF(I6=100,"Capacity unknown","") | K6: =INDEX(Nodes!$A:$A,MATCH(Arcs!F6,Nodes!$B:$B,0)) -> 23 | L6: =INDEX(Nodes!$A:$A,MATCH(Arcs!G6,Nodes!$B:$B,0)) -> 21 | M6: 1 | N6: 0.2 | O6: {=SUBSTITUTE(INDEX(Nodes!$A$3:$E$64,Arcs!K6,4) & " " & INDEX(Nodes!$A$3:$E$64,Arcs!K6,5), ",",".")} -> 4.22262200000006 55.7069690000001 | P6: {=SUBSTITUTE(INDEX(Nodes!$A$3:$E$64,Arcs!L6,4) & " " & INDEX(Nodes!$A$3:$E$64,Arcs!L6,5), ",",".")} -> 7.32642000000004 53.6797000000001 | Q6: =SUBSTITUTE(AVERAGE(INDEX(Nodes!$A$3:$E$64,Arcs!K6,4), INDEX(Nodes!$A$3:$E$64,Arcs!L6,4)) & " " & AVERAGE(INDEX(Nodes!$A$3:$E$64,Arcs!K6,5), INDEX(Nodes!$A$3:$E$64,Arcs!L6,5)), ",", ".") -> 5.77452100000005 54.6933345000001
A7: 6 | B7: Europipe II-a | C7: Gassco AS | D7: IN SERVICE | E7: 1999-10-01 | F7: KaRSTo | G7: BALTIC ENTRANCE | H7: ="LINESTRING(" & O7 & "," & Q7 & "," & P7 & ")" -> LINESTRING(5.51292133344356 59.2721156278364,6.00836066672178 57.4910578139182,6.5038 55.71) | I7: 73.5 | J7: =IF(I7=100,"Capacity unknown","") | K7: =INDEX(Nodes!$A:$A,MATCH(Arcs!F7,Nodes!$B:$B,0)) -> 36 | L7: =INDEX(Nodes!$A:$A,MATCH(Arcs!G7,Nodes!$B:$B,0)) -> 5 | M7: 1 | N7: 0.2 | O7: {=SUBSTITUTE(INDEX(Nodes!$A$3:$E$64,Arcs!K7,4) & " " & INDEX(Nodes!$A$3:$E$64,Arcs!K7,5), ",",".")} -> 5.51292133344356 59.2721156278364 | P7: {=SUBSTITUTE(INDEX(Nodes!$A$3:$E$64,Arcs!L7,4) & " " & INDEX(Nodes!$A$3:$E$64,Arcs!L7,5), ",",".")} -> 6.5038 55.71 | Q7: =SUBSTITUTE(AVERAGE(INDEX(Nodes!$A$3:$E$64,Arcs!K7,4), INDEX(Nodes!$A$3:$E$64,Arcs!L7,4)) & " " & AVERAGE(INDEX(Nodes!$A$3:$E$64,Arcs!K7,5), INDEX(Nodes!$A$3:$E$64,Arcs!L7,5)), ",", ".") -> 6.00836066672178 57.4910578139182
A8: 7 | B8: Europipe II-b | C8: Gassco AS | D8: IN SERVICE | E8: 1999-10-01 | F8: BALTIC ENTRANCE | G8: DORNUM | H8: ="LINESTRING(" & O8 & "," & Q8 & "," & P8 & ")" -> LINESTRING(6.5038 55.71,6.91511000000002 54.69485,7.32642000000004 53.6797000000001) | I8: 73.5 | J8: =IF(I8=100,"Capacity unknown","") | K8: =INDEX(Nodes!$A:$A,MATCH(Arcs!F8,Nodes!$B:$B,0)) -> 5 | L8: =INDEX(Nodes!$A:$A,MATCH(Arcs!G8,Nodes!$B:$B,0)) -> 21 | M8: 1 | N8: 0.2 | O8: {=SUBSTITUTE(INDEX(Nodes!$A$3:$E$64,Arcs!K8,4) & " " & INDEX(Nodes!$A$3:$E$64,Arcs!K8,5), ",",".")} -> 6.5038 55.71 | P8: {=SUBSTITUTE(INDEX(Nodes!$A$3:$E$64,Arcs!L8,4) & " " & INDEX(Nodes!$A$3:$E$64,Arcs!L8,5), ",",".")} -> 7.32642000000004 53.6797000000001 | Q8: =SUBSTITUTE(AVERAGE(INDEX(Nodes!$A$3:$E$64,Arcs!K8,4), INDEX(Nodes!$A$3:$E$64,Arcs!L8,4)) & " " & AVERAGE(INDEX(Nodes!$A$3:$E$64,Arcs!K8,5), INDEX(Nodes!$A$3:$E$64,Arcs!L8,5)), ",", ".") -> 6.91511000000002 54.69485
A9: 8 | B9: Franpipe | C9: Gassco AS | D9: IN SERVICE | E9: 1998-07-01 | F9: DRAUPNER E | G9: DUNKERQUE | H9: ="LINESTRING(" & O9 & "," & Q9 & "," & P9 & ")" -> LINESTRING(2.46440416605363 58.1881490174125,2.35855658302684 54.6172775087063,2.25270900000004 51.046406) | I9: 54.2 | J9: =IF(I9=100,"Capacity unknown","") | K9: =INDEX(Nodes!$A:$A,MATCH(Arcs!F9,Nodes!$B:$B,0)) -> 15 | L9: =INDEX(Nodes!$A:$A,MATCH(Arcs!G9,Nodes!$B:$B,0)) -> 17 | M9: 1 | N9: 0.2 | O9: {=SUBSTITUTE(INDEX(Nodes!$A$3:$E$64,Arcs!K9,4) & " " & INDEX(Nodes!$A$3:$E$64,Arcs!K9,5), ",",".")} -> 2.46440416605363 58.1881490174125 | P9: {=SUBSTITUTE(INDEX(Nodes!$A$3:$E$64,Arcs!L9,4) & " " & INDEX(Nodes!$A$3:$E$64,Arcs!L9,5), ",",".")} -> 2.25270900000004 51.046406 | Q9: =SUBSTITUTE(AVERAGE(INDEX(Nodes!$A$3:$E$64,Arcs!K9,4), INDEX(Nodes!$A$3:$E$64,Arcs!L9,4)) & " " & AVERAGE(INDEX(Nodes!$A$3:$E$64,Arcs!K9,5), INDEX(Nodes!$A$3:$E$64,Arcs!L9,5)), ",", ".") -> 2.35855658302684 54.6172775087063
A10: 9 | B10: Kvitebjorn Gassror | C10: Gassco AS | D10: IN SERVICE | E10: 2004-09-26 | F10: KVITEBJoRN | G10: KOLLSNES | H10: ="LINESTRING(" & O10 & "," & Q10 & "," & P10 & ")" -> LINESTRING(2.50707808340931 61.0775819356338,3.67283754339515 60.8114652109992,4.838597003381 60.5453484863646) | I10: 33.5 | J10: =IF(I10=100,"Capacity unknown","") | K10: =INDEX(Nodes!$A:$A,MATCH(Arcs!F10,Nodes!$B:$B,0)) -> 38 | L10: =INDEX(Nodes!$A:$A,MATCH(Arcs!G10,Nodes!$B:$B,0)) -> 37 | M10: 1 | N10: 0.2 | O10: {=SUBSTITUTE(INDEX(Nodes!$A$3:$E$64,Arcs!K10,4) & " " & INDEX(Nodes!$A$3:$E$64,Arcs!K10,5), ",",".")} -> 2.50707808340931 61.0775819356338 | P10: {=SUBSTITUTE(INDEX(Nodes!$A$3:$E$64,Arcs!L10,4) & " " & INDEX(Nodes!$A$3:$E$64,Arcs!L10,5), ",",".")} -> 4.838597003381 60.5453484863646 | Q10: =SUBSTITUTE(AVERAGE(INDEX(Nodes!$A$3:$E$64,Arcs!K10,4), INDEX(Nodes!$A$3:$E$64,Arcs!L10,4)) & " " & AVERAGE(INDEX(Nodes!$A$3:$E$64,Arcs!K10,5), INDEX(Nodes!$A$3:$E$64,Arcs!L10,5)), ",", ".") -> 3.67283754339515 60.8114652109992
A11: 10 | B11: Langeled | C11: Gassco AS | D11: IN SERVICE | E11: 2007-09-13 | F11: NYHAMNA | G11: SLEIPNER R | H11: ="LINESTRING(" & O11 & "," & Q11 & "," & P11 & ")" -> LINESTRING(6.94577121700007 62.851558685,4.43081880699815 60.6082514294188,1.91586639699623 58.3649441738375) | I11: 74.7 | J11: =IF(I11=100,"Capacity unknown","") | K11: =INDEX(Nodes!$A:$A,MATCH(Arcs!F11,Nodes!$B:$B,0)) -> 44 | L11: =INDEX(Nodes!$A:$A,MATCH(Arcs!G11,Nodes!$B:$B,0)) -> 51 | M11: 1 | N11: 0.2 | O11: {=SUBSTITUTE(INDEX(Nodes!$A$3:$E$64,Arcs!K11,4) & " " & INDEX(Nodes!$A$3:$E$64,Arcs!K11,5), ",",".")} -> 6.94577121700007 62.851558685 | P11: {=SUBSTITUTE(INDEX(Nodes!$A$3:$E$64,Arcs!L11,4) & " " & INDEX(Nodes!$A$3:$E$64,Arcs!L11,5), ",",".")} -> 1.91586639699623 58.3649441738375 | Q11: =SUBSTITUTE(AVERAGE(INDEX(Nodes!$A$3:$E$64,Arcs!K11,4), INDEX(Nodes!$A$3:$E$64,Arcs!L11,4)) & " " & AVERAGE(INDEX(Nodes!$A$3:$E$64,Arcs!K11,5), INDEX(Nodes!$A$3:$E$64,Arcs!L11,5)), ",", ".") -> 4.43081880699815 60.6082514294188
A12: 11 | B12: Langeled | C12: Gassco AS | D12: IN SERVICE | E12: 2006-10-01 | F12: SLEIPNER R | G12: EASINGTON | H12: ="LINESTRING(" & O12 & "," & Q12 & "," & P12 & ")" -> LINESTRING(1.91586639699623 58.3649441738375,1.01594869849812 56.0120875869188,0.116031000000021 53.659231) | I12: 73.8 | J12: =IF(I12=100,"Capacity unknown","") | K12: =INDEX(Nodes!$A:$A,MATCH(Arcs!F12,Nodes!$B:$B,0)) -> 51 | L12: =INDEX(Nodes!$A:$A,MATCH(Arcs!G12,Nodes!$B:$B,0)) -> 18 | M12: 1 | N12: 0.2 | O12: {=SUBSTITUTE(INDEX(Nodes!$A$3:$E$64,Arcs!K12,4) & " " & INDEX(Nodes!$A$3:$E$64,Arcs!K12,5), ",",".")} -> 1.91586639699623 58.3649441738375 | P12: {=SUBSTITUTE(INDEX(Nodes!$A$3:$E$64,Arcs!L12,4) & " " & INDEX(Nodes!$A$3:$E$64,Arcs!L12,5), ",",".")} -> 0.116031000000021 53.659231 | Q12: =SUBSTITUTE(AVERAGE(INDEX(Nodes!$A$3:$E$64,Arcs!K12,4), INDEX(Nodes!$A$3:$E$64,Arcs!L12,4)) & " " & AVERAGE(INDEX(Nodes!$A$3:$E$64,Arcs!K12,5), INDEX(Nodes!$A$3:$E$64,Arcs!L12,5)), ",", ".") -> 1.01594869849812 56.0120875869188
A13: 12 | B13: Norne Gasstransport | C13: Gassco AS | D13: IN SERVICE | E13: 2001-02-05 | F13: NORNE ERB | G13: NORNE/HEIDRUN T | H13: ="LINESTRING(" & O13 & "," & Q13 & "," & P13 & ")" -> LINESTRING(8.0785441179034 66.0293308994089,7.44000255895174 65.5569234497045,6.80146100000007 65.0845160000001) | I13: 11 | J13: =IF(I13=100,"Capacity unknown","") | K13: =INDEX(Nodes!$A:$A,MATCH(Arcs!F13,Nodes!$B:$B,0)) -> 41 | L13: =INDEX(Nodes!$A:$A,MATCH(Arcs!G13,Nodes!$B:$B,0)) -> 42 | M13: 1 | N13: 0.2 | O13: {=SUBSTITUTE(INDEX(Nodes!$A$3:$E$64,Arcs!K13,4) & " " & INDEX(Nodes!$A$3:$E$64,Arcs!K13,5), ",",".")} -> 8.0785441179034 66.0293308994089 | P13: {=SUBSTITUTE(INDEX(Nodes!$A$3:$E$64,Arcs!L13,4) & " " & INDEX(Nodes!$A$3:$E$64,Arcs!L13,5), ",",".")} -> 6.80146100000007 65.0845160000001 | Q13: =SUBSTITUTE(AVERAGE(INDEX(Nodes!$A$3:$E$64,Arcs!K13,4), INDEX(Nodes!$A$3:$E$64,Arcs!L13,4)) & " " & AVERAGE(INDEX(Nodes!$A$3:$E$64,Arcs!K13,5), INDEX(Nodes!$A$3:$E$64,Arcs!L13,5)), ",", ".") -> 7.44000255895174 65.5569234497045
... A42: 41 | B42: Zeepipe I | C42: Gassco AS | D42: IN SERVICE | E42: 1993-10-01 | F42: SLEIPNER R | G42: DRAUPNER S | H42: ="LINESTRING(" & O42 & "," & Q42 & "," & P42 & ")" -> LINESTRING(1.91586639699623 58.3649441738375,2.19479968579955 58.2746767014261,2.47373297460288 58.1844092290148) | I42: 55 | J42: =IF(I42=100,"Capacity unknown","") | K42: =INDEX(Nodes!$A:$A,MATCH(Arcs!F42,Nodes!$B:$B,0)) -> 51 | L42: =INDEX(Nodes!$A:$A,MATCH(Arcs!G42,Nodes!$B:$B,0)) -> 16 | M42: 1 | N42: 0.2 | O42: {=SUBSTITUTE(INDEX(Nodes!$A$3:$E$64,Arcs!K42,4) & " " & INDEX(Nodes!$A$3:$E$64,Arcs!K42,5), ",",".")} -> 1.91586639699623 58.3649441738375 | P42: {=SUBSTITUTE(INDEX(Nodes!$A$3:$E$64,Arcs!L42,4) & " " & INDEX(Nodes!$A$3:$E$64,Arcs!L42,5), ",",".")} -> 2.47373297460288 58.1844092290148 | Q42: =SUBSTITUTE(AVERAGE(INDEX(Nodes!$A$3:$E$64,Arcs!K42,4), INDEX(Nodes!$A$3:$E$64,Arcs!L42,4)) & " " & AVERAGE(INDEX(Nodes!$A$3:$E$64,Arcs!K42,5), INDEX(Nodes!$A$3:$E$64,Arcs!L42,5)), ",", ".") -> 2.19479968579955 58.2746767014261
A43: 42 | B43: Baltic Pipe 1 | F43: BALTIC ENTRANCE | G43: Denmark 1 | H43: ="LINESTRING(" & O43 & "," & Q43 & "," & P43 & ")" -> LINESTRING(6.5038 55.71,7.45555 55.7275,8.4073 55.745) | I43: 32 | J43: =IF(I43=100,"Capacity unknown","") | K43: =INDEX(Nodes!$A:$A,MATCH(Arcs!F43,Nodes!$B:$B,0)) -> 5 | L43: =INDEX(Nodes!$A:$A,MATCH(Arcs!G43,Nodes!$B:$B,0)) -> 9 | M43: 1 | N43: 0.2 | O43: {=SUBSTITUTE(INDEX(Nodes!$A$3:$E$64,Arcs!K43,4) & " " & INDEX(Nodes!$A$3:$E$64,Arcs!K43,5), ",",".")} -> 6.5038 55.71 | P43: {=SUBSTITUTE(INDEX(Nodes!$A$3:$E$64,Arcs!L43,4) & " " & INDEX(Nodes!$A$3:$E$64,Arcs!L43,5), ",",".")} -> 8.4073 55.745 | Q43: =SUBSTITUTE(AVERAGE(INDEX(Nodes!$A$3:$E$64,Arcs!K43,4), INDEX(Nodes!$A$3:$E$64,Arcs!L43,4)) & " " & AVERAGE(INDEX(Nodes!$A$3:$E$64,Arcs!K43,5), INDEX(Nodes!$A$3:$E$64,Arcs!L43,5)), ",", ".") -> 7.45555 55.7275
A44: 43 | B44: Baltic Pipe 2 | F44: Denmark 2 | G44: Denmark 3 | H44: ="LINESTRING(" & O44 & "," & Q44 & "," & P44 & ")" -> LINESTRING(9.3108 55.617,10.05295 55.452,10.7951 55.287) | I44: 52 | J44: =IF(I44=100,"Capacity unknown","") | K44: =INDEX(Nodes!$A:$A,MATCH(Arcs!F44,Nodes!$B:$B,0)) -> 10 | L44: =INDEX(Nodes!$A:$A,MATCH(Arcs!G44,Nodes!$B:$B,0)) -> 11 | M44: 1 | N44: 0.2 | O44: {=SUBSTITUTE(INDEX(Nodes!$A$3:$E$64,Arcs!K44,4) & " " & INDEX(Nodes!$A$3:$E$64,Arcs!K44,5), ",",".")} -> 9.3108 55.617 | P44: {=SUBSTITUTE(INDEX(Nodes!$A$3:$E$64,Arcs!L44,4) & " " & INDEX(Nodes!$A$3:$E$64,Arcs!L44,5), ",",".")} -> 10.7951 55.287 | Q44: =SUBSTITUTE(AVERAGE(INDEX(Nodes!$A$3:$E$64,Arcs!K44,4), INDEX(Nodes!$A$3:$E$64,Arcs!L44,4)) & " " & AVERAGE(INDEX(Nodes!$A$3:$E$64,Arcs!K44,5), INDEX(Nodes!$A$3:$E$64,Arcs!L44,5)), ",", ".") -> 10.05295 55.452
A45: 44 | B45: Baltic Pipe 3 | F45: Denmark 4 | G45: POLAND | H45: ="LINESTRING(" & O45 & "," & Q45 & "," & P45 & ")" -> LINESTRING(11.2102 55.389,13.23505 54.5945,15.2599 53.8) | I45: 32 | J45: =IF(I45=100,"Capacity unknown","") | K45: =INDEX(Nodes!$A:$A,MATCH(Arcs!F45,Nodes!$B:$B,0)) -> 12 | L45: =INDEX(Nodes!$A:$A,MATCH(Arcs!G45,Nodes!$B:$B,0)) -> 47 | M45: 1 | N45: 0.2 | O45: {=SUBSTITUTE(INDEX(Nodes!$A$3:$E$64,Arcs!K45,4) & " " & INDEX(Nodes!$A$3:$E$64,Arcs!K45,5), ",",".")} -> 11.2102 55.389 | P45: {=SUBSTITUTE(INDEX(Nodes!$A$3:$E$64,Arcs!L45,4) & " " & INDEX(Nodes!$A$3:$E$64,Arcs!L45,5), ",",".")} -> 15.2599 53.8 | Q45: =SUBSTITUTE(AVERAGE(INDEX(Nodes!$A$3:$E$64,Arcs!K45,4), INDEX(Nodes!$A$3:$E$64,Arcs!L45,4)) & " " & AVERAGE(INDEX(Nodes!$A$3:$E$64,Arcs!K45,5), INDEX(Nodes!$A$3:$E$64,Arcs!L45,5)), ",", ".") -> 13.23505 54.5945
A46: 45 | B46: CATS | F46: CATS PLATFORM | G46: TEESSIDE | H46: ="LINESTRING(" & O46 & "," & Q46 & "," & P46 & ")" -> LINESTRING(1.803328 57.758069,0.349372 56.1913345,-1.104584 54.6246) | I46: 48 | J46: Source en sink omgegraaid. | K46: =INDEX(Nodes!$A:$A,MATCH(Arcs!F46,Nodes!$B:$B,0)) -> 8 | L46: =INDEX(Nodes!$A:$A,MATCH(Arcs!G46,Nodes!$B:$B,0)) -> 55 | M46: 1 | N46: 0.2 | O46: {=SUBSTITUTE(INDEX(Nodes!$A$3:$E$64,Arcs!K46,4) & " " & INDEX(Nodes!$A$3:$E$64,Arcs!K46,5), ",",".")} -> 1.803328 57.758069 | P46: {=SUBSTITUTE(INDEX(Nodes!$A$3:$E$64,Arcs!L46,4) & " " & INDEX(Nodes!$A$3:$E$64,Arcs!L46,5), ",",".")} -> -1.104584 54.6246 | Q46: =SUBSTITUTE(AVERAGE(INDEX(Nodes!$A$3:$E$64,Arcs!K46,4), INDEX(Nodes!$A$3:$E$64,Arcs!L46,4)) & " " & AVERAGE(INDEX(Nodes!$A$3:$E$64,Arcs!K46,5), INDEX(Nodes!$A$3:$E$64,Arcs!L46,5)), ",", ".") -> 0.349372 56.1913345
