Workbook

Sheet pipes
A1: # | B1: pipName | C1: idPipeline | D1: mapLabel | E1: belongs_to | F1: curOperNam | G1: curPhase | H1: curPhDate | I1: fromFacili | J1: toFacility | K1: mainGrp | L1: dimension | M1: WaterDepth | N1: medium | O1: idBelongTo | P1: idFrmFacil | Q1: idToFacili | R1: idOperator | S1: dtUpdated | T1: FactUrl | U1: MapUrl | V1: geometry | W1: Capacity | X1: Source Lon | Y1: Source Lat | Z1: Dest Lon | AA1: Dest Lat | AB1: Facility start | AC1: Facility end | AD1: comment
A2: 22 | B2: 8.625" Gas BRAGE, BRAGE-T | C2: 325524 | D2: Statpipe | E2: BRAGE | F2: OKEA ASA | G2: IN SERVICE | H2: 1993-09-23 | I2: BRAGE | J2: BRAGE-T | K2: Transportation | L2: 8.625 | M2: 136 | N2: Gas | O2: 43651 | P2: 277405 | Q2: 287037 | R2: 34925006 | S2: 2024-01-02 | T2: https://factpages.sodir.no/factpages/default.aspx?nav1=tuf&nav2=PageView|Pipeline|All&nav3=325524 | U2: https://factmaps.sodir.no/factmaps/3_0/?run=PipelineByNPDID&NPDID=325524 | V2: LINESTRING (2.8963509232204276 60.56011387499288, 3.0081770764843703 60.54330065370974, 3.0361264151934804 60.54281098835386) | X2: 2.898055 | Y2: 60.560633 | Z2: 3.0378255 | AA2: 60.543329 | AB2: =VLOOKUP(I2,facilities!$B:$Z,9,FALSE) -> NO_BG | AC2: =VLOOKUP(J2,facilities!$B:$Z,9,FALSE) -> NO_BG
A3: 23 | B3: 16" Gas DRAUGEN, DRAUGEN T | C3: 326068 | D3: Draugen Gasseksport | E3: DRAUGEN GASSEKSPORT | F3: OKEA ASA | G3: IN SERVICE | H3: 2000-10-10 | I3: DRAUGEN | J3: DRAUGEN T | K3: Transportation | L3: 16 | M3: 344 | N3: Gas | O3: 1035952 | P3: 272393 | Q3: 287373 | R3: 34925006 | S3: 2024-01-02 | T3: https://factpages.sodir.no/factpages/default.aspx?nav1=tuf&nav2=PageView|Pipeline|All&nav3=326068 | U3: https://factmaps.sodir.no/factmaps/3_0/?run=PipelineByNPDID&NPDID=326068 | V3: LINESTRING (6.439513710701037 64.2329284780315, 6.449055151210916 64.23122552146818, 6.9889691272997645 64.16618923704642, 7.002129636522198 64.1654333609896, 7.062959750852773 64.16582309393723, 7.079793180607852 64.1684484007406, 7.315588528377448 64.21648815910106, 7.404876944904599 64.22853570382964, 7.7111336534916886 64.26379673831497, 7.742816609118542 64.26662022380145, 7.7583349842149065 64.26951952443925, 7.768576121988894 64.27321979697747, 7.777126085464185 64.27877412682054, 7.794889263285606 64.30243431539115, 7.799528206240841 64.30605051942663, 7.814497208966536 64.31468805195007, 7.818431088596768 64.31892227349209, 7.822468792099478 64.3260716173518, 7.822654557749491 64.32997778178854, 7.820946211228841 64.33460195407923, 7.813834552501298 64.34114814350907, 7.803842909263228 64.34577121958141, 7.789322217253073 64.35026182872208) | W3: 5 | X3: 6.441258 | Y3: 64.233255 | Z3: 7.7910261 | AA3: 64.350568 | AB3: =VLOOKUP(I3,facilities!$B:$Z,9,FALSE) -> NO_NN | AC3: =VLOOKUP(J3,facilities!$B:$Z,9,FALSE) -> NO_NN
A4: 0 | B4: 42" Gas ÅSGARD ERB, KÅRSTØ | C4: 307674 | D4: Åsgard Transport | E4: GASSLED | F4: Gassco AS | G4: IN SERVICE | H4: 2000-10-04 | I4: ÅSGARD ERB | J4: KÅRSTØ | K4: Transportation | L4: 42 | M4: 372 | N4: Gas | O4: 2252643 | P4: 282613 | Q4: 286169 | R4: 1944954 | S4: 2024-01-02 | T4: https://factpages.sodir.no/factpages/default.aspx?nav1=tuf&nav2=PageView|Pipeline|All&nav3=307674 | U4: https://factmaps.sodir.no/factmaps/3_0/?run=PipelineByNPDID&NPDID=307674 | V4: LINESTRING (4.686853131474261 62.302302667129126, 4.718448369792201 62.33153457574122, 4.688439971644288 62.3037851068389, 4.686853131474261 62.302302667129126) | W4: 70 | X4: 4.6885411 | Y4: 62.302729 | Z4: 4.6885411 | AA4: 62.302729 | AB4: =VLOOKUP(I4,facilities!$B:$Z,9,FALSE) -> NO0A2 | AC4: =VLOOKUP(J4,facilities!$B:$Z,9,FALSE) -> NO0A1
A5: 24 | B5: 40" Gas DRAUPNER E, EUROPIPE-SCP | C5: 326340 | D5: Europipe I | E5: GASSLED | F5: Gassco AS | G5: IN SERVICE | H5: 1995-10-01 | I5: DRAUPNER E | J5: EUROPIPE-SCP | K5: Transportation | L5: 40 | M5: 76 | N5: Gas | O5: 2252643 | P5: 278357 | Q5: 286841 | R5: 1944954 | S5: 2024-01-02 | T5: https://factpages.sodir.no/factpages/default.aspx?nav1=tuf&nav2=PageView|Pipeline|All&nav3=326340 | U5: https://factmaps.sodir.no/factmaps/3_0/?run=PipelineByNPDID&NPDID=326340 | V5: LINESTRING (2.4628033065972583 58.187535644407276, 2.4552520524712187 58.184953438321706, 2.4452049867077155 58.180375145706634, 2.436617995005262 58.175027843433966, 2.429810080350187 58.16903554003433, 2.4242352589667133 58.16170720354026, 2.4216804587721366 58.15572095378309, 2.420763668776968 58.150490752095145, 2.426013302961221 57.79197297830305, 2.4273683651050777 57.744652296305, 2.4307660116249323 57.731640871117875, 2.5189763662906746 57.54282418963404, 2.525334834467185 57.53571501317608, 2.533882330387126 57.52932388902057, 2.626753808075191 57.48140630803102, 2.634996253186544 57.476003215383955, 2.6416436818262556 57.469978081185985, 2.892508614943398 57.19726841667463, 3.1808761081020624 56.87852461127476, 3.3815273271602124 56.652408055910364, 3.3877327714301955 56.645227877927695, 3.3940302923778023 56.63614363434331, 3.407040228398652 56.62094625631261, 3.488556990884267 56.527907966634345, 3.5023358534307882 56.514987678083074, 3.5316709132669435 56.48164286007732, 3.7483611486674855 56.23177571073057, 3.7531254465816257 56.227200607773526, 3.7643760649266835 56.218642442647905, 3.7697814095819724 56.21326931952618, 3.790266850389006 56.18931372836613, 3.839064504651688 56.126131109314514, 3.934679180445567 56.01437035940241, 4.162862090050761 55.74384669140317, 4.169082473425813 55.737766554617956, 4.174770772717963 55.73361347786694, 4.22120097485071 55.70629307727897) | W5: 46 | X5: 2.4644042 | Y5: 58.188149 | Z5: 4.222622 | AA5: 55.706969 | AB5: =VLOOKUP(I5,facilities!$B:$Z,9,FALSE) -> NO_DE | AC5: =VLOOKUP(J5,facilities!$B:$Z,9,FALSE) -> DE_EP | AD5: EUROPIPE-SCP - check coordinates see #24 & #28
A6: 28 | B6: 40" Gas EUROPIPE-SCP, EMDEN | C6: 327394 | D6: Europipe I | E6: GASSLED | F6: Gassco AS | G6: IN SERVICE | H6: 1995-10-01 | I6: EUROPIPE-SCP | J6: EMDEN | K6: Transportation | L6: 40 | M6: 45 | N6: Gas | O6: 2252643 | P6: 286841 | Q6: 286141 | R6: 1944954 | S6: 2024-01-02 | T6: https://factpages.sodir.no/factpages/default.aspx?nav1=tuf&nav2=PageView|Pipeline|All&nav3=327394 | U6: https://factmaps.sodir.no/factmaps/3_0/?run=PipelineByNPDID&NPDID=327394 | V6: LINESTRING (7.32514696267687 53.678990373954015, 7.4011991596642055 53.6717909446933, 7.457720037063928 53.69159219597222, 7.459880117479199 53.690792192525514, 7.392222039507814 53.80041408933186, 7.385774700403287 53.806039206561145, 7.376466304590163 53.81106727365384, 7.328866404808301 53.83265948047898, 7.288392929172429 53.8464035035132, 7.278673552321244 53.8504395333066, 7.262380893760357 53.85808161218755, 7.228824429980407 53.87731789016703, 7.198848206644844 53.891721046428636, 7.074762247452948 53.94774357279723, 7.057455583514114 53.95463561550292, 6.935184657906649 54.01079416322335, 6.913802682890788 54.024247379246496, 6.899254985907223 54.03447256177636, 6.723974812853038 54.149766498876836, 6.711057289384026 54.15570555657124, 6.682101245030956 54.16490554899234, 6.669647722687629 54.17118562296475, 6.656208075879919 54.1805967904066, 6.6363099722722305 54.199142191830155, 6.626373370356491 54.21000044551771, 6.614460706207759 54.221186688736346, 6.5628532775701665 54.255379267317224, 6.308824390950888 54.42001799284584, 6.070030196798607 54.57315649992453, 5.825662722185294 54.72824000985346, 5.538138196814379 54.90863989146273, 5.192243895422825 55.12265125287183, 4.842733392057502 55.33561553316483, 4.433070006211278 55.58123923441443, 4.22120097485071 55.70629307727897) | W6: 46 | X6: 4.222622 | Y6: 55.706969 | Z6: 7.32642 | AA6: 53.6797 | AB6: =VLOOKUP(I6,facilities!$B:$Z,9,FALSE) -> DE_EP | AC6: =VLOOKUP(J6,facilities!$B:$Z,9,FALSE) -> DE947 | AD6: EUROPIPE-SCP - check coordinates see #24 & #28; coordinates reversed?
A7: 20 | B7: 42" Gas KÅRSTØ, EMDEN | C7: 323212 | D7: Europipe II | E7: GASSLED | F7: Gassco AS | G7: IN SERVICE | H7: 1999-10-01 | I7: KÅRSTØ | J7: EMDEN | K7: Transportation | L7: 42 | M7: 347 | N7: Gas | O7: 2252643 | P7: 286169 | Q7: 286141 | R7: 1944954 | S7: 2024-01-02 | T7: https://factpages.sodir.no/factpages/default.aspx?nav1=tuf&nav2=PageView|Pipeline|All&nav3=323212 | U7: https://factmaps.sodir.no/factmaps/3_0/?run=PipelineByNPDID&NPDID=323212 | V7: LINESTRING (7.32514696267687 53.678990373954015, 7.4018391191549755 53.6736910140084, 7.457720037063928 53.69159219597222, 7.3912040184029255 53.80023307253265, 7.385839745862257 53.804597159626695, 7.376585359132399 53.80937321896535, 7.207379156798347 53.86794435123968, 7.196257682974817 53.873948430963466, 7.189033325096543 53.87948353680844, 7.1828019512158905 53.88638469845168, 7.179239668743901 53.892571865029815, 7.07287915992026 54.238568222291235, 6.954123952986654 54.618748694382255, 6.951744735480611 54.62355083050632, 6.9475274407248255 54.629238976605, 6.91435341083016 54.66494882157537, 6.844013037278041 54.77318271501995, 6.82572387531898 54.79395421902926, 6.822869642321458 54.798776351217526, 6.82105105899166 54.81517188666376, 6.817557502901281 54.82935532914016, 6.8184742056092515 54.83919367254637, 6.822799022993953 54.84828902798043, 6.851084508911495 54.88695264766349, 6.853805318302932 54.89497494962288, 6.853867156811409 54.8999491191781, 6.852907985843898 54.90438225926019, 6.762586539463472 55.14724854526278, 6.732610119020615 55.225489892557896, 6.7192063448907815 55.2675981877146, 6.659437622153171 55.41888172462993, 6.55948781700785 55.68425977905299, 6.376442937430352 56.163945446675825, 6.366990912207593 56.18532809009322, 6.29007689498581 56.37653394351937, 6.2266440960601335 56.5419370636239, 6.153750360678373 56.72334266488432, 6.144533402332305 56.742187229560564, 6.136373445064696 56.76175383205678, 6.124713422188593 56.78046136477, 6.117670442948578 56.801375028289215, 6.112261406836086 56.82496880591513, 6.045868384363048 56.988414877144784, 6.029937475492769 57.0268990706172, 6.027259235876948 57.03122819487978, 6.019634679573686 57.04025043069543, 6.0164003707718985 57.045980598748336, 6.01129617661792 57.073485524093144, 6.006053392813598 57.090137060133635, 5.882265323070877 57.389813406797785, 5.843181573649857 57.48274231021467, 5.787723210177421 57.578864147378475, 5.744195143467337 57.70012603894833, 5.743078892679234 57.70559322438704, 5.7430824558562765 57.71647661920235, 5.74153615304275 57.72293083557926, 5.713664200236187 57.776762469129466, 5.705743181431557 57.8094292930658, 5.702134676544558 57.81916460592942, 5.671704604767221 57.87246119397898, 5.666207992134112 57.88345153086098, 5.663974538366843 57.8928358476163, 5.661309827761735 57.91690221334874, 5.659574547773731 57.92263240230303, 5.634282228764614 57.962359561519165, 5.626826441051245 57.97661599626146, 5.6015447869922745 58.04900234957891, 5.498052523352002 58.276132480791766, 5.44886896626917 58.400045469897265, 5.33373284953689 58.63294373411097, 5.27303743191979 58.76560394442499, 5.255784732723547 58.83989350175517, 5.253779094368541 58.85331797723998, 5.253486657785566 58.86321034148343, 5.256935376568359 58.964048133727054, 5.260937900080833 58.97762868624936, 5.3341410520985 59.13667047515026, 5.336396470526604 59.15135705078712, 5.337335211527728 59.1805031525413, 5.338832006547012 59.18612938060962, 5.341812890901496 59.19071158688051, 5.346003841716669 59.194587780810494, 5.351645846687613 59.19819598159988, 5.359979924926262 59.20192321817846, 5.45263349810432 59.22752925491493, 5.460363677174937 59.228590384492115, 5.49151883392187 59.245650386055004, 5.495891764726569 59.250106603985515, 5.500656462097981 59.260094034013406, 5.511409601642026 59.27158221781404) | W7: 71 | X7: 5.5129213 | Y7: 59.272116 | Z7: 7.32642 | AA7: 53.6797 | AB7: =VLOOKUP(I7,facilities!$B:$Z,9,FALSE) -> NO0A1 | AC7: =VLOOKUP(J7,facilities!$B:$Z,9,FALSE) -> DE947 | AD7: EUROPIPE-SCP - check coordinates see #24 & #28; coordinates reversed?
A8: 25 | B8: 42" Gas DRAUPNER E, DUNKERQUE | C8: 326374 | D8: Franpipe | E8: GASSLED | F8: Gassco AS | G8: IN SERVICE | H8: 1998-07-01 | I8: DRAUPNER E | J8: DUNKERQUE | K8: Transportation | L8: 42 | M8: 85 | N8: Gas | O8: 2252643 | P8: 278357 | Q8: 286757 | R8: 1944954 | S8: 2024-01-02 | T8: https://factpages.sodir.no/factpages/default.aspx?nav1=tuf&nav2=PageView|Pipeline|All&nav3=326374 | U8: https://factmaps.sodir.no/factmaps/3_0/?run=PipelineByNPDID&NPDID=326374 | V8: LINESTRING (2.462793932626184 58.187564308871586, 2.4407347681738827 58.18254916875378, 2.426581608721842 58.17758981075382, 2.4141335463681033 58.171497432927865, 2.4037985870977585 58.164382044429516, 2.3958257278646333 58.15645865623247, 2.3905159669324467 58.14794428002664, 2.3878312920834315 58.13908592432718, 2.3942545139056106 57.74391486502216, 2.387481133220786 57.46549682910719, 2.3888157116288666 57.11516541679584, 2.390744497161882 57.09724380729154, 2.396017361690176 57.07950824522029, 2.3998048184557836 57.07076898278174, 2.4097907794122495 57.05365550019906, 2.63990297551028 56.7267347917067, 2.8607632624317807 56.40789431612352, 2.867710756570045 56.39981411825243, 3.061844761120804 56.24502205988923, 3.24525613774847 56.09731012445693, 3.2632701670217603 56.082428823517695, 3.2789201643187957 56.06675446732257, 3.2857666484025527 56.0586242675889, 3.2971025757273944 56.04181282137616, 3.4010379791351397 55.86237586888284, 3.408059811401045 55.844858349797924, 3.410425202336356 55.83597407256406, 3.4120395757060216 55.82703578471101, 3.4127432600317906 55.809071176508034, 3.3431789865448183 55.19035530975019, 3.282337974893751 54.63431698371356, 3.1851965057591403 54.01682552402704, 3.135769926735322 53.694618487704055, 3.0911947458113174 53.26400114276598, 3.091156317275986 53.24603256896663, 3.0942339600355293 53.22816003421934, 3.2037699603857526 52.80179077223789, 3.2071115923871907 52.783934247959635, 3.207720884431341 52.77495397222961, 3.2074711561753078 52.765962686469784, 3.205415660530116 52.7480320991446, 3.174522790252268 52.5240867312607, 3.1739213229452417 52.506119163544994, 3.18474229895764 52.41647849224174, 3.184623839880268 52.39849993148289, 3.1584716876897474 52.183331965428664, 3.1555421524577936 52.16545238011896, 3.1498395442142417 52.14781977147627, 3.141337856629478 52.130630145252326, 3.1267442708620528 52.10520119669943, 3.1198786288976716 52.08774058135959, 3.117578838818818 52.078859281936154, 3.0872904764791085 51.86391334551881, 3.0871567363904235 51.854948069918784, 3.0909870791640435 51.84630384878643, 3.0890822929111246 51.83749555821743, 3.080738311574879 51.83022124217935, 3.0608402312024108 51.817139618953796, 3.0517792256296037 51.81012430290981, 2.9980102156698405 51.76771440474135, 2.9809162426556606 51.75320277034245, 2.8184741674922567 51.626732099228725, 2.8031982578395813 51.61149546550424, 2.7205786636528777 51.51668869826472, 2.7104296225124846 51.51038639641104, 2.6460147788171158 51.490312068927075, 2.623609610011189 51.479092482289715, 2.6099223823597675 51.47649424938388, 2.595557080088606 51.47593306874132, 2.581872851999604 51.47335883653051, 2.5705497621159252 51.46785754506058, 2.53871559060467 51.44962964446193, 2.5289405669249545 51.443045338935626, 2.520946608594902 51.43557602778169, 2.4738328880111853 51.39038916096986, 2.4678189927197107 51.38225585339655, 2.443803698849599 51.33988033575361, 2.436647766224928 51.33215202744673, 2.425260671340582 51.326791740203085, 2.412102485705382 51.32320948480792, 2.401068407625747 51.317544192701256, 2.3832054235947027 51.303486576859704, 2.3756774805384007 51.295837266918205, 2.3693475758917097 51.2877729586066, 2.311210966950842 51.195854609782266, 2.2945163201719656 51.17100869498148, 2.2815557795434653 51.14530079847652, 2.2727493489165576 51.11890593020748, 2.2667172274891216 51.08385184294803, 2.263658413378572 51.075073553186826, 2.255355726345203 51.05789195982969, 2.251373994112591 51.04555455657972) | W8: 55 | X8: 2.4643948 | Y8: 58.188178 | Z8: 2.252709 | AA8: 51.046406 | AB8: =VLOOKUP(I8,facilities!$B:$Z,9,FALSE) -> NO_DE | AC8: =VLOOKUP(J8,facilities!$B:$Z,9,FALSE) -> FRE12
A9: 29 | B9: 30" Gas KVITEBJØRN, KOLLSNES | C9: 357492 | D9: Kvitebjørn Gassrør | E9: GASSLED | F9: Gassco AS | G9: IN SERVICE | H9: 2004-09-26 | I9: KVITEBJØRN | J9: KOLLSNES | K9: Transportation | L9: 30 | M9: 350 | N9: Gas | O9: 2252643 | P9: 280877 | Q9: 286729 | R9: 1944954 | S9: 2024-01-02 | T9: https://factpages.sodir.no/factpages/default.aspx?nav1=tuf&nav2=PageView|Pipeline|All&nav3=357492 | U9: https://factmaps.sodir.no/factmaps/3_0/?run=PipelineByNPDID&NPDID=357492 | V9: LINESTRING (2.505334724239661 61.07707774169544, 2.5156455681055907 61.071997878159074, 2.5377977279092474 61.062647978419804, 2.5646782087413573 61.055777788606115, 2.5935935079498407 61.0428191329123, 2.6304754065886806 61.03267211951432, 2.6736810405753033 61.0142813077769, 2.691757822526383 61.00430190560882, 2.724656463325102 60.99193841544909, 2.7895566473072657 60.965345963761706, 2.913002584879702 60.9191345135096, 3.0241658483214495 60.87601292793791, 3.1000395791199953 60.84453761159612, 3.172550595707477 60.81665202010422, 3.3402050598966624 60.75399914125977, 3.4108706043382027 60.72244745743365, 3.4877486817090713 60.693158054533534, 3.5033281260282663 60.68867962360441, 3.594309140523922 60.67182678982449, 3.6199527070745785 60.66853871729266, 3.671705600727987 60.65977667129293, 3.8279352729208194 60.6449427054429, 3.9666037675743664 60.6243633591868, 4.106784461393816 60.60645441721475, 4.49082348304984 60.543371875521764, 4.57487746809513 60.52691946001078, 4.594357104033375 60.52176202389192, 4.638453194429097 60.50789177918331, 4.660990819612634 60.5039169817447, 4.675405125324347 60.50311603612439, 4.689631966698213 60.503573987585554, 4.720515491488312 60.508407762922886, 4.737185003204646 60.51374492891444, 4.7556554022336295 60.5227901439113, 4.779853432830677 60.528390623758156, 4.7989680591442845 60.53742821614213, 4.817711490441821 60.54090757731105, 4.824484073357435 60.543738272883424, 4.8354464342204535 60.54606225557832) | W9: 27 | X9: 2.5070781 | Y9: 61.077582 | Z9: 4.8370377 | AA9: 60.546555 | AB9: =VLOOKUP(I9,facilities!$B:$Z,9,FALSE) -> NO_KV | AC9: =VLOOKUP(J9,facilities!$B:$Z,9,FALSE) -> NO0A2
A10: 30 | B10: 42" Gas NYHAMNA, SLEIPNER R | C10: 369461 | D10: Langeled | E10: GASSLED | F10: Gassco AS | G10: IN SERVICE | H10: 2007-09-13 | I10: NYHAMNA | J10: SLEIPNER R | K10: Transportation | L10: 42 | M10: 360 | N10: Gas | O10: 2252643 | P10: 364693 | Q10: 277797 | R10: 1944954 | S10: 2024-01-02 | T10: https://factpages.sodir.no/factpages/default.aspx?nav1=tuf&nav2=PageView|Pipeline|All&nav3=369461 | U10: https://factmaps.sodir.no/factmaps/3_0/?run=PipelineByNPDID&NPDID=369461 | V10: LINESTRING (6.944126203226062 62.851181615233024, 6.958395523951621 62.86029927747193, 6.959437244320278 62.86393865781273, 6.9570327642936345 62.86726899544155, 6.951934588436433 62.8697485892215, 6.921528053263533 62.87815616721939, 6.899386123315378 62.89035198884869, 6.886777842767185 62.8953836300255, 6.877956384860074 62.898088257304074, 6.866665841970104 62.89970943684877, 6.83570513329627 62.90083445610842, 6.793422846264172 62.90430929058319, 6.784754991596397 62.90599916839668, 6.776374110964865 62.909314176300974, 6.770653550753617 62.91340362970615, 6.76783554845767 62.9183133113238, 6.767935965344757 62.921849679595034, 6.771996710328848 62.93271442488213, 6.769980083879582 62.941404632985616, 6.76733956506815 62.94464722628713, 6.763156912161753 62.94771813255899, 6.7510231137718995 62.95249799976163, 6.7421721503336025 62.95411539341296, 6.732601671465161 62.954748545754484, 6.66374699991203 62.95367576380796, 6.645619018729286 62.9524738731098, 6.612273046705815 62.9544190547306, 6.550780152010196 62.951316856424924, 6.459188607203072 62.934301539519794, 6.436844037625559 62.92923133783547, 6.2005430893532365 62.89161792298806, 6.171018100836043 62.88602500007172, 6.096305416462524 62.86645392639351, 5.841660615074013 62.809678282241926, 5.192750669676527 62.653437105178334, 5.179054745778569 62.64927875317483, 5.168065967344774 62.644197239808406, 5.161009295330372 62.63946674097722, 5.141530320079816 62.623131317043836, 4.978638417356975 62.472305442665856, 4.960700515785536 62.457911797772326, 4.947616128029106 62.441595527969056, 4.924426817586714 62.42423768153443, 4.900299455459889 62.399883390834034, 4.893937102167241 62.394756156317406, 4.882526842824044 62.38867896282539, 4.787859027736522 62.350121134033316, 4.659694523144031 62.30671041013584, 4.649196899707808 62.301716644888145, 4.640969617538731 62.29586456608697, 4.386800200301029 62.05731660282345, 4.344596452933942 61.99795702500478, 4.331978453627834 61.97310312695476, 4.312378293852157 61.949851377941584, 4.304935303551111 61.93804432811713, 4.296090688329816 61.928999211186444, 4.290280306466911 61.91951923933059, 4.284526071151988 61.91219084348436, 4.279965704523582 61.90785330319081, 4.263948932725386 61.89570280908999, 4.234825690039018 61.878516550479596, 4.20494980972435 61.85583690118129, 4.1858528843090435 61.83818917221627, 4.181106630707915 61.83232569146734, 4.174332658602673 61.82054916939476, 4.16149276505776 61.80677740603877, 4.153950028858588 61.79639329452358, 4.146609219179174 61.78214474499531, 4.141779098870773 61.75823321677975, 4.139030309714342 61.75356762390407, 4.127781706248229 61.73913591233521, 4.121785130033305 61.733547084116445, 4.0794075301593695 61.703920441550636, 4.014854046984061 61.655223097072806, 4.01100086725725 61.65054986033026, 4.004321738780614 61.63960116278898, 3.9908766863041434 61.62634439799704, 3.9843833160585347 61.61492647855347, 3.9745948550849732 61.5914574134949, 3.970326636309154 61.58571601473945, 3.962803048038805 61.57820067011437, 3.629607258110459 61.34867237440673, 3.5752092436308605 61.30916132071472, 3.494087609241543 61.25485213912258, 3.4597742196430663 61.230654135216966, 3.4462868956168147 61.21859523561273, 3.4216982246851844 61.202263567473395, 3.4093542306531215 61.193119224210825, 3.3995006317451986 61.18327298233412, 3.397093442024004 61.17968699604514, 3.393819791372758 61.17213737438463, 3.3900507889606226 61.140908998705584, 3.389776202126317 61.13067757906042, 3.391300162378597 61.1097913188949, 3.388695423088713 61.09106420854371, 3.3892034290231026 61.07052127145189, 3.3862908686188864 61.052000159780484, 3.386362031653565 61.041101147310734, 3.3853111305414125 61.030797236791564, 3.3855537990687727 61.00959814382851, 3.382780905819289 60.9697634940148, 3.384481065935622 60.952997271426035, 3.381848548125957 60.92743396013548, 3.383092846115363 60.88817922032942, 3.38124857775132 60.87563980145837, 3.3803649341987922 60.854005804957886, 3.3827216333948305 60.83870067770924, 3.382445159220309 60.82787414445291, 3.3802421990845675 60.81266814554372, 3.3820061365706895 60.7709871741128, 3.382273086189696 60.74561464662316, 3.3785967067959195 60.72934810312221, 3.3788071556994534 60.70830160864621, 3.3779709834892895 60.69950838184881, 3.37592077600572 60.69018487629203, 3.376504560987115 60.67432657520458, 3.3753646170917464 60.66132175647101, 3.3714182916589293 60.64587921742628, 3.3715713883183196 60.6226391881461, 3.370418808309397 60.60499933435139, 3.369268180546799 60.600181171316635, 3.3597410039294595 60.5760025693117, 3.356536744401816 60.56340591320805, 3.3532057786795852 60.557344083931305, 3.345279347989877 60.5476504659061, 3.3240438579901035 60.531559185660484, 3.300682079642526 60.515635731140485, 3.282358438439253 60.50493486214748, 3.2609818019447743 60.488809247282354, 3.2298410553365464 60.470119933555196, 3.170495063566217 60.42807960522853, 3.1233680792447562 60.396446326663835, 3.1166119253331637 60.38970159767318, 3.079377328322243 60.34205754789581, 3.077626587173248 60.33710204413744, 3.0322829970271283 60.07278245829359, 2.664302445883573 59.239975130681586, 2.289287471492959 58.75941515474237, 2.034339921087082 58.43834759060378, 2.030182684178442 58.43442970075392, 2.023888448104477 58.43041259822925, 1.9164397893768848 58.37203959978089) | W10: 75 | X10: 6.9457712 | Y10: 62.851559 | Z10: 1.9180638 | AA10: 58.372653 | AB10: =VLOOKUP(I10,facilities!$B:$Z,9,FALSE) -> NO0A3 | AC10: =VLOOKUP(J10,facilities!$B:$Z,9,FALSE) -> NO_SR
A11: 48 | B11: 44" Co2 injection SLEIPNER R, EASINGTON | C11: 369498 | D11: Langeled | E11: GASSLED | F11: Gassco AS | G11: IN SERVICE | H11: 2006-10-01 | I11: SLEIPNER R | J11: EASINGTON | K11: Transportation | L11: 44 | M11: 83 | N11: Co2 injection | O11: 2252643 | P11: 277797 | Q11: 369424 | R11: 1944954 | S11: 2024-05-25 | T11: https://factpages.sodir.no/factpages/default.aspx?nav1=tuf&nav2=PageView|Pipeline|All&nav3=369498 | U11: https://factmaps.sodir.no/factmaps/3_0/?run=PipelineByNPDID&NPDID=369498 | V11: LINESTRING (1.899695221113172 58.36436527043758, 1.8784147277470742 58.35608339708614, 1.850138658654632 58.341038489896164, 1.8409389688885731 58.32889193053247, 1.8254206604383028 58.316987892258354, 1.817204956533934 58.30553737567446, 1.799309087369085 58.29205066522481, 1.7869555250903297 58.27498589443389, 1.764993670007685 58.25877703540146, 1.749683217143433 58.23750107623741, 1.7358973286119976 58.22686252056317, 1.6188505027315663 58.10889481118326, 1.6125886598478378 58.10165547269084, 1.6101848864723851 58.09512920791515, 1.6102523595573162 58.08450582652492, 1.6000687353883531 58.047421366318446, 1.5013792065167715 57.84171876517869, 1.4040590209838884 57.63632581368914, 1.3179819853842516 57.51537844049209, 1.29433545304512 57.44339959195478, 1.1896400889962824 57.223380512825265, 1.187218640410845 57.208822969644636, 1.1685140002338135 57.04565799932774, 1.1688008648754984 56.807433667010045, 1.1680780376993984 56.80277649561659, 1.166123156518566 56.79867132827492, 1.1590063798473484 56.788821896865095, 1.1120108933437145 56.747194865586714, 1.107709988244552 56.74221363897368, 0.9372868461785486 56.44282315190418, 0.9361600473351338 56.43712394120704, 0.9374433255271666 56.43100874594434, 0.9404375971719453 56.42611961415787, 0.9562207131693672 56.40818519010667, 0.9584770060263339 56.402298014848355, 0.9582082510818832 56.396023795107276, 0.8252127156613631 55.972768641740736, 0.7029410893581942 55.57533666453199, 0.6506142793224539 55.05845672177157, 0.5901340949215869 54.44661982830093, 0.5385180611860005 54.329051369838716, 0.3965376078347606 54.16261624745859, 0.2969573911825778 53.959658493290895, 0.2740877003561589 53.90673851599404, 0.266623964650687 53.89413602111301, 0.1891298583283023 53.72956281570764, 0.1795411137006649 53.71570425739035, 0.1712915183957134 53.69839260535605, 0.1678125985223448 53.69372441440906, 0.162787629415652 53.68945121737258, 0.1283854800068933 53.67071220389232, 0.1225264955098541 53.666328993356274, 0.1145815833180996 53.65843864590715) | W11: 72 | X11: 1.9013193 | Y11: 58.364979 | Z11: 0.116031 | AA11: 53.659231 | AB11: =VLOOKUP(I11,facilities!$B:$Z,9,FALSE) -> NO_SR | AC11: =VLOOKUP(J11,facilities!$B:$Z,9,FALSE) -> UKE12
A12: 6 | B12: 16" Gas NORNE ERB, NORNE/HEIDRUN T | C12: 319132 | D12: Norne Gasstransport | E12: GASSLED | F12: Gassco AS | G12: IN SERVICE | H12: 2001-02-05 | I12: NORNE ERB | J12: NORNE/HEIDRUN T | K12: Transportation | L12: 16 | M12: 430 | N12: Gas | O12: 2252643 | P12: 282221 | Q12: 287261 | R12: 1944954 | S12: 2024-01-02 | T12: https://factpages.sodir.no/factpages/default.aspx?nav1=tuf&nav2=PageView|Pipeline|All&nav3=319132 | U12: https://factmaps.sodir.no/factmaps/3_0/?run=PipelineByNPDID&NPDID=319132 | V12: LINESTRING (8.076739809297488 66.0290992001487, 8.049952275789764 66.03461122233705, 8.035274630789567 66.03578610056198, 8.020745093151788 66.03552691927945, 8.005136630697196 66.03362665528284, 7.9916243513180385 66.03027735399247, 7.980457256940544 66.02558502288387, 7.972929349330346 66.02022070578727, 7.969554515997286 66.01604748821262, 7.968156733270531 66.0122253088075, 7.96428376514426 65.98140094910526, 7.9653086077705195 65.97001747590772, 7.9644519857133345 65.9641962177665, 7.942484711062593 65.91358780424298, 7.937239044184883 65.906003419779, 7.896733556792352 65.86248309230324, 7.885406442938344 65.84367615932851, 7.8844501200532 65.83346771392577, 7.881150449543889 65.82695939843613, 7.878190546808611 65.82396023617277, 7.864722738061047 65.81391265092375, 7.837636371099828 65.80448193205186, 7.828952414651774 65.7991486033899, 7.792946698166718 65.7611895676376, 7.7632301135033455 65.7246886685379, 7.756237371962055 65.71716626704935, 7.751546688410944 65.71005491009879, 7.743322892885875 65.70263849870216, 7.738034904854274 65.69959430736218, 7.714613695874004 65.68989662049826, 7.6910600134438365 65.67252360651625, 7.665076124627933 65.65681363456532, 7.617081927697724 65.63362708656271, 7.551842006791016 65.59710977056594, 7.511467699108599 65.57969855702473, 7.465527269203192 65.5610662259892, 7.385117687556028 65.51147217787529, 7.287001952985897 65.46914122757471, 7.26798671189772 65.46238871704533, 7.260522735840396 65.45800944362855, 7.257023876196616 65.45407223588359, 7.242717150681102 65.42772695397366, 7.215395845411127 65.37347134086356, 7.208600948218103 65.33887780173625, 7.206963770594495 65.32587723438796, 7.202632686463978 65.31002251496722, 7.200227812604905 65.30685635306799, 7.156537079376469 65.26442704817285, 7.15054808814501 65.26104683484508, 7.1279918556371085 65.25224919695133, 7.109142767445553 65.24333059793251, 7.073263195053345 65.217534086688, 7.061720612881881 65.20507442560248, 7.024843484883916 65.17211360186565, 6.985108536241274 65.1497961918335, 6.9600837249260525 65.13341520619272, 6.950211905367923 65.12537275104032, 6.934112979023002 65.11554514688243, 6.903849653220438 65.10400130210719, 6.871178380308759 65.09037434117272, 6.862755247975175 65.08778813231534, 6.846844815577928 65.085628852136, 6.799674199493331 65.08422923098904) | W12: 7 | X12: 8.0785441 | Y12: 66.029331 | Z12: 6.801461 | AA12: 65.084516 | AB12: =VLOOKUP(I12,facilities!$B:$Z,9,FALSE) -> NO_NN | AC12: =VLOOKUP(J12,facilities!$B:$Z,9,FALSE) -> NO_NN
A13: 27 | B13: 36" Gas EKOFISK J, NORPIPE Y | C13: 326918 | D13: Norpipe Gassledning | E13: GASSLED | F13: Gassco AS | G13: IN SERVICE | H13: 1998-08-18 | I13: NORPIPE Y | J13: EKOFISK J | K13: Transportation | L13: 36 | M13: 75 | N13: Gas | O13: 2252643 | P13: 277937 | Q13: 287065 | R13: 1944954 | S13: 2024-01-02 | T13: https://factpages.sodir.no/factpages/default.aspx?nav1=tuf&nav2=PageView|Pipeline|All&nav3=326918 | U13: https://factmaps.sodir.no/factmaps/3_0/?run=PipelineByNPDID&NPDID=326918 | V13: LINESTRING (3.3290292860187574 56.489709742026285, 3.305546804781628 56.51203524273058, 3.284842350708143 56.5354888160289, 3.2749758273122316 56.542294936603795, 3.261916303978955 56.54694794399001, 3.2445327335121013 56.549902840591834, 3.2366435192292764 56.55009975366412, 3.227394481609175 56.54814556522217) | W13: 32 | X13: 3.330503 | Y13: 56.490369 | Z13: 3.2288731 | AA13: 56.548804 | AB13: =VLOOKUP(I13,facilities!$B:$Z,9,FALSE) -> NO_EV | AC13: =VLOOKUP(J13,facilities!$B:$Z,9,FALSE) -> NO_EV | AD13: norpipe
A14: 7 | B14: 36" Gas NORPIPE Y, B-11 | C14: 319166 | D14: Norpipe Gassledning | E14: GASSLED | F14: Gassco AS | G14: IN SERVICE | H14: 1977-09-17 | I14: NORPIPE Y | J14: B-11 | K14: Transportation | L14: 36 | M14: 75 | N14: Gas | O14: 2252643 | P14: 287065 | Q14: 277265 | R14: 1944954 | S14: 2024-01-02 | T14: https://factpages.sodir.no/factpages/default.aspx?nav1=tuf&nav2=PageView|Pipeline|All&nav3=319166 | U14: https://factmaps.sodir.no/factmaps/3_0/?run=PipelineByNPDID&NPDID=319166 | V14: LINESTRING (3.3290292860187574 56.489709742026285, 3.330676444777829 56.486726657455016, 3.3424942583349124 56.47371234349503, 3.3466835075679904 56.47010726739637, 3.3579143381240786 56.45623691671912, 3.3714012584881563 56.44155356452933, 3.3906724879526906 56.42276113772779, 3.500879958309773 56.30318627870742, 3.538557411491352 56.264666384736444, 3.6118027526864562 56.200712027635284, 3.617145022389291 56.197272971205486, 3.632026916265012 56.183916683072184, 3.6470438822864732 56.16872733304711, 3.6602286326813025 56.15796611503218, 3.6874852624572165 56.133601591060824, 3.6924105188970278 56.13020453122605, 3.732323963684818 56.092867706920444, 3.746171744326769 56.08168748240841, 3.7673570726015866 56.06098101441544, 3.7897775378020495 56.037433462847105, 3.7961808790999045 56.03276637649111, 3.8818753890969773 55.94471133785859, 3.90155955962649 55.92695895535068, 3.9354507273911428 55.89219915248219, 3.943859218329518 55.88482999659486, 4.000729775000716 55.82842871696599, 4.009163257640626 55.82126156848398, 4.0201009632657625 55.809786300960184, 4.059361351803726 55.77244947357689, 4.073331257970057 55.75759312533259, 4.083434855224062 55.74842992784704, 4.162088622104297 55.701162216958906, 4.181978616239381 55.688030996722, 4.189575955366003 55.68413095086749, 4.241700454113648 55.65257847170792, 4.544898599545277 55.46494113096292) | W14: 32 | X14: 3.330503 | Y14: 56.490369 | Z14: 4.5463025 | AA14: 55.465622 | AB14: =VLOOKUP(I14,facilities!$B:$Z,9,FALSE) -> NO_EV | AC14: =VLOOKUP(J14,facilities!$B:$Z,9,FALSE) -> NOB11 | AD14: norpipe
A15: 21 | B15: 36" Gas B-11, H-7 BP | C15: 324844 | D15: Norpipe Gassledning | E15: GASSLED | F15: Gassco AS | G15: IN SERVICE | H15: 1977-09-17 | I15: B-11 | J15: H-7 BP | K15: Transportation | L15: 36 | M15: 75 | N15: Gas | O15: 2252643 | P15: 277265 | Q15: 377218 | R15: 1944954 | S15: 2024-01-02 | T15: https://factpages.sodir.no/factpages/default.aspx?nav1=tuf&nav2=PageView|Pipeline|All&nav3=324844 | U15: https://factmaps.sodir.no/factmaps/3_0/?run=PipelineByNPDID&NPDID=324844 | V15: LINESTRING (4.555543700984773 55.458301808769356, 4.650384162399258 55.39868748851234, 4.8079166879876665 55.30126396665721, 4.8192652574455925 55.29343082925558, 4.936497867206868 55.22004066589839, 5.034094569035456 55.15764765311913, 5.045064058330728 55.1517475770384, 5.115123448024602 55.1062918272438, 5.124404923711334 55.09948070115307, 5.178745507185681 55.06540515960004, 5.191610074909951 55.05860507429792, 5.2905348748623675 54.99341198121595, 5.345942518048307 54.958061408333, 5.363632327437174 54.947769259017264, 5.3856224342494965 54.93198597237713, 5.414015721189716 54.91578274335029, 5.435746821952378 54.89993245156406, 5.463482103050209 54.883346202176995, 5.483977127802918 54.86875193897939, 5.529157276279768 54.839806467663415, 5.5381547380845335 54.8330203393477, 5.580245669092001 54.80807796844945, 5.6045830002358406 54.78720253654166, 5.631781399446805 54.766480141792954, 5.673997750851817 54.72883234475741, 5.694370789990234 54.71350105569486, 5.718775089698997 54.693448652761596, 5.727820610078458 54.68483946389196, 5.741073303883913 54.67428925655231, 5.750004819224051 54.66572806808691, 5.7835066402528605 54.636955473548426, 5.831677707560235 54.6122221773034, 5.867968296463304 54.59259392057246, 5.887686107724785 54.58350183376937, 5.98067607740759 54.536121272780754, 5.9987348705370165 54.526215140109315, 6.028643076035905 54.51153546562834) | W15: 32 | X15: 4.5569471 | Y15: 55.458982 | Z15: 6.0299759 | AA15: 54.512231 | AB15: =VLOOKUP(I15,facilities!$B:$Z,9,FALSE) -> NOB11 | AC15: =VLOOKUP(J15,facilities!$B:$Z,9,FALSE) -> DE_H7 | AD15: norpipe
A16: 11 | B16: 36" Gas H-7 BP, EMDEN | C16: 321784 | D16: Norpipe Gassledning | E16: GASSLED | F16: Gassco AS | G16: IN SERVICE | H16: 1977-09-17 | I16: H-7 BP | J16: EMDEN | K16: Transportation | L16: 36 | M16: 75 | N16: Gas | O16: 2252643 | P16: 377218 | Q16: 286141 | R16: 1944954 | S16: 2024-01-02 | T16: https://factpages.sodir.no/factpages/default.aspx?nav1=tuf&nav2=PageView|Pipeline|All&nav3=321784 | U16: https://factmaps.sodir.no/factmaps/3_0/?run=PipelineByNPDID&NPDID=321784 | V16: LINESTRING (6.039301167830125 54.50510521442703, 6.04343482142148 54.5020348229678, 6.069416034794971 54.48550955583884, 6.084983805487862 54.474250350345805, 6.102828607588238 54.463839198286756, 6.117974362229504 54.452713992650715, 6.13477813960399 54.4422088259877, 6.142297520862314 54.43647171675608, 6.2393021009702485 54.37271865069528, 6.263970230829005 54.357532413852404, 6.36868917207517 54.28828624888128, 6.411518815572208 54.24025711608296, 6.455716602766651 54.18861187908468, 6.471372466295029 54.1741785695788, 6.4953016272830375 54.1571162627455, 6.532534557694476 54.12657765287666, 6.541851068552621 54.11803847050697, 6.561061011429534 54.103927210582434, 6.567266364932028 54.09780707479565, 6.593451676482341 54.07769269141038, 6.6241972689033926 54.05235118420208, 6.629778533634648 54.04852311774389, 6.638859036225852 54.0399919332903, 6.650509597102145 54.03172578546046, 6.693986822268945 53.99658009153512, 6.699295186134762 53.989318908507926, 6.738751332391408 53.92095007321798, 6.769575828616295 53.86603759216567, 6.773168176681616 53.857768358013395, 6.781254715593925 53.84707909248904, 6.8111351374293925 53.793471647100766, 6.815213404218818 53.78821651787531, 6.818527704221049 53.78123032345002, 6.830414610418238 53.761690807986554, 6.855169663143446 53.71547555376438, 6.879996546110087 53.67473548162355, 6.899916670264981 53.65468803701827, 6.959918524930978 53.64468535132143, 6.98991990651654 53.624685015990714, 7.023203537569012 53.532822361582674, 7.023208907913416 53.35327650078332, 7.18802338147323 53.34547799895728) | W16: 32 | X16: 6.0406336 | Y16: 54.505801 | Z16: 7.18929 | AA16: 53.3462 | AB16: =VLOOKUP(I16,facilities!$B:$Z,9,FALSE) -> DE_H7 | AC16: =VLOOKUP(J16,facilities!$B:$Z,9,FALSE) -> DE947
A17: 8 | B17: 36" Gas OSEBERG D, HEIMDAL HRP | C17: 319676 | D17: Oseberg Gasstransport | E17: GASSLED | F17: Gassco AS | G17: IN SERVICE | H17: 2001-09-30 | I17: OSEBERG D | J17: HEIMDAL HRP | K17: Transportation | L17: 36 | M17: 122 | N17: Gas | O17: 2252643 | P17: 280541 | Q17: 280569 | R17: 1944954 | S17: 2024-01-02 | T17: https://factpages.sodir.no/factpages/default.aspx?nav1=tuf&nav2=PageView|Pipeline|All&nav3=319676 | U17: https://factmaps.sodir.no/factmaps/3_0/?run=PipelineByNPDID&NPDID=319676 | V17: LINESTRING (2.822343823006944 60.48637755543986, 2.819238625765153 60.48484800357955, 2.813665724976562 60.479857741189896, 2.808083035005395 60.4708353241696, 2.7743733532336714 60.426884210607554, 2.769288655486858 60.418266815857464, 2.7639560916682613 60.406940314340716, 2.763056340901885 60.40166010082124, 2.7637721686916965 60.36695678264522, 2.7410110002419406 60.24163470737024, 2.7377857592785984 60.20567229552815, 2.7361920219092952 60.19967204661943, 2.7335121839510212 60.1950178351767, 2.7171408357347637 60.173150793831624, 2.697875298776772 60.13380805114621, 2.6810709577248892 60.111498988650624, 2.616570054261434 59.99485473810632, 2.600937598949472 59.97532279851361, 2.5480828847363655 59.92017503629881, 2.539068154779294 59.90975652712506, 2.5158026657739625 59.88653535214452, 2.4323727999958678 59.79714091136518, 2.4096613258737816 59.773862743539425, 2.344849065194971 59.70257723063006, 2.22451758480264 59.60422599639641, 2.2207947473367002 59.5988577472748, 2.217991212273688 59.58792130090927, 2.2196314968334367 59.583118141585814, 2.2238303654890808 59.57899054577102) | W17: 35 | X17: 2.8240462 | Y17: 60.4869 | Z17: 2.2255035 | AA17: 59.579556 | AB17: =VLOOKUP(I17,facilities!$B:$Z,9,FALSE) -> NO_BO | AC17: =VLOOKUP(J17,facilities!$B:$Z,9,FALSE) -> NO_AE
A18: 2 | B18: 30" Gas STAT-SSTC, KÅRSTØ | C18: 313556 | D18: Statpipe | E18: GASSLED | F18: Gassco AS | G18: IN SERVICE | H18: 1985-10-01 | I18: STAT-SSTC | J18: KÅRSTØ | K18: Transportation | L18: 30 | M18: 300 | N18: Gas | O18: 2252643 | P18: 286365 | Q18: 286169 | R18: 1944954 | S18: 2024-01-02 | T18: https://factpages.sodir.no/factpages/default.aspx?nav1=tuf&nav2=PageView|Pipeline|All&nav3=313556 | U18: https://factmaps.sodir.no/factmaps/3_0/?run=PipelineByNPDID&NPDID=313556 | V18: LINESTRING (1.844167218716536 61.185321420985844, 1.8544151797612212 61.1735100969537, 1.8601436158227025 61.16870998569168, 1.8677831156663394 61.16376589379229, 1.8784257044334849 61.15879884018001, 1.9441950483914874 61.13333471109721, 1.9639551818155145 61.12335958211587, 2.0909597393781514 61.05407255159421, 2.4005142023408426 60.88234292174657, 2.5515011949876376 60.79771860187375, 2.779058755965756 60.668639548750185, 2.7890594407361387 60.661255392556534, 2.9244341651343384 60.533063194350795, 3.149525616405527 60.40116999724175, 3.1585510903064153 60.39710895606737, 3.1687875628614512 60.39375595734497, 3.1902244269381446 60.38915905282618, 3.354615878428507 60.37671865524025, 3.3710385274755503 60.373457737649346, 3.385151259102972 60.3672766789666, 3.4086797400927153 60.35187938599911, 3.4390375777920257 60.33340406122959, 3.4447909881866883 60.3286869531259, 3.4597031826819347 60.31389557475976, 3.4904714346095225 60.28747495110002, 3.5101709484271386 60.26911049647158, 3.544373096910258 60.24658306508891, 3.562490298057159 60.233387788310935, 3.5779504086774683 60.22042648711208, 3.585336834139601 60.21630142222688, 3.6099461162467286 60.20521830765332, 3.6599022472856326 60.172222673829225, 3.6805834520096097 60.16034447943186, 3.7104474224089334 60.138583022709945, 3.7542220869460685 60.11105552001942, 3.7901524646681186 60.08459595992801, 3.8264673673568357 60.0677987730315, 3.834526828712713 60.063284701549435, 3.882376974972347 60.02826696389474, 3.909942562075824 60.01257270957484, 4.100443356836905 59.88659828396718, 4.123527918103729 59.86853088346314, 4.183228633702968 59.828252092697, 4.2091033213928215 59.809157687785735, 4.236809925545285 59.79284341106092, 4.289135153660181 59.75786473013443, 4.319620944867454 59.73927840137284, 4.347808750744626 59.71896397870245, 4.412281783734146 59.6761248922683, 4.467359690040704 59.6481104906598, 4.474347088577124 59.643907415203905, 4.481827588957691 59.63781527437096, 4.530253229900562 59.58958603160386, 4.538264791457011 59.58246985858145, 4.550690493351881 59.57509172805898, 4.6031300549374645 59.55260850291716, 4.615066756740915 59.54489935403915, 4.637445358721813 59.52418783935917, 4.672934636530157 59.497001236260395, 4.678498110833904 59.49016804501143, 4.694166793058012 59.46330622014112, 4.702103381898934 59.455453018706116, 4.711759952932388 59.449082893339515, 4.938799360061654 59.34300658382575, 4.950051890704025 59.33849054652712, 4.961166354946383 59.335359559549396, 4.972238775580322 59.33317060739415, 4.995328567568457 59.33050177820411, 5.031068770127716 59.326896062054814, 5.044164174472908 59.32638519638624, 5.065453734364789 59.327730496335306, 5.1157678329327 59.33594239374459, 5.127435123479551 59.33705357201233, 5.145680665213971 59.33684577769815, 5.1727196174210786 59.33320895739473, 5.184846127768808 59.33300779164941) | W18: 25 | X18: 1.845936 | Y18: 61.18583 | Z18: 5.1863701 | AA18: 59.333543 | AB18: =VLOOKUP(I18,facilities!$B:$Z,9,FALSE) -> NO_SG | AC18: =VLOOKUP(J18,facilities!$B:$Z,9,FALSE) -> NO0A1
A19: 14 | B19: 36" Gas HEIMDAL, DRAUPNER S | C19: 322464 | D19: Statpipe | E19: GASSLED | F19: Gassco AS | G19: IN SERVICE | H19: 1985-10-15 | I19: HEIMDAL | J19: DRAUPNER S | K19: Transportation | L19: 36 | M19: 130 | N19: Gas | O19: 2252643 | P19: 271777 | Q19: 271945 | R19: 1944954 | S19: 2024-01-02 | T19: https://factpages.sodir.no/factpages/default.aspx?nav1=tuf&nav2=PageView|Pipeline|All&nav3=322464 | U19: https://factmaps.sodir.no/factmaps/3_0/?run=PipelineByNPDID&NPDID=322464 | V19: LINESTRING (2.2328500878055273 59.57017269735443, 2.23985604363817 59.56336765873878, 2.244217542088986 59.5557764296348, 2.245650848274539 59.5504062464957, 2.244821296122599 59.540891879082615, 2.230474830359906 59.501735228287316, 2.229731228202462 59.49325390106795, 2.2377276344280794 59.40822882103771, 2.245642478762275 59.33415115434442, 2.258623104496853 59.163727969454506, 2.3315714689888742 58.84154795405019, 2.4294717557257828 58.3968938469033, 2.47123769269886 58.202565279912484, 2.471891052123577 58.194968011495014, 2.471877023541268 58.193846915382665) | W19: 10 | X19: 2.2345226 | Y19: 59.570738 | Z19: 2.4734779 | AA19: 58.19446 | AB19: =VLOOKUP(I19,facilities!$B:$Z,9,FALSE) -> NO_AE | AC19: =VLOOKUP(J19,facilities!$B:$Z,9,FALSE) -> NO_DS
A20: 17 | B20: 28" Gas KÅRSTØ, DRAUPNER S | C20: 323042 | D20: Statpipe | E20: GASSLED | F20: Gassco AS | G20: IN SERVICE | H20: 1985-10-15 | I20: KÅRSTØ | J20: DRAUPNER S | K20: Transportation | L20: 28 | M20: 300 | N20: Gas | O20: 2252643 | P20: 286169 | Q20: 271945 | R20: 1944954 | S20: 2024-01-02 | T20: https://factpages.sodir.no/factpages/default.aspx?nav1=tuf&nav2=PageView|Pipeline|All&nav3=323042 | U20: https://factmaps.sodir.no/factmaps/3_0/?run=PipelineByNPDID&NPDID=323042 | V20: LINESTRING (5.184843019862938 59.332944946012596, 5.1721116061208035 59.33306494487901, 5.144263628879562 59.33673375691488, 5.124668074497887 59.336345513048634, 5.1123957957468855 59.33457830306812, 5.100981592434936 59.33168906099436, 5.092434488491649 59.32844983934513, 5.084326445327226 59.324141582720564, 5.011221030543739 59.263552454404476, 4.983416078637286 59.2444064113127, 4.944027402122258 59.211565720125634, 4.937121562006698 59.20349333711618, 4.909381863374926 59.15623324477502, 4.904403954942874 59.150935988453654, 4.898064995936392 59.14589072560349, 4.884033921157646 59.13844828298742, 4.59043624892652 59.030818817201904, 4.222598904595299 58.89439846347256, 4.1198924828060655 58.8616759869584, 4.107117378932639 58.85602061994826, 4.076039320786786 58.838013569270025, 4.064622221192284 58.83311324704139, 3.9369955361262035 58.79098311454787, 3.881601019441824 58.768067583074156, 3.8710728912129406 58.76437531659266, 3.857342672732184 58.7606860107883, 3.812813821495397 58.751868135503386, 3.7849104369265576 58.74309546660859, 3.759860304463947 58.730564693706114, 3.733454011337372 58.72073000393956, 3.7239709692063836 58.715815705065225, 3.7176270188369536 58.71082144197623, 3.69724138621323 58.690206427808896, 3.6909634569632295 58.68478714992594, 3.6203387198985566 58.63553445799982, 3.606141673311473 58.6278249979919, 3.375629924075715 58.54693916387834, 3.0363966599579015 58.412026993851455, 2.7495043400351014 58.31157773939249, 2.589499556574674 58.254562656641916, 2.574057461424373 58.247371201014936, 2.4784758508557214 58.19158092983042) | W20: 21 | X20: 5.186367 | Y20: 59.33348 | Z20: 2.4800765 | AA20: 58.192194 | AB20: =VLOOKUP(I20,facilities!$B:$Z,9,FALSE) -> NO0A1 | AC20: =VLOOKUP(J20,facilities!$B:$Z,9,FALSE) -> NO_DS
A21: 26 | B21: 36" Gas DRAUPNER S, NORPIPE Y | C21: 326408 | D21: Statpipe | E21: GASSLED | F21: Gassco AS | G21: IN SERVICE | H21: 1985-10-15 | I21: DRAUPNER S | J21: NORPIPE Y | K21: Transportation | L21: 36 | M21: 80 | N21: Gas | O21: 2252643 | P21: 271945 | Q21: 287065 | R21: 1944954 | S21: 2024-01-02 | T21: https://factpages.sodir.no/factpages/default.aspx?nav1=tuf&nav2=PageView|Pipeline|All&nav3=326408 | U21: https://factmaps.sodir.no/factmaps/3_0/?run=PipelineByNPDID&NPDID=326408 | V21: LINESTRING (2.4721325354982553 58.18379583685691, 2.4725476073516663 58.16074077414816, 2.47752170530007 57.74459990713223, 2.4788890891010507 57.73646563198972, 2.550930569192368 57.58188297432267, 2.6215309049224587 57.42791533762265, 2.701351268730091 57.253015086063286, 2.81255329463184 57.00573267797487, 2.817267711966899 56.99847947882871, 2.822012034388426 56.993590363468535, 2.9982147512125095 56.842065142629686, 3.0696525763318827 56.76793039256551, 3.076317165207713 56.75748810563184, 3.1626038735164483 56.593800400073135, 3.168918359822925 56.585597188438214, 3.171165499697498 56.583525142754546, 3.228211007442319 56.58317880970515, 3.2381493436037427 56.581240860166325, 3.246246692586636 56.57773883401469, 3.252767078954243 56.57221871853683, 3.3290292860187574 56.489709742026285) | W21: 30 | X21: 2.473733 | Y21: 58.184409 | Z21: 3.330503 | AA21: 56.490369 | AB21: =VLOOKUP(I21,facilities!$B:$Z,9,FALSE) -> NO_DS | AC21: =VLOOKUP(J21,facilities!$B:$Z,9,FALSE) -> NO_EV | AD21: norpipe
A22: 5 | B22: 30" Gas STATFJORD B, STAT-SSTC | C22: 318010 | D22: Statpipe | E22: GASSLED | F22: Gassco AS | G22: IN SERVICE | H22: 1985-10-01 | I22: STATFJORD B | J22: STAT-SSTC | K22: Transportation | L22: 30 | M22: 145 | N22: Gas | O22: 2252643 | P22: 271301 | Q22: 286365 | R22: 1944954 | S22: 2024-01-02 | T22: https://factpages.sodir.no/factpages/default.aspx?nav1=tuf&nav2=PageView|Pipeline|All&nav3=318010 | U22: https://factmaps.sodir.no/factmaps/3_0/?run=PipelineByNPDID&NPDID=318010 | V22: LINESTRING (1.8297556432426154 61.20193692457381, 1.844167218716536 61.185321420985844) | W22: 25 | X22: 1.8315258 | Y22: 61.202445 | Z22: 1.845936 | AA22: 61.18583 | AB22: =VLOOKUP(I22,facilities!$B:$Z,9,FALSE) -> NO_SG | AC22: =VLOOKUP(J22,facilities!$B:$Z,9,FALSE) -> NO_SG
A23: 34 | B23: 32" Gas STATFJORD B, FLAGS-T | C23: 377106 | D23: Tampen Link | E23: GASSLED | F23: Gassco AS | G23: IN SERVICE | H23: 2007-10-12 | I23: STATFJORD B | J23: FLAGS-T | K23: Transportation | L23: 32 | M23: 145 | N23: Gas | O23: 2252643 | P23: 271301 | Q23: 377070 | R23: 1944954 | S23: 2024-01-02 | T23: https://factpages.sodir.no/factpages/default.aspx?nav1=tuf&nav2=PageView|Pipeline|All&nav3=377106 | U23: https://factmaps.sodir.no/factmaps/3_0/?run=PipelineByNPDID&NPDID=377106 | V23: LINESTRING (1.8212863257780907 61.20380475710424, 1.8209631769263472 61.20323097829491, 1.8366340800707561 61.192126168418724, 1.851723087077361 61.17497482258146, 1.8531525868750693 61.17249137699074, 1.8531638563135522 61.169237314027306, 1.8469327194398473 61.15226498707672, 1.8243535782614093 61.12884917347858, 1.8152578449172525 61.11029746359552, 1.7957541593819484 61.088926448070495, 1.78444105955216 61.06620126950183, 1.7657078041124847 61.045536011107124, 1.7586724987705151 61.04059951048421, 1.7500593498457067 61.03681125763887, 1.698425223783683 61.021501611747546) | W23: 13.5 | X23: 1.8230568 | Y23: 61.204313 | Z23: 1.7001891 | AA23: 61.022018 | AB23: =VLOOKUP(I23,facilities!$B:$Z,9,FALSE) -> NO_SG | AC23: =VLOOKUP(J23,facilities!$B:$Z,9,FALSE) -> NO_FT
A24: 16 | B24: 32" Gas HEIMDAL HRP, ST.FERGUS | C24: 322532 | D24: Vesterled | E24: GASSLED | F24: Gassco AS | G24: IN SERVICE | H24: 2001-09-30 | I24: HEIMDAL HRP | J24: ST.FERGUS | K24: Transportation | L24: 32 | M24: 120 | N24: Gas | O24: 2252643 | P24: 280569 | Q24: 286225 | R24: 1944954 | S24: 2024-01-02 | T24: https://factpages.sodir.no/factpages/default.aspx?nav1=tuf&nav2=PageView|Pipeline|All&nav3=322532 | U24: https://factmaps.sodir.no/factmaps/3_0/?run=PipelineByNPDID&NPDID=322532 | V24: LINESTRING (2.2202473573918815 59.57783967183809, 2.213110145821148 59.586505185399375, 2.2090428595053697 59.58997326360567, 2.2036405609711798 59.59293330568482, 2.196248231438083 59.59539430359397, 2.1076767355094486 59.61577593579078, 1.892148383191021 59.662256916267815, 1.8686005693835466 59.66536973041592, 1.6975387338296093 59.665569865300974, 1.6831364283988641 59.66373461491118, 1.6598311441374147 59.65651605117658, 1.6453758509564007 59.65441078997169, 1.593876402048782 59.65512316535473, 1.3388839574971945 59.644319530452385, 1.3172924464504985 59.64274019732987, 1.3034661832042396 59.64044093600193, 1.2888270405125861 59.63526555721629, 1.275946993638028 59.62912716493873, 1.227021947491085 59.60316157647706, 1.1018826953811245 59.53954861931261, 1.0540187016902205 59.51317203041842, 0.9794605757691631 59.47487265955311, 0.9573386694100628 59.46085785803094, 0.9320746052027312 59.44833207170136, 0.920640634619756 59.44147667191718, 0.8589015465220349 59.409496700105336, 0.8229185508269315 59.3897395097975, 0.7851044617595276 59.37089433003002, 0.7497104930288491 59.35092914002913, 0.7241494152128038 59.33856435660639, 0.6901685166677063 59.31795216121357, 0.5770822616547027 59.2615266334141, 0.5542183226036714 59.24782883606125, 0.4936632942537729 59.215453868499694, 0.481207117030582 59.212312593249784, 0.4694242841062991 59.20247808048807, 0.385526289112243 59.156775324753, 0.3122402285417055 59.11823196923259, 0.2417153037520088 59.07842960397774, 0.2173042843230545 59.065597820145435, 0.170126331326679 59.039066242166136, 0.1330152750052743 59.020134072110984, 0.122082327754823 59.01312567512611, 0.0973822937674088 59.00046089420657, 0.062171334466901 58.980570714064996, 0.0378013142044246 58.96781193421993, 0.0154213978828332 58.95398014094601, -0.0210596252712475 58.9347459690009, -0.1035645520256901 58.888676225770865, -0.1279315703189976 58.875908446394696, -0.1405596001721058 58.86971705801825, -0.1541176895676767 58.86426368452727, -0.1696679120163416 58.860505347027235, -0.1866042816194448 58.859063075901496, -0.238566711430342 58.860806468203066, -0.2557420481727264 58.85856716476681, -0.2705122042891571 58.85387280306291, -0.2810261340049247 58.84676440857481, -0.2868728814544138 58.8383750278851, -0.2881913800601565 58.827240606003315, -0.2881159532070142 58.818399285591674, -0.2844744263507468 58.809388005157906, -0.2664202166116006 58.79389267541945, -0.2601226583915484 58.785639456957874, -0.2584101822872721 58.77662315161027, -0.2612988321109742 58.76775079213963, -0.2688686351587294 58.759552396756874, -0.2943871769998281 58.73620722004678, -0.3404255576303238 58.69840525474867, -0.3820307543170144 58.659108293886945, -0.3913326319190398 58.65151989901583, -0.3986804324318998 58.6433635088986, -0.4075992947129852 58.63565711481705, -0.4317377813943648 58.61183394128526, -0.4663431963769648 58.58083837385867, -0.4734679918011188 58.57267898705184, -0.4985645190484822 58.54915881345012, -0.5140471541792587 58.533094033599255, -0.5484795637698059 58.50202346794374, -0.5723430435823799 58.47812429817116, -0.5896767548371443 58.462646516567496, -0.6804219899920044 58.37614223164384, -0.6877357937522424 58.36801084496164, -0.6961886401020856 58.36017145408073, -0.7029634222609754 58.35186606825326, -0.7209651597740258 58.3365452854398, -0.7464507086123305 58.31314711631274, -0.762334370148448 58.297332343766456, -0.7769749805989323 58.28108757214901, -0.803288564892802 58.25797240363942, -0.8316332312040565 58.23551223274387, -0.8483049185722394 58.21979845474771, -0.8674767095817217 58.20495867582902, -0.9106149973982574 58.166347737522834, -0.9293727707086918 58.15133895865967, -0.9396846954952819 58.144152568556414, -0.9669593233325505 58.12140440358425, -1.009752596873753 58.082613466323004, -1.0379632658756004 58.06022830342417, -1.0560160132824972 58.04501652793785, -1.0639128430609064 58.03706614267347, -1.1364568482042594 57.97633004294208, -1.1523065118255988 57.960462273949055, -1.1714423042153155 57.94562049894077, -1.1886140206768858 57.930180728424446, -1.2246665202406826 57.899820184262, -1.250352092874894 57.87663302952878, -1.3043513404642826 57.83105071545151, -1.311811832857413 57.81590308307419, -1.321379053371838 57.81557794730331, -1.3293618885994363 57.8076605638179, -1.3576309639108244 57.78533900220265, -1.3653897929060732 57.777352618738234, -1.4013863053338729 57.74700407745753, -1.435749754615652 57.71614154011591, -1.453965522418392 57.701090771770154, -1.4886269854933374 57.67034423598293, -1.4968377416767902 57.66048278139606, -1.50647873777079 57.655138467553265, -1.5156266230475965 57.64761508333423, -1.5324263347914897 57.632081317359294, -1.5763916919416878 57.593876400001776, -1.58702264551911 57.58705102147636, -1.6127367551497698 57.57546427918638, -1.6293090606958565 57.57320898412036, -1.6462534776693738 57.57322476403093, -1.6793153934165583 57.575527414314244, -1.7613957871039314 57.583943640017424, -1.7778851767285884 57.58362341359304, -1.7943885140631364 57.58214314615699, -1.8269691252251694 57.5780205758784) | W24: 39 | X24: 2.2219206 | Y24: 59.578405 | Z24: -1.825319 | AA24: 57.578706 | AB24: =VLOOKUP(I24,facilities!$B:$Z,9,FALSE) -> NO_AE | AC24: =VLOOKUP(J24,facilities!$B:$Z,9,FALSE) -> UKM50
A25: 9 | B25: 40" Gas SLEIPNER R, ZEEPIPE-SCP | C25: 321002 | D25: Zeepipe I | E25: GASSLED | F25: Gassco AS | G25: IN SERVICE | H25: 1993-10-01 | I25: SLEIPNER R | J25: ZEEPIPE-SCP | K25: Transportation | L25: 40 | M25: 90 | N25: Gas | O25: 2252643 | P25: 277797 | Q25: 286533 | R25: 1944954 | S25: 2024-01-02 | T25: https://factpages.sodir.no/factpages/default.aspx?nav1=tuf&nav2=PageView|Pipeline|All&nav3=321002 | U25: https://factmaps.sodir.no/factmaps/3_0/?run=PipelineByNPDID&NPDID=321002 | V25: LINESTRING (1.9142427095681973 58.36433032603462, 1.9325662409974538 58.35484203840274, 1.9383805703393375 58.35107197459627, 1.9424888806748513 58.34671386773139, 1.9449812056533624 58.341085694095156, 1.970671140474452 58.13787262731023, 1.9752390931634245 58.11947801762247, 1.981700928385055 58.10478856646904, 2.245581814718489 57.69117015492063, 2.3658071271879457 57.499570779190925, 2.3741999473645032 57.485356374850504, 2.3795475900494063 57.47343301513901, 2.384748472606545 57.45569144648078, 2.386056818606071 57.448269198077185, 2.386807334780063 57.436431785715754, 2.3879938720058878 57.11073225022503, 2.3896694363859385 57.0980398223435, 2.392008889227447 57.08848351336151, 2.397247609430104 57.07424207430163, 2.4029292093403565 57.06321075401834, 2.409104777729052 57.05325747783625, 2.501740509576659 56.922617998708745, 2.6511859669155684 56.70921231406008, 2.8622844625760844 56.4037601905823, 3.173341099334298 56.154666255428225, 3.256047779649187 56.087728921156234, 3.27241276731688 56.0728065993516, 3.2829104822914283 56.06106731816471, 3.293914347963523 56.04566691669549, 3.3926842547100544 55.87605124048241, 3.4034303067295473 55.85522565140453, 3.407505830773987 55.84395231217095, 3.411067525083488 55.82772479693309, 3.412093027230579 55.81489936883415, 3.411451470212081 55.80250093593298, 3.3610944256035946 55.35804419000616, 3.298404019965438 54.78877631323162) | W25: 55 | X25: 1.9158664 | Y25: 58.364944 | Z25: 3.299816 | AA25: 54.789494 | AB25: =VLOOKUP(I25,facilities!$B:$Z,9,FALSE) -> NO_SR | AC25: =VLOOKUP(J25,facilities!$B:$Z,9,FALSE) -> BE_ZP
A26: 1 | B26: 40" Gas ZEEPIPE-SCP, ZEEBRUGGE | C26: 310326 | D26: Zeepipe I | E26: GASSLED | F26: Gassco AS | G26: IN SERVICE | H26: 1993-10-01 | I26: ZEEPIPE-SCP | J26: ZEEBRUGGE | K26: Transportation | L26: 40 | M26: 39.9 | N26: Gas | O26: 2252643 | P26: 286533 | Q26: 286281 | R26: 1944954 | S26: 2024-01-02 | T26: https://factpages.sodir.no/factpages/default.aspx?nav1=tuf&nav2=PageView|Pipeline|All&nav3=310326 | U26: https://factmaps.sodir.no/factmaps/3_0/?run=PipelineByNPDID&NPDID=310326 | V26: LINESTRING (3.298404019965438 54.78877631323162, 3.28085414095209 54.628432771002274, 3.209498703522583 54.17824208553879, 3.1353648208748073 53.69755557799866, 3.090372769814031 53.26262708949295, 3.09036527384928 53.24679858434184, 3.091426591254613 53.237629304027244, 3.0945071241043154 53.22320687943221, 3.1204078736011764 53.12453703463878, 3.1961029755918693 52.82767850072616, 3.204087151153907 52.795869589368316, 3.206159634617467 52.7818331710049, 3.206452062389697 52.768212745686036, 3.205333416984055 52.75586234445874, 3.1728838967025257 52.51931556371773, 3.1726122500297187 52.50749619169142, 3.1733405370255374 52.498628923231855, 3.1838063372182033 52.41448241952888, 3.1834988247411724 52.39812090696865, 3.1552000473017046 52.16870747677852, 3.151361374159261 52.15472400173724, 3.146761612184605 52.1431125915034, 3.1257142393792057 52.10544719266412, 3.120998458998452 52.0943407972862, 3.1176786902232076 52.083940439521804, 3.114874015501233 52.07077400252987, 3.0810803156475903 51.83035425008762, 3.020509736976767 51.63031447988052, 3.0175880503974843 51.61716104808776, 3.016710310459683 51.60747774461323, 3.0168295284413094 51.6000415205279, 3.0184939240700643 51.58769616508144, 3.024041556111355 51.57026869942282, 3.033214577303187 51.553133333998424, 3.0466623614122517 51.53659399699194, 3.0572999042959186 51.526149808606895, 3.216901291690337 51.39470273250931, 3.2326830466986243 51.3807805002686, 3.2358993117496877 51.374083339192644, 3.2359664645167823 51.36883318524507, 3.2284748483936863 51.34967653644988) | W26: 42 | X26: 3.299816 | Y26: 54.789494 | Z26: 3.229797 | AA26: 51.350508 | AB26: =VLOOKUP(I26,facilities!$B:$Z,9,FALSE) -> BE_ZP | AC26: =VLOOKUP(J26,facilities!$B:$Z,9,FALSE) -> BE251
